I0731 07:30:25.892608       1 cache.go:1581] "SnapShot for scheduling" jobNum=0 QueueNum=2 NodeNum=1
I0731 07:30:25.892658       1 session.go:1036] Start adjusting jobs' network topology spec according to hyperNodeTierNameMap map[]
I0731 07:30:25.892683       1 session.go:1079] Finish adjusting jobs' network topology spec according to hyperNodeTierNameMap map[]
I0731 07:30:25.892707       1 session.go:279] Open Session c20f36a7-4ba4-4427-b7a7-6aeaee8ce912 with <0> Job and <2> Queues. HyperNodesReadyToSchedule: true
I0731 07:30:25.893293       1 enqueue.go:79] Try to enqueue PodGroup to 0 Queues
I0731 07:30:25.893317       1 allocate.go:138] Try to allocate resource to 0 Queues
I0731 07:30:25.893390       1 session.go:577] Close Session c20f36a7-4ba4-4427-b7a7-6aeaee8ce912
I0731 07:30:26.894590       1 cache.go:1581] "SnapShot for scheduling" jobNum=0 QueueNum=2 NodeNum=1
I0731 07:30:26.894644       1 session.go:1036] Start adjusting jobs' network topology spec according to hyperNodeTierNameMap map[]
I0731 07:30:26.894671       1 session.go:1079] Finish adjusting jobs' network topology spec according to hyperNodeTierNameMap map[]
I0731 07:30:26.894697       1 session.go:279] Open Session 55fc5bc0-7d45-4692-8ce1-0dbbe4c9ed97 with <0> Job and <2> Queues. HyperNodesReadyToSchedule: true
I0731 07:30:26.895356       1 enqueue.go:79] Try to enqueue PodGroup to 0 Queues
I0731 07:30:26.895382       1 allocate.go:138] Try to allocate resource to 0 Queues
I0731 07:30:26.895479       1 session.go:577] Close Session 55fc5bc0-7d45-4692-8ce1-0dbbe4c9ed97
I0731 07:30:27.896530       1 cache.go:1581] "SnapShot for scheduling" jobNum=0 QueueNum=2 NodeNum=1
I0731 07:30:27.896597       1 session.go:1036] Start adjusting jobs' network topology spec according to hyperNodeTierNameMap map[]
I0731 07:30:27.896622       1 session.go:1079] Finish adjusting jobs' network topology spec according to hyperNodeTierNameMap map[]
I0731 07:30:27.896646       1 session.go:279] Open Session 0c98670c-5aa7-435b-a96a-6643f288e622 with <0> Job and <2> Queues. HyperNodesReadyToSchedule: true
I0731 07:30:27.897305       1 enqueue.go:79] Try to enqueue PodGroup to 0 Queues
I0731 07:30:27.897328       1 allocate.go:138] Try to allocate resource to 0 Queues
I0731 07:30:27.897410       1 session.go:577] Close Session 0c98670c-5aa7-435b-a96a-6643f288e622
I0731 07:30:28.898372       1 cache.go:1581] "SnapShot for scheduling" jobNum=0 QueueNum=2 NodeNum=1
I0731 07:30:28.898414       1 session.go:1036] Start adjusting jobs' network topology spec according to hyperNodeTierNameMap map[]
I0731 07:30:28.898440       1 session.go:1079] Finish adjusting jobs' network topology spec according to hyperNodeTierNameMap map[]
I0731 07:30:28.898465       1 session.go:279] Open Session cb25a94d-1e3f-4d0f-89ef-3c20768e4b3a with <0> Job and <2> Queues. HyperNodesReadyToSchedule: true
I0731 07:30:28.899031       1 enqueue.go:79] Try to enqueue PodGroup to 0 Queues
I0731 07:30:28.899054       1 allocate.go:138] Try to allocate resource to 0 Queues
I0731 07:30:28.899129       1 session.go:577] Close Session cb25a94d-1e3f-4d0f-89ef-3c20768e4b3a
I0731 07:30:29.902081       1 cache.go:1581] "SnapShot for scheduling" jobNum=0 QueueNum=2 NodeNum=1
I0731 07:30:29.902223       1 session.go:1036] Start adjusting jobs' network topology spec according to hyperNodeTierNameMap map[]
I0731 07:30:29.902256       1 session.go:1079] Finish adjusting jobs' network topology spec according to hyperNodeTierNameMap map[]
I0731 07:30:29.902284       1 session.go:279] Open Session c088b647-5188-4261-8093-b103ec68ecf6 with <0> Job and <2> Queues. HyperNodesReadyToSchedule: true
I0731 07:30:29.903450       1 enqueue.go:79] Try to enqueue PodGroup to 0 Queues
I0731 07:30:29.903481       1 allocate.go:138] Try to allocate resource to 0 Queues
I0731 07:30:29.903721       1 session.go:577] Close Session c088b647-5188-4261-8093-b103ec68ecf6
I0731 07:30:30.904917       1 cache.go:1581] "SnapShot for scheduling" jobNum=0 QueueNum=2 NodeNum=1
I0731 07:30:30.904967       1 session.go:1036] Start adjusting jobs' network topology spec according to hyperNodeTierNameMap map[]
I0731 07:30:30.904994       1 session.go:1079] Finish adjusting jobs' network topology spec according to hyperNodeTierNameMap map[]
I0731 07:30:30.905018       1 session.go:279] Open Session 2cd49f4e-44d0-4094-bab4-efd0658297eb with <0> Job and <2> Queues. HyperNodesReadyToSchedule: true
I0731 07:30:30.905504       1 enqueue.go:79] Try to enqueue PodGroup to 0 Queues
I0731 07:30:30.905525       1 allocate.go:138] Try to allocate resource to 0 Queues
I0731 07:30:30.905599       1 session.go:577] Close Session 2cd49f4e-44d0-4094-bab4-efd0658297eb
I0731 07:30:31.906637       1 cache.go:1581] "SnapShot for scheduling" jobNum=0 QueueNum=2 NodeNum=1
I0731 07:30:31.906667       1 session.go:1036] Start adjusting jobs' network topology spec according to hyperNodeTierNameMap map[]
I0731 07:30:31.906685       1 session.go:1079] Finish adjusting jobs' network topology spec according to hyperNodeTierNameMap map[]
I0731 07:30:31.906708       1 session.go:279] Open Session 9954d3a9-0dc6-421a-b29c-dd3caf2a3462 with <0> Job and <2> Queues. HyperNodesReadyToSchedule: true
I0731 07:30:31.907099       1 enqueue.go:79] Try to enqueue PodGroup to 0 Queues
I0731 07:30:31.907119       1 allocate.go:138] Try to allocate resource to 0 Queues
I0731 07:30:31.907173       1 session.go:577] Close Session 9954d3a9-0dc6-421a-b29c-dd3caf2a3462
I0731 07:30:32.907701       1 cache.go:1581] "SnapShot for scheduling" jobNum=0 QueueNum=2 NodeNum=1
I0731 07:30:32.907744       1 session.go:1036] Start adjusting jobs' network topology spec according to hyperNodeTierNameMap map[]
I0731 07:30:32.907768       1 session.go:1079] Finish adjusting jobs' network topology spec according to hyperNodeTierNameMap map[]
I0731 07:30:32.907793       1 session.go:279] Open Session 25c52b5b-023a-4b3f-90f6-9a0f7fca9d32 with <0> Job and <2> Queues. HyperNodesReadyToSchedule: true
I0731 07:30:32.908323       1 enqueue.go:79] Try to enqueue PodGroup to 0 Queues
I0731 07:30:32.908346       1 allocate.go:138] Try to allocate resource to 0 Queues
I0731 07:30:32.908424       1 session.go:577] Close Session 25c52b5b-023a-4b3f-90f6-9a0f7fca9d32
I0731 07:30:33.909495       1 cache.go:1581] "SnapShot for scheduling" jobNum=0 QueueNum=2 NodeNum=1
I0731 07:30:33.909539       1 session.go:1036] Start adjusting jobs' network topology spec according to hyperNodeTierNameMap map[]
I0731 07:30:33.909563       1 session.go:1079] Finish adjusting jobs' network topology spec according to hyperNodeTierNameMap map[]
I0731 07:30:33.909587       1 session.go:279] Open Session df8a5075-1897-4d47-8b6c-c084972fe3b0 with <0> Job and <2> Queues. HyperNodesReadyToSchedule: true
I0731 07:30:33.910112       1 enqueue.go:79] Try to enqueue PodGroup to 0 Queues
I0731 07:30:33.910134       1 allocate.go:138] Try to allocate resource to 0 Queues
I0731 07:30:33.910204       1 session.go:577] Close Session df8a5075-1897-4d47-8b6c-c084972fe3b0
I0731 07:30:34.911045       1 cache.go:1581] "SnapShot for scheduling" jobNum=0 QueueNum=2 NodeNum=1
I0731 07:30:34.911095       1 session.go:1036] Start adjusting jobs' network topology spec according to hyperNodeTierNameMap map[]
I0731 07:30:34.911119       1 session.go:1079] Finish adjusting jobs' network topology spec according to hyperNodeTierNameMap map[]
I0731 07:30:34.911143       1 session.go:279] Open Session 91dac250-ef17-45db-8bfb-160ed5672417 with <0> Job and <2> Queues. HyperNodesReadyToSchedule: true
I0731 07:30:34.911666       1 enqueue.go:79] Try to enqueue PodGroup to 0 Queues
I0731 07:30:34.911689       1 allocate.go:138] Try to allocate resource to 0 Queues
I0731 07:30:34.911758       1 session.go:577] Close Session 91dac250-ef17-45db-8bfb-160ed5672417
I0731 07:30:35.912739       1 cache.go:1581] "SnapShot for scheduling" jobNum=0 QueueNum=2 NodeNum=1
I0731 07:30:35.912770       1 session.go:1036] Start adjusting jobs' network topology spec according to hyperNodeTierNameMap map[]
I0731 07:30:35.912789       1 session.go:1079] Finish adjusting jobs' network topology spec according to hyperNodeTierNameMap map[]
I0731 07:30:35.912810       1 session.go:279] Open Session 0a14790f-5a7b-4dd3-a85b-fe6ac2f3e2ba with <0> Job and <2> Queues. HyperNodesReadyToSchedule: true
I0731 07:30:35.913173       1 enqueue.go:79] Try to enqueue PodGroup to 0 Queues
I0731 07:30:35.913193       1 allocate.go:138] Try to allocate resource to 0 Queues
I0731 07:30:35.913249       1 session.go:577] Close Session 0a14790f-5a7b-4dd3-a85b-fe6ac2f3e2ba
I0731 07:30:36.914452       1 cache.go:1581] "SnapShot for scheduling" jobNum=0 QueueNum=2 NodeNum=1
I0731 07:30:36.914500       1 session.go:1036] Start adjusting jobs' network topology spec according to hyperNodeTierNameMap map[]
I0731 07:30:36.914526       1 session.go:1079] Finish adjusting jobs' network topology spec according to hyperNodeTierNameMap map[]
I0731 07:30:36.914551       1 session.go:279] Open Session 2646c49c-d0cf-4291-b7a0-5a93bd848886 with <0> Job and <2> Queues. HyperNodesReadyToSchedule: true
I0731 07:30:36.915057       1 enqueue.go:79] Try to enqueue PodGroup to 0 Queues
I0731 07:30:36.915080       1 allocate.go:138] Try to allocate resource to 0 Queues
I0731 07:30:36.915154       1 session.go:577] Close Session 2646c49c-d0cf-4291-b7a0-5a93bd848886
I0731 07:30:37.916601       1 cache.go:1581] "SnapShot for scheduling" jobNum=0 QueueNum=2 NodeNum=1
I0731 07:30:37.916645       1 session.go:1036] Start adjusting jobs' network topology spec according to hyperNodeTierNameMap map[]
I0731 07:30:37.916673       1 session.go:1079] Finish adjusting jobs' network topology spec according to hyperNodeTierNameMap map[]
I0731 07:30:37.916696       1 session.go:279] Open Session bef781a4-8fe2-4f0d-8b59-09ebdf2bcf85 with <0> Job and <2> Queues. HyperNodesReadyToSchedule: true
I0731 07:30:37.917239       1 enqueue.go:79] Try to enqueue PodGroup to 0 Queues
I0731 07:30:37.917263       1 allocate.go:138] Try to allocate resource to 0 Queues
I0731 07:30:37.917334       1 session.go:577] Close Session bef781a4-8fe2-4f0d-8b59-09ebdf2bcf85
I0731 07:30:38.917867       1 cache.go:1581] "SnapShot for scheduling" jobNum=0 QueueNum=2 NodeNum=1
I0731 07:30:38.917920       1 session.go:1036] Start adjusting jobs' network topology spec according to hyperNodeTierNameMap map[]
I0731 07:30:38.917946       1 session.go:1079] Finish adjusting jobs' network topology spec according to hyperNodeTierNameMap map[]
I0731 07:30:38.917970       1 session.go:279] Open Session 6fe2bf86-d109-439f-9666-bbad41da249f with <0> Job and <2> Queues. HyperNodesReadyToSchedule: true
I0731 07:30:38.918581       1 enqueue.go:79] Try to enqueue PodGroup to 0 Queues
I0731 07:30:38.918607       1 allocate.go:138] Try to allocate resource to 0 Queues
I0731 07:30:38.918690       1 session.go:577] Close Session 6fe2bf86-d109-439f-9666-bbad41da249f
I0731 07:30:39.920117       1 cache.go:1581] "SnapShot for scheduling" jobNum=0 QueueNum=2 NodeNum=1
I0731 07:30:39.920204       1 session.go:1036] Start adjusting jobs' network topology spec according to hyperNodeTierNameMap map[]
I0731 07:30:39.920233       1 session.go:1079] Finish adjusting jobs' network topology spec according to hyperNodeTierNameMap map[]
I0731 07:30:39.920258       1 session.go:279] Open Session 850b46e8-ac6e-4bab-866f-bcab83792c01 with <0> Job and <2> Queues. HyperNodesReadyToSchedule: true
I0731 07:30:39.920860       1 enqueue.go:79] Try to enqueue PodGroup to 0 Queues
I0731 07:30:39.920885       1 allocate.go:138] Try to allocate resource to 0 Queues
I0731 07:30:39.920982       1 session.go:577] Close Session 850b46e8-ac6e-4bab-866f-bcab83792c01
I0731 07:30:40.922223       1 cache.go:1581] "SnapShot for scheduling" jobNum=0 QueueNum=2 NodeNum=1
I0731 07:30:40.922273       1 session.go:1036] Start adjusting jobs' network topology spec according to hyperNodeTierNameMap map[]
I0731 07:30:40.922299       1 session.go:1079] Finish adjusting jobs' network topology spec according to hyperNodeTierNameMap map[]
I0731 07:30:40.922326       1 session.go:279] Open Session c7d81f4e-1d7e-4c38-88a7-045fd608c9c8 with <0> Job and <2> Queues. HyperNodesReadyToSchedule: true
I0731 07:30:40.922818       1 enqueue.go:79] Try to enqueue PodGroup to 0 Queues
I0731 07:30:40.922841       1 allocate.go:138] Try to allocate resource to 0 Queues
I0731 07:30:40.922919       1 session.go:577] Close Session c7d81f4e-1d7e-4c38-88a7-045fd608c9c8
I0731 07:30:41.924297       1 cache.go:1581] "SnapShot for scheduling" jobNum=0 QueueNum=2 NodeNum=1
I0731 07:30:41.924331       1 session.go:1036] Start adjusting jobs' network topology spec according to hyperNodeTierNameMap map[]
I0731 07:30:41.924351       1 session.go:1079] Finish adjusting jobs' network topology spec according to hyperNodeTierNameMap map[]
I0731 07:30:41.924374       1 session.go:279] Open Session 76198414-d2d9-49b2-8ddd-e10b9a3559cf with <0> Job and <2> Queues. HyperNodesReadyToSchedule: true
I0731 07:30:41.924778       1 enqueue.go:79] Try to enqueue PodGroup to 0 Queues
I0731 07:30:41.924798       1 allocate.go:138] Try to allocate resource to 0 Queues
I0731 07:30:41.924851       1 session.go:577] Close Session 76198414-d2d9-49b2-8ddd-e10b9a3559cf
I0731 07:30:42.926288       1 cache.go:1581] "SnapShot for scheduling" jobNum=0 QueueNum=2 NodeNum=1
I0731 07:30:42.926336       1 session.go:1036] Start adjusting jobs' network topology spec according to hyperNodeTierNameMap map[]
I0731 07:30:42.926362       1 session.go:1079] Finish adjusting jobs' network topology spec according to hyperNodeTierNameMap map[]
I0731 07:30:42.926388       1 session.go:279] Open Session 391ef0be-1701-4a61-abe0-f50d68649319 with <0> Job and <2> Queues. HyperNodesReadyToSchedule: true
I0731 07:30:42.926912       1 enqueue.go:79] Try to enqueue PodGroup to 0 Queues
I0731 07:30:42.926936       1 allocate.go:138] Try to allocate resource to 0 Queues
I0731 07:30:42.927021       1 session.go:577] Close Session 391ef0be-1701-4a61-abe0-f50d68649319
I0731 07:30:43.928044       1 cache.go:1581] "SnapShot for scheduling" jobNum=0 QueueNum=2 NodeNum=1
I0731 07:30:43.928096       1 session.go:1036] Start adjusting jobs' network topology spec according to hyperNodeTierNameMap map[]
I0731 07:30:43.928122       1 session.go:1079] Finish adjusting jobs' network topology spec according to hyperNodeTierNameMap map[]
I0731 07:30:43.928147       1 session.go:279] Open Session bdfe53da-d4b6-45c6-b039-c656f03177eb with <0> Job and <2> Queues. HyperNodesReadyToSchedule: true
I0731 07:30:43.928639       1 enqueue.go:79] Try to enqueue PodGroup to 0 Queues
I0731 07:30:43.928666       1 allocate.go:138] Try to allocate resource to 0 Queues
I0731 07:30:43.928751       1 session.go:577] Close Session bdfe53da-d4b6-45c6-b039-c656f03177eb
I0731 07:30:44.929882       1 cache.go:1581] "SnapShot for scheduling" jobNum=0 QueueNum=2 NodeNum=1
I0731 07:30:44.929926       1 session.go:1036] Start adjusting jobs' network topology spec according to hyperNodeTierNameMap map[]
I0731 07:30:44.929950       1 session.go:1079] Finish adjusting jobs' network topology spec according to hyperNodeTierNameMap map[]
I0731 07:30:44.929975       1 session.go:279] Open Session 51d13bc1-3d8a-4eb0-95a9-08dbe8d262fb with <0> Job and <2> Queues. HyperNodesReadyToSchedule: true
I0731 07:30:44.930486       1 enqueue.go:79] Try to enqueue PodGroup to 0 Queues
I0731 07:30:44.930511       1 allocate.go:138] Try to allocate resource to 0 Queues
I0731 07:30:44.930594       1 session.go:577] Close Session 51d13bc1-3d8a-4eb0-95a9-08dbe8d262fb
I0731 07:30:45.931021       1 cache.go:1581] "SnapShot for scheduling" jobNum=0 QueueNum=2 NodeNum=1
I0731 07:30:45.931049       1 session.go:1036] Start adjusting jobs' network topology spec according to hyperNodeTierNameMap map[]
I0731 07:30:45.931065       1 session.go:1079] Finish adjusting jobs' network topology spec according to hyperNodeTierNameMap map[]
I0731 07:30:45.931086       1 session.go:279] Open Session 259f45c8-3eaa-45cd-b76b-13ee2707c062 with <0> Job and <2> Queues. HyperNodesReadyToSchedule: true
I0731 07:30:45.931441       1 enqueue.go:79] Try to enqueue PodGroup to 0 Queues
I0731 07:30:45.931460       1 allocate.go:138] Try to allocate resource to 0 Queues
I0731 07:30:45.931510       1 session.go:577] Close Session 259f45c8-3eaa-45cd-b76b-13ee2707c062
I0731 07:30:46.481416       1 cache.go:1771] The metrics type is not set in the volcano scheduler configmap file. As a result, the CPU and memory load information of the node is not collected.
I0731 07:30:46.932345       1 cache.go:1581] "SnapShot for scheduling" jobNum=0 QueueNum=2 NodeNum=1
I0731 07:30:46.932387       1 session.go:1036] Start adjusting jobs' network topology spec according to hyperNodeTierNameMap map[]
I0731 07:30:46.932410       1 session.go:1079] Finish adjusting jobs' network topology spec according to hyperNodeTierNameMap map[]
I0731 07:30:46.932433       1 session.go:279] Open Session 883cdf61-2c68-49d7-bdcd-c0c7132ce7ef with <0> Job and <2> Queues. HyperNodesReadyToSchedule: true
I0731 07:30:46.932884       1 enqueue.go:79] Try to enqueue PodGroup to 0 Queues
I0731 07:30:46.932908       1 allocate.go:138] Try to allocate resource to 0 Queues
I0731 07:30:46.932980       1 session.go:577] Close Session 883cdf61-2c68-49d7-bdcd-c0c7132ce7ef
I0731 07:30:47.934223       1 cache.go:1581] "SnapShot for scheduling" jobNum=0 QueueNum=2 NodeNum=1
I0731 07:30:47.934262       1 session.go:1036] Start adjusting jobs' network topology spec according to hyperNodeTierNameMap map[]
I0731 07:30:47.934285       1 session.go:1079] Finish adjusting jobs' network topology spec according to hyperNodeTierNameMap map[]
I0731 07:30:47.934311       1 session.go:279] Open Session b998d7a8-8b40-4357-8abe-8dca083212fe with <0> Job and <2> Queues. HyperNodesReadyToSchedule: true
I0731 07:30:47.934751       1 enqueue.go:79] Try to enqueue PodGroup to 0 Queues
I0731 07:30:47.934773       1 allocate.go:138] Try to allocate resource to 0 Queues
I0731 07:30:47.934848       1 session.go:577] Close Session b998d7a8-8b40-4357-8abe-8dca083212fe
I0731 07:30:48.935926       1 cache.go:1581] "SnapShot for scheduling" jobNum=0 QueueNum=2 NodeNum=1
I0731 07:30:48.935959       1 session.go:1036] Start adjusting jobs' network topology spec according to hyperNodeTierNameMap map[]
I0731 07:30:48.935975       1 session.go:1079] Finish adjusting jobs' network topology spec according to hyperNodeTierNameMap map[]
I0731 07:30:48.935995       1 session.go:279] Open Session 1ec1b02b-a8c2-42c0-ad99-48b1c96c2512 with <0> Job and <2> Queues. HyperNodesReadyToSchedule: true
I0731 07:30:48.936327       1 enqueue.go:79] Try to enqueue PodGroup to 0 Queues
I0731 07:30:48.936344       1 allocate.go:138] Try to allocate resource to 0 Queues
I0731 07:30:48.936390       1 session.go:577] Close Session 1ec1b02b-a8c2-42c0-ad99-48b1c96c2512
I0731 07:30:49.937653       1 cache.go:1581] "SnapShot for scheduling" jobNum=0 QueueNum=2 NodeNum=1
I0731 07:30:49.937698       1 session.go:1036] Start adjusting jobs' network topology spec according to hyperNodeTierNameMap map[]
I0731 07:30:49.937723       1 session.go:1079] Finish adjusting jobs' network topology spec according to hyperNodeTierNameMap map[]
I0731 07:30:49.937747       1 session.go:279] Open Session d64408bb-8300-4548-8c05-895c5eb2fabe with <0> Job and <2> Queues. HyperNodesReadyToSchedule: true
I0731 07:30:49.938195       1 enqueue.go:79] Try to enqueue PodGroup to 0 Queues
I0731 07:30:49.938219       1 allocate.go:138] Try to allocate resource to 0 Queues
I0731 07:30:49.938293       1 session.go:577] Close Session d64408bb-8300-4548-8c05-895c5eb2fabe
I0731 07:30:50.939274       1 cache.go:1581] "SnapShot for scheduling" jobNum=0 QueueNum=2 NodeNum=1
I0731 07:30:50.939317       1 session.go:1036] Start adjusting jobs' network topology spec according to hyperNodeTierNameMap map[]
I0731 07:30:50.939341       1 session.go:1079] Finish adjusting jobs' network topology spec according to hyperNodeTierNameMap map[]
I0731 07:30:50.939365       1 session.go:279] Open Session 4097d005-0db3-4eb2-86f3-3089f89fe7fb with <0> Job and <2> Queues. HyperNodesReadyToSchedule: true
I0731 07:30:50.939864       1 enqueue.go:79] Try to enqueue PodGroup to 0 Queues
I0731 07:30:50.939887       1 allocate.go:138] Try to allocate resource to 0 Queues
I0731 07:30:50.939957       1 session.go:577] Close Session 4097d005-0db3-4eb2-86f3-3089f89fe7fb
I0731 07:30:51.941388       1 cache.go:1581] "SnapShot for scheduling" jobNum=0 QueueNum=2 NodeNum=1
I0731 07:30:51.941445       1 session.go:1036] Start adjusting jobs' network topology spec according to hyperNodeTierNameMap map[]
I0731 07:30:51.941472       1 session.go:1079] Finish adjusting jobs' network topology spec according to hyperNodeTierNameMap map[]
I0731 07:30:51.941497       1 session.go:279] Open Session 8036d8c4-54d5-47a5-b285-c8f4cc13b7e3 with <0> Job and <2> Queues. HyperNodesReadyToSchedule: true
I0731 07:30:51.942065       1 enqueue.go:79] Try to enqueue PodGroup to 0 Queues
I0731 07:30:51.942090       1 allocate.go:138] Try to allocate resource to 0 Queues
I0731 07:30:51.942177       1 session.go:577] Close Session 8036d8c4-54d5-47a5-b285-c8f4cc13b7e3
I0731 07:30:52.943102       1 cache.go:1581] "SnapShot for scheduling" jobNum=0 QueueNum=2 NodeNum=1
I0731 07:30:52.943160       1 session.go:1036] Start adjusting jobs' network topology spec according to hyperNodeTierNameMap map[]
I0731 07:30:52.943188       1 session.go:1079] Finish adjusting jobs' network topology spec according to hyperNodeTierNameMap map[]
I0731 07:30:52.943216       1 session.go:279] Open Session 42c2c477-4b36-49f5-8f79-b9f503f78978 with <0> Job and <2> Queues. HyperNodesReadyToSchedule: true
I0731 07:30:52.943738       1 enqueue.go:79] Try to enqueue PodGroup to 0 Queues
I0731 07:30:52.943764       1 allocate.go:138] Try to allocate resource to 0 Queues
I0731 07:30:52.943848       1 session.go:577] Close Session 42c2c477-4b36-49f5-8f79-b9f503f78978
I0731 07:30:53.944906       1 cache.go:1581] "SnapShot for scheduling" jobNum=0 QueueNum=2 NodeNum=1
I0731 07:30:53.944948       1 session.go:1036] Start adjusting jobs' network topology spec according to hyperNodeTierNameMap map[]
I0731 07:30:53.944972       1 session.go:1079] Finish adjusting jobs' network topology spec according to hyperNodeTierNameMap map[]
I0731 07:30:53.944997       1 session.go:279] Open Session d039c163-98a6-4962-a379-e138129f80c2 with <0> Job and <2> Queues. HyperNodesReadyToSchedule: true
I0731 07:30:53.945446       1 enqueue.go:79] Try to enqueue PodGroup to 0 Queues
I0731 07:30:53.945469       1 allocate.go:138] Try to allocate resource to 0 Queues
I0731 07:30:53.945552       1 session.go:577] Close Session d039c163-98a6-4962-a379-e138129f80c2
I0731 07:30:54.946588       1 cache.go:1581] "SnapShot for scheduling" jobNum=0 QueueNum=2 NodeNum=1
I0731 07:30:54.946641       1 session.go:1036] Start adjusting jobs' network topology spec according to hyperNodeTierNameMap map[]
I0731 07:30:54.946665       1 session.go:1079] Finish adjusting jobs' network topology spec according to hyperNodeTierNameMap map[]
I0731 07:30:54.946689       1 session.go:279] Open Session 3e3b5f4d-5723-46f3-956f-7cc337a93dce with <0> Job and <2> Queues. HyperNodesReadyToSchedule: true
I0731 07:30:54.947178       1 enqueue.go:79] Try to enqueue PodGroup to 0 Queues
I0731 07:30:54.947203       1 allocate.go:138] Try to allocate resource to 0 Queues
I0731 07:30:54.947288       1 session.go:577] Close Session 3e3b5f4d-5723-46f3-956f-7cc337a93dce
I0731 07:30:55.947919       1 cache.go:1581] "SnapShot for scheduling" jobNum=0 QueueNum=2 NodeNum=1
I0731 07:30:55.947971       1 session.go:1036] Start adjusting jobs' network topology spec according to hyperNodeTierNameMap map[]
I0731 07:30:55.947996       1 session.go:1079] Finish adjusting jobs' network topology spec according to hyperNodeTierNameMap map[]
I0731 07:30:55.948021       1 session.go:279] Open Session 1018d23f-c09a-4871-aa61-92103926550a with <0> Job and <2> Queues. HyperNodesReadyToSchedule: true
I0731 07:30:55.948482       1 enqueue.go:79] Try to enqueue PodGroup to 0 Queues
I0731 07:30:55.948505       1 allocate.go:138] Try to allocate resource to 0 Queues
I0731 07:30:55.948583       1 session.go:577] Close Session 1018d23f-c09a-4871-aa61-92103926550a
I0731 07:30:56.949303       1 cache.go:1581] "SnapShot for scheduling" jobNum=0 QueueNum=2 NodeNum=1
I0731 07:30:56.949351       1 session.go:1036] Start adjusting jobs' network topology spec according to hyperNodeTierNameMap map[]
I0731 07:30:56.949375       1 session.go:1079] Finish adjusting jobs' network topology spec according to hyperNodeTierNameMap map[]
I0731 07:30:56.949399       1 session.go:279] Open Session 8b36a28b-11cd-4e1e-b5b7-00b5f5158416 with <0> Job and <2> Queues. HyperNodesReadyToSchedule: true
I0731 07:30:56.949869       1 enqueue.go:79] Try to enqueue PodGroup to 0 Queues
I0731 07:30:56.949891       1 allocate.go:138] Try to allocate resource to 0 Queues
I0731 07:30:56.949966       1 session.go:577] Close Session 8b36a28b-11cd-4e1e-b5b7-00b5f5158416
I0731 07:30:57.950490       1 cache.go:1581] "SnapShot for scheduling" jobNum=0 QueueNum=2 NodeNum=1
I0731 07:30:57.950521       1 session.go:1036] Start adjusting jobs' network topology spec according to hyperNodeTierNameMap map[]
I0731 07:30:57.950541       1 session.go:1079] Finish adjusting jobs' network topology spec according to hyperNodeTierNameMap map[]
I0731 07:30:57.950563       1 session.go:279] Open Session 3f275565-556c-4389-8329-3c4b77cf0a75 with <0> Job and <2> Queues. HyperNodesReadyToSchedule: true
I0731 07:30:57.950968       1 enqueue.go:79] Try to enqueue PodGroup to 0 Queues
I0731 07:30:57.950986       1 allocate.go:138] Try to allocate resource to 0 Queues
I0731 07:30:57.951038       1 session.go:577] Close Session 3f275565-556c-4389-8329-3c4b77cf0a75
I0731 07:30:58.952445       1 cache.go:1581] "SnapShot for scheduling" jobNum=0 QueueNum=2 NodeNum=1
I0731 07:30:58.952495       1 session.go:1036] Start adjusting jobs' network topology spec according to hyperNodeTierNameMap map[]
I0731 07:30:58.952519       1 session.go:1079] Finish adjusting jobs' network topology spec according to hyperNodeTierNameMap map[]
I0731 07:30:58.952543       1 session.go:279] Open Session 7088bf58-26af-4243-b278-7bb53622b19f with <0> Job and <2> Queues. HyperNodesReadyToSchedule: true
I0731 07:30:58.952992       1 enqueue.go:79] Try to enqueue PodGroup to 0 Queues
I0731 07:30:58.953015       1 allocate.go:138] Try to allocate resource to 0 Queues
I0731 07:30:58.953096       1 session.go:577] Close Session 7088bf58-26af-4243-b278-7bb53622b19f
I0731 07:30:59.954237       1 cache.go:1581] "SnapShot for scheduling" jobNum=0 QueueNum=2 NodeNum=1
I0731 07:30:59.954287       1 session.go:1036] Start adjusting jobs' network topology spec according to hyperNodeTierNameMap map[]
I0731 07:30:59.954313       1 session.go:1079] Finish adjusting jobs' network topology spec according to hyperNodeTierNameMap map[]
I0731 07:30:59.954338       1 session.go:279] Open Session 3eef3e89-40db-4d07-ac8a-d1a4ee737a64 with <0> Job and <2> Queues. HyperNodesReadyToSchedule: true
I0731 07:30:59.954819       1 enqueue.go:79] Try to enqueue PodGroup to 0 Queues
I0731 07:30:59.954845       1 allocate.go:138] Try to allocate resource to 0 Queues
I0731 07:30:59.954927       1 session.go:577] Close Session 3eef3e89-40db-4d07-ac8a-d1a4ee737a64
I0731 07:31:00.955909       1 cache.go:1581] "SnapShot for scheduling" jobNum=0 QueueNum=2 NodeNum=1
I0731 07:31:00.955948       1 session.go:1036] Start adjusting jobs' network topology spec according to hyperNodeTierNameMap map[]
I0731 07:31:00.955969       1 session.go:1079] Finish adjusting jobs' network topology spec according to hyperNodeTierNameMap map[]
I0731 07:31:00.955992       1 session.go:279] Open Session f9194932-ac66-4389-8c97-d668e2efa621 with <0> Job and <2> Queues. HyperNodesReadyToSchedule: true
I0731 07:31:00.956455       1 enqueue.go:79] Try to enqueue PodGroup to 0 Queues
I0731 07:31:00.956476       1 allocate.go:138] Try to allocate resource to 0 Queues
I0731 07:31:00.956539       1 session.go:577] Close Session f9194932-ac66-4389-8c97-d668e2efa621
I0731 07:31:01.957014       1 cache.go:1581] "SnapShot for scheduling" jobNum=0 QueueNum=2 NodeNum=1
I0731 07:31:01.957064       1 session.go:1036] Start adjusting jobs' network topology spec according to hyperNodeTierNameMap map[]
I0731 07:31:01.957089       1 session.go:1079] Finish adjusting jobs' network topology spec according to hyperNodeTierNameMap map[]
I0731 07:31:01.957115       1 session.go:279] Open Session 7f667574-f25f-46d4-a294-6b232c237510 with <0> Job and <2> Queues. HyperNodesReadyToSchedule: true
I0731 07:31:01.957581       1 enqueue.go:79] Try to enqueue PodGroup to 0 Queues
I0731 07:31:01.957604       1 allocate.go:138] Try to allocate resource to 0 Queues
I0731 07:31:01.957681       1 session.go:577] Close Session 7f667574-f25f-46d4-a294-6b232c237510
I0731 07:31:02.957954       1 cache.go:1581] "SnapShot for scheduling" jobNum=0 QueueNum=2 NodeNum=1
I0731 07:31:02.957990       1 session.go:1036] Start adjusting jobs' network topology spec according to hyperNodeTierNameMap map[]
I0731 07:31:02.958010       1 session.go:1079] Finish adjusting jobs' network topology spec according to hyperNodeTierNameMap map[]
I0731 07:31:02.958033       1 session.go:279] Open Session f9db4a29-6146-4e77-ba3f-3ad898a23c4f with <0> Job and <2> Queues. HyperNodesReadyToSchedule: true
I0731 07:31:02.958408       1 enqueue.go:79] Try to enqueue PodGroup to 0 Queues
I0731 07:31:02.958428       1 allocate.go:138] Try to allocate resource to 0 Queues
I0731 07:31:02.958489       1 session.go:577] Close Session f9db4a29-6146-4e77-ba3f-3ad898a23c4f
I0731 07:31:03.959121       1 cache.go:1581] "SnapShot for scheduling" jobNum=0 QueueNum=2 NodeNum=1
I0731 07:31:03.959175       1 session.go:1036] Start adjusting jobs' network topology spec according to hyperNodeTierNameMap map[]
I0731 07:31:03.959200       1 session.go:1079] Finish adjusting jobs' network topology spec according to hyperNodeTierNameMap map[]
I0731 07:31:03.959228       1 session.go:279] Open Session 83628d57-91d6-475c-b329-8ae76b6e7c4a with <0> Job and <2> Queues. HyperNodesReadyToSchedule: true
I0731 07:31:03.959673       1 enqueue.go:79] Try to enqueue PodGroup to 0 Queues
I0731 07:31:03.959695       1 allocate.go:138] Try to allocate resource to 0 Queues
I0731 07:31:03.959769       1 session.go:577] Close Session 83628d57-91d6-475c-b329-8ae76b6e7c4a
I0731 07:31:04.961119       1 cache.go:1581] "SnapShot for scheduling" jobNum=0 QueueNum=2 NodeNum=1
I0731 07:31:04.961168       1 session.go:1036] Start adjusting jobs' network topology spec according to hyperNodeTierNameMap map[]
I0731 07:31:04.961193       1 session.go:1079] Finish adjusting jobs' network topology spec according to hyperNodeTierNameMap map[]
I0731 07:31:04.961218       1 session.go:279] Open Session 9329f3a4-648c-44de-8e43-ae08a5fbbe9c with <0> Job and <2> Queues. HyperNodesReadyToSchedule: true
I0731 07:31:04.961661       1 enqueue.go:79] Try to enqueue PodGroup to 0 Queues
I0731 07:31:04.961684       1 allocate.go:138] Try to allocate resource to 0 Queues
I0731 07:31:04.961760       1 session.go:577] Close Session 9329f3a4-648c-44de-8e43-ae08a5fbbe9c
I0731 07:31:05.963010       1 cache.go:1581] "SnapShot for scheduling" jobNum=0 QueueNum=2 NodeNum=1
I0731 07:31:05.963052       1 session.go:1036] Start adjusting jobs' network topology spec according to hyperNodeTierNameMap map[]
I0731 07:31:05.963077       1 session.go:1079] Finish adjusting jobs' network topology spec according to hyperNodeTierNameMap map[]
I0731 07:31:05.963102       1 session.go:279] Open Session ad98700f-0270-4b2e-9a85-45b430e59233 with <0> Job and <2> Queues. HyperNodesReadyToSchedule: true
I0731 07:31:05.963536       1 enqueue.go:79] Try to enqueue PodGroup to 0 Queues
I0731 07:31:05.963558       1 allocate.go:138] Try to allocate resource to 0 Queues
I0731 07:31:05.963628       1 session.go:577] Close Session ad98700f-0270-4b2e-9a85-45b430e59233
I0731 07:31:06.964159       1 cache.go:1581] "SnapShot for scheduling" jobNum=0 QueueNum=2 NodeNum=1
I0731 07:31:06.964212       1 session.go:1036] Start adjusting jobs' network topology spec according to hyperNodeTierNameMap map[]
I0731 07:31:06.964235       1 session.go:1079] Finish adjusting jobs' network topology spec according to hyperNodeTierNameMap map[]
I0731 07:31:06.964258       1 session.go:279] Open Session 35a5f4c5-f4e9-4304-bf54-b36fe7967b86 with <0> Job and <2> Queues. HyperNodesReadyToSchedule: true
I0731 07:31:06.964710       1 enqueue.go:79] Try to enqueue PodGroup to 0 Queues
I0731 07:31:06.964733       1 allocate.go:138] Try to allocate resource to 0 Queues
I0731 07:31:06.964811       1 session.go:577] Close Session 35a5f4c5-f4e9-4304-bf54-b36fe7967b86
I0731 07:31:07.966057       1 cache.go:1581] "SnapShot for scheduling" jobNum=0 QueueNum=2 NodeNum=1
I0731 07:31:07.966101       1 session.go:1036] Start adjusting jobs' network topology spec according to hyperNodeTierNameMap map[]
I0731 07:31:07.966125       1 session.go:1079] Finish adjusting jobs' network topology spec according to hyperNodeTierNameMap map[]
I0731 07:31:07.966150       1 session.go:279] Open Session 4ae194a7-21f8-454b-9c60-eadc3fa7b486 with <0> Job and <2> Queues. HyperNodesReadyToSchedule: true
I0731 07:31:07.966638       1 enqueue.go:79] Try to enqueue PodGroup to 0 Queues
I0731 07:31:07.966661       1 allocate.go:138] Try to allocate resource to 0 Queues
I0731 07:31:07.966764       1 session.go:577] Close Session 4ae194a7-21f8-454b-9c60-eadc3fa7b486
I0731 07:31:08.968058       1 cache.go:1581] "SnapShot for scheduling" jobNum=0 QueueNum=2 NodeNum=1
I0731 07:31:08.968101       1 session.go:1036] Start adjusting jobs' network topology spec according to hyperNodeTierNameMap map[]
I0731 07:31:08.968127       1 session.go:1079] Finish adjusting jobs' network topology spec according to hyperNodeTierNameMap map[]
I0731 07:31:08.968151       1 session.go:279] Open Session 268dcd6e-863a-4fe9-acd7-671c11f00c8a with <0> Job and <2> Queues. HyperNodesReadyToSchedule: true
I0731 07:31:08.968639       1 enqueue.go:79] Try to enqueue PodGroup to 0 Queues
I0731 07:31:08.968663       1 allocate.go:138] Try to allocate resource to 0 Queues
I0731 07:31:08.968736       1 session.go:577] Close Session 268dcd6e-863a-4fe9-acd7-671c11f00c8a
I0731 07:31:09.969883       1 cache.go:1581] "SnapShot for scheduling" jobNum=0 QueueNum=2 NodeNum=1
I0731 07:31:09.969928       1 session.go:1036] Start adjusting jobs' network topology spec according to hyperNodeTierNameMap map[]
I0731 07:31:09.969952       1 session.go:1079] Finish adjusting jobs' network topology spec according to hyperNodeTierNameMap map[]
I0731 07:31:09.969978       1 session.go:279] Open Session e1f1f7d2-4b44-4b80-aa7e-4e50f0025bde with <0> Job and <2> Queues. HyperNodesReadyToSchedule: true
I0731 07:31:09.970413       1 enqueue.go:79] Try to enqueue PodGroup to 0 Queues
I0731 07:31:09.970456       1 allocate.go:138] Try to allocate resource to 0 Queues
I0731 07:31:09.970529       1 session.go:577] Close Session e1f1f7d2-4b44-4b80-aa7e-4e50f0025bde
I0731 07:31:10.971366       1 cache.go:1581] "SnapShot for scheduling" jobNum=0 QueueNum=2 NodeNum=1
I0731 07:31:10.971408       1 session.go:1036] Start adjusting jobs' network topology spec according to hyperNodeTierNameMap map[]
I0731 07:31:10.971432       1 session.go:1079] Finish adjusting jobs' network topology spec according to hyperNodeTierNameMap map[]
I0731 07:31:10.971456       1 session.go:279] Open Session 6141ef0a-369b-4e3e-856d-60a3a1788661 with <0> Job and <2> Queues. HyperNodesReadyToSchedule: true
I0731 07:31:10.971896       1 enqueue.go:79] Try to enqueue PodGroup to 0 Queues
I0731 07:31:10.971917       1 allocate.go:138] Try to allocate resource to 0 Queues
I0731 07:31:10.971987       1 session.go:577] Close Session 6141ef0a-369b-4e3e-856d-60a3a1788661
I0731 07:31:11.973257       1 cache.go:1581] "SnapShot for scheduling" jobNum=0 QueueNum=2 NodeNum=1
I0731 07:31:11.973301       1 session.go:1036] Start adjusting jobs' network topology spec according to hyperNodeTierNameMap map[]
I0731 07:31:11.973532       1 session.go:1079] Finish adjusting jobs' network topology spec according to hyperNodeTierNameMap map[]
I0731 07:31:11.974143       1 session.go:279] Open Session 2d2e86c1-86bd-445b-8c0f-ae3de9ac3787 with <0> Job and <2> Queues. HyperNodesReadyToSchedule: true
I0731 07:31:11.975685       1 enqueue.go:79] Try to enqueue PodGroup to 0 Queues
I0731 07:31:11.975748       1 allocate.go:138] Try to allocate resource to 0 Queues
I0731 07:31:11.975893       1 session.go:577] Close Session 2d2e86c1-86bd-445b-8c0f-ae3de9ac3787
I0731 07:31:12.977337       1 cache.go:1581] "SnapShot for scheduling" jobNum=0 QueueNum=2 NodeNum=1
I0731 07:31:12.977401       1 session.go:1036] Start adjusting jobs' network topology spec according to hyperNodeTierNameMap map[]
I0731 07:31:12.977432       1 session.go:1079] Finish adjusting jobs' network topology spec according to hyperNodeTierNameMap map[]
I0731 07:31:12.977456       1 session.go:279] Open Session fee4136a-f782-489f-9a8e-c9d3ada08cb9 with <0> Job and <2> Queues. HyperNodesReadyToSchedule: true
I0731 07:31:12.978055       1 enqueue.go:79] Try to enqueue PodGroup to 0 Queues
I0731 07:31:12.978080       1 allocate.go:138] Try to allocate resource to 0 Queues
I0731 07:31:12.978168       1 session.go:577] Close Session fee4136a-f782-489f-9a8e-c9d3ada08cb9
I0731 07:31:13.979135       1 cache.go:1581] "SnapShot for scheduling" jobNum=0 QueueNum=2 NodeNum=1
I0731 07:31:13.979193       1 session.go:1036] Start adjusting jobs' network topology spec according to hyperNodeTierNameMap map[]
I0731 07:31:13.979220       1 session.go:1079] Finish adjusting jobs' network topology spec according to hyperNodeTierNameMap map[]
I0731 07:31:13.979245       1 session.go:279] Open Session b84733a5-f838-4f71-9db3-67e91ade5587 with <0> Job and <2> Queues. HyperNodesReadyToSchedule: true
I0731 07:31:13.979710       1 enqueue.go:79] Try to enqueue PodGroup to 0 Queues
I0731 07:31:13.979732       1 allocate.go:138] Try to allocate resource to 0 Queues
I0731 07:31:13.979819       1 session.go:577] Close Session b84733a5-f838-4f71-9db3-67e91ade5587
I0731 07:31:14.981200       1 cache.go:1581] "SnapShot for scheduling" jobNum=0 QueueNum=2 NodeNum=1
I0731 07:31:14.981254       1 session.go:1036] Start adjusting jobs' network topology spec according to hyperNodeTierNameMap map[]
I0731 07:31:14.981280       1 session.go:1079] Finish adjusting jobs' network topology spec according to hyperNodeTierNameMap map[]
I0731 07:31:14.981305       1 session.go:279] Open Session b68d9123-13de-4820-ab6e-d55ea388793b with <0> Job and <2> Queues. HyperNodesReadyToSchedule: true
I0731 07:31:14.981807       1 enqueue.go:79] Try to enqueue PodGroup to 0 Queues
I0731 07:31:14.981837       1 allocate.go:138] Try to allocate resource to 0 Queues
I0731 07:31:14.981917       1 session.go:577] Close Session b68d9123-13de-4820-ab6e-d55ea388793b
I0731 07:31:15.983060       1 cache.go:1581] "SnapShot for scheduling" jobNum=0 QueueNum=2 NodeNum=1
I0731 07:31:15.983113       1 session.go:1036] Start adjusting jobs' network topology spec according to hyperNodeTierNameMap map[]
I0731 07:31:15.983141       1 session.go:1079] Finish adjusting jobs' network topology spec according to hyperNodeTierNameMap map[]
I0731 07:31:15.983164       1 session.go:279] Open Session 1e42b12b-5260-4a17-80b9-eadc5b4c8d30 with <0> Job and <2> Queues. HyperNodesReadyToSchedule: true
I0731 07:31:15.983706       1 enqueue.go:79] Try to enqueue PodGroup to 0 Queues
I0731 07:31:15.983729       1 allocate.go:138] Try to allocate resource to 0 Queues
I0731 07:31:15.983822       1 session.go:577] Close Session 1e42b12b-5260-4a17-80b9-eadc5b4c8d30
I0731 07:31:16.482494       1 cache.go:1771] The metrics type is not set in the volcano scheduler configmap file. As a result, the CPU and memory load information of the node is not collected.
I0731 07:31:16.985283       1 cache.go:1581] "SnapShot for scheduling" jobNum=0 QueueNum=2 NodeNum=1
I0731 07:31:16.985340       1 session.go:1036] Start adjusting jobs' network topology spec according to hyperNodeTierNameMap map[]
I0731 07:31:16.985368       1 session.go:1079] Finish adjusting jobs' network topology spec according to hyperNodeTierNameMap map[]
I0731 07:31:16.985393       1 session.go:279] Open Session 022388b9-f94a-4f18-8dcb-7386c40b1537 with <0> Job and <2> Queues. HyperNodesReadyToSchedule: true
I0731 07:31:16.985889       1 enqueue.go:79] Try to enqueue PodGroup to 0 Queues
I0731 07:31:16.985914       1 allocate.go:138] Try to allocate resource to 0 Queues
I0731 07:31:16.985995       1 session.go:577] Close Session 022388b9-f94a-4f18-8dcb-7386c40b1537
I0731 07:31:17.986844       1 cache.go:1581] "SnapShot for scheduling" jobNum=0 QueueNum=2 NodeNum=1
I0731 07:31:17.986909       1 session.go:1036] Start adjusting jobs' network topology spec according to hyperNodeTierNameMap map[]
I0731 07:31:17.986939       1 session.go:1079] Finish adjusting jobs' network topology spec according to hyperNodeTierNameMap map[]
I0731 07:31:17.986964       1 session.go:279] Open Session b6ca8743-da07-44d4-8de2-335e88387180 with <0> Job and <2> Queues. HyperNodesReadyToSchedule: true
I0731 07:31:17.987554       1 enqueue.go:79] Try to enqueue PodGroup to 0 Queues
I0731 07:31:17.987579       1 allocate.go:138] Try to allocate resource to 0 Queues
I0731 07:31:17.987668       1 session.go:577] Close Session b6ca8743-da07-44d4-8de2-335e88387180
I0731 07:31:18.988687       1 cache.go:1581] "SnapShot for scheduling" jobNum=0 QueueNum=2 NodeNum=1
I0731 07:31:18.988746       1 session.go:1036] Start adjusting jobs' network topology spec according to hyperNodeTierNameMap map[]
I0731 07:31:18.988772       1 session.go:1079] Finish adjusting jobs' network topology spec according to hyperNodeTierNameMap map[]
I0731 07:31:18.988796       1 session.go:279] Open Session a0b38860-4425-41e1-b041-8c0a5cce04a5 with <0> Job and <2> Queues. HyperNodesReadyToSchedule: true
I0731 07:31:18.989399       1 enqueue.go:79] Try to enqueue PodGroup to 0 Queues
I0731 07:31:18.989428       1 allocate.go:138] Try to allocate resource to 0 Queues
I0731 07:31:18.989512       1 session.go:577] Close Session a0b38860-4425-41e1-b041-8c0a5cce04a5
I0731 07:31:19.990633       1 cache.go:1581] "SnapShot for scheduling" jobNum=0 QueueNum=2 NodeNum=1
I0731 07:31:19.990687       1 session.go:1036] Start adjusting jobs' network topology spec according to hyperNodeTierNameMap map[]
I0731 07:31:19.990713       1 session.go:1079] Finish adjusting jobs' network topology spec according to hyperNodeTierNameMap map[]
I0731 07:31:19.990750       1 session.go:279] Open Session 33264938-cf4c-4205-a5b1-12a9ae5d8b11 with <0> Job and <2> Queues. HyperNodesReadyToSchedule: true
I0731 07:31:19.991234       1 enqueue.go:79] Try to enqueue PodGroup to 0 Queues
I0731 07:31:19.991257       1 allocate.go:138] Try to allocate resource to 0 Queues
I0731 07:31:19.991343       1 session.go:577] Close Session 33264938-cf4c-4205-a5b1-12a9ae5d8b11
I0731 07:31:20.991912       1 cache.go:1581] "SnapShot for scheduling" jobNum=0 QueueNum=2 NodeNum=1
I0731 07:31:20.991960       1 session.go:1036] Start adjusting jobs' network topology spec according to hyperNodeTierNameMap map[]
I0731 07:31:20.991987       1 session.go:1079] Finish adjusting jobs' network topology spec according to hyperNodeTierNameMap map[]
I0731 07:31:20.992013       1 session.go:279] Open Session 6760c773-e801-417f-8ce7-ab6d5c301ce4 with <0> Job and <2> Queues. HyperNodesReadyToSchedule: true
I0731 07:31:20.992541       1 enqueue.go:79] Try to enqueue PodGroup to 0 Queues
I0731 07:31:20.992565       1 allocate.go:138] Try to allocate resource to 0 Queues
I0731 07:31:20.992644       1 session.go:577] Close Session 6760c773-e801-417f-8ce7-ab6d5c301ce4
I0731 07:31:21.993200       1 cache.go:1581] "SnapShot for scheduling" jobNum=0 QueueNum=2 NodeNum=1
I0731 07:31:21.993248       1 session.go:1036] Start adjusting jobs' network topology spec according to hyperNodeTierNameMap map[]
I0731 07:31:21.993275       1 session.go:1079] Finish adjusting jobs' network topology spec according to hyperNodeTierNameMap map[]
I0731 07:31:21.993299       1 session.go:279] Open Session 29a479d7-c41a-41aa-b7c6-b0b2d66d9105 with <0> Job and <2> Queues. HyperNodesReadyToSchedule: true
I0731 07:31:21.993790       1 enqueue.go:79] Try to enqueue PodGroup to 0 Queues
I0731 07:31:21.993813       1 allocate.go:138] Try to allocate resource to 0 Queues
I0731 07:31:21.993886       1 session.go:577] Close Session 29a479d7-c41a-41aa-b7c6-b0b2d66d9105
I0731 07:31:22.995234       1 cache.go:1581] "SnapShot for scheduling" jobNum=0 QueueNum=2 NodeNum=1
I0731 07:31:22.995285       1 session.go:1036] Start adjusting jobs' network topology spec according to hyperNodeTierNameMap map[]
I0731 07:31:22.995310       1 session.go:1079] Finish adjusting jobs' network topology spec according to hyperNodeTierNameMap map[]
I0731 07:31:22.995334       1 session.go:279] Open Session bef5a8d7-93b5-4c78-9500-104b02f796bf with <0> Job and <2> Queues. HyperNodesReadyToSchedule: true
I0731 07:31:22.995920       1 enqueue.go:79] Try to enqueue PodGroup to 0 Queues
I0731 07:31:22.995943       1 allocate.go:138] Try to allocate resource to 0 Queues
I0731 07:31:22.996022       1 session.go:577] Close Session bef5a8d7-93b5-4c78-9500-104b02f796bf
I0731 07:31:23.997149       1 cache.go:1581] "SnapShot for scheduling" jobNum=0 QueueNum=2 NodeNum=1
I0731 07:31:23.997203       1 session.go:1036] Start adjusting jobs' network topology spec according to hyperNodeTierNameMap map[]
I0731 07:31:23.997232       1 session.go:1079] Finish adjusting jobs' network topology spec according to hyperNodeTierNameMap map[]
I0731 07:31:23.997257       1 session.go:279] Open Session 2eef7c57-b59c-4394-8d70-e60edc3e09f4 with <0> Job and <2> Queues. HyperNodesReadyToSchedule: true
I0731 07:31:23.997829       1 enqueue.go:79] Try to enqueue PodGroup to 0 Queues
I0731 07:31:23.997854       1 allocate.go:138] Try to allocate resource to 0 Queues
I0731 07:31:23.997931       1 session.go:577] Close Session 2eef7c57-b59c-4394-8d70-e60edc3e09f4
I0731 07:31:24.999239       1 cache.go:1581] "SnapShot for scheduling" jobNum=0 QueueNum=2 NodeNum=1
I0731 07:31:24.999293       1 session.go:1036] Start adjusting jobs' network topology spec according to hyperNodeTierNameMap map[]
I0731 07:31:24.999322       1 session.go:1079] Finish adjusting jobs' network topology spec according to hyperNodeTierNameMap map[]
I0731 07:31:24.999347       1 session.go:279] Open Session d925bd15-5faa-440c-8d0a-a9a286e8f9d3 with <0> Job and <2> Queues. HyperNodesReadyToSchedule: true
I0731 07:31:24.999895       1 enqueue.go:79] Try to enqueue PodGroup to 0 Queues
I0731 07:31:24.999920       1 allocate.go:138] Try to allocate resource to 0 Queues
I0731 07:31:25.000006       1 session.go:577] Close Session d925bd15-5faa-440c-8d0a-a9a286e8f9d3
I0731 07:31:26.000536       1 cache.go:1581] "SnapShot for scheduling" jobNum=0 QueueNum=2 NodeNum=1
I0731 07:31:26.000590       1 session.go:1036] Start adjusting jobs' network topology spec according to hyperNodeTierNameMap map[]
I0731 07:31:26.000616       1 session.go:1079] Finish adjusting jobs' network topology spec according to hyperNodeTierNameMap map[]
I0731 07:31:26.000643       1 session.go:279] Open Session e3f51ba5-a74a-41a9-85cc-103671efffa4 with <0> Job and <2> Queues. HyperNodesReadyToSchedule: true
I0731 07:31:26.001237       1 enqueue.go:79] Try to enqueue PodGroup to 0 Queues
I0731 07:31:26.001261       1 allocate.go:138] Try to allocate resource to 0 Queues
I0731 07:31:26.001340       1 session.go:577] Close Session e3f51ba5-a74a-41a9-85cc-103671efffa4
I0731 07:31:27.002756       1 cache.go:1581] "SnapShot for scheduling" jobNum=0 QueueNum=2 NodeNum=1
I0731 07:31:27.002806       1 session.go:1036] Start adjusting jobs' network topology spec according to hyperNodeTierNameMap map[]
I0731 07:31:27.002831       1 session.go:1079] Finish adjusting jobs' network topology spec according to hyperNodeTierNameMap map[]
I0731 07:31:27.002855       1 session.go:279] Open Session 9ac4cf1b-837b-4287-8fd8-edaec018b4bb with <0> Job and <2> Queues. HyperNodesReadyToSchedule: true
I0731 07:31:27.003350       1 enqueue.go:79] Try to enqueue PodGroup to 0 Queues
I0731 07:31:27.003374       1 allocate.go:138] Try to allocate resource to 0 Queues
I0731 07:31:27.003457       1 session.go:577] Close Session 9ac4cf1b-837b-4287-8fd8-edaec018b4bb
I0731 07:31:28.004463       1 cache.go:1581] "SnapShot for scheduling" jobNum=0 QueueNum=2 NodeNum=1
I0731 07:31:28.004511       1 session.go:1036] Start adjusting jobs' network topology spec according to hyperNodeTierNameMap map[]
I0731 07:31:28.004536       1 session.go:1079] Finish adjusting jobs' network topology spec according to hyperNodeTierNameMap map[]
I0731 07:31:28.004562       1 session.go:279] Open Session a44faee4-f631-4a16-95e4-272a1000355d with <0> Job and <2> Queues. HyperNodesReadyToSchedule: true
I0731 07:31:28.005025       1 enqueue.go:79] Try to enqueue PodGroup to 0 Queues
I0731 07:31:28.005048       1 allocate.go:138] Try to allocate resource to 0 Queues
I0731 07:31:28.005131       1 session.go:577] Close Session a44faee4-f631-4a16-95e4-272a1000355d
I0731 07:31:29.005991       1 cache.go:1581] "SnapShot for scheduling" jobNum=0 QueueNum=2 NodeNum=1
I0731 07:31:29.006048       1 session.go:1036] Start adjusting jobs' network topology spec according to hyperNodeTierNameMap map[]
I0731 07:31:29.006075       1 session.go:1079] Finish adjusting jobs' network topology spec according to hyperNodeTierNameMap map[]
I0731 07:31:29.006101       1 session.go:279] Open Session d28201d0-d139-443d-9900-c090298a65a5 with <0> Job and <2> Queues. HyperNodesReadyToSchedule: true
I0731 07:31:29.006620       1 enqueue.go:79] Try to enqueue PodGroup to 0 Queues
I0731 07:31:29.006646       1 allocate.go:138] Try to allocate resource to 0 Queues
I0731 07:31:29.006745       1 session.go:577] Close Session d28201d0-d139-443d-9900-c090298a65a5
I0731 07:31:30.007819       1 cache.go:1581] "SnapShot for scheduling" jobNum=0 QueueNum=2 NodeNum=1
I0731 07:31:30.007868       1 session.go:1036] Start adjusting jobs' network topology spec according to hyperNodeTierNameMap map[]
I0731 07:31:30.007894       1 session.go:1079] Finish adjusting jobs' network topology spec according to hyperNodeTierNameMap map[]
I0731 07:31:30.007922       1 session.go:279] Open Session 7edbfe04-367a-4973-9d61-d90e0f398c9e with <0> Job and <2> Queues. HyperNodesReadyToSchedule: true
I0731 07:31:30.008432       1 enqueue.go:79] Try to enqueue PodGroup to 0 Queues
I0731 07:31:30.008458       1 allocate.go:138] Try to allocate resource to 0 Queues
I0731 07:31:30.008537       1 session.go:577] Close Session 7edbfe04-367a-4973-9d61-d90e0f398c9e
I0731 07:31:31.009843       1 cache.go:1581] "SnapShot for scheduling" jobNum=0 QueueNum=2 NodeNum=1
I0731 07:31:31.009887       1 session.go:1036] Start adjusting jobs' network topology spec according to hyperNodeTierNameMap map[]
I0731 07:31:31.009912       1 session.go:1079] Finish adjusting jobs' network topology spec according to hyperNodeTierNameMap map[]
I0731 07:31:31.009936       1 session.go:279] Open Session 7f92d121-29eb-46e1-b591-82634a6393ca with <0> Job and <2> Queues. HyperNodesReadyToSchedule: true
I0731 07:31:31.010377       1 enqueue.go:79] Try to enqueue PodGroup to 0 Queues
I0731 07:31:31.010399       1 allocate.go:138] Try to allocate resource to 0 Queues
I0731 07:31:31.010473       1 session.go:577] Close Session 7f92d121-29eb-46e1-b591-82634a6393ca
I0731 07:31:32.010847       1 cache.go:1581] "SnapShot for scheduling" jobNum=0 QueueNum=2 NodeNum=1
I0731 07:31:32.010891       1 session.go:1036] Start adjusting jobs' network topology spec according to hyperNodeTierNameMap map[]
I0731 07:31:32.010916       1 session.go:1079] Finish adjusting jobs' network topology spec according to hyperNodeTierNameMap map[]
I0731 07:31:32.010940       1 session.go:279] Open Session 8cfea5d7-0df3-4e66-8793-c6112bdcc392 with <0> Job and <2> Queues. HyperNodesReadyToSchedule: true
I0731 07:31:32.011472       1 enqueue.go:79] Try to enqueue PodGroup to 0 Queues
I0731 07:31:32.011495       1 allocate.go:138] Try to allocate resource to 0 Queues
I0731 07:31:32.011571       1 session.go:577] Close Session 8cfea5d7-0df3-4e66-8793-c6112bdcc392
I0731 07:31:33.012517       1 cache.go:1581] "SnapShot for scheduling" jobNum=0 QueueNum=2 NodeNum=1
I0731 07:31:33.012560       1 session.go:1036] Start adjusting jobs' network topology spec according to hyperNodeTierNameMap map[]
I0731 07:31:33.012582       1 session.go:1079] Finish adjusting jobs' network topology spec according to hyperNodeTierNameMap map[]
I0731 07:31:33.012606       1 session.go:279] Open Session 51b40858-15ff-45df-bbb8-7c8f36a82965 with <0> Job and <2> Queues. HyperNodesReadyToSchedule: true
I0731 07:31:33.013034       1 enqueue.go:79] Try to enqueue PodGroup to 0 Queues
I0731 07:31:33.013056       1 allocate.go:138] Try to allocate resource to 0 Queues
I0731 07:31:33.013129       1 session.go:577] Close Session 51b40858-15ff-45df-bbb8-7c8f36a82965
I0731 07:31:34.013449       1 cache.go:1581] "SnapShot for scheduling" jobNum=0 QueueNum=2 NodeNum=1
I0731 07:31:34.013497       1 session.go:1036] Start adjusting jobs' network topology spec according to hyperNodeTierNameMap map[]
I0731 07:31:34.013522       1 session.go:1079] Finish adjusting jobs' network topology spec according to hyperNodeTierNameMap map[]
I0731 07:31:34.013547       1 session.go:279] Open Session 67953a83-cbd7-4e5b-8193-2b81e499fd9a with <0> Job and <2> Queues. HyperNodesReadyToSchedule: true
I0731 07:31:34.013997       1 enqueue.go:79] Try to enqueue PodGroup to 0 Queues
I0731 07:31:34.014019       1 allocate.go:138] Try to allocate resource to 0 Queues
I0731 07:31:34.014092       1 session.go:577] Close Session 67953a83-cbd7-4e5b-8193-2b81e499fd9a
I0731 07:31:35.014407       1 cache.go:1581] "SnapShot for scheduling" jobNum=0 QueueNum=2 NodeNum=1
I0731 07:31:35.014449       1 session.go:1036] Start adjusting jobs' network topology spec according to hyperNodeTierNameMap map[]
I0731 07:31:35.014472       1 session.go:1079] Finish adjusting jobs' network topology spec according to hyperNodeTierNameMap map[]
I0731 07:31:35.014497       1 session.go:279] Open Session 3fec17ec-0786-46fb-b430-57e7aca80f03 with <0> Job and <2> Queues. HyperNodesReadyToSchedule: true
I0731 07:31:35.014934       1 enqueue.go:79] Try to enqueue PodGroup to 0 Queues
I0731 07:31:35.014957       1 allocate.go:138] Try to allocate resource to 0 Queues
I0731 07:31:35.015025       1 session.go:577] Close Session 3fec17ec-0786-46fb-b430-57e7aca80f03
I0731 07:31:36.015555       1 cache.go:1581] "SnapShot for scheduling" jobNum=0 QueueNum=2 NodeNum=1
I0731 07:31:36.015600       1 session.go:1036] Start adjusting jobs' network topology spec according to hyperNodeTierNameMap map[]
I0731 07:31:36.015626       1 session.go:1079] Finish adjusting jobs' network topology spec according to hyperNodeTierNameMap map[]
I0731 07:31:36.015650       1 session.go:279] Open Session fe164807-7b83-4a58-ac4b-02769591837e with <0> Job and <2> Queues. HyperNodesReadyToSchedule: true
I0731 07:31:36.016094       1 enqueue.go:79] Try to enqueue PodGroup to 0 Queues
I0731 07:31:36.016115       1 allocate.go:138] Try to allocate resource to 0 Queues
I0731 07:31:36.016188       1 session.go:577] Close Session fe164807-7b83-4a58-ac4b-02769591837e
I0731 07:31:37.016529       1 cache.go:1581] "SnapShot for scheduling" jobNum=0 QueueNum=2 NodeNum=1
I0731 07:31:37.016566       1 session.go:1036] Start adjusting jobs' network topology spec according to hyperNodeTierNameMap map[]
I0731 07:31:37.016586       1 session.go:1079] Finish adjusting jobs' network topology spec according to hyperNodeTierNameMap map[]
I0731 07:31:37.016608       1 session.go:279] Open Session e6c01e23-03e1-4782-ae0c-373d73de6309 with <0> Job and <2> Queues. HyperNodesReadyToSchedule: true
I0731 07:31:37.017077       1 enqueue.go:79] Try to enqueue PodGroup to 0 Queues
I0731 07:31:37.017100       1 allocate.go:138] Try to allocate resource to 0 Queues
I0731 07:31:37.017166       1 session.go:577] Close Session e6c01e23-03e1-4782-ae0c-373d73de6309
I0731 07:31:38.017939       1 cache.go:1581] "SnapShot for scheduling" jobNum=0 QueueNum=2 NodeNum=1
I0731 07:31:38.017983       1 session.go:1036] Start adjusting jobs' network topology spec according to hyperNodeTierNameMap map[]
I0731 07:31:38.018007       1 session.go:1079] Finish adjusting jobs' network topology spec according to hyperNodeTierNameMap map[]
I0731 07:31:38.018031       1 session.go:279] Open Session e7bb6d24-0394-4539-867b-b6c1de7ffab6 with <0> Job and <2> Queues. HyperNodesReadyToSchedule: true
I0731 07:31:38.018458       1 enqueue.go:79] Try to enqueue PodGroup to 0 Queues
I0731 07:31:38.018481       1 allocate.go:138] Try to allocate resource to 0 Queues
I0731 07:31:38.018551       1 session.go:577] Close Session e7bb6d24-0394-4539-867b-b6c1de7ffab6
I0731 07:31:39.019856       1 cache.go:1581] "SnapShot for scheduling" jobNum=0 QueueNum=2 NodeNum=1
I0731 07:31:39.019891       1 session.go:1036] Start adjusting jobs' network topology spec according to hyperNodeTierNameMap map[]
I0731 07:31:39.019913       1 session.go:1079] Finish adjusting jobs' network topology spec according to hyperNodeTierNameMap map[]
I0731 07:31:39.019935       1 session.go:279] Open Session 9f6989d1-d007-4c69-ab2e-83aa5d8c24a4 with <0> Job and <2> Queues. HyperNodesReadyToSchedule: true
I0731 07:31:39.020362       1 enqueue.go:79] Try to enqueue PodGroup to 0 Queues
I0731 07:31:39.020382       1 allocate.go:138] Try to allocate resource to 0 Queues
I0731 07:31:39.020449       1 session.go:577] Close Session 9f6989d1-d007-4c69-ab2e-83aa5d8c24a4
I0731 07:31:40.021326       1 cache.go:1581] "SnapShot for scheduling" jobNum=0 QueueNum=2 NodeNum=1
I0731 07:31:40.021366       1 session.go:1036] Start adjusting jobs' network topology spec according to hyperNodeTierNameMap map[]
I0731 07:31:40.021389       1 session.go:1079] Finish adjusting jobs' network topology spec according to hyperNodeTierNameMap map[]
I0731 07:31:40.021413       1 session.go:279] Open Session 272a6b74-c336-408f-8c6a-b2c2dcd642ba with <0> Job and <2> Queues. HyperNodesReadyToSchedule: true
I0731 07:31:40.021824       1 enqueue.go:79] Try to enqueue PodGroup to 0 Queues
I0731 07:31:40.021848       1 allocate.go:138] Try to allocate resource to 0 Queues
I0731 07:31:40.021914       1 session.go:577] Close Session 272a6b74-c336-408f-8c6a-b2c2dcd642ba
I0731 07:31:41.023133       1 cache.go:1581] "SnapShot for scheduling" jobNum=0 QueueNum=2 NodeNum=1
I0731 07:31:41.023198       1 session.go:1036] Start adjusting jobs' network topology spec according to hyperNodeTierNameMap map[]
I0731 07:31:41.023227       1 session.go:1079] Finish adjusting jobs' network topology spec according to hyperNodeTierNameMap map[]
I0731 07:31:41.023253       1 session.go:279] Open Session 3259d0b3-5254-4ffb-a708-860aa4a68fc4 with <0> Job and <2> Queues. HyperNodesReadyToSchedule: true
I0731 07:31:41.023779       1 enqueue.go:79] Try to enqueue PodGroup to 0 Queues
I0731 07:31:41.023805       1 allocate.go:138] Try to allocate resource to 0 Queues
I0731 07:31:41.023894       1 session.go:577] Close Session 3259d0b3-5254-4ffb-a708-860aa4a68fc4
I0731 07:31:42.024373       1 cache.go:1581] "SnapShot for scheduling" jobNum=0 QueueNum=2 NodeNum=1
I0731 07:31:42.024409       1 session.go:1036] Start adjusting jobs' network topology spec according to hyperNodeTierNameMap map[]
I0731 07:31:42.024431       1 session.go:1079] Finish adjusting jobs' network topology spec according to hyperNodeTierNameMap map[]
I0731 07:31:42.024457       1 session.go:279] Open Session adfe5604-1f47-474f-a531-de5751d16f17 with <0> Job and <2> Queues. HyperNodesReadyToSchedule: true
I0731 07:31:42.024859       1 enqueue.go:79] Try to enqueue PodGroup to 0 Queues
I0731 07:31:42.024880       1 allocate.go:138] Try to allocate resource to 0 Queues
I0731 07:31:42.024949       1 session.go:577] Close Session adfe5604-1f47-474f-a531-de5751d16f17
I0731 07:31:43.026074       1 cache.go:1581] "SnapShot for scheduling" jobNum=0 QueueNum=2 NodeNum=1
I0731 07:31:43.026107       1 session.go:1036] Start adjusting jobs' network topology spec according to hyperNodeTierNameMap map[]
I0731 07:31:43.026125       1 session.go:1079] Finish adjusting jobs' network topology spec according to hyperNodeTierNameMap map[]
I0731 07:31:43.026148       1 session.go:279] Open Session deeebba5-ad0e-42e8-8990-cbf3c35f7c0f with <0> Job and <2> Queues. HyperNodesReadyToSchedule: true
I0731 07:31:43.026564       1 enqueue.go:79] Try to enqueue PodGroup to 0 Queues
I0731 07:31:43.026585       1 allocate.go:138] Try to allocate resource to 0 Queues
I0731 07:31:43.026654       1 session.go:577] Close Session deeebba5-ad0e-42e8-8990-cbf3c35f7c0f
I0731 07:31:44.027141       1 cache.go:1581] "SnapShot for scheduling" jobNum=0 QueueNum=2 NodeNum=1
I0731 07:31:44.027171       1 session.go:1036] Start adjusting jobs' network topology spec according to hyperNodeTierNameMap map[]
I0731 07:31:44.027188       1 session.go:1079] Finish adjusting jobs' network topology spec according to hyperNodeTierNameMap map[]
I0731 07:31:44.027208       1 session.go:279] Open Session 12e3554a-cb4d-4302-87fa-3ada4cc6e08d with <0> Job and <2> Queues. HyperNodesReadyToSchedule: true
I0731 07:31:44.027543       1 enqueue.go:79] Try to enqueue PodGroup to 0 Queues
I0731 07:31:44.027561       1 allocate.go:138] Try to allocate resource to 0 Queues
I0731 07:31:44.027611       1 session.go:577] Close Session 12e3554a-cb4d-4302-87fa-3ada4cc6e08d
I0731 07:31:45.028161       1 cache.go:1581] "SnapShot for scheduling" jobNum=0 QueueNum=2 NodeNum=1
I0731 07:31:45.028203       1 session.go:1036] Start adjusting jobs' network topology spec according to hyperNodeTierNameMap map[]
I0731 07:31:45.028229       1 session.go:1079] Finish adjusting jobs' network topology spec according to hyperNodeTierNameMap map[]
I0731 07:31:45.028255       1 session.go:279] Open Session 5419619c-dda3-4644-b3cb-e9990575039f with <0> Job and <2> Queues. HyperNodesReadyToSchedule: true
I0731 07:31:45.028716       1 enqueue.go:79] Try to enqueue PodGroup to 0 Queues
I0731 07:31:45.028737       1 allocate.go:138] Try to allocate resource to 0 Queues
I0731 07:31:45.028812       1 session.go:577] Close Session 5419619c-dda3-4644-b3cb-e9990575039f
I0731 07:31:46.030071       1 cache.go:1581] "SnapShot for scheduling" jobNum=0 QueueNum=2 NodeNum=1
I0731 07:31:46.030114       1 session.go:1036] Start adjusting jobs' network topology spec according to hyperNodeTierNameMap map[]
I0731 07:31:46.030174       1 session.go:1079] Finish adjusting jobs' network topology spec according to hyperNodeTierNameMap map[]
I0731 07:31:46.030199       1 session.go:279] Open Session 82b4311e-f5b7-429f-ae7a-09be6aa37fe1 with <0> Job and <2> Queues. HyperNodesReadyToSchedule: true
I0731 07:31:46.030674       1 enqueue.go:79] Try to enqueue PodGroup to 0 Queues
I0731 07:31:46.030695       1 allocate.go:138] Try to allocate resource to 0 Queues
I0731 07:31:46.030791       1 session.go:577] Close Session 82b4311e-f5b7-429f-ae7a-09be6aa37fe1
I0731 07:31:46.483336       1 cache.go:1771] The metrics type is not set in the volcano scheduler configmap file. As a result, the CPU and memory load information of the node is not collected.
I0731 07:31:47.032177       1 cache.go:1581] "SnapShot for scheduling" jobNum=0 QueueNum=2 NodeNum=1
I0731 07:31:47.032227       1 session.go:1036] Start adjusting jobs' network topology spec according to hyperNodeTierNameMap map[]
I0731 07:31:47.032255       1 session.go:1079] Finish adjusting jobs' network topology spec according to hyperNodeTierNameMap map[]
I0731 07:31:47.032283       1 session.go:279] Open Session 7681476d-e4d7-44fe-9364-079658bcea7f with <0> Job and <2> Queues. HyperNodesReadyToSchedule: true
I0731 07:31:47.032815       1 enqueue.go:79] Try to enqueue PodGroup to 0 Queues
I0731 07:31:47.032842       1 allocate.go:138] Try to allocate resource to 0 Queues
I0731 07:31:47.032933       1 session.go:577] Close Session 7681476d-e4d7-44fe-9364-079658bcea7f
I0731 07:31:48.033964       1 cache.go:1581] "SnapShot for scheduling" jobNum=0 QueueNum=2 NodeNum=1
I0731 07:31:48.034001       1 session.go:1036] Start adjusting jobs' network topology spec according to hyperNodeTierNameMap map[]
I0731 07:31:48.034019       1 session.go:1079] Finish adjusting jobs' network topology spec according to hyperNodeTierNameMap map[]
I0731 07:31:48.034040       1 session.go:279] Open Session 9f3c0158-2d92-41fe-a3a2-fc1409fd99fe with <0> Job and <2> Queues. HyperNodesReadyToSchedule: true
I0731 07:31:48.034402       1 enqueue.go:79] Try to enqueue PodGroup to 0 Queues
I0731 07:31:48.034422       1 allocate.go:138] Try to allocate resource to 0 Queues
I0731 07:31:48.034483       1 session.go:577] Close Session 9f3c0158-2d92-41fe-a3a2-fc1409fd99fe
I0731 07:31:49.034935       1 cache.go:1581] "SnapShot for scheduling" jobNum=0 QueueNum=2 NodeNum=1
I0731 07:31:49.034964       1 session.go:1036] Start adjusting jobs' network topology spec according to hyperNodeTierNameMap map[]
I0731 07:31:49.034981       1 session.go:1079] Finish adjusting jobs' network topology spec according to hyperNodeTierNameMap map[]
I0731 07:31:49.035001       1 session.go:279] Open Session bdee034b-b6a2-4354-b09a-b564175745ee with <0> Job and <2> Queues. HyperNodesReadyToSchedule: true
I0731 07:31:49.035322       1 enqueue.go:79] Try to enqueue PodGroup to 0 Queues
I0731 07:31:49.035342       1 allocate.go:138] Try to allocate resource to 0 Queues
I0731 07:31:49.035390       1 session.go:577] Close Session bdee034b-b6a2-4354-b09a-b564175745ee
I0731 07:31:50.035844       1 cache.go:1581] "SnapShot for scheduling" jobNum=0 QueueNum=2 NodeNum=1
I0731 07:31:50.035868       1 session.go:1036] Start adjusting jobs' network topology spec according to hyperNodeTierNameMap map[]
I0731 07:31:50.035885       1 session.go:1079] Finish adjusting jobs' network topology spec according to hyperNodeTierNameMap map[]
I0731 07:31:50.035909       1 session.go:279] Open Session f85381af-1c7f-4ac5-b459-c380e38a8064 with <0> Job and <2> Queues. HyperNodesReadyToSchedule: true
I0731 07:31:50.036216       1 enqueue.go:79] Try to enqueue PodGroup to 0 Queues
I0731 07:31:50.036233       1 allocate.go:138] Try to allocate resource to 0 Queues
I0731 07:31:50.036288       1 session.go:577] Close Session f85381af-1c7f-4ac5-b459-c380e38a8064
I0731 07:31:51.036933       1 cache.go:1581] "SnapShot for scheduling" jobNum=0 QueueNum=2 NodeNum=1
I0731 07:31:51.036973       1 session.go:1036] Start adjusting jobs' network topology spec according to hyperNodeTierNameMap map[]
I0731 07:31:51.036995       1 session.go:1079] Finish adjusting jobs' network topology spec according to hyperNodeTierNameMap map[]
I0731 07:31:51.037020       1 session.go:279] Open Session 8ea4a714-6210-40b5-bc00-8423e8fe1ef5 with <0> Job and <2> Queues. HyperNodesReadyToSchedule: true
I0731 07:31:51.039950       1 enqueue.go:79] Try to enqueue PodGroup to 0 Queues
I0731 07:31:51.040038       1 allocate.go:138] Try to allocate resource to 0 Queues
I0731 07:31:51.040183       1 session.go:577] Close Session 8ea4a714-6210-40b5-bc00-8423e8fe1ef5
I0731 07:31:52.040633       1 cache.go:1581] "SnapShot for scheduling" jobNum=0 QueueNum=2 NodeNum=1
I0731 07:31:52.040689       1 session.go:1036] Start adjusting jobs' network topology spec according to hyperNodeTierNameMap map[]
I0731 07:31:52.040715       1 session.go:1079] Finish adjusting jobs' network topology spec according to hyperNodeTierNameMap map[]
I0731 07:31:52.040740       1 session.go:279] Open Session 5d587b84-ab72-4b48-b5f3-498b2a13f062 with <0> Job and <2> Queues. HyperNodesReadyToSchedule: true
I0731 07:31:52.041206       1 enqueue.go:79] Try to enqueue PodGroup to 0 Queues
I0731 07:31:52.041230       1 allocate.go:138] Try to allocate resource to 0 Queues
I0731 07:31:52.041310       1 session.go:577] Close Session 5d587b84-ab72-4b48-b5f3-498b2a13f062
I0731 07:31:53.042258       1 cache.go:1581] "SnapShot for scheduling" jobNum=0 QueueNum=2 NodeNum=1
I0731 07:31:53.042287       1 session.go:1036] Start adjusting jobs' network topology spec according to hyperNodeTierNameMap map[]
I0731 07:31:53.042305       1 session.go:1079] Finish adjusting jobs' network topology spec according to hyperNodeTierNameMap map[]
I0731 07:31:53.042325       1 session.go:279] Open Session 61ec067a-14da-41c9-954d-bb8b499af242 with <0> Job and <2> Queues. HyperNodesReadyToSchedule: true
I0731 07:31:53.042675       1 enqueue.go:79] Try to enqueue PodGroup to 0 Queues
I0731 07:31:53.042694       1 allocate.go:138] Try to allocate resource to 0 Queues
I0731 07:31:53.042756       1 session.go:577] Close Session 61ec067a-14da-41c9-954d-bb8b499af242
I0731 07:31:54.044196       1 cache.go:1581] "SnapShot for scheduling" jobNum=0 QueueNum=2 NodeNum=1
I0731 07:31:54.044244       1 session.go:1036] Start adjusting jobs' network topology spec according to hyperNodeTierNameMap map[]
I0731 07:31:54.044269       1 session.go:1079] Finish adjusting jobs' network topology spec according to hyperNodeTierNameMap map[]
I0731 07:31:54.044292       1 session.go:279] Open Session f26f9ea0-f932-4696-8b7c-4db2138f5824 with <0> Job and <2> Queues. HyperNodesReadyToSchedule: true
I0731 07:31:54.044766       1 enqueue.go:79] Try to enqueue PodGroup to 0 Queues
I0731 07:31:54.044789       1 allocate.go:138] Try to allocate resource to 0 Queues
I0731 07:31:54.044859       1 session.go:577] Close Session f26f9ea0-f932-4696-8b7c-4db2138f5824
I0731 07:31:55.046120       1 cache.go:1581] "SnapShot for scheduling" jobNum=0 QueueNum=2 NodeNum=1
I0731 07:31:55.046182       1 session.go:1036] Start adjusting jobs' network topology spec according to hyperNodeTierNameMap map[]
I0731 07:31:55.046214       1 session.go:1079] Finish adjusting jobs' network topology spec according to hyperNodeTierNameMap map[]
I0731 07:31:55.046239       1 session.go:279] Open Session cb5e758e-64ea-4a10-958f-5fc06e394020 with <0> Job and <2> Queues. HyperNodesReadyToSchedule: true
I0731 07:31:55.046717       1 enqueue.go:79] Try to enqueue PodGroup to 0 Queues
I0731 07:31:55.046753       1 allocate.go:138] Try to allocate resource to 0 Queues
I0731 07:31:55.046833       1 session.go:577] Close Session cb5e758e-64ea-4a10-958f-5fc06e394020
I0731 07:31:56.047353       1 cache.go:1581] "SnapShot for scheduling" jobNum=0 QueueNum=2 NodeNum=1
I0731 07:31:56.047397       1 session.go:1036] Start adjusting jobs' network topology spec according to hyperNodeTierNameMap map[]
I0731 07:31:56.047421       1 session.go:1079] Finish adjusting jobs' network topology spec according to hyperNodeTierNameMap map[]
I0731 07:31:56.047444       1 session.go:279] Open Session 0d57c245-0c54-4528-af38-221846ee984d with <0> Job and <2> Queues. HyperNodesReadyToSchedule: true
I0731 07:31:56.047955       1 enqueue.go:79] Try to enqueue PodGroup to 0 Queues
I0731 07:31:56.047979       1 allocate.go:138] Try to allocate resource to 0 Queues
I0731 07:31:56.048054       1 session.go:577] Close Session 0d57c245-0c54-4528-af38-221846ee984d
I0731 07:31:57.049439       1 cache.go:1581] "SnapShot for scheduling" jobNum=0 QueueNum=2 NodeNum=1
I0731 07:31:57.049485       1 session.go:1036] Start adjusting jobs' network topology spec according to hyperNodeTierNameMap map[]
I0731 07:31:57.049509       1 session.go:1079] Finish adjusting jobs' network topology spec according to hyperNodeTierNameMap map[]
I0731 07:31:57.049532       1 session.go:279] Open Session 69f5ecdb-bc6e-4644-99b4-bb51168f6c3a with <0> Job and <2> Queues. HyperNodesReadyToSchedule: true
I0731 07:31:57.049992       1 enqueue.go:79] Try to enqueue PodGroup to 0 Queues
I0731 07:31:57.050015       1 allocate.go:138] Try to allocate resource to 0 Queues
I0731 07:31:57.050088       1 session.go:577] Close Session 69f5ecdb-bc6e-4644-99b4-bb51168f6c3a
I0731 07:31:58.050872       1 cache.go:1581] "SnapShot for scheduling" jobNum=0 QueueNum=2 NodeNum=1
I0731 07:31:58.050921       1 session.go:1036] Start adjusting jobs' network topology spec according to hyperNodeTierNameMap map[]
I0731 07:31:58.050943       1 session.go:1079] Finish adjusting jobs' network topology spec according to hyperNodeTierNameMap map[]
I0731 07:31:58.050969       1 session.go:279] Open Session 57ef7bb7-0367-4c45-b8eb-a4fda75849ca with <0> Job and <2> Queues. HyperNodesReadyToSchedule: true
I0731 07:31:58.051481       1 enqueue.go:79] Try to enqueue PodGroup to 0 Queues
I0731 07:31:58.051505       1 allocate.go:138] Try to allocate resource to 0 Queues
I0731 07:31:58.051585       1 session.go:577] Close Session 57ef7bb7-0367-4c45-b8eb-a4fda75849ca
I0731 07:31:59.051965       1 cache.go:1581] "SnapShot for scheduling" jobNum=0 QueueNum=2 NodeNum=1
I0731 07:31:59.052013       1 session.go:1036] Start adjusting jobs' network topology spec according to hyperNodeTierNameMap map[]
I0731 07:31:59.052038       1 session.go:1079] Finish adjusting jobs' network topology spec according to hyperNodeTierNameMap map[]
I0731 07:31:59.052064       1 session.go:279] Open Session 9728f63c-eb7a-4831-841f-c18944044270 with <0> Job and <2> Queues. HyperNodesReadyToSchedule: true
I0731 07:31:59.052554       1 enqueue.go:79] Try to enqueue PodGroup to 0 Queues
I0731 07:31:59.052577       1 allocate.go:138] Try to allocate resource to 0 Queues
I0731 07:31:59.052658       1 session.go:577] Close Session 9728f63c-eb7a-4831-841f-c18944044270
I0731 07:32:00.053355       1 cache.go:1581] "SnapShot for scheduling" jobNum=0 QueueNum=2 NodeNum=1
I0731 07:32:00.053407       1 session.go:1036] Start adjusting jobs' network topology spec according to hyperNodeTierNameMap map[]
I0731 07:32:00.053435       1 session.go:1079] Finish adjusting jobs' network topology spec according to hyperNodeTierNameMap map[]
I0731 07:32:00.053458       1 session.go:279] Open Session 22cc7de1-8f41-4976-b35d-04f8e45b9b29 with <0> Job and <2> Queues. HyperNodesReadyToSchedule: true
I0731 07:32:00.053959       1 enqueue.go:79] Try to enqueue PodGroup to 0 Queues
I0731 07:32:00.053984       1 allocate.go:138] Try to allocate resource to 0 Queues
I0731 07:32:00.054060       1 session.go:577] Close Session 22cc7de1-8f41-4976-b35d-04f8e45b9b29
I0731 07:32:01.054809       1 cache.go:1581] "SnapShot for scheduling" jobNum=0 QueueNum=2 NodeNum=1
I0731 07:32:01.054854       1 session.go:1036] Start adjusting jobs' network topology spec according to hyperNodeTierNameMap map[]
I0731 07:32:01.054879       1 session.go:1079] Finish adjusting jobs' network topology spec according to hyperNodeTierNameMap map[]
I0731 07:32:01.054905       1 session.go:279] Open Session 78ab027e-b035-4dd8-84a2-1a572ef176f2 with <0> Job and <2> Queues. HyperNodesReadyToSchedule: true
I0731 07:32:01.055435       1 enqueue.go:79] Try to enqueue PodGroup to 0 Queues
I0731 07:32:01.055458       1 allocate.go:138] Try to allocate resource to 0 Queues
I0731 07:32:01.055530       1 session.go:577] Close Session 78ab027e-b035-4dd8-84a2-1a572ef176f2
I0731 07:32:02.055899       1 cache.go:1581] "SnapShot for scheduling" jobNum=0 QueueNum=2 NodeNum=1
I0731 07:32:02.055942       1 session.go:1036] Start adjusting jobs' network topology spec according to hyperNodeTierNameMap map[]
I0731 07:32:02.055966       1 session.go:1079] Finish adjusting jobs' network topology spec according to hyperNodeTierNameMap map[]
I0731 07:32:02.055990       1 session.go:279] Open Session 15d96c08-62f7-42be-82a7-cab019ee9a32 with <0> Job and <2> Queues. HyperNodesReadyToSchedule: true
I0731 07:32:02.056457       1 enqueue.go:79] Try to enqueue PodGroup to 0 Queues
I0731 07:32:02.056478       1 allocate.go:138] Try to allocate resource to 0 Queues
I0731 07:32:02.056552       1 session.go:577] Close Session 15d96c08-62f7-42be-82a7-cab019ee9a32
I0731 07:32:03.057005       1 cache.go:1581] "SnapShot for scheduling" jobNum=0 QueueNum=2 NodeNum=1
I0731 07:32:03.057062       1 session.go:1036] Start adjusting jobs' network topology spec according to hyperNodeTierNameMap map[]
I0731 07:32:03.057088       1 session.go:1079] Finish adjusting jobs' network topology spec according to hyperNodeTierNameMap map[]
I0731 07:32:03.057114       1 session.go:279] Open Session 4403c60a-f6b2-42ee-9f1e-b1d3c3efa918 with <0> Job and <2> Queues. HyperNodesReadyToSchedule: true
I0731 07:32:03.057650       1 enqueue.go:79] Try to enqueue PodGroup to 0 Queues
I0731 07:32:03.057674       1 allocate.go:138] Try to allocate resource to 0 Queues
I0731 07:32:03.057759       1 session.go:577] Close Session 4403c60a-f6b2-42ee-9f1e-b1d3c3efa918
I0731 07:32:04.058732       1 cache.go:1581] "SnapShot for scheduling" jobNum=0 QueueNum=2 NodeNum=1
I0731 07:32:04.058763       1 session.go:1036] Start adjusting jobs' network topology spec according to hyperNodeTierNameMap map[]
I0731 07:32:04.058782       1 session.go:1079] Finish adjusting jobs' network topology spec according to hyperNodeTierNameMap map[]
I0731 07:32:04.058808       1 session.go:279] Open Session 87d0b51c-3d0e-4cf6-b9b9-8a230458f6a7 with <0> Job and <2> Queues. HyperNodesReadyToSchedule: true
I0731 07:32:04.059172       1 enqueue.go:79] Try to enqueue PodGroup to 0 Queues
I0731 07:32:04.059194       1 allocate.go:138] Try to allocate resource to 0 Queues
I0731 07:32:04.059248       1 session.go:577] Close Session 87d0b51c-3d0e-4cf6-b9b9-8a230458f6a7
I0731 07:32:05.059889       1 cache.go:1581] "SnapShot for scheduling" jobNum=0 QueueNum=2 NodeNum=1
I0731 07:32:05.059936       1 session.go:1036] Start adjusting jobs' network topology spec according to hyperNodeTierNameMap map[]
I0731 07:32:05.059962       1 session.go:1079] Finish adjusting jobs' network topology spec according to hyperNodeTierNameMap map[]
I0731 07:32:05.059986       1 session.go:279] Open Session e25e6e02-e195-4671-ae48-e1004e2958bf with <0> Job and <2> Queues. HyperNodesReadyToSchedule: true
I0731 07:32:05.060466       1 enqueue.go:79] Try to enqueue PodGroup to 0 Queues
I0731 07:32:05.060489       1 allocate.go:138] Try to allocate resource to 0 Queues
I0731 07:32:05.060567       1 session.go:577] Close Session e25e6e02-e195-4671-ae48-e1004e2958bf
I0731 07:32:06.061238       1 cache.go:1581] "SnapShot for scheduling" jobNum=0 QueueNum=2 NodeNum=1
I0731 07:32:06.061284       1 session.go:1036] Start adjusting jobs' network topology spec according to hyperNodeTierNameMap map[]
I0731 07:32:06.061307       1 session.go:1079] Finish adjusting jobs' network topology spec according to hyperNodeTierNameMap map[]
I0731 07:32:06.061338       1 session.go:279] Open Session 656edc58-1d9b-455b-a4a5-7df70c5f8840 with <0> Job and <2> Queues. HyperNodesReadyToSchedule: true
I0731 07:32:06.061788       1 enqueue.go:79] Try to enqueue PodGroup to 0 Queues
I0731 07:32:06.061810       1 allocate.go:138] Try to allocate resource to 0 Queues
I0731 07:32:06.061880       1 session.go:577] Close Session 656edc58-1d9b-455b-a4a5-7df70c5f8840
I0731 07:32:07.062768       1 cache.go:1581] "SnapShot for scheduling" jobNum=0 QueueNum=2 NodeNum=1
I0731 07:32:07.062814       1 session.go:1036] Start adjusting jobs' network topology spec according to hyperNodeTierNameMap map[]
I0731 07:32:07.062839       1 session.go:1079] Finish adjusting jobs' network topology spec according to hyperNodeTierNameMap map[]
I0731 07:32:07.062862       1 session.go:279] Open Session a7ba8ae9-34cc-485a-9013-9d7e71f1ae91 with <0> Job and <2> Queues. HyperNodesReadyToSchedule: true
I0731 07:32:07.063299       1 enqueue.go:79] Try to enqueue PodGroup to 0 Queues
I0731 07:32:07.063321       1 allocate.go:138] Try to allocate resource to 0 Queues
I0731 07:32:07.063394       1 session.go:577] Close Session a7ba8ae9-34cc-485a-9013-9d7e71f1ae91
I0731 07:32:08.064024       1 cache.go:1581] "SnapShot for scheduling" jobNum=0 QueueNum=2 NodeNum=1
I0731 07:32:08.064068       1 session.go:1036] Start adjusting jobs' network topology spec according to hyperNodeTierNameMap map[]
I0731 07:32:08.064095       1 session.go:1079] Finish adjusting jobs' network topology spec according to hyperNodeTierNameMap map[]
I0731 07:32:08.064119       1 session.go:279] Open Session a6c3837c-549e-4571-90fa-bd93d585e3eb with <0> Job and <2> Queues. HyperNodesReadyToSchedule: true
I0731 07:32:08.064551       1 enqueue.go:79] Try to enqueue PodGroup to 0 Queues
I0731 07:32:08.064573       1 allocate.go:138] Try to allocate resource to 0 Queues
I0731 07:32:08.064639       1 session.go:577] Close Session a6c3837c-549e-4571-90fa-bd93d585e3eb
I0731 07:32:09.065670       1 cache.go:1581] "SnapShot for scheduling" jobNum=0 QueueNum=2 NodeNum=1
I0731 07:32:09.065707       1 session.go:1036] Start adjusting jobs' network topology spec according to hyperNodeTierNameMap map[]
I0731 07:32:09.065728       1 session.go:1079] Finish adjusting jobs' network topology spec according to hyperNodeTierNameMap map[]
I0731 07:32:09.065753       1 session.go:279] Open Session 848f2715-4e3b-41df-93c8-3f0a9b839cb1 with <0> Job and <2> Queues. HyperNodesReadyToSchedule: true
I0731 07:32:09.066108       1 enqueue.go:79] Try to enqueue PodGroup to 0 Queues
I0731 07:32:09.066128       1 allocate.go:138] Try to allocate resource to 0 Queues
I0731 07:32:09.066189       1 session.go:577] Close Session 848f2715-4e3b-41df-93c8-3f0a9b839cb1
I0731 07:32:10.067013       1 cache.go:1581] "SnapShot for scheduling" jobNum=0 QueueNum=2 NodeNum=1
I0731 07:32:10.067059       1 session.go:1036] Start adjusting jobs' network topology spec according to hyperNodeTierNameMap map[]
I0731 07:32:10.067083       1 session.go:1079] Finish adjusting jobs' network topology spec according to hyperNodeTierNameMap map[]
I0731 07:32:10.067110       1 session.go:279] Open Session b8410916-9eea-4d65-b78b-f9f1e4b84ae2 with <0> Job and <2> Queues. HyperNodesReadyToSchedule: true
I0731 07:32:10.067565       1 enqueue.go:79] Try to enqueue PodGroup to 0 Queues
I0731 07:32:10.067586       1 allocate.go:138] Try to allocate resource to 0 Queues
I0731 07:32:10.067659       1 session.go:577] Close Session b8410916-9eea-4d65-b78b-f9f1e4b84ae2
I0731 07:32:11.068363       1 cache.go:1581] "SnapShot for scheduling" jobNum=0 QueueNum=2 NodeNum=1
I0731 07:32:11.068405       1 session.go:1036] Start adjusting jobs' network topology spec according to hyperNodeTierNameMap map[]
I0731 07:32:11.068429       1 session.go:1079] Finish adjusting jobs' network topology spec according to hyperNodeTierNameMap map[]
I0731 07:32:11.068455       1 session.go:279] Open Session fddc3249-b69f-4cec-a1e5-9d96199de89a with <0> Job and <2> Queues. HyperNodesReadyToSchedule: true
I0731 07:32:11.068898       1 enqueue.go:79] Try to enqueue PodGroup to 0 Queues
I0731 07:32:11.068937       1 allocate.go:138] Try to allocate resource to 0 Queues
I0731 07:32:11.069013       1 session.go:577] Close Session fddc3249-b69f-4cec-a1e5-9d96199de89a
I0731 07:32:12.070268       1 cache.go:1581] "SnapShot for scheduling" jobNum=0 QueueNum=2 NodeNum=1
I0731 07:32:12.070308       1 session.go:1036] Start adjusting jobs' network topology spec according to hyperNodeTierNameMap map[]
I0731 07:32:12.070331       1 session.go:1079] Finish adjusting jobs' network topology spec according to hyperNodeTierNameMap map[]
I0731 07:32:12.070357       1 session.go:279] Open Session d2ac366a-acb9-4733-b455-6944b2511280 with <0> Job and <2> Queues. HyperNodesReadyToSchedule: true
I0731 07:32:12.070802       1 enqueue.go:79] Try to enqueue PodGroup to 0 Queues
I0731 07:32:12.070825       1 allocate.go:138] Try to allocate resource to 0 Queues
I0731 07:32:12.070896       1 session.go:577] Close Session d2ac366a-acb9-4733-b455-6944b2511280
I0731 07:32:13.072109       1 cache.go:1581] "SnapShot for scheduling" jobNum=0 QueueNum=2 NodeNum=1
I0731 07:32:13.072154       1 session.go:1036] Start adjusting jobs' network topology spec according to hyperNodeTierNameMap map[]
I0731 07:32:13.072178       1 session.go:1079] Finish adjusting jobs' network topology spec according to hyperNodeTierNameMap map[]
I0731 07:32:13.072205       1 session.go:279] Open Session ecc3beaf-8ed1-4504-a526-c79e2fdd7809 with <0> Job and <2> Queues. HyperNodesReadyToSchedule: true
I0731 07:32:13.072636       1 enqueue.go:79] Try to enqueue PodGroup to 0 Queues
I0731 07:32:13.072658       1 allocate.go:138] Try to allocate resource to 0 Queues
I0731 07:32:13.072733       1 session.go:577] Close Session ecc3beaf-8ed1-4504-a526-c79e2fdd7809
I0731 07:32:14.073762       1 cache.go:1581] "SnapShot for scheduling" jobNum=0 QueueNum=2 NodeNum=1
I0731 07:32:14.073809       1 session.go:1036] Start adjusting jobs' network topology spec according to hyperNodeTierNameMap map[]
I0731 07:32:14.073833       1 session.go:1079] Finish adjusting jobs' network topology spec according to hyperNodeTierNameMap map[]
I0731 07:32:14.073856       1 session.go:279] Open Session e9fddfa9-31f8-48e0-a4ad-f47b1d14f916 with <0> Job and <2> Queues. HyperNodesReadyToSchedule: true
I0731 07:32:14.074303       1 enqueue.go:79] Try to enqueue PodGroup to 0 Queues
I0731 07:32:14.074324       1 allocate.go:138] Try to allocate resource to 0 Queues
I0731 07:32:14.074398       1 session.go:577] Close Session e9fddfa9-31f8-48e0-a4ad-f47b1d14f916
I0731 07:32:15.075456       1 cache.go:1581] "SnapShot for scheduling" jobNum=0 QueueNum=2 NodeNum=1
I0731 07:32:15.075520       1 session.go:1036] Start adjusting jobs' network topology spec according to hyperNodeTierNameMap map[]
I0731 07:32:15.075549       1 session.go:1079] Finish adjusting jobs' network topology spec according to hyperNodeTierNameMap map[]
I0731 07:32:15.075578       1 session.go:279] Open Session 6bd427ce-1eef-445e-bd33-4d2bbf5bec09 with <0> Job and <2> Queues. HyperNodesReadyToSchedule: true
I0731 07:32:15.076099       1 enqueue.go:79] Try to enqueue PodGroup to 0 Queues
I0731 07:32:15.076125       1 allocate.go:138] Try to allocate resource to 0 Queues
I0731 07:32:15.076216       1 session.go:577] Close Session 6bd427ce-1eef-445e-bd33-4d2bbf5bec09
I0731 07:32:16.076839       1 cache.go:1581] "SnapShot for scheduling" jobNum=0 QueueNum=2 NodeNum=1
I0731 07:32:16.076899       1 session.go:1036] Start adjusting jobs' network topology spec according to hyperNodeTierNameMap map[]
I0731 07:32:16.076928       1 session.go:1079] Finish adjusting jobs' network topology spec according to hyperNodeTierNameMap map[]
I0731 07:32:16.076953       1 session.go:279] Open Session f72731c3-0eeb-486b-bd6b-3adba8acaf98 with <0> Job and <2> Queues. HyperNodesReadyToSchedule: true
I0731 07:32:16.077481       1 enqueue.go:79] Try to enqueue PodGroup to 0 Queues
I0731 07:32:16.077507       1 allocate.go:138] Try to allocate resource to 0 Queues
I0731 07:32:16.077595       1 session.go:577] Close Session f72731c3-0eeb-486b-bd6b-3adba8acaf98
I0731 07:32:16.483967       1 cache.go:1771] The metrics type is not set in the volcano scheduler configmap file. As a result, the CPU and memory load information of the node is not collected.
I0731 07:32:17.078553       1 cache.go:1581] "SnapShot for scheduling" jobNum=0 QueueNum=2 NodeNum=1
I0731 07:32:17.078599       1 session.go:1036] Start adjusting jobs' network topology spec according to hyperNodeTierNameMap map[]
I0731 07:32:17.078623       1 session.go:1079] Finish adjusting jobs' network topology spec according to hyperNodeTierNameMap map[]
I0731 07:32:17.078650       1 session.go:279] Open Session 0a6a7631-49b1-49ad-ba1f-2be9bd27b265 with <0> Job and <2> Queues. HyperNodesReadyToSchedule: true
I0731 07:32:17.079109       1 enqueue.go:79] Try to enqueue PodGroup to 0 Queues
I0731 07:32:17.079131       1 allocate.go:138] Try to allocate resource to 0 Queues
I0731 07:32:17.079205       1 session.go:577] Close Session 0a6a7631-49b1-49ad-ba1f-2be9bd27b265
I0731 07:32:18.080098       1 cache.go:1581] "SnapShot for scheduling" jobNum=0 QueueNum=2 NodeNum=1
I0731 07:32:18.080147       1 session.go:1036] Start adjusting jobs' network topology spec according to hyperNodeTierNameMap map[]
I0731 07:32:18.080173       1 session.go:1079] Finish adjusting jobs' network topology spec according to hyperNodeTierNameMap map[]
I0731 07:32:18.080198       1 session.go:279] Open Session a0222622-7e12-4b4d-aa75-54ea1b07f060 with <0> Job and <2> Queues. HyperNodesReadyToSchedule: true
I0731 07:32:18.080672       1 enqueue.go:79] Try to enqueue PodGroup to 0 Queues
I0731 07:32:18.080696       1 allocate.go:138] Try to allocate resource to 0 Queues
I0731 07:32:18.080777       1 session.go:577] Close Session a0222622-7e12-4b4d-aa75-54ea1b07f060
I0731 07:32:19.081823       1 cache.go:1581] "SnapShot for scheduling" jobNum=0 QueueNum=2 NodeNum=1
I0731 07:32:19.081864       1 session.go:1036] Start adjusting jobs' network topology spec according to hyperNodeTierNameMap map[]
I0731 07:32:19.081891       1 session.go:1079] Finish adjusting jobs' network topology spec according to hyperNodeTierNameMap map[]
I0731 07:32:19.081915       1 session.go:279] Open Session 70a15f7d-cf4c-44e1-a470-c2144b375bd1 with <0> Job and <2> Queues. HyperNodesReadyToSchedule: true
I0731 07:32:19.082341       1 enqueue.go:79] Try to enqueue PodGroup to 0 Queues
I0731 07:32:19.082365       1 allocate.go:138] Try to allocate resource to 0 Queues
I0731 07:32:19.082439       1 session.go:577] Close Session 70a15f7d-cf4c-44e1-a470-c2144b375bd1
I0731 07:32:20.083607       1 cache.go:1581] "SnapShot for scheduling" jobNum=0 QueueNum=2 NodeNum=1
I0731 07:32:20.083644       1 session.go:1036] Start adjusting jobs' network topology spec according to hyperNodeTierNameMap map[]
I0731 07:32:20.083664       1 session.go:1079] Finish adjusting jobs' network topology spec according to hyperNodeTierNameMap map[]
I0731 07:32:20.083687       1 session.go:279] Open Session 72e4343c-c636-4919-9b5e-07d7b058baa2 with <0> Job and <2> Queues. HyperNodesReadyToSchedule: true
I0731 07:32:20.084136       1 enqueue.go:79] Try to enqueue PodGroup to 0 Queues
I0731 07:32:20.084157       1 allocate.go:138] Try to allocate resource to 0 Queues
I0731 07:32:20.084222       1 session.go:577] Close Session 72e4343c-c636-4919-9b5e-07d7b058baa2
I0731 07:32:21.085565       1 cache.go:1581] "SnapShot for scheduling" jobNum=0 QueueNum=2 NodeNum=1
I0731 07:32:21.085613       1 session.go:1036] Start adjusting jobs' network topology spec according to hyperNodeTierNameMap map[]
I0731 07:32:21.085637       1 session.go:1079] Finish adjusting jobs' network topology spec according to hyperNodeTierNameMap map[]
I0731 07:32:21.085665       1 session.go:279] Open Session bc442b77-e81a-4912-b6a6-1709514ef34b with <0> Job and <2> Queues. HyperNodesReadyToSchedule: true
I0731 07:32:21.086134       1 enqueue.go:79] Try to enqueue PodGroup to 0 Queues
I0731 07:32:21.086157       1 allocate.go:138] Try to allocate resource to 0 Queues
I0731 07:32:21.086230       1 session.go:577] Close Session bc442b77-e81a-4912-b6a6-1709514ef34b
I0731 07:32:22.087418       1 cache.go:1581] "SnapShot for scheduling" jobNum=0 QueueNum=2 NodeNum=1
I0731 07:32:22.087462       1 session.go:1036] Start adjusting jobs' network topology spec according to hyperNodeTierNameMap map[]
I0731 07:32:22.087487       1 session.go:1079] Finish adjusting jobs' network topology spec according to hyperNodeTierNameMap map[]
I0731 07:32:22.087514       1 session.go:279] Open Session 1f4b62f6-3109-4d9b-bd34-48055bdf6980 with <0> Job and <2> Queues. HyperNodesReadyToSchedule: true
I0731 07:32:22.087985       1 enqueue.go:79] Try to enqueue PodGroup to 0 Queues
I0731 07:32:22.088008       1 allocate.go:138] Try to allocate resource to 0 Queues
I0731 07:32:22.088078       1 session.go:577] Close Session 1f4b62f6-3109-4d9b-bd34-48055bdf6980
I0731 07:32:23.089303       1 cache.go:1581] "SnapShot for scheduling" jobNum=0 QueueNum=2 NodeNum=1
I0731 07:32:23.089348       1 session.go:1036] Start adjusting jobs' network topology spec according to hyperNodeTierNameMap map[]
I0731 07:32:23.089374       1 session.go:1079] Finish adjusting jobs' network topology spec according to hyperNodeTierNameMap map[]
I0731 07:32:23.089400       1 session.go:279] Open Session 47e11383-aaf7-4798-b6c9-261d1e8f57ad with <0> Job and <2> Queues. HyperNodesReadyToSchedule: true
I0731 07:32:23.089832       1 enqueue.go:79] Try to enqueue PodGroup to 0 Queues
I0731 07:32:23.089856       1 allocate.go:138] Try to allocate resource to 0 Queues
I0731 07:32:23.089927       1 session.go:577] Close Session 47e11383-aaf7-4798-b6c9-261d1e8f57ad
I0731 07:32:24.090999       1 cache.go:1581] "SnapShot for scheduling" jobNum=0 QueueNum=2 NodeNum=1
I0731 07:32:24.091045       1 session.go:1036] Start adjusting jobs' network topology spec according to hyperNodeTierNameMap map[]
I0731 07:32:24.091068       1 session.go:1079] Finish adjusting jobs' network topology spec according to hyperNodeTierNameMap map[]
I0731 07:32:24.091091       1 session.go:279] Open Session 7b2649a1-558f-449a-ba95-a8f20f7dc857 with <0> Job and <2> Queues. HyperNodesReadyToSchedule: true
I0731 07:32:24.091542       1 enqueue.go:79] Try to enqueue PodGroup to 0 Queues
I0731 07:32:24.091565       1 allocate.go:138] Try to allocate resource to 0 Queues
I0731 07:32:24.091636       1 session.go:577] Close Session 7b2649a1-558f-449a-ba95-a8f20f7dc857
I0731 07:32:25.092944       1 cache.go:1581] "SnapShot for scheduling" jobNum=0 QueueNum=2 NodeNum=1
I0731 07:32:25.092988       1 session.go:1036] Start adjusting jobs' network topology spec according to hyperNodeTierNameMap map[]
I0731 07:32:25.093011       1 session.go:1079] Finish adjusting jobs' network topology spec according to hyperNodeTierNameMap map[]
I0731 07:32:25.093035       1 session.go:279] Open Session d5dff28d-54d9-4363-af4b-450c939de6e0 with <0> Job and <2> Queues. HyperNodesReadyToSchedule: true
I0731 07:32:25.093546       1 enqueue.go:79] Try to enqueue PodGroup to 0 Queues
I0731 07:32:25.093568       1 allocate.go:138] Try to allocate resource to 0 Queues
I0731 07:32:25.093639       1 session.go:577] Close Session d5dff28d-54d9-4363-af4b-450c939de6e0
I0731 07:32:26.094654       1 cache.go:1581] "SnapShot for scheduling" jobNum=0 QueueNum=2 NodeNum=1
I0731 07:32:26.094704       1 session.go:1036] Start adjusting jobs' network topology spec according to hyperNodeTierNameMap map[]
I0731 07:32:26.094742       1 session.go:1079] Finish adjusting jobs' network topology spec according to hyperNodeTierNameMap map[]
I0731 07:32:26.094767       1 session.go:279] Open Session 608d44cd-027f-4fec-8e4c-3132e923b072 with <0> Job and <2> Queues. HyperNodesReadyToSchedule: true
I0731 07:32:26.095289       1 enqueue.go:79] Try to enqueue PodGroup to 0 Queues
I0731 07:32:26.095320       1 allocate.go:138] Try to allocate resource to 0 Queues
I0731 07:32:26.095399       1 session.go:577] Close Session 608d44cd-027f-4fec-8e4c-3132e923b072
I0731 07:32:27.096371       1 cache.go:1581] "SnapShot for scheduling" jobNum=0 QueueNum=2 NodeNum=1
I0731 07:32:27.096418       1 session.go:1036] Start adjusting jobs' network topology spec according to hyperNodeTierNameMap map[]
I0731 07:32:27.096444       1 session.go:1079] Finish adjusting jobs' network topology spec according to hyperNodeTierNameMap map[]
I0731 07:32:27.096467       1 session.go:279] Open Session d5a23a51-5861-4028-8ec7-e684787fb48a with <0> Job and <2> Queues. HyperNodesReadyToSchedule: true
I0731 07:32:27.096945       1 enqueue.go:79] Try to enqueue PodGroup to 0 Queues
I0731 07:32:27.096968       1 allocate.go:138] Try to allocate resource to 0 Queues
I0731 07:32:27.097043       1 session.go:577] Close Session d5a23a51-5861-4028-8ec7-e684787fb48a
I0731 07:32:28.098223       1 cache.go:1581] "SnapShot for scheduling" jobNum=0 QueueNum=2 NodeNum=1
I0731 07:32:28.098253       1 session.go:1036] Start adjusting jobs' network topology spec according to hyperNodeTierNameMap map[]
I0731 07:32:28.098273       1 session.go:1079] Finish adjusting jobs' network topology spec according to hyperNodeTierNameMap map[]
I0731 07:32:28.098296       1 session.go:279] Open Session 177731b6-57db-4a0c-8162-a527991c127c with <0> Job and <2> Queues. HyperNodesReadyToSchedule: true
I0731 07:32:28.098651       1 enqueue.go:79] Try to enqueue PodGroup to 0 Queues
I0731 07:32:28.098671       1 allocate.go:138] Try to allocate resource to 0 Queues
I0731 07:32:28.098737       1 session.go:577] Close Session 177731b6-57db-4a0c-8162-a527991c127c
I0731 07:32:29.100960       1 cache.go:1581] "SnapShot for scheduling" jobNum=0 QueueNum=2 NodeNum=1
I0731 07:32:29.101097       1 session.go:1036] Start adjusting jobs' network topology spec according to hyperNodeTierNameMap map[]
I0731 07:32:29.101398       1 session.go:1079] Finish adjusting jobs' network topology spec according to hyperNodeTierNameMap map[]
I0731 07:32:29.101575       1 session.go:279] Open Session 21d5a383-6820-4f19-a144-a0976c3bafa2 with <0> Job and <2> Queues. HyperNodesReadyToSchedule: true
I0731 07:32:29.102803       1 enqueue.go:79] Try to enqueue PodGroup to 0 Queues
I0731 07:32:29.102833       1 allocate.go:138] Try to allocate resource to 0 Queues
I0731 07:32:29.102959       1 session.go:577] Close Session 21d5a383-6820-4f19-a144-a0976c3bafa2
I0731 07:32:30.104052       1 cache.go:1581] "SnapShot for scheduling" jobNum=0 QueueNum=2 NodeNum=1
I0731 07:32:30.104103       1 session.go:1036] Start adjusting jobs' network topology spec according to hyperNodeTierNameMap map[]
I0731 07:32:30.104130       1 session.go:1079] Finish adjusting jobs' network topology spec according to hyperNodeTierNameMap map[]
I0731 07:32:30.104155       1 session.go:279] Open Session 8e222216-2fb3-417e-897e-88e8efa251a6 with <0> Job and <2> Queues. HyperNodesReadyToSchedule: true
I0731 07:32:30.104664       1 enqueue.go:79] Try to enqueue PodGroup to 0 Queues
I0731 07:32:30.104688       1 allocate.go:138] Try to allocate resource to 0 Queues
I0731 07:32:30.104773       1 session.go:577] Close Session 8e222216-2fb3-417e-897e-88e8efa251a6
I0731 07:32:31.105719       1 cache.go:1581] "SnapShot for scheduling" jobNum=0 QueueNum=2 NodeNum=1
I0731 07:32:31.105769       1 session.go:1036] Start adjusting jobs' network topology spec according to hyperNodeTierNameMap map[]
I0731 07:32:31.105793       1 session.go:1079] Finish adjusting jobs' network topology spec according to hyperNodeTierNameMap map[]
I0731 07:32:31.105817       1 session.go:279] Open Session 9b83082f-c3cb-4cab-a350-85e79a098327 with <0> Job and <2> Queues. HyperNodesReadyToSchedule: true
I0731 07:32:31.106327       1 enqueue.go:79] Try to enqueue PodGroup to 0 Queues
I0731 07:32:31.106352       1 allocate.go:138] Try to allocate resource to 0 Queues
I0731 07:32:31.106439       1 session.go:577] Close Session 9b83082f-c3cb-4cab-a350-85e79a098327
I0731 07:32:32.107607       1 cache.go:1581] "SnapShot for scheduling" jobNum=0 QueueNum=2 NodeNum=1
I0731 07:32:32.107650       1 session.go:1036] Start adjusting jobs' network topology spec according to hyperNodeTierNameMap map[]
I0731 07:32:32.107674       1 session.go:1079] Finish adjusting jobs' network topology spec according to hyperNodeTierNameMap map[]
I0731 07:32:32.107699       1 session.go:279] Open Session 1f3c110a-717d-4aa5-9baf-0a51bebed2e3 with <0> Job and <2> Queues. HyperNodesReadyToSchedule: true
I0731 07:32:32.108166       1 enqueue.go:79] Try to enqueue PodGroup to 0 Queues
I0731 07:32:32.108188       1 allocate.go:138] Try to allocate resource to 0 Queues
I0731 07:32:32.108260       1 session.go:577] Close Session 1f3c110a-717d-4aa5-9baf-0a51bebed2e3
I0731 07:32:33.109404       1 cache.go:1581] "SnapShot for scheduling" jobNum=0 QueueNum=2 NodeNum=1
I0731 07:32:33.109455       1 session.go:1036] Start adjusting jobs' network topology spec according to hyperNodeTierNameMap map[]
I0731 07:32:33.109481       1 session.go:1079] Finish adjusting jobs' network topology spec according to hyperNodeTierNameMap map[]
I0731 07:32:33.109505       1 session.go:279] Open Session 9901ead2-e003-467f-b88b-3597ec0775ec with <0> Job and <2> Queues. HyperNodesReadyToSchedule: true
I0731 07:32:33.109975       1 enqueue.go:79] Try to enqueue PodGroup to 0 Queues
I0731 07:32:33.109997       1 allocate.go:138] Try to allocate resource to 0 Queues
I0731 07:32:33.110069       1 session.go:577] Close Session 9901ead2-e003-467f-b88b-3597ec0775ec
I0731 07:32:34.110975       1 cache.go:1581] "SnapShot for scheduling" jobNum=0 QueueNum=2 NodeNum=1
I0731 07:32:34.111020       1 session.go:1036] Start adjusting jobs' network topology spec according to hyperNodeTierNameMap map[]
I0731 07:32:34.111044       1 session.go:1079] Finish adjusting jobs' network topology spec according to hyperNodeTierNameMap map[]
I0731 07:32:34.111068       1 session.go:279] Open Session 79132294-f059-49b1-b74e-745956cc69d8 with <0> Job and <2> Queues. HyperNodesReadyToSchedule: true
I0731 07:32:34.111535       1 enqueue.go:79] Try to enqueue PodGroup to 0 Queues
I0731 07:32:34.111558       1 allocate.go:138] Try to allocate resource to 0 Queues
I0731 07:32:34.111633       1 session.go:577] Close Session 79132294-f059-49b1-b74e-745956cc69d8
I0731 07:32:35.112918       1 cache.go:1581] "SnapShot for scheduling" jobNum=0 QueueNum=2 NodeNum=1
I0731 07:32:35.112960       1 session.go:1036] Start adjusting jobs' network topology spec according to hyperNodeTierNameMap map[]
I0731 07:32:35.112983       1 session.go:1079] Finish adjusting jobs' network topology spec according to hyperNodeTierNameMap map[]
I0731 07:32:35.113007       1 session.go:279] Open Session b1ef6949-a065-4515-8085-78bb0c9ea135 with <0> Job and <2> Queues. HyperNodesReadyToSchedule: true
I0731 07:32:35.113466       1 enqueue.go:79] Try to enqueue PodGroup to 0 Queues
I0731 07:32:35.113489       1 allocate.go:138] Try to allocate resource to 0 Queues
I0731 07:32:35.113560       1 session.go:577] Close Session b1ef6949-a065-4515-8085-78bb0c9ea135
I0731 07:32:36.114023       1 cache.go:1581] "SnapShot for scheduling" jobNum=0 QueueNum=2 NodeNum=1
I0731 07:32:36.114049       1 session.go:1036] Start adjusting jobs' network topology spec according to hyperNodeTierNameMap map[]
I0731 07:32:36.114067       1 session.go:1079] Finish adjusting jobs' network topology spec according to hyperNodeTierNameMap map[]
I0731 07:32:36.114091       1 session.go:279] Open Session b0559742-02db-420e-97b4-6981eb37836b with <0> Job and <2> Queues. HyperNodesReadyToSchedule: true
I0731 07:32:36.114444       1 enqueue.go:79] Try to enqueue PodGroup to 0 Queues
I0731 07:32:36.114463       1 allocate.go:138] Try to allocate resource to 0 Queues
I0731 07:32:36.114517       1 session.go:577] Close Session b0559742-02db-420e-97b4-6981eb37836b
I0731 07:32:37.115648       1 cache.go:1581] "SnapShot for scheduling" jobNum=0 QueueNum=2 NodeNum=1
I0731 07:32:37.115693       1 session.go:1036] Start adjusting jobs' network topology spec according to hyperNodeTierNameMap map[]
I0731 07:32:37.115716       1 session.go:1079] Finish adjusting jobs' network topology spec according to hyperNodeTierNameMap map[]
I0731 07:32:37.115740       1 session.go:279] Open Session 834fa5a5-b0ae-458f-b07d-a854c43a5d40 with <0> Job and <2> Queues. HyperNodesReadyToSchedule: true
I0731 07:32:37.116207       1 enqueue.go:79] Try to enqueue PodGroup to 0 Queues
I0731 07:32:37.116229       1 allocate.go:138] Try to allocate resource to 0 Queues
I0731 07:32:37.116305       1 session.go:577] Close Session 834fa5a5-b0ae-458f-b07d-a854c43a5d40
I0731 07:32:38.117625       1 cache.go:1581] "SnapShot for scheduling" jobNum=0 QueueNum=2 NodeNum=1
I0731 07:32:38.117672       1 session.go:1036] Start adjusting jobs' network topology spec according to hyperNodeTierNameMap map[]
I0731 07:32:38.117697       1 session.go:1079] Finish adjusting jobs' network topology spec according to hyperNodeTierNameMap map[]
I0731 07:32:38.117721       1 session.go:279] Open Session b4bab714-2112-4a9a-a4b8-400764709b2b with <0> Job and <2> Queues. HyperNodesReadyToSchedule: true
I0731 07:32:38.118172       1 enqueue.go:79] Try to enqueue PodGroup to 0 Queues
I0731 07:32:38.118195       1 allocate.go:138] Try to allocate resource to 0 Queues
I0731 07:32:38.118270       1 session.go:577] Close Session b4bab714-2112-4a9a-a4b8-400764709b2b
I0731 07:32:39.118898       1 cache.go:1581] "SnapShot for scheduling" jobNum=0 QueueNum=2 NodeNum=1
I0731 07:32:39.118943       1 session.go:1036] Start adjusting jobs' network topology spec according to hyperNodeTierNameMap map[]
I0731 07:32:39.118968       1 session.go:1079] Finish adjusting jobs' network topology spec according to hyperNodeTierNameMap map[]
I0731 07:32:39.118994       1 session.go:279] Open Session 1489f2ef-9bbd-4247-ad92-45995ea6adb1 with <0> Job and <2> Queues. HyperNodesReadyToSchedule: true
I0731 07:32:39.119455       1 enqueue.go:79] Try to enqueue PodGroup to 0 Queues
I0731 07:32:39.119478       1 allocate.go:138] Try to allocate resource to 0 Queues
I0731 07:32:39.119550       1 session.go:577] Close Session 1489f2ef-9bbd-4247-ad92-45995ea6adb1
I0731 07:32:40.120105       1 cache.go:1581] "SnapShot for scheduling" jobNum=0 QueueNum=2 NodeNum=1
I0731 07:32:40.120150       1 session.go:1036] Start adjusting jobs' network topology spec according to hyperNodeTierNameMap map[]
I0731 07:32:40.120174       1 session.go:1079] Finish adjusting jobs' network topology spec according to hyperNodeTierNameMap map[]
I0731 07:32:40.120198       1 session.go:279] Open Session 40f03074-b3c7-4359-a7a6-49ec8ab12e9e with <0> Job and <2> Queues. HyperNodesReadyToSchedule: true
I0731 07:32:40.120625       1 enqueue.go:79] Try to enqueue PodGroup to 0 Queues
I0731 07:32:40.120646       1 allocate.go:138] Try to allocate resource to 0 Queues
I0731 07:32:40.120718       1 session.go:577] Close Session 40f03074-b3c7-4359-a7a6-49ec8ab12e9e
I0731 07:32:41.121861       1 cache.go:1581] "SnapShot for scheduling" jobNum=0 QueueNum=2 NodeNum=1
I0731 07:32:41.121916       1 session.go:1036] Start adjusting jobs' network topology spec according to hyperNodeTierNameMap map[]
I0731 07:32:41.121943       1 session.go:1079] Finish adjusting jobs' network topology spec according to hyperNodeTierNameMap map[]
I0731 07:32:41.121969       1 session.go:279] Open Session cb16197b-204c-4468-b3f4-f7e75622f4ba with <0> Job and <2> Queues. HyperNodesReadyToSchedule: true
I0731 07:32:41.122489       1 enqueue.go:79] Try to enqueue PodGroup to 0 Queues
I0731 07:32:41.122512       1 allocate.go:138] Try to allocate resource to 0 Queues
I0731 07:32:41.122593       1 session.go:577] Close Session cb16197b-204c-4468-b3f4-f7e75622f4ba
I0731 07:32:42.123577       1 cache.go:1581] "SnapShot for scheduling" jobNum=0 QueueNum=2 NodeNum=1
I0731 07:32:42.123653       1 session.go:1036] Start adjusting jobs' network topology spec according to hyperNodeTierNameMap map[]
I0731 07:32:42.123678       1 session.go:1079] Finish adjusting jobs' network topology spec according to hyperNodeTierNameMap map[]
I0731 07:32:42.123701       1 session.go:279] Open Session 5185b4a5-7a7a-40f0-b714-2abc1c9ad9bf with <0> Job and <2> Queues. HyperNodesReadyToSchedule: true
I0731 07:32:42.124177       1 enqueue.go:79] Try to enqueue PodGroup to 0 Queues
I0731 07:32:42.124198       1 allocate.go:138] Try to allocate resource to 0 Queues
I0731 07:32:42.124273       1 session.go:577] Close Session 5185b4a5-7a7a-40f0-b714-2abc1c9ad9bf
I0731 07:32:43.125681       1 cache.go:1581] "SnapShot for scheduling" jobNum=0 QueueNum=2 NodeNum=1
I0731 07:32:43.125735       1 session.go:1036] Start adjusting jobs' network topology spec according to hyperNodeTierNameMap map[]
I0731 07:32:43.125760       1 session.go:1079] Finish adjusting jobs' network topology spec according to hyperNodeTierNameMap map[]
I0731 07:32:43.125785       1 session.go:279] Open Session 3dac3045-0136-4ee7-aa63-4c354c7ef7ff with <0> Job and <2> Queues. HyperNodesReadyToSchedule: true
I0731 07:32:43.126304       1 enqueue.go:79] Try to enqueue PodGroup to 0 Queues
I0731 07:32:43.126327       1 allocate.go:138] Try to allocate resource to 0 Queues
I0731 07:32:43.126407       1 session.go:577] Close Session 3dac3045-0136-4ee7-aa63-4c354c7ef7ff
I0731 07:32:44.126812       1 cache.go:1581] "SnapShot for scheduling" jobNum=0 QueueNum=2 NodeNum=1
I0731 07:32:44.126859       1 session.go:1036] Start adjusting jobs' network topology spec according to hyperNodeTierNameMap map[]
I0731 07:32:44.126884       1 session.go:1079] Finish adjusting jobs' network topology spec according to hyperNodeTierNameMap map[]
I0731 07:32:44.126909       1 session.go:279] Open Session ab715fdb-0f53-4827-b5d0-c93a6a9ddcc3 with <0> Job and <2> Queues. HyperNodesReadyToSchedule: true
I0731 07:32:44.127427       1 enqueue.go:79] Try to enqueue PodGroup to 0 Queues
I0731 07:32:44.127450       1 allocate.go:138] Try to allocate resource to 0 Queues
I0731 07:32:44.127529       1 session.go:577] Close Session ab715fdb-0f53-4827-b5d0-c93a6a9ddcc3
I0731 07:32:45.128517       1 cache.go:1581] "SnapShot for scheduling" jobNum=0 QueueNum=2 NodeNum=1
I0731 07:32:45.128565       1 session.go:1036] Start adjusting jobs' network topology spec according to hyperNodeTierNameMap map[]
I0731 07:32:45.128589       1 session.go:1079] Finish adjusting jobs' network topology spec according to hyperNodeTierNameMap map[]
I0731 07:32:45.128617       1 session.go:279] Open Session b29530e6-6c12-4ae0-a6be-3b1fa484cb1c with <0> Job and <2> Queues. HyperNodesReadyToSchedule: true
I0731 07:32:45.129196       1 enqueue.go:79] Try to enqueue PodGroup to 0 Queues
I0731 07:32:45.129221       1 allocate.go:138] Try to allocate resource to 0 Queues
I0731 07:32:45.129297       1 session.go:577] Close Session b29530e6-6c12-4ae0-a6be-3b1fa484cb1c
I0731 07:32:46.129835       1 cache.go:1581] "SnapShot for scheduling" jobNum=0 QueueNum=2 NodeNum=1
I0731 07:32:46.129883       1 session.go:1036] Start adjusting jobs' network topology spec according to hyperNodeTierNameMap map[]
I0731 07:32:46.129908       1 session.go:1079] Finish adjusting jobs' network topology spec according to hyperNodeTierNameMap map[]
I0731 07:32:46.129933       1 session.go:279] Open Session 20c995ef-7904-40c4-8d8e-ac284e3933d8 with <0> Job and <2> Queues. HyperNodesReadyToSchedule: true
I0731 07:32:46.130395       1 enqueue.go:79] Try to enqueue PodGroup to 0 Queues
I0731 07:32:46.130419       1 allocate.go:138] Try to allocate resource to 0 Queues
I0731 07:32:46.130493       1 session.go:577] Close Session 20c995ef-7904-40c4-8d8e-ac284e3933d8
I0731 07:32:46.484351       1 cache.go:1771] The metrics type is not set in the volcano scheduler configmap file. As a result, the CPU and memory load information of the node is not collected.
I0731 07:32:47.131760       1 cache.go:1581] "SnapShot for scheduling" jobNum=0 QueueNum=2 NodeNum=1
I0731 07:32:47.131795       1 session.go:1036] Start adjusting jobs' network topology spec according to hyperNodeTierNameMap map[]
I0731 07:32:47.131814       1 session.go:1079] Finish adjusting jobs' network topology spec according to hyperNodeTierNameMap map[]
I0731 07:32:47.131836       1 session.go:279] Open Session 08eaecd5-76f5-4c11-8d5c-3a8347ca1042 with <0> Job and <2> Queues. HyperNodesReadyToSchedule: true
I0731 07:32:47.132191       1 enqueue.go:79] Try to enqueue PodGroup to 0 Queues
I0731 07:32:47.132209       1 allocate.go:138] Try to allocate resource to 0 Queues
I0731 07:32:47.132269       1 session.go:577] Close Session 08eaecd5-76f5-4c11-8d5c-3a8347ca1042
I0731 07:32:48.132951       1 cache.go:1581] "SnapShot for scheduling" jobNum=0 QueueNum=2 NodeNum=1
I0731 07:32:48.132997       1 session.go:1036] Start adjusting jobs' network topology spec according to hyperNodeTierNameMap map[]
I0731 07:32:48.133022       1 session.go:1079] Finish adjusting jobs' network topology spec according to hyperNodeTierNameMap map[]
I0731 07:32:48.133045       1 session.go:279] Open Session 393cc231-dc28-4d0e-bc18-fa5d9b401559 with <0> Job and <2> Queues. HyperNodesReadyToSchedule: true
I0731 07:32:48.133494       1 enqueue.go:79] Try to enqueue PodGroup to 0 Queues
I0731 07:32:48.133516       1 allocate.go:138] Try to allocate resource to 0 Queues
I0731 07:32:48.133589       1 session.go:577] Close Session 393cc231-dc28-4d0e-bc18-fa5d9b401559
I0731 07:32:49.133848       1 cache.go:1581] "SnapShot for scheduling" jobNum=0 QueueNum=2 NodeNum=1
I0731 07:32:49.133885       1 session.go:1036] Start adjusting jobs' network topology spec according to hyperNodeTierNameMap map[]
I0731 07:32:49.133908       1 session.go:1079] Finish adjusting jobs' network topology spec according to hyperNodeTierNameMap map[]
I0731 07:32:49.133931       1 session.go:279] Open Session 17c415ab-f77d-4a79-bfaf-6d5f2dbc984e with <0> Job and <2> Queues. HyperNodesReadyToSchedule: true
I0731 07:32:49.134313       1 enqueue.go:79] Try to enqueue PodGroup to 0 Queues
I0731 07:32:49.134333       1 allocate.go:138] Try to allocate resource to 0 Queues
I0731 07:32:49.134397       1 session.go:577] Close Session 17c415ab-f77d-4a79-bfaf-6d5f2dbc984e
I0731 07:32:50.135043       1 cache.go:1581] "SnapShot for scheduling" jobNum=0 QueueNum=2 NodeNum=1
I0731 07:32:50.135084       1 session.go:1036] Start adjusting jobs' network topology spec according to hyperNodeTierNameMap map[]
I0731 07:32:50.135110       1 session.go:1079] Finish adjusting jobs' network topology spec according to hyperNodeTierNameMap map[]
I0731 07:32:50.135134       1 session.go:279] Open Session 48824a72-7bc7-4d3f-9d1d-3365a6720ec3 with <0> Job and <2> Queues. HyperNodesReadyToSchedule: true
I0731 07:32:50.135676       1 enqueue.go:79] Try to enqueue PodGroup to 0 Queues
I0731 07:32:50.135697       1 allocate.go:138] Try to allocate resource to 0 Queues
I0731 07:32:50.135770       1 session.go:577] Close Session 48824a72-7bc7-4d3f-9d1d-3365a6720ec3
I0731 07:32:51.136128       1 cache.go:1581] "SnapShot for scheduling" jobNum=0 QueueNum=2 NodeNum=1
I0731 07:32:51.136173       1 session.go:1036] Start adjusting jobs' network topology spec according to hyperNodeTierNameMap map[]
I0731 07:32:51.136196       1 session.go:1079] Finish adjusting jobs' network topology spec according to hyperNodeTierNameMap map[]
I0731 07:32:51.136225       1 session.go:279] Open Session dda00595-f011-48e8-bdeb-1bd5e4037f6b with <0> Job and <2> Queues. HyperNodesReadyToSchedule: true
I0731 07:32:51.136686       1 enqueue.go:79] Try to enqueue PodGroup to 0 Queues
I0731 07:32:51.136710       1 allocate.go:138] Try to allocate resource to 0 Queues
I0731 07:32:51.136778       1 session.go:577] Close Session dda00595-f011-48e8-bdeb-1bd5e4037f6b
I0731 07:32:52.137312       1 cache.go:1581] "SnapShot for scheduling" jobNum=0 QueueNum=2 NodeNum=1
I0731 07:32:52.137352       1 session.go:1036] Start adjusting jobs' network topology spec according to hyperNodeTierNameMap map[]
I0731 07:32:52.137377       1 session.go:1079] Finish adjusting jobs' network topology spec according to hyperNodeTierNameMap map[]
I0731 07:32:52.137401       1 session.go:279] Open Session 4d290dc4-1bbc-4ce7-8cc9-7bb888e6c1b0 with <0> Job and <2> Queues. HyperNodesReadyToSchedule: true
I0731 07:32:52.137840       1 enqueue.go:79] Try to enqueue PodGroup to 0 Queues
I0731 07:32:52.137864       1 allocate.go:138] Try to allocate resource to 0 Queues
I0731 07:32:52.137937       1 session.go:577] Close Session 4d290dc4-1bbc-4ce7-8cc9-7bb888e6c1b0
I0731 07:32:53.139054       1 cache.go:1581] "SnapShot for scheduling" jobNum=0 QueueNum=2 NodeNum=1
I0731 07:32:53.139081       1 session.go:1036] Start adjusting jobs' network topology spec according to hyperNodeTierNameMap map[]
I0731 07:32:53.139099       1 session.go:1079] Finish adjusting jobs' network topology spec according to hyperNodeTierNameMap map[]
I0731 07:32:53.139121       1 session.go:279] Open Session fd2b22f5-2670-4fe1-b48f-7181b9566e00 with <0> Job and <2> Queues. HyperNodesReadyToSchedule: true
I0731 07:32:53.139445       1 enqueue.go:79] Try to enqueue PodGroup to 0 Queues
I0731 07:32:53.139463       1 allocate.go:138] Try to allocate resource to 0 Queues
I0731 07:32:53.139512       1 session.go:577] Close Session fd2b22f5-2670-4fe1-b48f-7181b9566e00
I0731 07:32:54.140331       1 cache.go:1581] "SnapShot for scheduling" jobNum=0 QueueNum=2 NodeNum=1
I0731 07:32:54.140385       1 session.go:1036] Start adjusting jobs' network topology spec according to hyperNodeTierNameMap map[]
I0731 07:32:54.140410       1 session.go:1079] Finish adjusting jobs' network topology spec according to hyperNodeTierNameMap map[]
I0731 07:32:54.140437       1 session.go:279] Open Session 7ab12f0b-a645-4ea9-b615-6cc3aa18cf7a with <0> Job and <2> Queues. HyperNodesReadyToSchedule: true
I0731 07:32:54.140983       1 enqueue.go:79] Try to enqueue PodGroup to 0 Queues
I0731 07:32:54.141005       1 allocate.go:138] Try to allocate resource to 0 Queues
I0731 07:32:54.141083       1 session.go:577] Close Session 7ab12f0b-a645-4ea9-b615-6cc3aa18cf7a
I0731 07:32:55.142445       1 cache.go:1581] "SnapShot for scheduling" jobNum=0 QueueNum=2 NodeNum=1
I0731 07:32:55.142485       1 session.go:1036] Start adjusting jobs' network topology spec according to hyperNodeTierNameMap map[]
I0731 07:32:55.142510       1 session.go:1079] Finish adjusting jobs' network topology spec according to hyperNodeTierNameMap map[]
I0731 07:32:55.142533       1 session.go:279] Open Session b293b630-28b4-4f45-bb1c-7992d1f4acf4 with <0> Job and <2> Queues. HyperNodesReadyToSchedule: true
I0731 07:32:55.143018       1 enqueue.go:79] Try to enqueue PodGroup to 0 Queues
I0731 07:32:55.143041       1 allocate.go:138] Try to allocate resource to 0 Queues
I0731 07:32:55.143110       1 session.go:577] Close Session b293b630-28b4-4f45-bb1c-7992d1f4acf4
I0731 07:32:56.143698       1 cache.go:1581] "SnapShot for scheduling" jobNum=0 QueueNum=2 NodeNum=1
I0731 07:32:56.143741       1 session.go:1036] Start adjusting jobs' network topology spec according to hyperNodeTierNameMap map[]
I0731 07:32:56.143767       1 session.go:1079] Finish adjusting jobs' network topology spec according to hyperNodeTierNameMap map[]
I0731 07:32:56.143791       1 session.go:279] Open Session 80c4b1a2-97fc-488c-a588-2f2ef1412070 with <0> Job and <2> Queues. HyperNodesReadyToSchedule: true
I0731 07:32:56.144225       1 enqueue.go:79] Try to enqueue PodGroup to 0 Queues
I0731 07:32:56.144245       1 allocate.go:138] Try to allocate resource to 0 Queues
I0731 07:32:56.144317       1 session.go:577] Close Session 80c4b1a2-97fc-488c-a588-2f2ef1412070
I0731 07:32:57.145173       1 cache.go:1581] "SnapShot for scheduling" jobNum=0 QueueNum=2 NodeNum=1
I0731 07:32:57.145229       1 session.go:1036] Start adjusting jobs' network topology spec according to hyperNodeTierNameMap map[]
I0731 07:32:57.145257       1 session.go:1079] Finish adjusting jobs' network topology spec according to hyperNodeTierNameMap map[]
I0731 07:32:57.145283       1 session.go:279] Open Session 591424c8-26b9-4b36-b461-edc6bcd5080f with <0> Job and <2> Queues. HyperNodesReadyToSchedule: true
I0731 07:32:57.145732       1 enqueue.go:79] Try to enqueue PodGroup to 0 Queues
I0731 07:32:57.145755       1 allocate.go:138] Try to allocate resource to 0 Queues
I0731 07:32:57.145825       1 session.go:577] Close Session 591424c8-26b9-4b36-b461-edc6bcd5080f
I0731 07:32:58.146154       1 cache.go:1581] "SnapShot for scheduling" jobNum=0 QueueNum=2 NodeNum=1
I0731 07:32:58.146197       1 session.go:1036] Start adjusting jobs' network topology spec according to hyperNodeTierNameMap map[]
I0731 07:32:58.146221       1 session.go:1079] Finish adjusting jobs' network topology spec according to hyperNodeTierNameMap map[]
I0731 07:32:58.146246       1 session.go:279] Open Session 82912fd8-5c9e-49ad-b0fd-b7ab18c2c17f with <0> Job and <2> Queues. HyperNodesReadyToSchedule: true
I0731 07:32:58.146695       1 enqueue.go:79] Try to enqueue PodGroup to 0 Queues
I0731 07:32:58.146735       1 allocate.go:138] Try to allocate resource to 0 Queues
I0731 07:32:58.146804       1 session.go:577] Close Session 82912fd8-5c9e-49ad-b0fd-b7ab18c2c17f
I0731 07:32:59.147942       1 cache.go:1581] "SnapShot for scheduling" jobNum=0 QueueNum=2 NodeNum=1
I0731 07:32:59.147971       1 session.go:1036] Start adjusting jobs' network topology spec according to hyperNodeTierNameMap map[]
I0731 07:32:59.147986       1 session.go:1079] Finish adjusting jobs' network topology spec according to hyperNodeTierNameMap map[]
I0731 07:32:59.148000       1 session.go:279] Open Session 3cec2a3a-4f7c-484b-b784-aaa5e813b36d with <0> Job and <2> Queues. HyperNodesReadyToSchedule: true
I0731 07:32:59.148308       1 enqueue.go:79] Try to enqueue PodGroup to 0 Queues
I0731 07:32:59.148322       1 allocate.go:138] Try to allocate resource to 0 Queues
I0731 07:32:59.148365       1 session.go:577] Close Session 3cec2a3a-4f7c-484b-b784-aaa5e813b36d
I0731 07:33:00.149505       1 cache.go:1581] "SnapShot for scheduling" jobNum=0 QueueNum=2 NodeNum=1
I0731 07:33:00.149535       1 session.go:1036] Start adjusting jobs' network topology spec according to hyperNodeTierNameMap map[]
I0731 07:33:00.149551       1 session.go:1079] Finish adjusting jobs' network topology spec according to hyperNodeTierNameMap map[]
I0731 07:33:00.149565       1 session.go:279] Open Session 289b57ab-02e8-4bee-92d0-a2783423d2b0 with <0> Job and <2> Queues. HyperNodesReadyToSchedule: true
I0731 07:33:00.149859       1 enqueue.go:79] Try to enqueue PodGroup to 0 Queues
I0731 07:33:00.149874       1 allocate.go:138] Try to allocate resource to 0 Queues
I0731 07:33:00.149924       1 session.go:577] Close Session 289b57ab-02e8-4bee-92d0-a2783423d2b0
I0731 07:33:01.151136       1 cache.go:1581] "SnapShot for scheduling" jobNum=0 QueueNum=2 NodeNum=1
I0731 07:33:01.151177       1 session.go:1036] Start adjusting jobs' network topology spec according to hyperNodeTierNameMap map[]
I0731 07:33:01.151200       1 session.go:1079] Finish adjusting jobs' network topology spec according to hyperNodeTierNameMap map[]
I0731 07:33:01.151225       1 session.go:279] Open Session 858f8a16-50ba-4893-80bf-593ad960db48 with <0> Job and <2> Queues. HyperNodesReadyToSchedule: true
I0731 07:33:01.151659       1 enqueue.go:79] Try to enqueue PodGroup to 0 Queues
I0731 07:33:01.151680       1 allocate.go:138] Try to allocate resource to 0 Queues
I0731 07:33:01.151749       1 session.go:577] Close Session 858f8a16-50ba-4893-80bf-593ad960db48
I0731 07:33:02.152103       1 cache.go:1581] "SnapShot for scheduling" jobNum=0 QueueNum=2 NodeNum=1
I0731 07:33:02.152147       1 session.go:1036] Start adjusting jobs' network topology spec according to hyperNodeTierNameMap map[]
I0731 07:33:02.152170       1 session.go:1079] Finish adjusting jobs' network topology spec according to hyperNodeTierNameMap map[]
I0731 07:33:02.152194       1 session.go:279] Open Session 855853e3-a617-452a-a34d-34477bc6c994 with <0> Job and <2> Queues. HyperNodesReadyToSchedule: true
I0731 07:33:02.152690       1 enqueue.go:79] Try to enqueue PodGroup to 0 Queues
I0731 07:33:02.152712       1 allocate.go:138] Try to allocate resource to 0 Queues
I0731 07:33:02.152780       1 session.go:577] Close Session 855853e3-a617-452a-a34d-34477bc6c994
I0731 07:33:03.153785       1 cache.go:1581] "SnapShot for scheduling" jobNum=0 QueueNum=2 NodeNum=1
I0731 07:33:03.153832       1 session.go:1036] Start adjusting jobs' network topology spec according to hyperNodeTierNameMap map[]
I0731 07:33:03.153857       1 session.go:1079] Finish adjusting jobs' network topology spec according to hyperNodeTierNameMap map[]
I0731 07:33:03.153884       1 session.go:279] Open Session 773d9244-a128-4b07-984a-42d96453cc14 with <0> Job and <2> Queues. HyperNodesReadyToSchedule: true
I0731 07:33:03.154398       1 enqueue.go:79] Try to enqueue PodGroup to 0 Queues
I0731 07:33:03.154420       1 allocate.go:138] Try to allocate resource to 0 Queues
I0731 07:33:03.154487       1 session.go:577] Close Session 773d9244-a128-4b07-984a-42d96453cc14
I0731 07:33:04.155087       1 cache.go:1581] "SnapShot for scheduling" jobNum=0 QueueNum=2 NodeNum=1
I0731 07:33:04.155146       1 session.go:1036] Start adjusting jobs' network topology spec according to hyperNodeTierNameMap map[]
I0731 07:33:04.155175       1 session.go:1079] Finish adjusting jobs' network topology spec according to hyperNodeTierNameMap map[]
I0731 07:33:04.155200       1 session.go:279] Open Session 1d697afc-5883-4037-9217-f439036b5495 with <0> Job and <2> Queues. HyperNodesReadyToSchedule: true
I0731 07:33:04.155772       1 enqueue.go:79] Try to enqueue PodGroup to 0 Queues
I0731 07:33:04.155798       1 allocate.go:138] Try to allocate resource to 0 Queues
I0731 07:33:04.155889       1 session.go:577] Close Session 1d697afc-5883-4037-9217-f439036b5495
I0731 07:33:05.157306       1 cache.go:1581] "SnapShot for scheduling" jobNum=0 QueueNum=2 NodeNum=1
I0731 07:33:05.157355       1 session.go:1036] Start adjusting jobs' network topology spec according to hyperNodeTierNameMap map[]
I0731 07:33:05.157381       1 session.go:1079] Finish adjusting jobs' network topology spec according to hyperNodeTierNameMap map[]
I0731 07:33:05.157406       1 session.go:279] Open Session cd6bbdfc-7ee3-4964-90b4-b5c0edea5c9b with <0> Job and <2> Queues. HyperNodesReadyToSchedule: true
I0731 07:33:05.157927       1 enqueue.go:79] Try to enqueue PodGroup to 0 Queues
I0731 07:33:05.157950       1 allocate.go:138] Try to allocate resource to 0 Queues
I0731 07:33:05.158030       1 session.go:577] Close Session cd6bbdfc-7ee3-4964-90b4-b5c0edea5c9b
I0731 07:33:06.159237       1 cache.go:1581] "SnapShot for scheduling" jobNum=0 QueueNum=2 NodeNum=1
I0731 07:33:06.159269       1 session.go:1036] Start adjusting jobs' network topology spec according to hyperNodeTierNameMap map[]
I0731 07:33:06.159287       1 session.go:1079] Finish adjusting jobs' network topology spec according to hyperNodeTierNameMap map[]
I0731 07:33:06.159312       1 session.go:279] Open Session 126a6cfa-626f-4511-b295-1f6b050353bc with <0> Job and <2> Queues. HyperNodesReadyToSchedule: true
I0731 07:33:06.159666       1 enqueue.go:79] Try to enqueue PodGroup to 0 Queues
I0731 07:33:06.159685       1 allocate.go:138] Try to allocate resource to 0 Queues
I0731 07:33:06.159737       1 session.go:577] Close Session 126a6cfa-626f-4511-b295-1f6b050353bc
I0731 07:33:07.160517       1 cache.go:1581] "SnapShot for scheduling" jobNum=0 QueueNum=2 NodeNum=1
I0731 07:33:07.160559       1 session.go:1036] Start adjusting jobs' network topology spec according to hyperNodeTierNameMap map[]
I0731 07:33:07.160585       1 session.go:1079] Finish adjusting jobs' network topology spec according to hyperNodeTierNameMap map[]
I0731 07:33:07.160609       1 session.go:279] Open Session 5ee2a0de-f96b-4e37-8daa-7d0c6048b44b with <0> Job and <2> Queues. HyperNodesReadyToSchedule: true
I0731 07:33:07.161074       1 enqueue.go:79] Try to enqueue PodGroup to 0 Queues
I0731 07:33:07.161097       1 allocate.go:138] Try to allocate resource to 0 Queues
I0731 07:33:07.161171       1 session.go:577] Close Session 5ee2a0de-f96b-4e37-8daa-7d0c6048b44b
I0731 07:33:08.161716       1 cache.go:1581] "SnapShot for scheduling" jobNum=0 QueueNum=2 NodeNum=1
I0731 07:33:08.161768       1 session.go:1036] Start adjusting jobs' network topology spec according to hyperNodeTierNameMap map[]
I0731 07:33:08.161792       1 session.go:1079] Finish adjusting jobs' network topology spec according to hyperNodeTierNameMap map[]
I0731 07:33:08.161815       1 session.go:279] Open Session 88a54ff4-0fba-455d-a2c4-d2fd00f4c8ff with <0> Job and <2> Queues. HyperNodesReadyToSchedule: true
I0731 07:33:08.162265       1 enqueue.go:79] Try to enqueue PodGroup to 0 Queues
I0731 07:33:08.162288       1 allocate.go:138] Try to allocate resource to 0 Queues
I0731 07:33:08.162366       1 session.go:577] Close Session 88a54ff4-0fba-455d-a2c4-d2fd00f4c8ff
I0731 07:33:09.163775       1 cache.go:1581] "SnapShot for scheduling" jobNum=0 QueueNum=2 NodeNum=1
I0731 07:33:09.163819       1 session.go:1036] Start adjusting jobs' network topology spec according to hyperNodeTierNameMap map[]
I0731 07:33:09.163843       1 session.go:1079] Finish adjusting jobs' network topology spec according to hyperNodeTierNameMap map[]
I0731 07:33:09.163866       1 session.go:279] Open Session 7d5df5fc-ad5e-4d10-911e-74e3050c3e5d with <0> Job and <2> Queues. HyperNodesReadyToSchedule: true
I0731 07:33:09.164306       1 enqueue.go:79] Try to enqueue PodGroup to 0 Queues
I0731 07:33:09.164329       1 allocate.go:138] Try to allocate resource to 0 Queues
I0731 07:33:09.164403       1 session.go:577] Close Session 7d5df5fc-ad5e-4d10-911e-74e3050c3e5d
I0731 07:33:10.165126       1 cache.go:1581] "SnapShot for scheduling" jobNum=0 QueueNum=2 NodeNum=1
I0731 07:33:10.165179       1 session.go:1036] Start adjusting jobs' network topology spec according to hyperNodeTierNameMap map[]
I0731 07:33:10.165207       1 session.go:1079] Finish adjusting jobs' network topology spec according to hyperNodeTierNameMap map[]
I0731 07:33:10.165232       1 session.go:279] Open Session d22dbd64-2dcb-4be3-818a-fcd729d4013b with <0> Job and <2> Queues. HyperNodesReadyToSchedule: true
I0731 07:33:10.165799       1 enqueue.go:79] Try to enqueue PodGroup to 0 Queues
I0731 07:33:10.165824       1 allocate.go:138] Try to allocate resource to 0 Queues
I0731 07:33:10.165908       1 session.go:577] Close Session d22dbd64-2dcb-4be3-818a-fcd729d4013b
I0731 07:33:11.167223       1 cache.go:1581] "SnapShot for scheduling" jobNum=0 QueueNum=2 NodeNum=1
I0731 07:33:11.167280       1 session.go:1036] Start adjusting jobs' network topology spec according to hyperNodeTierNameMap map[]
I0731 07:33:11.167307       1 session.go:1079] Finish adjusting jobs' network topology spec according to hyperNodeTierNameMap map[]
I0731 07:33:11.167329       1 session.go:279] Open Session f927824d-c651-4f6e-8dc9-f5e4e18145a7 with <0> Job and <2> Queues. HyperNodesReadyToSchedule: true
I0731 07:33:11.167764       1 enqueue.go:79] Try to enqueue PodGroup to 0 Queues
I0731 07:33:11.167788       1 allocate.go:138] Try to allocate resource to 0 Queues
I0731 07:33:11.167871       1 session.go:577] Close Session f927824d-c651-4f6e-8dc9-f5e4e18145a7
I0731 07:33:12.169278       1 cache.go:1581] "SnapShot for scheduling" jobNum=0 QueueNum=2 NodeNum=1
I0731 07:33:12.169328       1 session.go:1036] Start adjusting jobs' network topology spec according to hyperNodeTierNameMap map[]
I0731 07:33:12.169354       1 session.go:1079] Finish adjusting jobs' network topology spec according to hyperNodeTierNameMap map[]
I0731 07:33:12.169380       1 session.go:279] Open Session 6280b504-f054-4ae0-a352-46bcfa5094d7 with <0> Job and <2> Queues. HyperNodesReadyToSchedule: true
I0731 07:33:12.169826       1 enqueue.go:79] Try to enqueue PodGroup to 0 Queues
I0731 07:33:12.169849       1 allocate.go:138] Try to allocate resource to 0 Queues
I0731 07:33:12.169919       1 session.go:577] Close Session 6280b504-f054-4ae0-a352-46bcfa5094d7
I0731 07:33:13.170219       1 cache.go:1581] "SnapShot for scheduling" jobNum=0 QueueNum=2 NodeNum=1
I0731 07:33:13.170253       1 session.go:1036] Start adjusting jobs' network topology spec according to hyperNodeTierNameMap map[]
I0731 07:33:13.170273       1 session.go:1079] Finish adjusting jobs' network topology spec according to hyperNodeTierNameMap map[]
I0731 07:33:13.170295       1 session.go:279] Open Session bc8bcab6-7099-44a3-8ed1-dfaf2fd4f2dc with <0> Job and <2> Queues. HyperNodesReadyToSchedule: true
I0731 07:33:13.170711       1 enqueue.go:79] Try to enqueue PodGroup to 0 Queues
I0731 07:33:13.170744       1 allocate.go:138] Try to allocate resource to 0 Queues
I0731 07:33:13.170810       1 session.go:577] Close Session bc8bcab6-7099-44a3-8ed1-dfaf2fd4f2dc
I0731 07:33:14.171833       1 cache.go:1581] "SnapShot for scheduling" jobNum=0 QueueNum=2 NodeNum=1
I0731 07:33:14.171885       1 session.go:1036] Start adjusting jobs' network topology spec according to hyperNodeTierNameMap map[]
I0731 07:33:14.171910       1 session.go:1079] Finish adjusting jobs' network topology spec according to hyperNodeTierNameMap map[]
I0731 07:33:14.171936       1 session.go:279] Open Session 719b8597-a19b-406f-9929-be2480502f4b with <0> Job and <2> Queues. HyperNodesReadyToSchedule: true
I0731 07:33:14.172464       1 enqueue.go:79] Try to enqueue PodGroup to 0 Queues
I0731 07:33:14.172486       1 allocate.go:138] Try to allocate resource to 0 Queues
I0731 07:33:14.172566       1 session.go:577] Close Session 719b8597-a19b-406f-9929-be2480502f4b
I0731 07:33:15.173892       1 cache.go:1581] "SnapShot for scheduling" jobNum=0 QueueNum=2 NodeNum=1
I0731 07:33:15.173945       1 session.go:1036] Start adjusting jobs' network topology spec according to hyperNodeTierNameMap map[]
I0731 07:33:15.173977       1 session.go:1079] Finish adjusting jobs' network topology spec according to hyperNodeTierNameMap map[]
I0731 07:33:15.174002       1 session.go:279] Open Session 37c46b57-4b53-4f3d-965a-98295e2b537a with <0> Job and <2> Queues. HyperNodesReadyToSchedule: true
I0731 07:33:15.174459       1 enqueue.go:79] Try to enqueue PodGroup to 0 Queues
I0731 07:33:15.174487       1 allocate.go:138] Try to allocate resource to 0 Queues
I0731 07:33:15.174563       1 session.go:577] Close Session 37c46b57-4b53-4f3d-965a-98295e2b537a
I0731 07:33:16.175211       1 cache.go:1581] "SnapShot for scheduling" jobNum=0 QueueNum=2 NodeNum=1
I0731 07:33:16.175270       1 session.go:1036] Start adjusting jobs' network topology spec according to hyperNodeTierNameMap map[]
I0731 07:33:16.175298       1 session.go:1079] Finish adjusting jobs' network topology spec according to hyperNodeTierNameMap map[]
I0731 07:33:16.175327       1 session.go:279] Open Session 91e730c2-c77e-4f09-a682-50586a533019 with <0> Job and <2> Queues. HyperNodesReadyToSchedule: true
I0731 07:33:16.175871       1 enqueue.go:79] Try to enqueue PodGroup to 0 Queues
I0731 07:33:16.175898       1 allocate.go:138] Try to allocate resource to 0 Queues
I0731 07:33:16.175986       1 session.go:577] Close Session 91e730c2-c77e-4f09-a682-50586a533019
I0731 07:33:16.484720       1 cache.go:1771] The metrics type is not set in the volcano scheduler configmap file. As a result, the CPU and memory load information of the node is not collected.
I0731 07:33:17.176664       1 cache.go:1581] "SnapShot for scheduling" jobNum=0 QueueNum=2 NodeNum=1
I0731 07:33:17.176717       1 session.go:1036] Start adjusting jobs' network topology spec according to hyperNodeTierNameMap map[]
I0731 07:33:17.176747       1 session.go:1079] Finish adjusting jobs' network topology spec according to hyperNodeTierNameMap map[]
I0731 07:33:17.176772       1 session.go:279] Open Session 5e7d356a-3208-4cbf-be70-79e05a69ef69 with <0> Job and <2> Queues. HyperNodesReadyToSchedule: true
I0731 07:33:17.177316       1 enqueue.go:79] Try to enqueue PodGroup to 0 Queues
I0731 07:33:17.177342       1 allocate.go:138] Try to allocate resource to 0 Queues
I0731 07:33:17.177429       1 session.go:577] Close Session 5e7d356a-3208-4cbf-be70-79e05a69ef69
I0731 07:33:18.178368       1 cache.go:1581] "SnapShot for scheduling" jobNum=0 QueueNum=2 NodeNum=1
I0731 07:33:18.178415       1 session.go:1036] Start adjusting jobs' network topology spec according to hyperNodeTierNameMap map[]
I0731 07:33:18.178439       1 session.go:1079] Finish adjusting jobs' network topology spec according to hyperNodeTierNameMap map[]
I0731 07:33:18.178466       1 session.go:279] Open Session 78dc100f-c17d-4f74-80c9-385500c209af with <0> Job and <2> Queues. HyperNodesReadyToSchedule: true
I0731 07:33:18.178922       1 enqueue.go:79] Try to enqueue PodGroup to 0 Queues
I0731 07:33:18.178945       1 allocate.go:138] Try to allocate resource to 0 Queues
I0731 07:33:18.179026       1 session.go:577] Close Session 78dc100f-c17d-4f74-80c9-385500c209af
I0731 07:33:19.179936       1 cache.go:1581] "SnapShot for scheduling" jobNum=0 QueueNum=2 NodeNum=1
I0731 07:33:19.179988       1 session.go:1036] Start adjusting jobs' network topology spec according to hyperNodeTierNameMap map[]
I0731 07:33:19.180012       1 session.go:1079] Finish adjusting jobs' network topology spec according to hyperNodeTierNameMap map[]
I0731 07:33:19.180036       1 session.go:279] Open Session a3cedd1c-c5a2-4563-8d76-27215077685f with <0> Job and <2> Queues. HyperNodesReadyToSchedule: true
I0731 07:33:19.180483       1 enqueue.go:79] Try to enqueue PodGroup to 0 Queues
I0731 07:33:19.180507       1 allocate.go:138] Try to allocate resource to 0 Queues
I0731 07:33:19.180580       1 session.go:577] Close Session a3cedd1c-c5a2-4563-8d76-27215077685f
I0731 07:33:20.181572       1 cache.go:1581] "SnapShot for scheduling" jobNum=0 QueueNum=2 NodeNum=1
I0731 07:33:20.181618       1 session.go:1036] Start adjusting jobs' network topology spec according to hyperNodeTierNameMap map[]
I0731 07:33:20.181642       1 session.go:1079] Finish adjusting jobs' network topology spec according to hyperNodeTierNameMap map[]
I0731 07:33:20.181667       1 session.go:279] Open Session fdecd329-5216-4002-b460-50b2c0ca6f98 with <0> Job and <2> Queues. HyperNodesReadyToSchedule: true
I0731 07:33:20.182117       1 enqueue.go:79] Try to enqueue PodGroup to 0 Queues
I0731 07:33:20.182138       1 allocate.go:138] Try to allocate resource to 0 Queues
I0731 07:33:20.182210       1 session.go:577] Close Session fdecd329-5216-4002-b460-50b2c0ca6f98
I0731 07:33:21.183366       1 cache.go:1581] "SnapShot for scheduling" jobNum=0 QueueNum=2 NodeNum=1
I0731 07:33:21.183415       1 session.go:1036] Start adjusting jobs' network topology spec according to hyperNodeTierNameMap map[]
I0731 07:33:21.183444       1 session.go:1079] Finish adjusting jobs' network topology spec according to hyperNodeTierNameMap map[]
I0731 07:33:21.183468       1 session.go:279] Open Session 740c0484-e252-4470-952f-ec25ab84a252 with <0> Job and <2> Queues. HyperNodesReadyToSchedule: true
I0731 07:33:21.183960       1 enqueue.go:79] Try to enqueue PodGroup to 0 Queues
I0731 07:33:21.183985       1 allocate.go:138] Try to allocate resource to 0 Queues
I0731 07:33:21.184066       1 session.go:577] Close Session 740c0484-e252-4470-952f-ec25ab84a252
I0731 07:33:22.184646       1 cache.go:1581] "SnapShot for scheduling" jobNum=0 QueueNum=2 NodeNum=1
I0731 07:33:22.184694       1 session.go:1036] Start adjusting jobs' network topology spec according to hyperNodeTierNameMap map[]
I0731 07:33:22.184720       1 session.go:1079] Finish adjusting jobs' network topology spec according to hyperNodeTierNameMap map[]
I0731 07:33:22.184746       1 session.go:279] Open Session cd776aa3-bd87-4c1f-8562-e3ea45426f72 with <0> Job and <2> Queues. HyperNodesReadyToSchedule: true
I0731 07:33:22.185219       1 enqueue.go:79] Try to enqueue PodGroup to 0 Queues
I0731 07:33:22.185243       1 allocate.go:138] Try to allocate resource to 0 Queues
I0731 07:33:22.185320       1 session.go:577] Close Session cd776aa3-bd87-4c1f-8562-e3ea45426f72
I0731 07:33:23.186501       1 cache.go:1581] "SnapShot for scheduling" jobNum=0 QueueNum=2 NodeNum=1
I0731 07:33:23.186549       1 session.go:1036] Start adjusting jobs' network topology spec according to hyperNodeTierNameMap map[]
I0731 07:33:23.186575       1 session.go:1079] Finish adjusting jobs' network topology spec according to hyperNodeTierNameMap map[]
I0731 07:33:23.186598       1 session.go:279] Open Session 143ced19-592f-483e-a0d3-a351f64bcd47 with <0> Job and <2> Queues. HyperNodesReadyToSchedule: true
I0731 07:33:23.187083       1 enqueue.go:79] Try to enqueue PodGroup to 0 Queues
I0731 07:33:23.187106       1 allocate.go:138] Try to allocate resource to 0 Queues
I0731 07:33:23.187182       1 session.go:577] Close Session 143ced19-592f-483e-a0d3-a351f64bcd47
I0731 07:33:24.187577       1 cache.go:1581] "SnapShot for scheduling" jobNum=0 QueueNum=2 NodeNum=1
I0731 07:33:24.187634       1 session.go:1036] Start adjusting jobs' network topology spec according to hyperNodeTierNameMap map[]
I0731 07:33:24.187660       1 session.go:1079] Finish adjusting jobs' network topology spec according to hyperNodeTierNameMap map[]
I0731 07:33:24.187687       1 session.go:279] Open Session 18faa713-d5cd-47d5-af0b-2dc4bf446be2 with <0> Job and <2> Queues. HyperNodesReadyToSchedule: true
I0731 07:33:24.188148       1 enqueue.go:79] Try to enqueue PodGroup to 0 Queues
I0731 07:33:24.188171       1 allocate.go:138] Try to allocate resource to 0 Queues
I0731 07:33:24.188247       1 session.go:577] Close Session 18faa713-d5cd-47d5-af0b-2dc4bf446be2
I0731 07:33:25.189127       1 cache.go:1581] "SnapShot for scheduling" jobNum=0 QueueNum=2 NodeNum=1
I0731 07:33:25.189184       1 session.go:1036] Start adjusting jobs' network topology spec according to hyperNodeTierNameMap map[]
I0731 07:33:25.189211       1 session.go:1079] Finish adjusting jobs' network topology spec according to hyperNodeTierNameMap map[]
I0731 07:33:25.189235       1 session.go:279] Open Session 04694fd3-5a8c-40e9-a0b9-60d96d870b64 with <0> Job and <2> Queues. HyperNodesReadyToSchedule: true
I0731 07:33:25.189719       1 enqueue.go:79] Try to enqueue PodGroup to 0 Queues
I0731 07:33:25.189749       1 allocate.go:138] Try to allocate resource to 0 Queues
I0731 07:33:25.189832       1 session.go:577] Close Session 04694fd3-5a8c-40e9-a0b9-60d96d870b64
I0731 07:33:26.190789       1 cache.go:1581] "SnapShot for scheduling" jobNum=0 QueueNum=2 NodeNum=1
I0731 07:33:26.190839       1 session.go:1036] Start adjusting jobs' network topology spec according to hyperNodeTierNameMap map[]
I0731 07:33:26.190865       1 session.go:1079] Finish adjusting jobs' network topology spec according to hyperNodeTierNameMap map[]
I0731 07:33:26.190888       1 session.go:279] Open Session 3e302cf7-a8e3-494e-b796-5ab802187442 with <0> Job and <2> Queues. HyperNodesReadyToSchedule: true
I0731 07:33:26.191349       1 enqueue.go:79] Try to enqueue PodGroup to 0 Queues
I0731 07:33:26.191373       1 allocate.go:138] Try to allocate resource to 0 Queues
I0731 07:33:26.191454       1 session.go:577] Close Session 3e302cf7-a8e3-494e-b796-5ab802187442
I0731 07:33:27.192633       1 cache.go:1581] "SnapShot for scheduling" jobNum=0 QueueNum=2 NodeNum=1
I0731 07:33:27.192689       1 session.go:1036] Start adjusting jobs' network topology spec according to hyperNodeTierNameMap map[]
I0731 07:33:27.192716       1 session.go:1079] Finish adjusting jobs' network topology spec according to hyperNodeTierNameMap map[]
I0731 07:33:27.192741       1 session.go:279] Open Session 45d4cbbb-ebb5-496f-b404-cb1e9bbd4cb8 with <0> Job and <2> Queues. HyperNodesReadyToSchedule: true
I0731 07:33:27.193334       1 enqueue.go:79] Try to enqueue PodGroup to 0 Queues
I0731 07:33:27.193359       1 allocate.go:138] Try to allocate resource to 0 Queues
I0731 07:33:27.193453       1 session.go:577] Close Session 45d4cbbb-ebb5-496f-b404-cb1e9bbd4cb8
I0731 07:33:28.194941       1 cache.go:1581] "SnapShot for scheduling" jobNum=0 QueueNum=2 NodeNum=1
I0731 07:33:28.195004       1 session.go:1036] Start adjusting jobs' network topology spec according to hyperNodeTierNameMap map[]
I0731 07:33:28.195031       1 session.go:1079] Finish adjusting jobs' network topology spec according to hyperNodeTierNameMap map[]
I0731 07:33:28.195057       1 session.go:279] Open Session 05772b9f-a7af-4554-9afb-533998609db4 with <0> Job and <2> Queues. HyperNodesReadyToSchedule: true
I0731 07:33:28.195633       1 enqueue.go:79] Try to enqueue PodGroup to 0 Queues
I0731 07:33:28.195661       1 allocate.go:138] Try to allocate resource to 0 Queues
I0731 07:33:28.195754       1 session.go:577] Close Session 05772b9f-a7af-4554-9afb-533998609db4
I0731 07:33:29.196854       1 cache.go:1581] "SnapShot for scheduling" jobNum=0 QueueNum=2 NodeNum=1
I0731 07:33:29.196893       1 session.go:1036] Start adjusting jobs' network topology spec according to hyperNodeTierNameMap map[]
I0731 07:33:29.196907       1 session.go:1079] Finish adjusting jobs' network topology spec according to hyperNodeTierNameMap map[]
I0731 07:33:29.196920       1 session.go:279] Open Session 63005609-4eb8-498b-8a2e-492d1777aa0c with <0> Job and <2> Queues. HyperNodesReadyToSchedule: true
I0731 07:33:29.197261       1 enqueue.go:79] Try to enqueue PodGroup to 0 Queues
I0731 07:33:29.197274       1 allocate.go:138] Try to allocate resource to 0 Queues
I0731 07:33:29.197327       1 session.go:577] Close Session 63005609-4eb8-498b-8a2e-492d1777aa0c
I0731 07:33:30.197866       1 cache.go:1581] "SnapShot for scheduling" jobNum=0 QueueNum=2 NodeNum=1
I0731 07:33:30.197915       1 session.go:1036] Start adjusting jobs' network topology spec according to hyperNodeTierNameMap map[]
I0731 07:33:30.197946       1 session.go:1079] Finish adjusting jobs' network topology spec according to hyperNodeTierNameMap map[]
I0731 07:33:30.197973       1 session.go:279] Open Session fa2d01a3-8ec2-4331-ac00-85ef3a51a559 with <0> Job and <2> Queues. HyperNodesReadyToSchedule: true
I0731 07:33:30.198480       1 enqueue.go:79] Try to enqueue PodGroup to 0 Queues
I0731 07:33:30.198505       1 allocate.go:138] Try to allocate resource to 0 Queues
I0731 07:33:30.198594       1 session.go:577] Close Session fa2d01a3-8ec2-4331-ac00-85ef3a51a559
I0731 07:33:31.200084       1 cache.go:1581] "SnapShot for scheduling" jobNum=0 QueueNum=8 NodeNum=1
I0731 07:33:31.200144       1 session.go:1036] Start adjusting jobs' network topology spec according to hyperNodeTierNameMap map[]
I0731 07:33:31.200172       1 session.go:1079] Finish adjusting jobs' network topology spec according to hyperNodeTierNameMap map[]
I0731 07:33:31.200200       1 session.go:279] Open Session b8ef918f-c453-4286-a8e9-d88e1537c8ca with <0> Job and <8> Queues. HyperNodesReadyToSchedule: true
I0731 07:33:31.200774       1 enqueue.go:79] Try to enqueue PodGroup to 0 Queues
I0731 07:33:31.200801       1 allocate.go:138] Try to allocate resource to 0 Queues
I0731 07:33:31.248288       1 session.go:577] Close Session b8ef918f-c453-4286-a8e9-d88e1537c8ca
I0731 07:33:32.249170       1 cache.go:1581] "SnapShot for scheduling" jobNum=0 QueueNum=8 NodeNum=1
I0731 07:33:32.249223       1 session.go:1036] Start adjusting jobs' network topology spec according to hyperNodeTierNameMap map[]
I0731 07:33:32.249250       1 session.go:1079] Finish adjusting jobs' network topology spec according to hyperNodeTierNameMap map[]
I0731 07:33:32.249276       1 session.go:279] Open Session 4cb9cc61-feb2-4e99-a8f1-7ad207516479 with <0> Job and <8> Queues. HyperNodesReadyToSchedule: true
I0731 07:33:32.249785       1 enqueue.go:79] Try to enqueue PodGroup to 0 Queues
I0731 07:33:32.249810       1 allocate.go:138] Try to allocate resource to 0 Queues
I0731 07:33:32.249941       1 session.go:577] Close Session 4cb9cc61-feb2-4e99-a8f1-7ad207516479
I0731 07:33:33.250550       1 cache.go:1581] "SnapShot for scheduling" jobNum=0 QueueNum=8 NodeNum=1
I0731 07:33:33.250631       1 session.go:1036] Start adjusting jobs' network topology spec according to hyperNodeTierNameMap map[]
I0731 07:33:33.250664       1 session.go:1079] Finish adjusting jobs' network topology spec according to hyperNodeTierNameMap map[]
I0731 07:33:33.250689       1 session.go:279] Open Session 6499f55a-40d5-4693-918d-3507c9ca4578 with <0> Job and <8> Queues. HyperNodesReadyToSchedule: true
I0731 07:33:33.251252       1 enqueue.go:79] Try to enqueue PodGroup to 0 Queues
I0731 07:33:33.251281       1 allocate.go:138] Try to allocate resource to 0 Queues
I0731 07:33:33.251418       1 session.go:577] Close Session 6499f55a-40d5-4693-918d-3507c9ca4578
I0731 07:33:34.252518       1 cache.go:1581] "SnapShot for scheduling" jobNum=0 QueueNum=8 NodeNum=1
I0731 07:33:34.252579       1 session.go:1036] Start adjusting jobs' network topology spec according to hyperNodeTierNameMap map[]
I0731 07:33:34.252614       1 session.go:1079] Finish adjusting jobs' network topology spec according to hyperNodeTierNameMap map[]
I0731 07:33:34.252641       1 session.go:279] Open Session 5a9100fd-2b6b-4461-9b16-2daf699515a5 with <0> Job and <8> Queues. HyperNodesReadyToSchedule: true
I0731 07:33:34.253191       1 enqueue.go:79] Try to enqueue PodGroup to 0 Queues
I0731 07:33:34.253218       1 allocate.go:138] Try to allocate resource to 0 Queues
I0731 07:33:34.253364       1 session.go:577] Close Session 5a9100fd-2b6b-4461-9b16-2daf699515a5
I0731 07:33:35.254465       1 cache.go:1581] "SnapShot for scheduling" jobNum=0 QueueNum=8 NodeNum=1
I0731 07:33:35.254533       1 session.go:1036] Start adjusting jobs' network topology spec according to hyperNodeTierNameMap map[]
I0731 07:33:35.254561       1 session.go:1079] Finish adjusting jobs' network topology spec according to hyperNodeTierNameMap map[]
I0731 07:33:35.254585       1 session.go:279] Open Session 47273b50-51f6-45c3-b163-6c4dcac0408e with <0> Job and <8> Queues. HyperNodesReadyToSchedule: true
I0731 07:33:35.255162       1 enqueue.go:79] Try to enqueue PodGroup to 0 Queues
I0731 07:33:35.255192       1 allocate.go:138] Try to allocate resource to 0 Queues
I0731 07:33:35.255325       1 session.go:577] Close Session 47273b50-51f6-45c3-b163-6c4dcac0408e
I0731 07:33:36.256118       1 cache.go:1581] "SnapShot for scheduling" jobNum=0 QueueNum=8 NodeNum=1
I0731 07:33:36.256171       1 session.go:1036] Start adjusting jobs' network topology spec according to hyperNodeTierNameMap map[]
I0731 07:33:36.256197       1 session.go:1079] Finish adjusting jobs' network topology spec according to hyperNodeTierNameMap map[]
I0731 07:33:36.256222       1 session.go:279] Open Session 01d03909-bd3b-4089-b303-66282da47c5a with <0> Job and <8> Queues. HyperNodesReadyToSchedule: true
I0731 07:33:36.256750       1 enqueue.go:79] Try to enqueue PodGroup to 0 Queues
I0731 07:33:36.256775       1 allocate.go:138] Try to allocate resource to 0 Queues
I0731 07:33:36.256910       1 session.go:577] Close Session 01d03909-bd3b-4089-b303-66282da47c5a
I0731 07:33:37.257818       1 cache.go:1581] "SnapShot for scheduling" jobNum=0 QueueNum=8 NodeNum=1
I0731 07:33:37.257872       1 session.go:1036] Start adjusting jobs' network topology spec according to hyperNodeTierNameMap map[]
I0731 07:33:37.257901       1 session.go:1079] Finish adjusting jobs' network topology spec according to hyperNodeTierNameMap map[]
I0731 07:33:37.257929       1 session.go:279] Open Session 15501d66-443b-43ea-b47f-35b269fceeec with <0> Job and <8> Queues. HyperNodesReadyToSchedule: true
I0731 07:33:37.258441       1 enqueue.go:79] Try to enqueue PodGroup to 0 Queues
I0731 07:33:37.258467       1 allocate.go:138] Try to allocate resource to 0 Queues
I0731 07:33:37.258596       1 session.go:577] Close Session 15501d66-443b-43ea-b47f-35b269fceeec
I0731 07:33:38.259837       1 cache.go:1581] "SnapShot for scheduling" jobNum=0 QueueNum=8 NodeNum=1
I0731 07:33:38.259891       1 session.go:1036] Start adjusting jobs' network topology spec according to hyperNodeTierNameMap map[]
I0731 07:33:38.259918       1 session.go:1079] Finish adjusting jobs' network topology spec according to hyperNodeTierNameMap map[]
I0731 07:33:38.259944       1 session.go:279] Open Session 64c0de3e-2487-4c39-a828-2666cb1eacf5 with <0> Job and <8> Queues. HyperNodesReadyToSchedule: true
I0731 07:33:38.260436       1 enqueue.go:79] Try to enqueue PodGroup to 0 Queues
I0731 07:33:38.260461       1 allocate.go:138] Try to allocate resource to 0 Queues
I0731 07:33:38.260593       1 session.go:577] Close Session 64c0de3e-2487-4c39-a828-2666cb1eacf5
I0731 07:33:39.263994       1 cache.go:1581] "SnapShot for scheduling" jobNum=0 QueueNum=8 NodeNum=1
I0731 07:33:39.264105       1 session.go:1036] Start adjusting jobs' network topology spec according to hyperNodeTierNameMap map[]
I0731 07:33:39.264143       1 session.go:1079] Finish adjusting jobs' network topology spec according to hyperNodeTierNameMap map[]
I0731 07:33:39.264199       1 session.go:279] Open Session 268450a9-304f-4f9e-8f43-0770c812782b with <0> Job and <8> Queues. HyperNodesReadyToSchedule: true
I0731 07:33:39.265805       1 enqueue.go:79] Try to enqueue PodGroup to 0 Queues
I0731 07:33:39.265864       1 allocate.go:138] Try to allocate resource to 0 Queues
I0731 07:33:39.266131       1 session.go:577] Close Session 268450a9-304f-4f9e-8f43-0770c812782b
I0731 07:33:40.267209       1 cache.go:1581] "SnapShot for scheduling" jobNum=0 QueueNum=8 NodeNum=1
I0731 07:33:40.267271       1 session.go:1036] Start adjusting jobs' network topology spec according to hyperNodeTierNameMap map[]
I0731 07:33:40.267301       1 session.go:1079] Finish adjusting jobs' network topology spec according to hyperNodeTierNameMap map[]
I0731 07:33:40.267326       1 session.go:279] Open Session e56c506d-3a79-4d20-9404-ebfbe24f45f0 with <0> Job and <8> Queues. HyperNodesReadyToSchedule: true
I0731 07:33:40.267850       1 enqueue.go:79] Try to enqueue PodGroup to 0 Queues
I0731 07:33:40.267874       1 allocate.go:138] Try to allocate resource to 0 Queues
I0731 07:33:40.268002       1 session.go:577] Close Session e56c506d-3a79-4d20-9404-ebfbe24f45f0
I0731 07:33:40.568100       1 event_handlers.go:445] Added pod <khalil-volcano-bench/khalil-volcano-smoke-n8cqc> into cache.
I0731 07:33:41.269437       1 cache.go:1581] "SnapShot for scheduling" jobNum=1 QueueNum=8 NodeNum=1
I0731 07:33:41.269496       1 session.go:1036] Start adjusting jobs' network topology spec according to hyperNodeTierNameMap map[]
I0731 07:33:41.269526       1 session.go:1079] Finish adjusting jobs' network topology spec according to hyperNodeTierNameMap map[]
I0731 07:33:41.269552       1 session.go:279] Open Session a07b759f-b9ca-477e-9f96-aaabc7dc1422 with <1> Job and <8> Queues. HyperNodesReadyToSchedule: true
I0731 07:33:41.270340       1 enqueue.go:79] Try to enqueue PodGroup to 1 Queues
I0731 07:33:41.270456       1 allocate.go:138] Try to allocate resource to 1 Queues
I0731 07:33:41.270551       1 allocate.go:328] "Try to allocate resource" queue="khalil-volcano-smoke" job="khalil-volcano-bench/khalil-volcano-smoke-pg" nominatedHyperNode="" taskNum=1
I0731 07:33:41.270599       1 allocate.go:777] There are <1> nodes for Job <khalil-volcano-bench/khalil-volcano-smoke-pg>
I0731 07:33:41.270827       1 allocate.go:956] Binding Task <khalil-volcano-bench/khalil-volcano-smoke-n8cqc> to node <gpu-dev-01>
I0731 07:33:41.270890       1 statement.go:277] After allocated Task <khalil-volcano-bench/khalil-volcano-smoke-n8cqc> to Node <gpu-dev-01>: idle <cpu 63085.00, memory 539520716800.00, ephemeral-storage 1015515997412000.00, hugepages-1Gi 0.00, hugepages-2Mi 0.00, nvidia.com/gpu 7000.00, pods 96.00>, used <cpu 915.00, memory 1153433600.00, nvidia.com/gpu 1000.00, pods 14.00>, releasing <cpu 0.00, memory 0.00>
I0731 07:33:41.271060       1 statement.go:307] Allocating operations ...
I0731 07:33:41.271122       1 allocate.go:855] "SubJob ready, return statement" job="khalil-volcano-bench/khalil-volcano-smoke-pg" subJob="khalil-volcano-bench/khalil-volcano-smoke-pg"
I0731 07:33:41.271145       1 statement.go:393] Committing operations ...
I0731 07:33:41.271242       1 proportion.go:326] Queue <khalil-volcano-smoke> is overused: deserved <cpu 100.00, memory 134217728.00, ephemeral-storage 0.00, hugepages-1Gi 0.00, hugepages-2Mi 0.00, nvidia.com/gpu 1000.00, pods 1.00>, allocated <cpu 100.00, memory 134217728.00, nvidia.com/gpu 1000.00, pods 1.00>, share <1>
I0731 07:33:41.271304       1 allocate.go:295] Queue <khalil-volcano-smoke> is overused, ignore it.
I0731 07:33:41.293933       1 cache.go:992] bind ok, latency 5.633266ms
I0731 07:33:41.296687       1 session.go:577] Close Session a07b759f-b9ca-477e-9f96-aaabc7dc1422
I0731 07:33:42.297850       1 cache.go:1581] "SnapShot for scheduling" jobNum=1 QueueNum=8 NodeNum=1
I0731 07:33:42.297923       1 session.go:1036] Start adjusting jobs' network topology spec according to hyperNodeTierNameMap map[]
I0731 07:33:42.297954       1 session.go:1079] Finish adjusting jobs' network topology spec according to hyperNodeTierNameMap map[]
I0731 07:33:42.297982       1 session.go:279] Open Session 5d728d5f-4bf0-4dda-8421-d91c4aff5d23 with <1> Job and <8> Queues. HyperNodesReadyToSchedule: true
I0731 07:33:42.298912       1 enqueue.go:79] Try to enqueue PodGroup to 0 Queues
I0731 07:33:42.298958       1 allocate.go:138] Try to allocate resource to 0 Queues
I0731 07:33:42.308095       1 session.go:577] Close Session 5d728d5f-4bf0-4dda-8421-d91c4aff5d23
I0731 07:33:43.309217       1 cache.go:1581] "SnapShot for scheduling" jobNum=1 QueueNum=8 NodeNum=1
I0731 07:33:43.309283       1 session.go:1036] Start adjusting jobs' network topology spec according to hyperNodeTierNameMap map[]
I0731 07:33:43.309313       1 session.go:1079] Finish adjusting jobs' network topology spec according to hyperNodeTierNameMap map[]
I0731 07:33:43.309341       1 session.go:279] Open Session 84bcccbc-fbd5-42d1-b81f-dde517872aa9 with <1> Job and <8> Queues. HyperNodesReadyToSchedule: true
I0731 07:33:43.310218       1 enqueue.go:79] Try to enqueue PodGroup to 0 Queues
I0731 07:33:43.310262       1 allocate.go:138] Try to allocate resource to 0 Queues
I0731 07:33:43.310566       1 session.go:577] Close Session 84bcccbc-fbd5-42d1-b81f-dde517872aa9
I0731 07:33:44.312003       1 cache.go:1581] "SnapShot for scheduling" jobNum=1 QueueNum=8 NodeNum=1
I0731 07:33:44.312052       1 session.go:1036] Start adjusting jobs' network topology spec according to hyperNodeTierNameMap map[]
I0731 07:33:44.312080       1 session.go:1079] Finish adjusting jobs' network topology spec according to hyperNodeTierNameMap map[]
I0731 07:33:44.312105       1 session.go:279] Open Session 6ae27ece-2a3b-46ad-8b7f-e7c754a2d481 with <1> Job and <8> Queues. HyperNodesReadyToSchedule: true
I0731 07:33:44.312862       1 enqueue.go:79] Try to enqueue PodGroup to 0 Queues
I0731 07:33:44.312902       1 allocate.go:138] Try to allocate resource to 0 Queues
I0731 07:33:44.313159       1 session.go:577] Close Session 6ae27ece-2a3b-46ad-8b7f-e7c754a2d481
I0731 07:33:45.313943       1 cache.go:1581] "SnapShot for scheduling" jobNum=1 QueueNum=8 NodeNum=1
I0731 07:33:45.314007       1 session.go:1036] Start adjusting jobs' network topology spec according to hyperNodeTierNameMap map[]
I0731 07:33:45.314034       1 session.go:1079] Finish adjusting jobs' network topology spec according to hyperNodeTierNameMap map[]
I0731 07:33:45.314061       1 session.go:279] Open Session 9f5946b1-8c74-4dd4-b4a0-23fa2a2578a9 with <1> Job and <8> Queues. HyperNodesReadyToSchedule: true
I0731 07:33:45.314974       1 enqueue.go:79] Try to enqueue PodGroup to 0 Queues
I0731 07:33:45.315022       1 allocate.go:138] Try to allocate resource to 0 Queues
I0731 07:33:45.323599       1 session.go:577] Close Session 9f5946b1-8c74-4dd4-b4a0-23fa2a2578a9
I0731 07:33:46.324804       1 cache.go:1581] "SnapShot for scheduling" jobNum=1 QueueNum=8 NodeNum=1
I0731 07:33:46.324855       1 session.go:1036] Start adjusting jobs' network topology spec according to hyperNodeTierNameMap map[]
I0731 07:33:46.324880       1 session.go:1079] Finish adjusting jobs' network topology spec according to hyperNodeTierNameMap map[]
I0731 07:33:46.324903       1 session.go:279] Open Session 1ee02b18-5deb-4357-b05e-b449ddb67aa4 with <1> Job and <8> Queues. HyperNodesReadyToSchedule: true
I0731 07:33:46.325637       1 enqueue.go:79] Try to enqueue PodGroup to 0 Queues
I0731 07:33:46.325679       1 allocate.go:138] Try to allocate resource to 0 Queues
I0731 07:33:46.325942       1 session.go:577] Close Session 1ee02b18-5deb-4357-b05e-b449ddb67aa4
I0731 07:33:46.485131       1 cache.go:1771] The metrics type is not set in the volcano scheduler configmap file. As a result, the CPU and memory load information of the node is not collected.
I0731 07:33:47.326634       1 cache.go:1581] "SnapShot for scheduling" jobNum=1 QueueNum=8 NodeNum=1
I0731 07:33:47.326672       1 session.go:1036] Start adjusting jobs' network topology spec according to hyperNodeTierNameMap map[]
I0731 07:33:47.326693       1 session.go:1079] Finish adjusting jobs' network topology spec according to hyperNodeTierNameMap map[]
I0731 07:33:47.326727       1 session.go:279] Open Session 0b7261fb-76a8-4880-8f30-bde72dc1bd9c with <1> Job and <8> Queues. HyperNodesReadyToSchedule: true
I0731 07:33:47.327435       1 enqueue.go:79] Try to enqueue PodGroup to 0 Queues
I0731 07:33:47.327472       1 allocate.go:138] Try to allocate resource to 0 Queues
I0731 07:33:47.327712       1 session.go:577] Close Session 0b7261fb-76a8-4880-8f30-bde72dc1bd9c
I0731 07:33:48.328458       1 cache.go:1581] "SnapShot for scheduling" jobNum=1 QueueNum=8 NodeNum=1
I0731 07:33:48.328512       1 session.go:1036] Start adjusting jobs' network topology spec according to hyperNodeTierNameMap map[]
I0731 07:33:48.328538       1 session.go:1079] Finish adjusting jobs' network topology spec according to hyperNodeTierNameMap map[]
I0731 07:33:48.328561       1 session.go:279] Open Session 30abe929-bdfc-4d07-a24e-11212fa36a83 with <1> Job and <8> Queues. HyperNodesReadyToSchedule: true
I0731 07:33:48.329322       1 enqueue.go:79] Try to enqueue PodGroup to 0 Queues
I0731 07:33:48.329360       1 allocate.go:138] Try to allocate resource to 0 Queues
I0731 07:33:48.329620       1 session.go:577] Close Session 30abe929-bdfc-4d07-a24e-11212fa36a83
I0731 07:33:49.330161       1 cache.go:1581] "SnapShot for scheduling" jobNum=1 QueueNum=8 NodeNum=1
I0731 07:33:49.330202       1 session.go:1036] Start adjusting jobs' network topology spec according to hyperNodeTierNameMap map[]
I0731 07:33:49.330226       1 session.go:1079] Finish adjusting jobs' network topology spec according to hyperNodeTierNameMap map[]
I0731 07:33:49.330251       1 session.go:279] Open Session 30ba10d6-35e2-4a16-8ab6-776fbe80ff89 with <1> Job and <8> Queues. HyperNodesReadyToSchedule: true
I0731 07:33:49.330983       1 enqueue.go:79] Try to enqueue PodGroup to 0 Queues
I0731 07:33:49.331025       1 allocate.go:138] Try to allocate resource to 0 Queues
I0731 07:33:49.331275       1 session.go:577] Close Session 30ba10d6-35e2-4a16-8ab6-776fbe80ff89
I0731 07:33:50.332783       1 cache.go:1581] "SnapShot for scheduling" jobNum=1 QueueNum=8 NodeNum=1
I0731 07:33:50.332829       1 session.go:1036] Start adjusting jobs' network topology spec according to hyperNodeTierNameMap map[]
I0731 07:33:50.332853       1 session.go:1079] Finish adjusting jobs' network topology spec according to hyperNodeTierNameMap map[]
I0731 07:33:50.332879       1 session.go:279] Open Session 174852e4-26ed-4ad2-898c-eac6510b21f2 with <1> Job and <8> Queues. HyperNodesReadyToSchedule: true
I0731 07:33:50.333616       1 enqueue.go:79] Try to enqueue PodGroup to 0 Queues
I0731 07:33:50.333657       1 allocate.go:138] Try to allocate resource to 0 Queues
I0731 07:33:50.333901       1 session.go:577] Close Session 174852e4-26ed-4ad2-898c-eac6510b21f2
I0731 07:33:51.335231       1 cache.go:1581] "SnapShot for scheduling" jobNum=1 QueueNum=8 NodeNum=1
I0731 07:33:51.335290       1 session.go:1036] Start adjusting jobs' network topology spec according to hyperNodeTierNameMap map[]
I0731 07:33:51.335317       1 session.go:1079] Finish adjusting jobs' network topology spec according to hyperNodeTierNameMap map[]
I0731 07:33:51.335343       1 session.go:279] Open Session 88a34dec-a019-405f-8eae-40bcacbc9e45 with <1> Job and <8> Queues. HyperNodesReadyToSchedule: true
I0731 07:33:51.336153       1 enqueue.go:79] Try to enqueue PodGroup to 0 Queues
I0731 07:33:51.336196       1 allocate.go:138] Try to allocate resource to 0 Queues
I0731 07:33:51.336458       1 session.go:577] Close Session 88a34dec-a019-405f-8eae-40bcacbc9e45
I0731 07:33:52.337514       1 cache.go:1581] "SnapShot for scheduling" jobNum=1 QueueNum=8 NodeNum=1
I0731 07:33:52.337568       1 session.go:1036] Start adjusting jobs' network topology spec according to hyperNodeTierNameMap map[]
I0731 07:33:52.337593       1 session.go:1079] Finish adjusting jobs' network topology spec according to hyperNodeTierNameMap map[]
I0731 07:33:52.337618       1 session.go:279] Open Session f5b7b757-548f-48f2-99ce-4506bfbfd504 with <1> Job and <8> Queues. HyperNodesReadyToSchedule: true
I0731 07:33:52.338237       1 enqueue.go:79] Try to enqueue PodGroup to 0 Queues
I0731 07:33:52.338276       1 allocate.go:138] Try to allocate resource to 0 Queues
I0731 07:33:52.362705       1 session.go:577] Close Session f5b7b757-548f-48f2-99ce-4506bfbfd504
I0731 07:33:53.363638       1 cache.go:1581] "SnapShot for scheduling" jobNum=1 QueueNum=8 NodeNum=1
I0731 07:33:53.363686       1 session.go:1036] Start adjusting jobs' network topology spec according to hyperNodeTierNameMap map[]
I0731 07:33:53.363711       1 session.go:1079] Finish adjusting jobs' network topology spec according to hyperNodeTierNameMap map[]
I0731 07:33:53.363735       1 session.go:279] Open Session 81ce86a2-1923-48d8-8a6c-1e4671c733cd with <1> Job and <8> Queues. HyperNodesReadyToSchedule: true
I0731 07:33:53.364343       1 enqueue.go:79] Try to enqueue PodGroup to 0 Queues
I0731 07:33:53.364382       1 allocate.go:138] Try to allocate resource to 0 Queues
I0731 07:33:53.364613       1 session.go:577] Close Session 81ce86a2-1923-48d8-8a6c-1e4671c733cd
I0731 07:33:54.366112       1 cache.go:1581] "SnapShot for scheduling" jobNum=1 QueueNum=8 NodeNum=1
I0731 07:33:54.366160       1 session.go:1036] Start adjusting jobs' network topology spec according to hyperNodeTierNameMap map[]
I0731 07:33:54.366185       1 session.go:1079] Finish adjusting jobs' network topology spec according to hyperNodeTierNameMap map[]
I0731 07:33:54.366209       1 session.go:279] Open Session e97b2410-e2c3-4e22-84c1-a0295bfebca0 with <1> Job and <8> Queues. HyperNodesReadyToSchedule: true
I0731 07:33:54.366858       1 enqueue.go:79] Try to enqueue PodGroup to 0 Queues
I0731 07:33:54.366904       1 allocate.go:138] Try to allocate resource to 0 Queues
I0731 07:33:54.367131       1 session.go:577] Close Session e97b2410-e2c3-4e22-84c1-a0295bfebca0
I0731 07:33:55.143099       1 event_handlers.go:500] Deleted pod <khalil-volcano-bench/khalil-volcano-smoke-n8cqc> from cache.
I0731 07:33:55.366311       1 cache.go:1126] Try to delete Job <khalil-volcano-bench/khalil-volcano-smoke-pg:khalil-volcano-bench/khalil-volcano-smoke-pg>
I0731 07:33:55.366393       1 cache.go:1166] Job <khalil-volcano-bench/khalil-volcano-smoke-pg:khalil-volcano-bench/khalil-volcano-smoke-pg> was deleted.
I0731 07:33:55.368102       1 cache.go:1581] "SnapShot for scheduling" jobNum=0 QueueNum=8 NodeNum=1
I0731 07:33:55.368147       1 session.go:1036] Start adjusting jobs' network topology spec according to hyperNodeTierNameMap map[]
I0731 07:33:55.368169       1 session.go:1079] Finish adjusting jobs' network topology spec according to hyperNodeTierNameMap map[]
I0731 07:33:55.368197       1 session.go:279] Open Session 7a2beb40-ba03-46a3-8bfe-dcdef153c74d with <0> Job and <8> Queues. HyperNodesReadyToSchedule: true
I0731 07:33:55.370701       1 enqueue.go:79] Try to enqueue PodGroup to 0 Queues
I0731 07:33:55.370816       1 allocate.go:138] Try to allocate resource to 0 Queues
I0731 07:33:55.371067       1 session.go:577] Close Session 7a2beb40-ba03-46a3-8bfe-dcdef153c74d
I0731 07:33:56.371962       1 cache.go:1581] "SnapShot for scheduling" jobNum=2 QueueNum=7 NodeNum=1
I0731 07:33:56.372042       1 session.go:1036] Start adjusting jobs' network topology spec according to hyperNodeTierNameMap map[]
I0731 07:33:56.372076       1 session.go:1079] Finish adjusting jobs' network topology spec according to hyperNodeTierNameMap map[]
I0731 07:33:56.372107       1 session.go:279] Open Session 54b96748-3173-47ff-bbfb-9b0a1fe42083 with <2> Job and <7> Queues. HyperNodesReadyToSchedule: true
I0731 07:33:56.372963       1 enqueue.go:79] Try to enqueue PodGroup to 1 Queues
I0731 07:33:56.373165       1 allocate.go:138] Try to allocate resource to 0 Queues
I0731 07:33:56.381570       1 session.go:577] Close Session 54b96748-3173-47ff-bbfb-9b0a1fe42083
I0731 07:33:57.382391       1 cache.go:1581] "SnapShot for scheduling" jobNum=2 QueueNum=7 NodeNum=1
I0731 07:33:57.382458       1 session.go:1036] Start adjusting jobs' network topology spec according to hyperNodeTierNameMap map[]
I0731 07:33:57.382489       1 session.go:1079] Finish adjusting jobs' network topology spec according to hyperNodeTierNameMap map[]
I0731 07:33:57.382520       1 session.go:279] Open Session b7709a6b-a38e-48d6-b7ca-bec9f1efa393 with <2> Job and <7> Queues. HyperNodesReadyToSchedule: true
I0731 07:33:57.383384       1 enqueue.go:79] Try to enqueue PodGroup to 1 Queues
I0731 07:33:57.383510       1 allocate.go:138] Try to allocate resource to 0 Queues
I0731 07:33:57.383792       1 session.go:577] Close Session b7709a6b-a38e-48d6-b7ca-bec9f1efa393
I0731 07:33:58.385259       1 cache.go:1581] "SnapShot for scheduling" jobNum=2 QueueNum=7 NodeNum=1
I0731 07:33:58.385322       1 session.go:1036] Start adjusting jobs' network topology spec according to hyperNodeTierNameMap map[]
I0731 07:33:58.385350       1 session.go:1079] Finish adjusting jobs' network topology spec according to hyperNodeTierNameMap map[]
I0731 07:33:58.385378       1 session.go:279] Open Session 5e72258a-98c5-4ea4-b615-859d077c7d60 with <2> Job and <7> Queues. HyperNodesReadyToSchedule: true
I0731 07:33:58.386095       1 enqueue.go:79] Try to enqueue PodGroup to 1 Queues
I0731 07:33:58.386222       1 allocate.go:138] Try to allocate resource to 0 Queues
I0731 07:33:58.386476       1 session.go:577] Close Session 5e72258a-98c5-4ea4-b615-859d077c7d60
I0731 07:33:58.551078       1 event_handlers.go:445] Added pod <khalil-volcano-bench/khalil-volcano-quota-holder-hrrpd> into cache.
I0731 07:33:59.388083       1 cache.go:1581] "SnapShot for scheduling" jobNum=2 QueueNum=7 NodeNum=1
I0731 07:33:59.388144       1 session.go:1036] Start adjusting jobs' network topology spec according to hyperNodeTierNameMap map[]
I0731 07:33:59.388171       1 session.go:1079] Finish adjusting jobs' network topology spec according to hyperNodeTierNameMap map[]
I0731 07:33:59.388198       1 session.go:279] Open Session 524a1aba-e9b6-41d8-a15d-09223062b7ce with <2> Job and <7> Queues. HyperNodesReadyToSchedule: true
I0731 07:33:59.388958       1 enqueue.go:79] Try to enqueue PodGroup to 1 Queues
I0731 07:33:59.389103       1 allocate.go:138] Try to allocate resource to 1 Queues
I0731 07:33:59.389147       1 allocate.go:328] "Try to allocate resource" queue="khalil-volcano-quota" job="khalil-volcano-bench/khalil-volcano-quota-holder-pg" nominatedHyperNode="" taskNum=1
I0731 07:33:59.389191       1 allocate.go:777] There are <1> nodes for Job <khalil-volcano-bench/khalil-volcano-quota-holder-pg>
I0731 07:33:59.389379       1 allocate.go:956] Binding Task <khalil-volcano-bench/khalil-volcano-quota-holder-hrrpd> to node <gpu-dev-01>
I0731 07:33:59.389427       1 statement.go:277] After allocated Task <khalil-volcano-bench/khalil-volcano-quota-holder-hrrpd> to Node <gpu-dev-01>: idle <cpu 63085.00, memory 539520716800.00, ephemeral-storage 1015515997412000.00, hugepages-1Gi 0.00, hugepages-2Mi 0.00, nvidia.com/gpu 7000.00, pods 96.00>, used <cpu 915.00, memory 1153433600.00, nvidia.com/gpu 1000.00, pods 14.00>, releasing <cpu 0.00, memory 0.00>
I0731 07:33:59.389581       1 statement.go:307] Allocating operations ...
I0731 07:33:59.389636       1 allocate.go:855] "SubJob ready, return statement" job="khalil-volcano-bench/khalil-volcano-quota-holder-pg" subJob="khalil-volcano-bench/khalil-volcano-quota-holder-pg"
I0731 07:33:59.389690       1 statement.go:393] Committing operations ...
I0731 07:33:59.389758       1 proportion.go:326] Queue <khalil-volcano-quota> is overused: deserved <cpu 100.00, memory 134217728.00, ephemeral-storage 0.00, hugepages-1Gi 0.00, hugepages-2Mi 0.00, nvidia.com/gpu 1000.00, pods 1.00>, allocated <cpu 100.00, memory 134217728.00, nvidia.com/gpu 1000.00, pods 1.00>, share <1>
I0731 07:33:59.389804       1 allocate.go:295] Queue <khalil-volcano-quota> is overused, ignore it.
I0731 07:33:59.411421       1 cache.go:992] bind ok, latency 4.848966ms
I0731 07:33:59.414715       1 session.go:577] Close Session 524a1aba-e9b6-41d8-a15d-09223062b7ce
I0731 07:34:00.415827       1 cache.go:1581] "SnapShot for scheduling" jobNum=2 QueueNum=7 NodeNum=1
I0731 07:34:00.415907       1 session.go:1036] Start adjusting jobs' network topology spec according to hyperNodeTierNameMap map[]
I0731 07:34:00.415938       1 session.go:1079] Finish adjusting jobs' network topology spec according to hyperNodeTierNameMap map[]
I0731 07:34:00.415968       1 session.go:279] Open Session 547c8dc6-da87-4905-9422-7c973d6137aa with <2> Job and <7> Queues. HyperNodesReadyToSchedule: true
I0731 07:34:00.416883       1 enqueue.go:79] Try to enqueue PodGroup to 1 Queues
I0731 07:34:00.417039       1 allocate.go:138] Try to allocate resource to 0 Queues
I0731 07:34:00.425141       1 session.go:577] Close Session 547c8dc6-da87-4905-9422-7c973d6137aa
I0731 07:34:01.426056       1 cache.go:1581] "SnapShot for scheduling" jobNum=2 QueueNum=7 NodeNum=1
I0731 07:34:01.426131       1 session.go:1036] Start adjusting jobs' network topology spec according to hyperNodeTierNameMap map[]
I0731 07:34:01.426166       1 session.go:1079] Finish adjusting jobs' network topology spec according to hyperNodeTierNameMap map[]
I0731 07:34:01.426251       1 session.go:279] Open Session 139a404c-45c5-4bf0-add5-0ff1b1c63d56 with <2> Job and <7> Queues. HyperNodesReadyToSchedule: true
I0731 07:34:01.427268       1 enqueue.go:79] Try to enqueue PodGroup to 1 Queues
I0731 07:34:01.427440       1 allocate.go:138] Try to allocate resource to 0 Queues
I0731 07:34:01.427849       1 session.go:577] Close Session 139a404c-45c5-4bf0-add5-0ff1b1c63d56
I0731 07:34:02.429062       1 cache.go:1581] "SnapShot for scheduling" jobNum=2 QueueNum=7 NodeNum=1
I0731 07:34:02.429122       1 session.go:1036] Start adjusting jobs' network topology spec according to hyperNodeTierNameMap map[]
I0731 07:34:02.429150       1 session.go:1079] Finish adjusting jobs' network topology spec according to hyperNodeTierNameMap map[]
I0731 07:34:02.429177       1 session.go:279] Open Session d796ceef-36a7-48f3-93e9-f3882def6442 with <2> Job and <7> Queues. HyperNodesReadyToSchedule: true
I0731 07:34:02.430035       1 enqueue.go:79] Try to enqueue PodGroup to 1 Queues
I0731 07:34:02.430224       1 allocate.go:138] Try to allocate resource to 0 Queues
I0731 07:34:02.430599       1 session.go:577] Close Session d796ceef-36a7-48f3-93e9-f3882def6442
I0731 07:34:03.431410       1 cache.go:1581] "SnapShot for scheduling" jobNum=2 QueueNum=7 NodeNum=1
I0731 07:34:03.431470       1 session.go:1036] Start adjusting jobs' network topology spec according to hyperNodeTierNameMap map[]
I0731 07:34:03.431501       1 session.go:1079] Finish adjusting jobs' network topology spec according to hyperNodeTierNameMap map[]
I0731 07:34:03.431528       1 session.go:279] Open Session af3035df-2e01-40db-b8d7-1e8392aba51a with <2> Job and <7> Queues. HyperNodesReadyToSchedule: true
I0731 07:34:03.432403       1 enqueue.go:79] Try to enqueue PodGroup to 1 Queues
I0731 07:34:03.432581       1 allocate.go:138] Try to allocate resource to 0 Queues
I0731 07:34:03.440965       1 session.go:577] Close Session af3035df-2e01-40db-b8d7-1e8392aba51a
I0731 07:34:03.559317       1 event_handlers.go:445] Added pod <khalil-volcano-bench/khalil-volcano-quota-waiter-lzv4l> into cache.
I0731 07:34:04.441940       1 cache.go:1581] "SnapShot for scheduling" jobNum=2 QueueNum=7 NodeNum=1
I0731 07:34:04.441994       1 session.go:1036] Start adjusting jobs' network topology spec according to hyperNodeTierNameMap map[]
I0731 07:34:04.442021       1 session.go:1079] Finish adjusting jobs' network topology spec according to hyperNodeTierNameMap map[]
I0731 07:34:04.442048       1 session.go:279] Open Session ba1535bf-f2b7-4f74-8819-41e5867bc8ca with <2> Job and <7> Queues. HyperNodesReadyToSchedule: true
I0731 07:34:04.442959       1 enqueue.go:79] Try to enqueue PodGroup to 1 Queues
I0731 07:34:04.443100       1 allocate.go:138] Try to allocate resource to 0 Queues
I0731 07:34:04.452033       1 cache.go:1101] Updating pod condition for khalil-volcano-bench/khalil-volcano-quota-waiter-lzv4l to (PodScheduled==False)
I0731 07:34:04.459863       1 session.go:577] Close Session ba1535bf-f2b7-4f74-8819-41e5867bc8ca
I0731 07:34:05.460828       1 cache.go:1581] "SnapShot for scheduling" jobNum=2 QueueNum=7 NodeNum=1
I0731 07:34:05.460890       1 session.go:1036] Start adjusting jobs' network topology spec according to hyperNodeTierNameMap map[]
I0731 07:34:05.460919       1 session.go:1079] Finish adjusting jobs' network topology spec according to hyperNodeTierNameMap map[]
I0731 07:34:05.460947       1 session.go:279] Open Session a614ff24-12cf-4a80-991f-f82b9106dab3 with <2> Job and <7> Queues. HyperNodesReadyToSchedule: true
I0731 07:34:05.461891       1 enqueue.go:79] Try to enqueue PodGroup to 1 Queues
I0731 07:34:05.462038       1 allocate.go:138] Try to allocate resource to 0 Queues
I0731 07:34:05.462424       1 session.go:577] Close Session a614ff24-12cf-4a80-991f-f82b9106dab3
I0731 07:34:06.464014       1 cache.go:1581] "SnapShot for scheduling" jobNum=2 QueueNum=7 NodeNum=1
I0731 07:34:06.464084       1 session.go:1036] Start adjusting jobs' network topology spec according to hyperNodeTierNameMap map[]
I0731 07:34:06.464112       1 session.go:1079] Finish adjusting jobs' network topology spec according to hyperNodeTierNameMap map[]
I0731 07:34:06.464140       1 session.go:279] Open Session bc94e020-acbc-455a-a7fc-f9dc4c50893f with <2> Job and <7> Queues. HyperNodesReadyToSchedule: true
I0731 07:34:06.465078       1 enqueue.go:79] Try to enqueue PodGroup to 1 Queues
I0731 07:34:06.465220       1 allocate.go:138] Try to allocate resource to 0 Queues
I0731 07:34:06.465670       1 session.go:577] Close Session bc94e020-acbc-455a-a7fc-f9dc4c50893f
I0731 07:34:07.467171       1 cache.go:1581] "SnapShot for scheduling" jobNum=2 QueueNum=7 NodeNum=1
I0731 07:34:07.467219       1 session.go:1036] Start adjusting jobs' network topology spec according to hyperNodeTierNameMap map[]
I0731 07:34:07.467243       1 session.go:1079] Finish adjusting jobs' network topology spec according to hyperNodeTierNameMap map[]
I0731 07:34:07.467271       1 session.go:279] Open Session 8391e31e-3cd6-4af1-94fc-6f7811a4bb53 with <2> Job and <7> Queues. HyperNodesReadyToSchedule: true
I0731 07:34:07.468075       1 enqueue.go:79] Try to enqueue PodGroup to 1 Queues
I0731 07:34:07.468204       1 allocate.go:138] Try to allocate resource to 0 Queues
I0731 07:34:07.468651       1 session.go:577] Close Session 8391e31e-3cd6-4af1-94fc-6f7811a4bb53
I0731 07:34:08.469887       1 cache.go:1581] "SnapShot for scheduling" jobNum=2 QueueNum=7 NodeNum=1
I0731 07:34:08.469954       1 session.go:1036] Start adjusting jobs' network topology spec according to hyperNodeTierNameMap map[]
I0731 07:34:08.469983       1 session.go:1079] Finish adjusting jobs' network topology spec according to hyperNodeTierNameMap map[]
I0731 07:34:08.470011       1 session.go:279] Open Session 51733297-97d4-42ae-96d6-0e7c60a3659f with <2> Job and <7> Queues. HyperNodesReadyToSchedule: true
I0731 07:34:08.472463       1 enqueue.go:79] Try to enqueue PodGroup to 1 Queues
I0731 07:34:08.472892       1 allocate.go:138] Try to allocate resource to 0 Queues
I0731 07:34:08.474461       1 session.go:577] Close Session 51733297-97d4-42ae-96d6-0e7c60a3659f
I0731 07:34:09.475452       1 cache.go:1581] "SnapShot for scheduling" jobNum=2 QueueNum=7 NodeNum=1
I0731 07:34:09.475511       1 session.go:1036] Start adjusting jobs' network topology spec according to hyperNodeTierNameMap map[]
I0731 07:34:09.475542       1 session.go:1079] Finish adjusting jobs' network topology spec according to hyperNodeTierNameMap map[]
I0731 07:34:09.475569       1 session.go:279] Open Session fce348a8-d0b2-48a0-82fa-ea12150c1f10 with <2> Job and <7> Queues. HyperNodesReadyToSchedule: true
I0731 07:34:09.476474       1 enqueue.go:79] Try to enqueue PodGroup to 1 Queues
I0731 07:34:09.476611       1 allocate.go:138] Try to allocate resource to 0 Queues
I0731 07:34:09.476977       1 session.go:577] Close Session fce348a8-d0b2-48a0-82fa-ea12150c1f10
I0731 07:34:10.478322       1 cache.go:1581] "SnapShot for scheduling" jobNum=2 QueueNum=7 NodeNum=1
I0731 07:34:10.478386       1 session.go:1036] Start adjusting jobs' network topology spec according to hyperNodeTierNameMap map[]
I0731 07:34:10.478415       1 session.go:1079] Finish adjusting jobs' network topology spec according to hyperNodeTierNameMap map[]
I0731 07:34:10.478441       1 session.go:279] Open Session da2dd20a-fe40-4530-93f0-b4566fbdda42 with <2> Job and <7> Queues. HyperNodesReadyToSchedule: true
I0731 07:34:10.479436       1 enqueue.go:79] Try to enqueue PodGroup to 1 Queues
I0731 07:34:10.479579       1 allocate.go:138] Try to allocate resource to 0 Queues
I0731 07:34:10.479927       1 session.go:577] Close Session da2dd20a-fe40-4530-93f0-b4566fbdda42
I0731 07:34:11.481226       1 cache.go:1581] "SnapShot for scheduling" jobNum=2 QueueNum=7 NodeNum=1
I0731 07:34:11.481287       1 session.go:1036] Start adjusting jobs' network topology spec according to hyperNodeTierNameMap map[]
I0731 07:34:11.481315       1 session.go:1079] Finish adjusting jobs' network topology spec according to hyperNodeTierNameMap map[]
I0731 07:34:11.481344       1 session.go:279] Open Session 9324f4a3-ddbc-4a5e-aef3-cda1f148fb98 with <2> Job and <7> Queues. HyperNodesReadyToSchedule: true
I0731 07:34:11.482204       1 enqueue.go:79] Try to enqueue PodGroup to 1 Queues
I0731 07:34:11.482342       1 allocate.go:138] Try to allocate resource to 0 Queues
I0731 07:34:11.482707       1 session.go:577] Close Session 9324f4a3-ddbc-4a5e-aef3-cda1f148fb98
I0731 07:34:12.483911       1 cache.go:1581] "SnapShot for scheduling" jobNum=2 QueueNum=7 NodeNum=1
I0731 07:34:12.483972       1 session.go:1036] Start adjusting jobs' network topology spec according to hyperNodeTierNameMap map[]
I0731 07:34:12.484000       1 session.go:1079] Finish adjusting jobs' network topology spec according to hyperNodeTierNameMap map[]
I0731 07:34:12.484026       1 session.go:279] Open Session d137108b-7f68-4039-a5ac-4f3281303f67 with <2> Job and <7> Queues. HyperNodesReadyToSchedule: true
I0731 07:34:12.484915       1 enqueue.go:79] Try to enqueue PodGroup to 1 Queues
I0731 07:34:12.485064       1 allocate.go:138] Try to allocate resource to 0 Queues
I0731 07:34:12.485433       1 session.go:577] Close Session d137108b-7f68-4039-a5ac-4f3281303f67
I0731 07:34:13.486693       1 cache.go:1581] "SnapShot for scheduling" jobNum=2 QueueNum=7 NodeNum=1
I0731 07:34:13.486778       1 session.go:1036] Start adjusting jobs' network topology spec according to hyperNodeTierNameMap map[]
I0731 07:34:13.486807       1 session.go:1079] Finish adjusting jobs' network topology spec according to hyperNodeTierNameMap map[]
I0731 07:34:13.486835       1 session.go:279] Open Session 911988da-fe49-48ea-a6df-96d919c51948 with <2> Job and <7> Queues. HyperNodesReadyToSchedule: true
I0731 07:34:13.487758       1 enqueue.go:79] Try to enqueue PodGroup to 1 Queues
I0731 07:34:13.487893       1 allocate.go:138] Try to allocate resource to 0 Queues
I0731 07:34:13.488321       1 session.go:577] Close Session 911988da-fe49-48ea-a6df-96d919c51948
I0731 07:34:14.489258       1 cache.go:1581] "SnapShot for scheduling" jobNum=2 QueueNum=7 NodeNum=1
I0731 07:34:14.489313       1 session.go:1036] Start adjusting jobs' network topology spec according to hyperNodeTierNameMap map[]
I0731 07:34:14.489339       1 session.go:1079] Finish adjusting jobs' network topology spec according to hyperNodeTierNameMap map[]
I0731 07:34:14.489367       1 session.go:279] Open Session 04e44a3b-670b-4d0a-924b-b80f90f36a00 with <2> Job and <7> Queues. HyperNodesReadyToSchedule: true
I0731 07:34:14.490291       1 enqueue.go:79] Try to enqueue PodGroup to 1 Queues
I0731 07:34:14.490428       1 allocate.go:138] Try to allocate resource to 0 Queues
I0731 07:34:14.490807       1 session.go:577] Close Session 04e44a3b-670b-4d0a-924b-b80f90f36a00
I0731 07:34:15.491833       1 cache.go:1581] "SnapShot for scheduling" jobNum=2 QueueNum=7 NodeNum=1
I0731 07:34:15.491918       1 session.go:1036] Start adjusting jobs' network topology spec according to hyperNodeTierNameMap map[]
I0731 07:34:15.491950       1 session.go:1079] Finish adjusting jobs' network topology spec according to hyperNodeTierNameMap map[]
I0731 07:34:15.491980       1 session.go:279] Open Session 51d40d72-acd1-414e-84a9-d74edf12b77b with <2> Job and <7> Queues. HyperNodesReadyToSchedule: true
I0731 07:34:15.493032       1 enqueue.go:79] Try to enqueue PodGroup to 1 Queues
I0731 07:34:15.493189       1 allocate.go:138] Try to allocate resource to 0 Queues
I0731 07:34:15.493600       1 session.go:577] Close Session 51d40d72-acd1-414e-84a9-d74edf12b77b
I0731 07:34:16.485268       1 cache.go:1771] The metrics type is not set in the volcano scheduler configmap file. As a result, the CPU and memory load information of the node is not collected.
I0731 07:34:16.495110       1 cache.go:1581] "SnapShot for scheduling" jobNum=2 QueueNum=7 NodeNum=1
I0731 07:34:16.495170       1 session.go:1036] Start adjusting jobs' network topology spec according to hyperNodeTierNameMap map[]
I0731 07:34:16.495205       1 session.go:1079] Finish adjusting jobs' network topology spec according to hyperNodeTierNameMap map[]
I0731 07:34:16.495234       1 session.go:279] Open Session fa3008ec-eea9-494d-9c95-6373d7183e5c with <2> Job and <7> Queues. HyperNodesReadyToSchedule: true
I0731 07:34:16.496247       1 enqueue.go:79] Try to enqueue PodGroup to 1 Queues
I0731 07:34:16.496395       1 allocate.go:138] Try to allocate resource to 0 Queues
I0731 07:34:16.496741       1 session.go:577] Close Session fa3008ec-eea9-494d-9c95-6373d7183e5c
I0731 07:34:17.497421       1 cache.go:1581] "SnapShot for scheduling" jobNum=2 QueueNum=7 NodeNum=1
I0731 07:34:17.497478       1 session.go:1036] Start adjusting jobs' network topology spec according to hyperNodeTierNameMap map[]
I0731 07:34:17.497507       1 session.go:1079] Finish adjusting jobs' network topology spec according to hyperNodeTierNameMap map[]
I0731 07:34:17.497534       1 session.go:279] Open Session 520401f0-0fa8-4d3c-8308-46f6f2a9808e with <2> Job and <7> Queues. HyperNodesReadyToSchedule: true
I0731 07:34:17.498439       1 enqueue.go:79] Try to enqueue PodGroup to 1 Queues
I0731 07:34:17.498581       1 allocate.go:138] Try to allocate resource to 0 Queues
I0731 07:34:17.498963       1 session.go:577] Close Session 520401f0-0fa8-4d3c-8308-46f6f2a9808e
I0731 07:34:18.500530       1 cache.go:1581] "SnapShot for scheduling" jobNum=2 QueueNum=7 NodeNum=1
I0731 07:34:18.500602       1 session.go:1036] Start adjusting jobs' network topology spec according to hyperNodeTierNameMap map[]
I0731 07:34:18.500635       1 session.go:1079] Finish adjusting jobs' network topology spec according to hyperNodeTierNameMap map[]
I0731 07:34:18.500665       1 session.go:279] Open Session 39e5c773-0c59-4df3-aafb-7211d2df6a85 with <2> Job and <7> Queues. HyperNodesReadyToSchedule: true
I0731 07:34:18.501623       1 enqueue.go:79] Try to enqueue PodGroup to 1 Queues
I0731 07:34:18.501779       1 allocate.go:138] Try to allocate resource to 0 Queues
I0731 07:34:18.502105       1 session.go:577] Close Session 39e5c773-0c59-4df3-aafb-7211d2df6a85
I0731 07:34:19.503211       1 cache.go:1581] "SnapShot for scheduling" jobNum=2 QueueNum=7 NodeNum=1
I0731 07:34:19.503251       1 session.go:1036] Start adjusting jobs' network topology spec according to hyperNodeTierNameMap map[]
I0731 07:34:19.503272       1 session.go:1079] Finish adjusting jobs' network topology spec according to hyperNodeTierNameMap map[]
I0731 07:34:19.503295       1 session.go:279] Open Session 9b8f5009-c558-4104-8d58-16bd8778fe79 with <2> Job and <7> Queues. HyperNodesReadyToSchedule: true
I0731 07:34:19.504021       1 enqueue.go:79] Try to enqueue PodGroup to 1 Queues
I0731 07:34:19.504132       1 allocate.go:138] Try to allocate resource to 0 Queues
I0731 07:34:19.504598       1 session.go:577] Close Session 9b8f5009-c558-4104-8d58-16bd8778fe79
I0731 07:34:20.505773       1 cache.go:1581] "SnapShot for scheduling" jobNum=2 QueueNum=7 NodeNum=1
I0731 07:34:20.505840       1 session.go:1036] Start adjusting jobs' network topology spec according to hyperNodeTierNameMap map[]
I0731 07:34:20.505869       1 session.go:1079] Finish adjusting jobs' network topology spec according to hyperNodeTierNameMap map[]
I0731 07:34:20.505901       1 session.go:279] Open Session 2f3dab18-c688-46f6-8de7-da4517bef0cd with <2> Job and <7> Queues. HyperNodesReadyToSchedule: true
I0731 07:34:20.506788       1 enqueue.go:79] Try to enqueue PodGroup to 1 Queues
I0731 07:34:20.506935       1 allocate.go:138] Try to allocate resource to 0 Queues
I0731 07:34:20.507241       1 session.go:577] Close Session 2f3dab18-c688-46f6-8de7-da4517bef0cd
I0731 07:34:21.508357       1 cache.go:1581] "SnapShot for scheduling" jobNum=2 QueueNum=7 NodeNum=1
I0731 07:34:21.508423       1 session.go:1036] Start adjusting jobs' network topology spec according to hyperNodeTierNameMap map[]
I0731 07:34:21.508453       1 session.go:1079] Finish adjusting jobs' network topology spec according to hyperNodeTierNameMap map[]
I0731 07:34:21.508481       1 session.go:279] Open Session c50e81ae-d8b2-46aa-b14f-7a3b47c2e79b with <2> Job and <7> Queues. HyperNodesReadyToSchedule: true
I0731 07:34:21.509427       1 enqueue.go:79] Try to enqueue PodGroup to 1 Queues
I0731 07:34:21.509592       1 allocate.go:138] Try to allocate resource to 0 Queues
I0731 07:34:21.509901       1 session.go:577] Close Session c50e81ae-d8b2-46aa-b14f-7a3b47c2e79b
I0731 07:34:22.510490       1 cache.go:1581] "SnapShot for scheduling" jobNum=2 QueueNum=7 NodeNum=1
I0731 07:34:22.510529       1 session.go:1036] Start adjusting jobs' network topology spec according to hyperNodeTierNameMap map[]
I0731 07:34:22.510551       1 session.go:1079] Finish adjusting jobs' network topology spec according to hyperNodeTierNameMap map[]
I0731 07:34:22.510580       1 session.go:279] Open Session 9661de92-c0d5-4b5a-9a5e-4c71375791c8 with <2> Job and <7> Queues. HyperNodesReadyToSchedule: true
I0731 07:34:22.511297       1 enqueue.go:79] Try to enqueue PodGroup to 1 Queues
I0731 07:34:22.511408       1 allocate.go:138] Try to allocate resource to 0 Queues
I0731 07:34:22.511781       1 session.go:577] Close Session 9661de92-c0d5-4b5a-9a5e-4c71375791c8
I0731 07:34:23.513240       1 cache.go:1581] "SnapShot for scheduling" jobNum=2 QueueNum=7 NodeNum=1
I0731 07:34:23.513289       1 session.go:1036] Start adjusting jobs' network topology spec according to hyperNodeTierNameMap map[]
I0731 07:34:23.513314       1 session.go:1079] Finish adjusting jobs' network topology spec according to hyperNodeTierNameMap map[]
I0731 07:34:23.513342       1 session.go:279] Open Session b70f126c-2222-444b-8a3d-c32b14cb5ada with <2> Job and <7> Queues. HyperNodesReadyToSchedule: true
I0731 07:34:23.514224       1 enqueue.go:79] Try to enqueue PodGroup to 1 Queues
I0731 07:34:23.514365       1 allocate.go:138] Try to allocate resource to 0 Queues
I0731 07:34:23.514657       1 session.go:577] Close Session b70f126c-2222-444b-8a3d-c32b14cb5ada
I0731 07:34:24.515511       1 cache.go:1581] "SnapShot for scheduling" jobNum=2 QueueNum=7 NodeNum=1
I0731 07:34:24.515572       1 session.go:1036] Start adjusting jobs' network topology spec according to hyperNodeTierNameMap map[]
I0731 07:34:24.515601       1 session.go:1079] Finish adjusting jobs' network topology spec according to hyperNodeTierNameMap map[]
I0731 07:34:24.515629       1 session.go:279] Open Session d781c343-d9b4-46a3-93d7-83d2137504c8 with <2> Job and <7> Queues. HyperNodesReadyToSchedule: true
I0731 07:34:24.517157       1 enqueue.go:79] Try to enqueue PodGroup to 1 Queues
I0731 07:34:24.517392       1 allocate.go:138] Try to allocate resource to 0 Queues
I0731 07:34:24.518091       1 session.go:577] Close Session d781c343-d9b4-46a3-93d7-83d2137504c8
I0731 07:34:25.519541       1 cache.go:1581] "SnapShot for scheduling" jobNum=2 QueueNum=7 NodeNum=1
I0731 07:34:25.519608       1 session.go:1036] Start adjusting jobs' network topology spec according to hyperNodeTierNameMap map[]
I0731 07:34:25.519639       1 session.go:1079] Finish adjusting jobs' network topology spec according to hyperNodeTierNameMap map[]
I0731 07:34:25.519667       1 session.go:279] Open Session 4d13d399-6a91-4c5a-9cfa-50eeba386246 with <2> Job and <7> Queues. HyperNodesReadyToSchedule: true
I0731 07:34:25.520549       1 enqueue.go:79] Try to enqueue PodGroup to 1 Queues
I0731 07:34:25.520688       1 allocate.go:138] Try to allocate resource to 0 Queues
I0731 07:34:25.521168       1 session.go:577] Close Session 4d13d399-6a91-4c5a-9cfa-50eeba386246
I0731 07:34:26.521718       1 cache.go:1581] "SnapShot for scheduling" jobNum=2 QueueNum=7 NodeNum=1
I0731 07:34:26.521779       1 session.go:1036] Start adjusting jobs' network topology spec according to hyperNodeTierNameMap map[]
I0731 07:34:26.521808       1 session.go:1079] Finish adjusting jobs' network topology spec according to hyperNodeTierNameMap map[]
I0731 07:34:26.521837       1 session.go:279] Open Session d359718d-6af3-4b0a-85e1-6cec9c0c5323 with <2> Job and <7> Queues. HyperNodesReadyToSchedule: true
I0731 07:34:26.522774       1 enqueue.go:79] Try to enqueue PodGroup to 1 Queues
I0731 07:34:26.522913       1 allocate.go:138] Try to allocate resource to 0 Queues
I0731 07:34:26.523269       1 session.go:577] Close Session d359718d-6af3-4b0a-85e1-6cec9c0c5323
I0731 07:34:27.524351       1 cache.go:1581] "SnapShot for scheduling" jobNum=2 QueueNum=7 NodeNum=1
I0731 07:34:27.524412       1 session.go:1036] Start adjusting jobs' network topology spec according to hyperNodeTierNameMap map[]
I0731 07:34:27.524440       1 session.go:1079] Finish adjusting jobs' network topology spec according to hyperNodeTierNameMap map[]
I0731 07:34:27.524469       1 session.go:279] Open Session b413a7a1-3152-4279-bca3-d8a86276460d with <2> Job and <7> Queues. HyperNodesReadyToSchedule: true
I0731 07:34:27.525321       1 enqueue.go:79] Try to enqueue PodGroup to 1 Queues
I0731 07:34:27.525466       1 allocate.go:138] Try to allocate resource to 0 Queues
I0731 07:34:27.526032       1 session.go:577] Close Session b413a7a1-3152-4279-bca3-d8a86276460d
I0731 07:34:28.526624       1 cache.go:1581] "SnapShot for scheduling" jobNum=2 QueueNum=7 NodeNum=1
I0731 07:34:28.526688       1 session.go:1036] Start adjusting jobs' network topology spec according to hyperNodeTierNameMap map[]
I0731 07:34:28.526731       1 session.go:1079] Finish adjusting jobs' network topology spec according to hyperNodeTierNameMap map[]
I0731 07:34:28.526760       1 session.go:279] Open Session 4ee28523-52c6-4ea4-8b05-1a76647230e7 with <2> Job and <7> Queues. HyperNodesReadyToSchedule: true
I0731 07:34:28.527661       1 enqueue.go:79] Try to enqueue PodGroup to 1 Queues
I0731 07:34:28.527802       1 allocate.go:138] Try to allocate resource to 0 Queues
I0731 07:34:28.528101       1 session.go:577] Close Session 4ee28523-52c6-4ea4-8b05-1a76647230e7
I0731 07:34:29.528639       1 cache.go:1581] "SnapShot for scheduling" jobNum=2 QueueNum=7 NodeNum=1
I0731 07:34:29.528687       1 session.go:1036] Start adjusting jobs' network topology spec according to hyperNodeTierNameMap map[]
I0731 07:34:29.528712       1 session.go:1079] Finish adjusting jobs' network topology spec according to hyperNodeTierNameMap map[]
I0731 07:34:29.528740       1 session.go:279] Open Session c61efcd4-70ce-4dd6-943c-777869dd4007 with <2> Job and <7> Queues. HyperNodesReadyToSchedule: true
I0731 07:34:29.529635       1 enqueue.go:79] Try to enqueue PodGroup to 1 Queues
I0731 07:34:29.529765       1 allocate.go:138] Try to allocate resource to 0 Queues
I0731 07:34:29.530047       1 session.go:577] Close Session c61efcd4-70ce-4dd6-943c-777869dd4007
I0731 07:34:30.531474       1 cache.go:1581] "SnapShot for scheduling" jobNum=2 QueueNum=7 NodeNum=1
I0731 07:34:30.531518       1 session.go:1036] Start adjusting jobs' network topology spec according to hyperNodeTierNameMap map[]
I0731 07:34:30.531542       1 session.go:1079] Finish adjusting jobs' network topology spec according to hyperNodeTierNameMap map[]
I0731 07:34:30.531571       1 session.go:279] Open Session faa9f63f-1384-42b2-9451-23ddad3865e9 with <2> Job and <7> Queues. HyperNodesReadyToSchedule: true
I0731 07:34:30.532370       1 enqueue.go:79] Try to enqueue PodGroup to 1 Queues
I0731 07:34:30.532495       1 allocate.go:138] Try to allocate resource to 0 Queues
I0731 07:34:30.532845       1 session.go:577] Close Session faa9f63f-1384-42b2-9451-23ddad3865e9
I0731 07:34:31.533910       1 cache.go:1581] "SnapShot for scheduling" jobNum=2 QueueNum=7 NodeNum=1
I0731 07:34:31.533952       1 session.go:1036] Start adjusting jobs' network topology spec according to hyperNodeTierNameMap map[]
I0731 07:34:31.533974       1 session.go:1079] Finish adjusting jobs' network topology spec according to hyperNodeTierNameMap map[]
I0731 07:34:31.534003       1 session.go:279] Open Session 3ecf5f4f-d112-4d4f-9416-063c8428b8a7 with <2> Job and <7> Queues. HyperNodesReadyToSchedule: true
I0731 07:34:31.534861       1 enqueue.go:79] Try to enqueue PodGroup to 1 Queues
I0731 07:34:31.534996       1 allocate.go:138] Try to allocate resource to 0 Queues
I0731 07:34:31.535391       1 session.go:577] Close Session 3ecf5f4f-d112-4d4f-9416-063c8428b8a7
I0731 07:34:32.536650       1 cache.go:1581] "SnapShot for scheduling" jobNum=2 QueueNum=7 NodeNum=1
I0731 07:34:32.536708       1 session.go:1036] Start adjusting jobs' network topology spec according to hyperNodeTierNameMap map[]
I0731 07:34:32.536735       1 session.go:1079] Finish adjusting jobs' network topology spec according to hyperNodeTierNameMap map[]
I0731 07:34:32.536763       1 session.go:279] Open Session 0d27db52-3675-4a10-af5f-bc4e257001fe with <2> Job and <7> Queues. HyperNodesReadyToSchedule: true
I0731 07:34:32.537626       1 enqueue.go:79] Try to enqueue PodGroup to 1 Queues
I0731 07:34:32.537756       1 allocate.go:138] Try to allocate resource to 0 Queues
I0731 07:34:32.538110       1 session.go:577] Close Session 0d27db52-3675-4a10-af5f-bc4e257001fe
I0731 07:34:33.538663       1 cache.go:1581] "SnapShot for scheduling" jobNum=2 QueueNum=7 NodeNum=1
I0731 07:34:33.538735       1 session.go:1036] Start adjusting jobs' network topology spec according to hyperNodeTierNameMap map[]
I0731 07:34:33.538763       1 session.go:1079] Finish adjusting jobs' network topology spec according to hyperNodeTierNameMap map[]
I0731 07:34:33.538790       1 session.go:279] Open Session b1c3d8fb-6427-442d-9bf9-b2213840603b with <2> Job and <7> Queues. HyperNodesReadyToSchedule: true
I0731 07:34:33.539721       1 enqueue.go:79] Try to enqueue PodGroup to 1 Queues
I0731 07:34:33.539862       1 allocate.go:138] Try to allocate resource to 0 Queues
I0731 07:34:33.540183       1 session.go:577] Close Session b1c3d8fb-6427-442d-9bf9-b2213840603b
I0731 07:34:34.541715       1 cache.go:1581] "SnapShot for scheduling" jobNum=2 QueueNum=7 NodeNum=1
I0731 07:34:34.541763       1 session.go:1036] Start adjusting jobs' network topology spec according to hyperNodeTierNameMap map[]
I0731 07:34:34.541782       1 session.go:1079] Finish adjusting jobs' network topology spec according to hyperNodeTierNameMap map[]
I0731 07:34:34.541798       1 session.go:279] Open Session 4c839d58-cddd-4a5f-8257-804558544cac with <2> Job and <7> Queues. HyperNodesReadyToSchedule: true
I0731 07:34:34.542469       1 enqueue.go:79] Try to enqueue PodGroup to 1 Queues
I0731 07:34:34.542640       1 allocate.go:138] Try to allocate resource to 0 Queues
I0731 07:34:34.543006       1 session.go:577] Close Session 4c839d58-cddd-4a5f-8257-804558544cac
I0731 07:34:35.544103       1 cache.go:1581] "SnapShot for scheduling" jobNum=2 QueueNum=7 NodeNum=1
I0731 07:34:35.544166       1 session.go:1036] Start adjusting jobs' network topology spec according to hyperNodeTierNameMap map[]
I0731 07:34:35.544197       1 session.go:1079] Finish adjusting jobs' network topology spec according to hyperNodeTierNameMap map[]
I0731 07:34:35.544224       1 session.go:279] Open Session 84b8e5b3-037b-4546-b5ae-82feaec67b90 with <2> Job and <7> Queues. HyperNodesReadyToSchedule: true
I0731 07:34:35.545040       1 enqueue.go:79] Try to enqueue PodGroup to 1 Queues
I0731 07:34:35.545163       1 allocate.go:138] Try to allocate resource to 1 Queues
I0731 07:34:35.545206       1 allocate.go:328] "Try to allocate resource" queue="khalil-volcano-quota" job="khalil-volcano-bench/khalil-volcano-quota-waiter-pg" nominatedHyperNode="" taskNum=1
I0731 07:34:35.545250       1 allocate.go:777] There are <1> nodes for Job <khalil-volcano-bench/khalil-volcano-quota-waiter-pg>
I0731 07:34:35.545444       1 allocate.go:956] Binding Task <khalil-volcano-bench/khalil-volcano-quota-waiter-lzv4l> to node <gpu-dev-01>
I0731 07:34:35.545493       1 statement.go:277] After allocated Task <khalil-volcano-bench/khalil-volcano-quota-waiter-lzv4l> to Node <gpu-dev-01>: idle <cpu 63085.00, memory 539520716800.00, ephemeral-storage 1015515997412000.00, hugepages-1Gi 0.00, hugepages-2Mi 0.00, nvidia.com/gpu 7000.00, pods 96.00>, used <cpu 915.00, memory 1153433600.00, nvidia.com/gpu 1000.00, pods 14.00>, releasing <cpu 0.00, memory 0.00>
I0731 07:34:35.545645       1 statement.go:307] Allocating operations ...
I0731 07:34:35.545704       1 allocate.go:855] "SubJob ready, return statement" job="khalil-volcano-bench/khalil-volcano-quota-waiter-pg" subJob="khalil-volcano-bench/khalil-volcano-quota-waiter-pg"
I0731 07:34:35.545730       1 statement.go:393] Committing operations ...
I0731 07:34:35.545798       1 proportion.go:326] Queue <khalil-volcano-quota> is overused: deserved <cpu 100.00, memory 134217728.00, ephemeral-storage 0.00, hugepages-1Gi 0.00, hugepages-2Mi 0.00, nvidia.com/gpu 1000.00, pods 1.00>, allocated <cpu 100.00, memory 134217728.00, nvidia.com/gpu 1000.00, pods 1.00>, share <1>
I0731 07:34:35.545847       1 allocate.go:295] Queue <khalil-volcano-quota> is overused, ignore it.
I0731 07:34:35.556018       1 session.go:577] Close Session 84b8e5b3-037b-4546-b5ae-82feaec67b90
I0731 07:34:35.564289       1 cache.go:992] bind ok, latency 4.952475ms
I0731 07:34:36.557064       1 cache.go:1581] "SnapShot for scheduling" jobNum=2 QueueNum=7 NodeNum=1
I0731 07:34:36.557134       1 session.go:1036] Start adjusting jobs' network topology spec according to hyperNodeTierNameMap map[]
I0731 07:34:36.557167       1 session.go:1079] Finish adjusting jobs' network topology spec according to hyperNodeTierNameMap map[]
I0731 07:34:36.557197       1 session.go:279] Open Session 6be21217-bbe3-4540-ac69-93c550cb0ecc with <2> Job and <7> Queues. HyperNodesReadyToSchedule: true
I0731 07:34:36.558117       1 enqueue.go:79] Try to enqueue PodGroup to 0 Queues
I0731 07:34:36.558172       1 allocate.go:138] Try to allocate resource to 0 Queues
I0731 07:34:36.567078       1 session.go:577] Close Session 6be21217-bbe3-4540-ac69-93c550cb0ecc
I0731 07:34:37.568064       1 cache.go:1581] "SnapShot for scheduling" jobNum=2 QueueNum=7 NodeNum=1
I0731 07:34:37.568130       1 session.go:1036] Start adjusting jobs' network topology spec according to hyperNodeTierNameMap map[]
I0731 07:34:37.568162       1 session.go:1079] Finish adjusting jobs' network topology spec according to hyperNodeTierNameMap map[]
I0731 07:34:37.568189       1 session.go:279] Open Session 35275f30-22a6-436f-88cc-8129dc628ecc with <2> Job and <7> Queues. HyperNodesReadyToSchedule: true
I0731 07:34:37.569024       1 enqueue.go:79] Try to enqueue PodGroup to 0 Queues
I0731 07:34:37.569074       1 allocate.go:138] Try to allocate resource to 0 Queues
I0731 07:34:37.569445       1 session.go:577] Close Session 35275f30-22a6-436f-88cc-8129dc628ecc
I0731 07:34:38.570505       1 cache.go:1581] "SnapShot for scheduling" jobNum=2 QueueNum=7 NodeNum=1
I0731 07:34:38.570565       1 session.go:1036] Start adjusting jobs' network topology spec according to hyperNodeTierNameMap map[]
I0731 07:34:38.570592       1 session.go:1079] Finish adjusting jobs' network topology spec according to hyperNodeTierNameMap map[]
I0731 07:34:38.570621       1 session.go:279] Open Session ce1ae64f-6345-4f03-b1d0-69f36d793e16 with <2> Job and <7> Queues. HyperNodesReadyToSchedule: true
I0731 07:34:38.571428       1 enqueue.go:79] Try to enqueue PodGroup to 0 Queues
I0731 07:34:38.571476       1 allocate.go:138] Try to allocate resource to 0 Queues
I0731 07:34:38.571825       1 session.go:577] Close Session ce1ae64f-6345-4f03-b1d0-69f36d793e16
I0731 07:34:39.572768       1 cache.go:1581] "SnapShot for scheduling" jobNum=2 QueueNum=7 NodeNum=1
I0731 07:34:39.572834       1 session.go:1036] Start adjusting jobs' network topology spec according to hyperNodeTierNameMap map[]
I0731 07:34:39.572861       1 session.go:1079] Finish adjusting jobs' network topology spec according to hyperNodeTierNameMap map[]
I0731 07:34:39.572888       1 session.go:279] Open Session f67a7648-4018-4bd3-b656-72262942ddca with <2> Job and <7> Queues. HyperNodesReadyToSchedule: true
I0731 07:34:39.573777       1 enqueue.go:79] Try to enqueue PodGroup to 0 Queues
I0731 07:34:39.573827       1 allocate.go:138] Try to allocate resource to 0 Queues
I0731 07:34:39.582711       1 session.go:577] Close Session f67a7648-4018-4bd3-b656-72262942ddca
I0731 07:34:40.585561       1 cache.go:1581] "SnapShot for scheduling" jobNum=2 QueueNum=7 NodeNum=1
I0731 07:34:40.585664       1 session.go:1036] Start adjusting jobs' network topology spec according to hyperNodeTierNameMap map[]
I0731 07:34:40.585701       1 session.go:1079] Finish adjusting jobs' network topology spec according to hyperNodeTierNameMap map[]
I0731 07:34:40.585754       1 session.go:279] Open Session fa1f4714-5692-484b-8328-8031c7141965 with <2> Job and <7> Queues. HyperNodesReadyToSchedule: true
I0731 07:34:40.588917       1 enqueue.go:79] Try to enqueue PodGroup to 0 Queues
I0731 07:34:40.588989       1 allocate.go:138] Try to allocate resource to 0 Queues
I0731 07:34:40.589425       1 session.go:577] Close Session fa1f4714-5692-484b-8328-8031c7141965
I0731 07:34:41.590995       1 cache.go:1581] "SnapShot for scheduling" jobNum=2 QueueNum=7 NodeNum=1
I0731 07:34:41.591056       1 session.go:1036] Start adjusting jobs' network topology spec according to hyperNodeTierNameMap map[]
I0731 07:34:41.591086       1 session.go:1079] Finish adjusting jobs' network topology spec according to hyperNodeTierNameMap map[]
I0731 07:34:41.591115       1 session.go:279] Open Session 8d39d071-cf81-454e-9c27-feadb2e57011 with <2> Job and <7> Queues. HyperNodesReadyToSchedule: true
I0731 07:34:41.591979       1 enqueue.go:79] Try to enqueue PodGroup to 0 Queues
I0731 07:34:41.592032       1 allocate.go:138] Try to allocate resource to 0 Queues
I0731 07:34:41.592412       1 session.go:577] Close Session 8d39d071-cf81-454e-9c27-feadb2e57011
I0731 07:34:42.593736       1 cache.go:1581] "SnapShot for scheduling" jobNum=2 QueueNum=7 NodeNum=1
I0731 07:34:42.593791       1 session.go:1036] Start adjusting jobs' network topology spec according to hyperNodeTierNameMap map[]
I0731 07:34:42.593820       1 session.go:1079] Finish adjusting jobs' network topology spec according to hyperNodeTierNameMap map[]
I0731 07:34:42.593847       1 session.go:279] Open Session 6be9d2d6-51cc-482f-a02b-79b4213895ee with <2> Job and <7> Queues. HyperNodesReadyToSchedule: true
I0731 07:34:42.594638       1 enqueue.go:79] Try to enqueue PodGroup to 0 Queues
I0731 07:34:42.594685       1 allocate.go:138] Try to allocate resource to 0 Queues
I0731 07:34:42.595056       1 session.go:577] Close Session 6be9d2d6-51cc-482f-a02b-79b4213895ee
I0731 07:34:43.596047       1 cache.go:1581] "SnapShot for scheduling" jobNum=2 QueueNum=7 NodeNum=1
I0731 07:34:43.596103       1 session.go:1036] Start adjusting jobs' network topology spec according to hyperNodeTierNameMap map[]
I0731 07:34:43.596130       1 session.go:1079] Finish adjusting jobs' network topology spec according to hyperNodeTierNameMap map[]
I0731 07:34:43.596158       1 session.go:279] Open Session f240e30b-d04d-42c1-9956-014b2d251e75 with <2> Job and <7> Queues. HyperNodesReadyToSchedule: true
I0731 07:34:43.597068       1 enqueue.go:79] Try to enqueue PodGroup to 0 Queues
I0731 07:34:43.597118       1 allocate.go:138] Try to allocate resource to 0 Queues
I0731 07:34:43.597475       1 session.go:577] Close Session f240e30b-d04d-42c1-9956-014b2d251e75
I0731 07:34:44.598951       1 cache.go:1581] "SnapShot for scheduling" jobNum=2 QueueNum=7 NodeNum=1
I0731 07:34:44.599047       1 session.go:1036] Start adjusting jobs' network topology spec according to hyperNodeTierNameMap map[]
I0731 07:34:44.599076       1 session.go:1079] Finish adjusting jobs' network topology spec according to hyperNodeTierNameMap map[]
I0731 07:34:44.599106       1 session.go:279] Open Session 42c2aced-5d88-4b7f-ad66-915b85f2fad4 with <2> Job and <7> Queues. HyperNodesReadyToSchedule: true
I0731 07:34:44.600075       1 enqueue.go:79] Try to enqueue PodGroup to 0 Queues
I0731 07:34:44.600128       1 allocate.go:138] Try to allocate resource to 0 Queues
I0731 07:34:44.600452       1 session.go:577] Close Session 42c2aced-5d88-4b7f-ad66-915b85f2fad4
I0731 07:34:45.601961       1 cache.go:1581] "SnapShot for scheduling" jobNum=2 QueueNum=7 NodeNum=1
I0731 07:34:45.602036       1 session.go:1036] Start adjusting jobs' network topology spec according to hyperNodeTierNameMap map[]
I0731 07:34:45.602066       1 session.go:1079] Finish adjusting jobs' network topology spec according to hyperNodeTierNameMap map[]
I0731 07:34:45.602098       1 session.go:279] Open Session 34cbb4b4-4cf6-4ce9-a70f-5cdeddea6879 with <2> Job and <7> Queues. HyperNodesReadyToSchedule: true
I0731 07:34:45.603062       1 enqueue.go:79] Try to enqueue PodGroup to 0 Queues
I0731 07:34:45.603114       1 allocate.go:138] Try to allocate resource to 0 Queues
I0731 07:34:45.603458       1 session.go:577] Close Session 34cbb4b4-4cf6-4ce9-a70f-5cdeddea6879
I0731 07:34:46.485543       1 cache.go:1771] The metrics type is not set in the volcano scheduler configmap file. As a result, the CPU and memory load information of the node is not collected.
I0731 07:34:46.604105       1 cache.go:1581] "SnapShot for scheduling" jobNum=2 QueueNum=7 NodeNum=1
I0731 07:34:46.604197       1 session.go:1036] Start adjusting jobs' network topology spec according to hyperNodeTierNameMap map[]
I0731 07:34:46.604228       1 session.go:1079] Finish adjusting jobs' network topology spec according to hyperNodeTierNameMap map[]
I0731 07:34:46.604255       1 session.go:279] Open Session a80c6e6d-4e68-4e8e-82a0-b66261aafbcf with <2> Job and <7> Queues. HyperNodesReadyToSchedule: true
I0731 07:34:46.605087       1 enqueue.go:79] Try to enqueue PodGroup to 0 Queues
I0731 07:34:46.605140       1 allocate.go:138] Try to allocate resource to 0 Queues
I0731 07:34:46.630832       1 session.go:577] Close Session a80c6e6d-4e68-4e8e-82a0-b66261aafbcf
I0731 07:34:47.631962       1 cache.go:1581] "SnapShot for scheduling" jobNum=2 QueueNum=7 NodeNum=1
I0731 07:34:47.632028       1 session.go:1036] Start adjusting jobs' network topology spec according to hyperNodeTierNameMap map[]
I0731 07:34:47.632057       1 session.go:1079] Finish adjusting jobs' network topology spec according to hyperNodeTierNameMap map[]
I0731 07:34:47.632086       1 session.go:279] Open Session b521d183-d3c0-4df5-8e4c-6252e3fe57de with <2> Job and <7> Queues. HyperNodesReadyToSchedule: true
I0731 07:34:47.632814       1 enqueue.go:79] Try to enqueue PodGroup to 0 Queues
I0731 07:34:47.632867       1 allocate.go:138] Try to allocate resource to 0 Queues
I0731 07:34:47.633151       1 session.go:577] Close Session b521d183-d3c0-4df5-8e4c-6252e3fe57de
I0731 07:34:48.633921       1 cache.go:1581] "SnapShot for scheduling" jobNum=2 QueueNum=7 NodeNum=1
I0731 07:34:48.633993       1 session.go:1036] Start adjusting jobs' network topology spec according to hyperNodeTierNameMap map[]
I0731 07:34:48.634020       1 session.go:1079] Finish adjusting jobs' network topology spec according to hyperNodeTierNameMap map[]
I0731 07:34:48.634049       1 session.go:279] Open Session d1d58bec-0116-4ae0-81bd-487241de6d45 with <2> Job and <7> Queues. HyperNodesReadyToSchedule: true
I0731 07:34:48.634761       1 enqueue.go:79] Try to enqueue PodGroup to 0 Queues
I0731 07:34:48.634813       1 allocate.go:138] Try to allocate resource to 0 Queues
I0731 07:34:48.635181       1 session.go:577] Close Session d1d58bec-0116-4ae0-81bd-487241de6d45
I0731 07:34:49.443227       1 event_handlers.go:500] Deleted pod <khalil-volcano-bench/khalil-volcano-quota-waiter-lzv4l> from cache.
I0731 07:34:49.444724       1 event_handlers.go:500] Deleted pod <khalil-volcano-bench/khalil-volcano-quota-holder-hrrpd> from cache.
E0731 07:34:49.636234       1 job_info.go:778] Failed to clone subJob khalil-volcano-bench/khalil-volcano-quota-waiter-pg for job khalil-volcano-bench/khalil-volcano-quota-waiter-pg
E0731 07:34:49.636288       1 job_info.go:778] Failed to clone subJob khalil-volcano-bench/khalil-volcano-quota-holder-pg for job khalil-volcano-bench/khalil-volcano-quota-holder-pg
I0731 07:34:49.636375       1 cache.go:1581] "SnapShot for scheduling" jobNum=2 QueueNum=7 NodeNum=1
I0731 07:34:49.636421       1 session.go:1036] Start adjusting jobs' network topology spec according to hyperNodeTierNameMap map[]
I0731 07:34:49.636446       1 session.go:1079] Finish adjusting jobs' network topology spec according to hyperNodeTierNameMap map[]
I0731 07:34:49.636472       1 session.go:279] Open Session d338e7d2-dfe1-42b1-9d74-34d8b9a1e1fa with <2> Job and <7> Queues. HyperNodesReadyToSchedule: true
I0731 07:34:49.637211       1 enqueue.go:79] Try to enqueue PodGroup to 0 Queues
I0731 07:34:49.637247       1 allocate.go:138] Try to allocate resource to 0 Queues
I0731 07:34:49.646401       1 session.go:577] Close Session d338e7d2-dfe1-42b1-9d74-34d8b9a1e1fa
I0731 07:34:49.682744       1 cache.go:1126] Try to delete Job <khalil-volcano-bench/khalil-volcano-quota-holder-pg:khalil-volcano-bench/khalil-volcano-quota-holder-pg>
I0731 07:34:49.682833       1 cache.go:1166] Job <khalil-volcano-bench/khalil-volcano-quota-holder-pg:khalil-volcano-bench/khalil-volcano-quota-holder-pg> was deleted.
I0731 07:34:49.689895       1 cache.go:1126] Try to delete Job <khalil-volcano-bench/khalil-volcano-quota-waiter-pg:khalil-volcano-bench/khalil-volcano-quota-waiter-pg>
I0731 07:34:49.689994       1 cache.go:1166] Job <khalil-volcano-bench/khalil-volcano-quota-waiter-pg:khalil-volcano-bench/khalil-volcano-quota-waiter-pg> was deleted.
I0731 07:34:50.631656       1 event_handlers.go:445] Added pod <khalil-volcano-bench/khalil-volcano-gang-0-xl4mg> into cache.
I0731 07:34:50.637186       1 event_handlers.go:445] Added pod <khalil-volcano-bench/khalil-volcano-gang-1-fw7mg> into cache.
I0731 07:34:50.647464       1 cache.go:1581] "SnapShot for scheduling" jobNum=1 QueueNum=6 NodeNum=1
I0731 07:34:50.647512       1 session.go:1036] Start adjusting jobs' network topology spec according to hyperNodeTierNameMap map[]
I0731 07:34:50.647543       1 session.go:1079] Finish adjusting jobs' network topology spec according to hyperNodeTierNameMap map[]
I0731 07:34:50.647569       1 session.go:279] Open Session 0e0d940d-bd5f-4f82-ae78-b902770634ac with <1> Job and <6> Queues. HyperNodesReadyToSchedule: true
I0731 07:34:50.648360       1 enqueue.go:79] Try to enqueue PodGroup to 1 Queues
I0731 07:34:50.648481       1 allocate.go:138] Try to allocate resource to 0 Queues
I0731 07:34:50.656471       1 cache.go:1101] Updating pod condition for khalil-volcano-bench/khalil-volcano-gang-0-xl4mg to (PodScheduled==False)
I0731 07:34:50.656491       1 cache.go:1101] Updating pod condition for khalil-volcano-bench/khalil-volcano-gang-1-fw7mg to (PodScheduled==False)
I0731 07:34:50.663924       1 session.go:577] Close Session 0e0d940d-bd5f-4f82-ae78-b902770634ac
I0731 07:34:51.664857       1 cache.go:1581] "SnapShot for scheduling" jobNum=1 QueueNum=6 NodeNum=1
I0731 07:34:51.664913       1 session.go:1036] Start adjusting jobs' network topology spec according to hyperNodeTierNameMap map[]
I0731 07:34:51.664942       1 session.go:1079] Finish adjusting jobs' network topology spec according to hyperNodeTierNameMap map[]
I0731 07:34:51.664966       1 session.go:279] Open Session 48951e27-dd8c-44be-af89-19bb55ae166d with <1> Job and <6> Queues. HyperNodesReadyToSchedule: true
I0731 07:34:51.665680       1 enqueue.go:79] Try to enqueue PodGroup to 1 Queues
I0731 07:34:51.665798       1 allocate.go:138] Try to allocate resource to 0 Queues
I0731 07:34:51.666082       1 session.go:577] Close Session 48951e27-dd8c-44be-af89-19bb55ae166d
I0731 07:34:52.666615       1 cache.go:1581] "SnapShot for scheduling" jobNum=1 QueueNum=6 NodeNum=1
I0731 07:34:52.666671       1 session.go:1036] Start adjusting jobs' network topology spec according to hyperNodeTierNameMap map[]
I0731 07:34:52.666699       1 session.go:1079] Finish adjusting jobs' network topology spec according to hyperNodeTierNameMap map[]
I0731 07:34:52.666737       1 session.go:279] Open Session 3066b37d-4fea-4779-bbb0-0f677235e59d with <1> Job and <6> Queues. HyperNodesReadyToSchedule: true
I0731 07:34:52.667466       1 enqueue.go:79] Try to enqueue PodGroup to 1 Queues
I0731 07:34:52.667593       1 allocate.go:138] Try to allocate resource to 0 Queues
I0731 07:34:52.667866       1 session.go:577] Close Session 3066b37d-4fea-4779-bbb0-0f677235e59d
I0731 07:34:53.669166       1 cache.go:1581] "SnapShot for scheduling" jobNum=1 QueueNum=6 NodeNum=1
I0731 07:34:53.669221       1 session.go:1036] Start adjusting jobs' network topology spec according to hyperNodeTierNameMap map[]
I0731 07:34:53.669245       1 session.go:1079] Finish adjusting jobs' network topology spec according to hyperNodeTierNameMap map[]
I0731 07:34:53.669271       1 session.go:279] Open Session b05a6ed4-bc46-4f8e-a793-2bc1620691b8 with <1> Job and <6> Queues. HyperNodesReadyToSchedule: true
I0731 07:34:53.669968       1 enqueue.go:79] Try to enqueue PodGroup to 1 Queues
I0731 07:34:53.670084       1 allocate.go:138] Try to allocate resource to 0 Queues
I0731 07:34:53.670354       1 session.go:577] Close Session b05a6ed4-bc46-4f8e-a793-2bc1620691b8
I0731 07:34:54.672970       1 cache.go:1581] "SnapShot for scheduling" jobNum=1 QueueNum=6 NodeNum=1
I0731 07:34:54.673094       1 session.go:1036] Start adjusting jobs' network topology spec according to hyperNodeTierNameMap map[]
I0731 07:34:54.673128       1 session.go:1079] Finish adjusting jobs' network topology spec according to hyperNodeTierNameMap map[]
I0731 07:34:54.673157       1 session.go:279] Open Session 21bea2ed-3c5a-4b42-8867-1820d0d46e03 with <1> Job and <6> Queues. HyperNodesReadyToSchedule: true
I0731 07:34:54.674521       1 enqueue.go:79] Try to enqueue PodGroup to 1 Queues
I0731 07:34:54.674715       1 allocate.go:138] Try to allocate resource to 0 Queues
I0731 07:34:54.677591       1 session.go:577] Close Session 21bea2ed-3c5a-4b42-8867-1820d0d46e03
I0731 07:34:55.678504       1 cache.go:1581] "SnapShot for scheduling" jobNum=1 QueueNum=6 NodeNum=1
I0731 07:34:55.678554       1 session.go:1036] Start adjusting jobs' network topology spec according to hyperNodeTierNameMap map[]
I0731 07:34:55.678582       1 session.go:1079] Finish adjusting jobs' network topology spec according to hyperNodeTierNameMap map[]
I0731 07:34:55.678607       1 session.go:279] Open Session 2bfc17ca-55dc-41ac-9586-6adc47bafc9f with <1> Job and <6> Queues. HyperNodesReadyToSchedule: true
I0731 07:34:55.679309       1 enqueue.go:79] Try to enqueue PodGroup to 1 Queues
I0731 07:34:55.679420       1 allocate.go:138] Try to allocate resource to 0 Queues
I0731 07:34:55.679678       1 session.go:577] Close Session 2bfc17ca-55dc-41ac-9586-6adc47bafc9f
I0731 07:34:56.681147       1 cache.go:1581] "SnapShot for scheduling" jobNum=1 QueueNum=6 NodeNum=1
I0731 07:34:56.681201       1 session.go:1036] Start adjusting jobs' network topology spec according to hyperNodeTierNameMap map[]
I0731 07:34:56.681228       1 session.go:1079] Finish adjusting jobs' network topology spec according to hyperNodeTierNameMap map[]
I0731 07:34:56.681252       1 session.go:279] Open Session 5f6ae468-0d3d-42a1-adf1-ff7bfa042757 with <1> Job and <6> Queues. HyperNodesReadyToSchedule: true
I0731 07:34:56.681948       1 enqueue.go:79] Try to enqueue PodGroup to 1 Queues
I0731 07:34:56.682071       1 allocate.go:138] Try to allocate resource to 0 Queues
I0731 07:34:56.682350       1 session.go:577] Close Session 5f6ae468-0d3d-42a1-adf1-ff7bfa042757
I0731 07:34:57.683720       1 cache.go:1581] "SnapShot for scheduling" jobNum=1 QueueNum=6 NodeNum=1
I0731 07:34:57.683777       1 session.go:1036] Start adjusting jobs' network topology spec according to hyperNodeTierNameMap map[]
I0731 07:34:57.683803       1 session.go:1079] Finish adjusting jobs' network topology spec according to hyperNodeTierNameMap map[]
I0731 07:34:57.683830       1 session.go:279] Open Session 39fbf219-85f9-4f06-9d50-19d5e18d6264 with <1> Job and <6> Queues. HyperNodesReadyToSchedule: true
I0731 07:34:57.684626       1 enqueue.go:79] Try to enqueue PodGroup to 1 Queues
I0731 07:34:57.684748       1 allocate.go:138] Try to allocate resource to 0 Queues
I0731 07:34:57.685027       1 session.go:577] Close Session 39fbf219-85f9-4f06-9d50-19d5e18d6264
I0731 07:34:58.685820       1 cache.go:1581] "SnapShot for scheduling" jobNum=1 QueueNum=6 NodeNum=1
I0731 07:34:58.685876       1 session.go:1036] Start adjusting jobs' network topology spec according to hyperNodeTierNameMap map[]
I0731 07:34:58.685901       1 session.go:1079] Finish adjusting jobs' network topology spec according to hyperNodeTierNameMap map[]
I0731 07:34:58.685927       1 session.go:279] Open Session d79e15c7-a110-46df-b0bb-ffcffad080fe with <1> Job and <6> Queues. HyperNodesReadyToSchedule: true
I0731 07:34:58.686694       1 enqueue.go:79] Try to enqueue PodGroup to 1 Queues
I0731 07:34:58.686827       1 allocate.go:138] Try to allocate resource to 0 Queues
I0731 07:34:58.687122       1 session.go:577] Close Session d79e15c7-a110-46df-b0bb-ffcffad080fe
I0731 07:34:59.687851       1 cache.go:1581] "SnapShot for scheduling" jobNum=1 QueueNum=6 NodeNum=1
I0731 07:34:59.687896       1 session.go:1036] Start adjusting jobs' network topology spec according to hyperNodeTierNameMap map[]
I0731 07:34:59.687922       1 session.go:1079] Finish adjusting jobs' network topology spec according to hyperNodeTierNameMap map[]
I0731 07:34:59.687947       1 session.go:279] Open Session d7e70c51-d4a8-44db-9290-9d661c0f49db with <1> Job and <6> Queues. HyperNodesReadyToSchedule: true
I0731 07:34:59.688630       1 enqueue.go:79] Try to enqueue PodGroup to 1 Queues
I0731 07:34:59.688750       1 allocate.go:138] Try to allocate resource to 1 Queues
I0731 07:34:59.688797       1 allocate.go:328] "Try to allocate resource" queue="khalil-volcano-gang" job="khalil-volcano-bench/khalil-volcano-gang-pg" nominatedHyperNode="" taskNum=2
I0731 07:34:59.688839       1 allocate.go:777] There are <1> nodes for Job <khalil-volcano-bench/khalil-volcano-gang-pg>
I0731 07:34:59.689031       1 allocate.go:956] Binding Task <khalil-volcano-bench/khalil-volcano-gang-0-xl4mg> to node <gpu-dev-01>
I0731 07:34:59.689071       1 statement.go:277] After allocated Task <khalil-volcano-bench/khalil-volcano-gang-0-xl4mg> to Node <gpu-dev-01>: idle <cpu 63085.00, memory 539520716800.00, ephemeral-storage 1015515997412000.00, hugepages-1Gi 0.00, hugepages-2Mi 0.00, nvidia.com/gpu 7000.00, pods 96.00>, used <cpu 915.00, memory 1153433600.00, nvidia.com/gpu 1000.00, pods 14.00>, releasing <cpu 0.00, memory 0.00>
I0731 07:34:59.689233       1 statement.go:307] Allocating operations ...
I0731 07:34:59.689289       1 allocate.go:777] There are <1> nodes for Job <khalil-volcano-bench/khalil-volcano-gang-pg>
I0731 07:34:59.689391       1 allocate.go:956] Binding Task <khalil-volcano-bench/khalil-volcano-gang-1-fw7mg> to node <gpu-dev-01>
I0731 07:34:59.689421       1 statement.go:277] After allocated Task <khalil-volcano-bench/khalil-volcano-gang-1-fw7mg> to Node <gpu-dev-01>: idle <cpu 62985.00, memory 539386499072.00, ephemeral-storage 1015515997412000.00, hugepages-1Gi 0.00, hugepages-2Mi 0.00, nvidia.com/gpu 6000.00, pods 95.00>, used <cpu 1015.00, memory 1287651328.00, nvidia.com/gpu 2000.00, pods 15.00>, releasing <cpu 0.00, memory 0.00>
I0731 07:34:59.689539       1 statement.go:307] Allocating operations ...
I0731 07:34:59.689583       1 allocate.go:855] "SubJob ready, return statement" job="khalil-volcano-bench/khalil-volcano-gang-pg" subJob="khalil-volcano-bench/khalil-volcano-gang-pg"
I0731 07:34:59.689603       1 statement.go:393] Committing operations ...
I0731 07:34:59.689699       1 proportion.go:326] Queue <khalil-volcano-gang> is overused: deserved <cpu 200.00, memory 268435456.00, ephemeral-storage 0.00, hugepages-1Gi 0.00, hugepages-2Mi 0.00, nvidia.com/gpu 2000.00, pods 2.00>, allocated <cpu 200.00, memory 268435456.00, nvidia.com/gpu 2000.00, pods 2.00>, share <1>
I0731 07:34:59.689741       1 allocate.go:295] Queue <khalil-volcano-gang> is overused, ignore it.
I0731 07:34:59.712730       1 cache.go:992] bind ok, latency 4.876837ms
I0731 07:34:59.713644       1 cache.go:992] bind ok, latency 5.809741ms
I0731 07:34:59.715299       1 session.go:577] Close Session d7e70c51-d4a8-44db-9290-9d661c0f49db
I0731 07:35:00.716581       1 cache.go:1581] "SnapShot for scheduling" jobNum=1 QueueNum=6 NodeNum=1
I0731 07:35:00.716639       1 session.go:1036] Start adjusting jobs' network topology spec according to hyperNodeTierNameMap map[]
I0731 07:35:00.716666       1 session.go:1079] Finish adjusting jobs' network topology spec according to hyperNodeTierNameMap map[]
I0731 07:35:00.716694       1 session.go:279] Open Session e9e2a07b-fc4b-46fb-9fc3-7e32847b3ecf with <1> Job and <6> Queues. HyperNodesReadyToSchedule: true
I0731 07:35:00.717620       1 enqueue.go:79] Try to enqueue PodGroup to 0 Queues
I0731 07:35:00.717667       1 allocate.go:138] Try to allocate resource to 0 Queues
I0731 07:35:00.726654       1 session.go:577] Close Session e9e2a07b-fc4b-46fb-9fc3-7e32847b3ecf
I0731 07:35:01.728115       1 cache.go:1581] "SnapShot for scheduling" jobNum=1 QueueNum=6 NodeNum=1
I0731 07:35:01.728178       1 session.go:1036] Start adjusting jobs' network topology spec according to hyperNodeTierNameMap map[]
I0731 07:35:01.728206       1 session.go:1079] Finish adjusting jobs' network topology spec according to hyperNodeTierNameMap map[]
I0731 07:35:01.728233       1 session.go:279] Open Session 5045eafd-3eb3-408f-8047-46be8e0249f8 with <1> Job and <6> Queues. HyperNodesReadyToSchedule: true
I0731 07:35:01.729126       1 enqueue.go:79] Try to enqueue PodGroup to 0 Queues
I0731 07:35:01.729174       1 allocate.go:138] Try to allocate resource to 0 Queues
I0731 07:35:01.729459       1 session.go:577] Close Session 5045eafd-3eb3-408f-8047-46be8e0249f8
I0731 07:35:02.731026       1 cache.go:1581] "SnapShot for scheduling" jobNum=1 QueueNum=6 NodeNum=1
I0731 07:35:02.731081       1 session.go:1036] Start adjusting jobs' network topology spec according to hyperNodeTierNameMap map[]
I0731 07:35:02.731107       1 session.go:1079] Finish adjusting jobs' network topology spec according to hyperNodeTierNameMap map[]
I0731 07:35:02.731133       1 session.go:279] Open Session 830b02e9-7291-436a-80df-224f3b589766 with <1> Job and <6> Queues. HyperNodesReadyToSchedule: true
I0731 07:35:02.731979       1 enqueue.go:79] Try to enqueue PodGroup to 0 Queues
I0731 07:35:02.732023       1 allocate.go:138] Try to allocate resource to 0 Queues
I0731 07:35:02.732353       1 session.go:577] Close Session 830b02e9-7291-436a-80df-224f3b589766
I0731 07:35:03.733242       1 cache.go:1581] "SnapShot for scheduling" jobNum=1 QueueNum=6 NodeNum=1
I0731 07:35:03.733297       1 session.go:1036] Start adjusting jobs' network topology spec according to hyperNodeTierNameMap map[]
I0731 07:35:03.733323       1 session.go:1079] Finish adjusting jobs' network topology spec according to hyperNodeTierNameMap map[]
I0731 07:35:03.733350       1 session.go:279] Open Session 8f61efc3-028c-4e9f-b73d-f89e6b234ec5 with <1> Job and <6> Queues. HyperNodesReadyToSchedule: true
I0731 07:35:03.734274       1 enqueue.go:79] Try to enqueue PodGroup to 0 Queues
I0731 07:35:03.734318       1 allocate.go:138] Try to allocate resource to 0 Queues
I0731 07:35:03.734599       1 session.go:577] Close Session 8f61efc3-028c-4e9f-b73d-f89e6b234ec5
I0731 07:35:04.735568       1 cache.go:1581] "SnapShot for scheduling" jobNum=1 QueueNum=6 NodeNum=1
I0731 07:35:04.735634       1 session.go:1036] Start adjusting jobs' network topology spec according to hyperNodeTierNameMap map[]
I0731 07:35:04.735662       1 session.go:1079] Finish adjusting jobs' network topology spec according to hyperNodeTierNameMap map[]
I0731 07:35:04.735689       1 session.go:279] Open Session bc3cc3e8-0be3-4c5c-a45b-cc7634e6fcc2 with <1> Job and <6> Queues. HyperNodesReadyToSchedule: true
I0731 07:35:04.736573       1 enqueue.go:79] Try to enqueue PodGroup to 0 Queues
I0731 07:35:04.736620       1 allocate.go:138] Try to allocate resource to 0 Queues
I0731 07:35:04.745848       1 session.go:577] Close Session bc3cc3e8-0be3-4c5c-a45b-cc7634e6fcc2
I0731 07:35:05.746559       1 cache.go:1581] "SnapShot for scheduling" jobNum=1 QueueNum=6 NodeNum=1
I0731 07:35:05.746609       1 session.go:1036] Start adjusting jobs' network topology spec according to hyperNodeTierNameMap map[]
I0731 07:35:05.746633       1 session.go:1079] Finish adjusting jobs' network topology spec according to hyperNodeTierNameMap map[]
I0731 07:35:05.746657       1 session.go:279] Open Session 382a589f-20c6-465f-810f-f3b72f7666d3 with <1> Job and <6> Queues. HyperNodesReadyToSchedule: true
I0731 07:35:05.747542       1 enqueue.go:79] Try to enqueue PodGroup to 0 Queues
I0731 07:35:05.747584       1 allocate.go:138] Try to allocate resource to 0 Queues
I0731 07:35:05.747835       1 session.go:577] Close Session 382a589f-20c6-465f-810f-f3b72f7666d3
I0731 07:35:06.748882       1 cache.go:1581] "SnapShot for scheduling" jobNum=1 QueueNum=6 NodeNum=1
I0731 07:35:06.748927       1 session.go:1036] Start adjusting jobs' network topology spec according to hyperNodeTierNameMap map[]
I0731 07:35:06.748952       1 session.go:1079] Finish adjusting jobs' network topology spec according to hyperNodeTierNameMap map[]
I0731 07:35:06.748979       1 session.go:279] Open Session 8d57476d-76c9-4600-b287-d7a3e56f84a8 with <1> Job and <6> Queues. HyperNodesReadyToSchedule: true
I0731 07:35:06.749839       1 enqueue.go:79] Try to enqueue PodGroup to 0 Queues
I0731 07:35:06.749880       1 allocate.go:138] Try to allocate resource to 0 Queues
I0731 07:35:06.750131       1 session.go:577] Close Session 8d57476d-76c9-4600-b287-d7a3e56f84a8
I0731 07:35:07.751490       1 cache.go:1581] "SnapShot for scheduling" jobNum=1 QueueNum=6 NodeNum=1
I0731 07:35:07.751526       1 session.go:1036] Start adjusting jobs' network topology spec according to hyperNodeTierNameMap map[]
I0731 07:35:07.751548       1 session.go:1079] Finish adjusting jobs' network topology spec according to hyperNodeTierNameMap map[]
I0731 07:35:07.751573       1 session.go:279] Open Session 219ed692-7178-47fb-9dac-239b3d06ffc4 with <1> Job and <6> Queues. HyperNodesReadyToSchedule: true
I0731 07:35:07.752330       1 enqueue.go:79] Try to enqueue PodGroup to 0 Queues
I0731 07:35:07.752368       1 allocate.go:138] Try to allocate resource to 0 Queues
I0731 07:35:07.752600       1 session.go:577] Close Session 219ed692-7178-47fb-9dac-239b3d06ffc4
I0731 07:35:08.753429       1 cache.go:1581] "SnapShot for scheduling" jobNum=1 QueueNum=6 NodeNum=1
I0731 07:35:08.753489       1 session.go:1036] Start adjusting jobs' network topology spec according to hyperNodeTierNameMap map[]
I0731 07:35:08.753516       1 session.go:1079] Finish adjusting jobs' network topology spec according to hyperNodeTierNameMap map[]
I0731 07:35:08.753542       1 session.go:279] Open Session c9e36c5b-a9f9-4e4d-91a7-62128bf397a5 with <1> Job and <6> Queues. HyperNodesReadyToSchedule: true
I0731 07:35:08.754323       1 enqueue.go:79] Try to enqueue PodGroup to 0 Queues
I0731 07:35:08.754362       1 allocate.go:138] Try to allocate resource to 0 Queues
I0731 07:35:08.754605       1 session.go:577] Close Session c9e36c5b-a9f9-4e4d-91a7-62128bf397a5
I0731 07:35:09.755489       1 cache.go:1581] "SnapShot for scheduling" jobNum=1 QueueNum=6 NodeNum=1
I0731 07:35:09.755543       1 session.go:1036] Start adjusting jobs' network topology spec according to hyperNodeTierNameMap map[]
I0731 07:35:09.755570       1 session.go:1079] Finish adjusting jobs' network topology spec according to hyperNodeTierNameMap map[]
I0731 07:35:09.755595       1 session.go:279] Open Session 0d167277-fca5-46b6-843f-37855a9be221 with <1> Job and <6> Queues. HyperNodesReadyToSchedule: true
I0731 07:35:09.758535       1 enqueue.go:79] Try to enqueue PodGroup to 0 Queues
I0731 07:35:09.758628       1 allocate.go:138] Try to allocate resource to 0 Queues
I0731 07:35:09.759220       1 session.go:577] Close Session 0d167277-fca5-46b6-843f-37855a9be221
I0731 07:35:10.760308       1 cache.go:1581] "SnapShot for scheduling" jobNum=1 QueueNum=6 NodeNum=1
I0731 07:35:10.760362       1 session.go:1036] Start adjusting jobs' network topology spec according to hyperNodeTierNameMap map[]
I0731 07:35:10.760392       1 session.go:1079] Finish adjusting jobs' network topology spec according to hyperNodeTierNameMap map[]
I0731 07:35:10.760419       1 session.go:279] Open Session 861d2643-27fb-46bd-9d78-98e3a0c7a722 with <1> Job and <6> Queues. HyperNodesReadyToSchedule: true
I0731 07:35:10.761289       1 enqueue.go:79] Try to enqueue PodGroup to 0 Queues
I0731 07:35:10.761333       1 allocate.go:138] Try to allocate resource to 0 Queues
I0731 07:35:10.761662       1 session.go:577] Close Session 861d2643-27fb-46bd-9d78-98e3a0c7a722
I0731 07:35:11.763052       1 cache.go:1581] "SnapShot for scheduling" jobNum=1 QueueNum=6 NodeNum=1
I0731 07:35:11.763109       1 session.go:1036] Start adjusting jobs' network topology spec according to hyperNodeTierNameMap map[]
I0731 07:35:11.763136       1 session.go:1079] Finish adjusting jobs' network topology spec according to hyperNodeTierNameMap map[]
I0731 07:35:11.763165       1 session.go:279] Open Session 6343f638-d4dd-4408-b237-d263e01bd1db with <1> Job and <6> Queues. HyperNodesReadyToSchedule: true
I0731 07:35:11.763989       1 enqueue.go:79] Try to enqueue PodGroup to 0 Queues
I0731 07:35:11.764030       1 allocate.go:138] Try to allocate resource to 0 Queues
I0731 07:35:11.764280       1 session.go:577] Close Session 6343f638-d4dd-4408-b237-d263e01bd1db
I0731 07:35:12.765561       1 cache.go:1571] The Queue <khalil-volcano-gang> of Job <khalil-volcano-bench/khalil-volcano-gang-pg> does not exist, ignore it.
I0731 07:35:12.765619       1 cache.go:1581] "SnapShot for scheduling" jobNum=0 QueueNum=5 NodeNum=1
I0731 07:35:12.765651       1 session.go:1036] Start adjusting jobs' network topology spec according to hyperNodeTierNameMap map[]
I0731 07:35:12.765675       1 session.go:1079] Finish adjusting jobs' network topology spec according to hyperNodeTierNameMap map[]
I0731 07:35:12.765700       1 session.go:279] Open Session 81c3e024-d6dd-45d4-9d6d-ee41cc04309c with <0> Job and <5> Queues. HyperNodesReadyToSchedule: true
I0731 07:35:12.766271       1 enqueue.go:79] Try to enqueue PodGroup to 0 Queues
I0731 07:35:12.766295       1 allocate.go:138] Try to allocate resource to 0 Queues
I0731 07:35:12.774574       1 session.go:577] Close Session 81c3e024-d6dd-45d4-9d6d-ee41cc04309c
I0731 07:35:13.775856       1 cache.go:1571] The Queue <khalil-volcano-gang> of Job <khalil-volcano-bench/khalil-volcano-gang-pg> does not exist, ignore it.
I0731 07:35:13.775921       1 cache.go:1581] "SnapShot for scheduling" jobNum=0 QueueNum=5 NodeNum=1
I0731 07:35:13.775957       1 session.go:1036] Start adjusting jobs' network topology spec according to hyperNodeTierNameMap map[]
I0731 07:35:13.775983       1 session.go:1079] Finish adjusting jobs' network topology spec according to hyperNodeTierNameMap map[]
I0731 07:35:13.776007       1 session.go:279] Open Session e1aa4216-cc16-4ad3-bf24-4c1e8ce7c48b with <0> Job and <5> Queues. HyperNodesReadyToSchedule: true
I0731 07:35:13.776531       1 enqueue.go:79] Try to enqueue PodGroup to 0 Queues
I0731 07:35:13.776554       1 allocate.go:138] Try to allocate resource to 0 Queues
I0731 07:35:13.776656       1 session.go:577] Close Session e1aa4216-cc16-4ad3-bf24-4c1e8ce7c48b
I0731 07:35:14.777312       1 cache.go:1571] The Queue <khalil-volcano-gang> of Job <khalil-volcano-bench/khalil-volcano-gang-pg> does not exist, ignore it.
I0731 07:35:14.777371       1 cache.go:1581] "SnapShot for scheduling" jobNum=0 QueueNum=5 NodeNum=1
I0731 07:35:14.777400       1 session.go:1036] Start adjusting jobs' network topology spec according to hyperNodeTierNameMap map[]
I0731 07:35:14.777422       1 session.go:1079] Finish adjusting jobs' network topology spec according to hyperNodeTierNameMap map[]
I0731 07:35:14.777450       1 session.go:279] Open Session bba945b8-11f1-4c80-ae33-b3bc2e4bc75f with <0> Job and <5> Queues. HyperNodesReadyToSchedule: true
I0731 07:35:14.778063       1 enqueue.go:79] Try to enqueue PodGroup to 0 Queues
I0731 07:35:14.778089       1 allocate.go:138] Try to allocate resource to 0 Queues
I0731 07:35:14.778195       1 session.go:577] Close Session bba945b8-11f1-4c80-ae33-b3bc2e4bc75f
I0731 07:35:15.778658       1 cache.go:1571] The Queue <khalil-volcano-gang> of Job <khalil-volcano-bench/khalil-volcano-gang-pg> does not exist, ignore it.
I0731 07:35:15.778713       1 cache.go:1581] "SnapShot for scheduling" jobNum=0 QueueNum=5 NodeNum=1
I0731 07:35:15.778757       1 session.go:1036] Start adjusting jobs' network topology spec according to hyperNodeTierNameMap map[]
I0731 07:35:15.778780       1 session.go:1079] Finish adjusting jobs' network topology spec according to hyperNodeTierNameMap map[]
I0731 07:35:15.778805       1 session.go:279] Open Session ce40f42a-ee07-436a-a776-8d25ad8ef052 with <0> Job and <5> Queues. HyperNodesReadyToSchedule: true
I0731 07:35:15.779338       1 enqueue.go:79] Try to enqueue PodGroup to 0 Queues
I0731 07:35:15.779362       1 allocate.go:138] Try to allocate resource to 0 Queues
I0731 07:35:15.779471       1 session.go:577] Close Session ce40f42a-ee07-436a-a776-8d25ad8ef052
I0731 07:35:16.486425       1 cache.go:1771] The metrics type is not set in the volcano scheduler configmap file. As a result, the CPU and memory load information of the node is not collected.
I0731 07:35:16.699773       1 event_handlers.go:500] Deleted pod <khalil-volcano-bench/khalil-volcano-gang-0-xl4mg> from cache.
I0731 07:35:16.704840       1 event_handlers.go:500] Deleted pod <khalil-volcano-bench/khalil-volcano-gang-1-fw7mg> from cache.
I0731 07:35:16.723395       1 cache.go:1126] Try to delete Job <khalil-volcano-bench/khalil-volcano-gang-pg:khalil-volcano-bench/khalil-volcano-gang-pg>
I0731 07:35:16.723485       1 cache.go:1166] Job <khalil-volcano-bench/khalil-volcano-gang-pg:khalil-volcano-bench/khalil-volcano-gang-pg> was deleted.
I0731 07:35:16.780705       1 cache.go:1581] "SnapShot for scheduling" jobNum=0 QueueNum=5 NodeNum=1
I0731 07:35:16.780751       1 session.go:1036] Start adjusting jobs' network topology spec according to hyperNodeTierNameMap map[]
I0731 07:35:16.780774       1 session.go:1079] Finish adjusting jobs' network topology spec according to hyperNodeTierNameMap map[]
I0731 07:35:16.780799       1 session.go:279] Open Session 7437bb74-432d-41a8-a0ad-01cfe4603252 with <0> Job and <5> Queues. HyperNodesReadyToSchedule: true
I0731 07:35:16.781273       1 enqueue.go:79] Try to enqueue PodGroup to 0 Queues
I0731 07:35:16.781298       1 allocate.go:138] Try to allocate resource to 0 Queues
I0731 07:35:16.781399       1 session.go:577] Close Session 7437bb74-432d-41a8-a0ad-01cfe4603252
I0731 07:35:17.782353       1 cache.go:1581] "SnapShot for scheduling" jobNum=0 QueueNum=5 NodeNum=1
I0731 07:35:17.782399       1 session.go:1036] Start adjusting jobs' network topology spec according to hyperNodeTierNameMap map[]
I0731 07:35:17.782422       1 session.go:1079] Finish adjusting jobs' network topology spec according to hyperNodeTierNameMap map[]
I0731 07:35:17.782445       1 session.go:279] Open Session 0f33fc0c-a109-4cf8-871f-a975369f34ab with <0> Job and <5> Queues. HyperNodesReadyToSchedule: true
I0731 07:35:17.782952       1 enqueue.go:79] Try to enqueue PodGroup to 0 Queues
I0731 07:35:17.782977       1 allocate.go:138] Try to allocate resource to 0 Queues
I0731 07:35:17.783077       1 session.go:577] Close Session 0f33fc0c-a109-4cf8-871f-a975369f34ab
I0731 07:35:18.783991       1 cache.go:1581] "SnapShot for scheduling" jobNum=0 QueueNum=5 NodeNum=1
I0731 07:35:18.784034       1 session.go:1036] Start adjusting jobs' network topology spec according to hyperNodeTierNameMap map[]
I0731 07:35:18.784058       1 session.go:1079] Finish adjusting jobs' network topology spec according to hyperNodeTierNameMap map[]
I0731 07:35:18.784082       1 session.go:279] Open Session 9c195cb8-a071-4174-940a-65fe114888a2 with <0> Job and <5> Queues. HyperNodesReadyToSchedule: true
I0731 07:35:18.784546       1 enqueue.go:79] Try to enqueue PodGroup to 0 Queues
I0731 07:35:18.784569       1 allocate.go:138] Try to allocate resource to 0 Queues
I0731 07:35:18.784671       1 session.go:577] Close Session 9c195cb8-a071-4174-940a-65fe114888a2
I0731 07:35:19.785786       1 cache.go:1581] "SnapShot for scheduling" jobNum=0 QueueNum=5 NodeNum=1
I0731 07:35:19.785828       1 session.go:1036] Start adjusting jobs' network topology spec according to hyperNodeTierNameMap map[]
I0731 07:35:19.785851       1 session.go:1079] Finish adjusting jobs' network topology spec according to hyperNodeTierNameMap map[]
I0731 07:35:19.785875       1 session.go:279] Open Session 91dd011f-7e4f-4fa8-a7bc-669bf2c765f0 with <0> Job and <5> Queues. HyperNodesReadyToSchedule: true
I0731 07:35:19.786346       1 enqueue.go:79] Try to enqueue PodGroup to 0 Queues
I0731 07:35:19.786366       1 allocate.go:138] Try to allocate resource to 0 Queues
I0731 07:35:19.786466       1 session.go:577] Close Session 91dd011f-7e4f-4fa8-a7bc-669bf2c765f0
I0731 07:35:20.787590       1 cache.go:1581] "SnapShot for scheduling" jobNum=0 QueueNum=5 NodeNum=1
I0731 07:35:20.787697       1 session.go:1036] Start adjusting jobs' network topology spec according to hyperNodeTierNameMap map[]
I0731 07:35:20.787723       1 session.go:1079] Finish adjusting jobs' network topology spec according to hyperNodeTierNameMap map[]
I0731 07:35:20.787748       1 session.go:279] Open Session 06ee74e7-7c87-4ad6-a55e-f6d13982fc6f with <0> Job and <5> Queues. HyperNodesReadyToSchedule: true
I0731 07:35:20.788239       1 enqueue.go:79] Try to enqueue PodGroup to 0 Queues
I0731 07:35:20.788261       1 allocate.go:138] Try to allocate resource to 0 Queues
I0731 07:35:20.788366       1 session.go:577] Close Session 06ee74e7-7c87-4ad6-a55e-f6d13982fc6f
I0731 07:35:21.788960       1 cache.go:1581] "SnapShot for scheduling" jobNum=0 QueueNum=5 NodeNum=1
I0731 07:35:21.789006       1 session.go:1036] Start adjusting jobs' network topology spec according to hyperNodeTierNameMap map[]
I0731 07:35:21.789029       1 session.go:1079] Finish adjusting jobs' network topology spec according to hyperNodeTierNameMap map[]
I0731 07:35:21.789052       1 session.go:279] Open Session 75c708ff-9095-43da-9d2d-5296205153e5 with <0> Job and <5> Queues. HyperNodesReadyToSchedule: true
I0731 07:35:21.789506       1 enqueue.go:79] Try to enqueue PodGroup to 0 Queues
I0731 07:35:21.789528       1 allocate.go:138] Try to allocate resource to 0 Queues
I0731 07:35:21.789627       1 session.go:577] Close Session 75c708ff-9095-43da-9d2d-5296205153e5
I0731 07:35:22.790924       1 cache.go:1581] "SnapShot for scheduling" jobNum=0 QueueNum=5 NodeNum=1
I0731 07:35:22.790968       1 session.go:1036] Start adjusting jobs' network topology spec according to hyperNodeTierNameMap map[]
I0731 07:35:22.790991       1 session.go:1079] Finish adjusting jobs' network topology spec according to hyperNodeTierNameMap map[]
I0731 07:35:22.791013       1 session.go:279] Open Session 579b1d0c-2e6b-4d2f-a7e6-ac6fe17096e8 with <0> Job and <5> Queues. HyperNodesReadyToSchedule: true
I0731 07:35:22.791466       1 enqueue.go:79] Try to enqueue PodGroup to 0 Queues
I0731 07:35:22.791489       1 allocate.go:138] Try to allocate resource to 0 Queues
I0731 07:35:22.791590       1 session.go:577] Close Session 579b1d0c-2e6b-4d2f-a7e6-ac6fe17096e8
I0731 07:35:23.792969       1 cache.go:1581] "SnapShot for scheduling" jobNum=0 QueueNum=5 NodeNum=1
I0731 07:35:23.793011       1 session.go:1036] Start adjusting jobs' network topology spec according to hyperNodeTierNameMap map[]
I0731 07:35:23.793033       1 session.go:1079] Finish adjusting jobs' network topology spec according to hyperNodeTierNameMap map[]
I0731 07:35:23.793060       1 session.go:279] Open Session 28d367c6-83f1-4c64-940d-f46f76c108c6 with <0> Job and <5> Queues. HyperNodesReadyToSchedule: true
I0731 07:35:23.793507       1 enqueue.go:79] Try to enqueue PodGroup to 0 Queues
I0731 07:35:23.793530       1 allocate.go:138] Try to allocate resource to 0 Queues
I0731 07:35:23.793627       1 session.go:577] Close Session 28d367c6-83f1-4c64-940d-f46f76c108c6
I0731 07:35:24.795042       1 cache.go:1581] "SnapShot for scheduling" jobNum=0 QueueNum=5 NodeNum=1
I0731 07:35:24.795086       1 session.go:1036] Start adjusting jobs' network topology spec according to hyperNodeTierNameMap map[]
I0731 07:35:24.795110       1 session.go:1079] Finish adjusting jobs' network topology spec according to hyperNodeTierNameMap map[]
I0731 07:35:24.795134       1 session.go:279] Open Session 3e6239e3-cb81-4a6b-a222-720b4886c80a with <0> Job and <5> Queues. HyperNodesReadyToSchedule: true
I0731 07:35:24.795629       1 enqueue.go:79] Try to enqueue PodGroup to 0 Queues
I0731 07:35:24.795650       1 allocate.go:138] Try to allocate resource to 0 Queues
I0731 07:35:24.795747       1 session.go:577] Close Session 3e6239e3-cb81-4a6b-a222-720b4886c80a
I0731 07:35:25.796819       1 cache.go:1581] "SnapShot for scheduling" jobNum=0 QueueNum=5 NodeNum=1
I0731 07:35:25.796867       1 session.go:1036] Start adjusting jobs' network topology spec according to hyperNodeTierNameMap map[]
I0731 07:35:25.796890       1 session.go:1079] Finish adjusting jobs' network topology spec according to hyperNodeTierNameMap map[]
I0731 07:35:25.796913       1 session.go:279] Open Session bc5023b3-5903-42b5-8f48-917b33479020 with <0> Job and <5> Queues. HyperNodesReadyToSchedule: true
I0731 07:35:25.797378       1 enqueue.go:79] Try to enqueue PodGroup to 0 Queues
I0731 07:35:25.797401       1 allocate.go:138] Try to allocate resource to 0 Queues
I0731 07:35:25.797492       1 session.go:577] Close Session bc5023b3-5903-42b5-8f48-917b33479020
I0731 07:35:26.798170       1 cache.go:1581] "SnapShot for scheduling" jobNum=0 QueueNum=5 NodeNum=1
I0731 07:35:26.798222       1 session.go:1036] Start adjusting jobs' network topology spec according to hyperNodeTierNameMap map[]
I0731 07:35:26.798247       1 session.go:1079] Finish adjusting jobs' network topology spec according to hyperNodeTierNameMap map[]
I0731 07:35:26.798272       1 session.go:279] Open Session b4356c48-9f43-4448-92ce-f8d2d9c82c73 with <0> Job and <5> Queues. HyperNodesReadyToSchedule: true
I0731 07:35:26.798794       1 enqueue.go:79] Try to enqueue PodGroup to 0 Queues
I0731 07:35:26.798819       1 allocate.go:138] Try to allocate resource to 0 Queues
I0731 07:35:26.798929       1 session.go:577] Close Session b4356c48-9f43-4448-92ce-f8d2d9c82c73
I0731 07:35:27.800123       1 cache.go:1581] "SnapShot for scheduling" jobNum=0 QueueNum=5 NodeNum=1
I0731 07:35:27.800176       1 session.go:1036] Start adjusting jobs' network topology spec according to hyperNodeTierNameMap map[]
I0731 07:35:27.800202       1 session.go:1079] Finish adjusting jobs' network topology spec according to hyperNodeTierNameMap map[]
I0731 07:35:27.800227       1 session.go:279] Open Session 954fefa0-dc83-4e15-a786-d0f733a046ed with <0> Job and <5> Queues. HyperNodesReadyToSchedule: true
I0731 07:35:27.800744       1 enqueue.go:79] Try to enqueue PodGroup to 0 Queues
I0731 07:35:27.800771       1 allocate.go:138] Try to allocate resource to 0 Queues
I0731 07:35:27.800878       1 session.go:577] Close Session 954fefa0-dc83-4e15-a786-d0f733a046ed
I0731 07:35:28.801477       1 cache.go:1581] "SnapShot for scheduling" jobNum=0 QueueNum=5 NodeNum=1
I0731 07:35:28.801534       1 session.go:1036] Start adjusting jobs' network topology spec according to hyperNodeTierNameMap map[]
I0731 07:35:28.801558       1 session.go:1079] Finish adjusting jobs' network topology spec according to hyperNodeTierNameMap map[]
I0731 07:35:28.801583       1 session.go:279] Open Session 63f3a87e-7a2b-40e1-a730-2d2201eb925d with <0> Job and <5> Queues. HyperNodesReadyToSchedule: true
I0731 07:35:28.802130       1 enqueue.go:79] Try to enqueue PodGroup to 0 Queues
I0731 07:35:28.802153       1 allocate.go:138] Try to allocate resource to 0 Queues
I0731 07:35:28.802262       1 session.go:577] Close Session 63f3a87e-7a2b-40e1-a730-2d2201eb925d
I0731 07:35:29.803399       1 cache.go:1581] "SnapShot for scheduling" jobNum=0 QueueNum=5 NodeNum=1
I0731 07:35:29.803444       1 session.go:1036] Start adjusting jobs' network topology spec according to hyperNodeTierNameMap map[]
I0731 07:35:29.803467       1 session.go:1079] Finish adjusting jobs' network topology spec according to hyperNodeTierNameMap map[]
I0731 07:35:29.803490       1 session.go:279] Open Session 3a0bed1a-604a-491c-a8b3-b648c45e9986 with <0> Job and <5> Queues. HyperNodesReadyToSchedule: true
I0731 07:35:29.803962       1 enqueue.go:79] Try to enqueue PodGroup to 0 Queues
I0731 07:35:29.803984       1 allocate.go:138] Try to allocate resource to 0 Queues
I0731 07:35:29.804081       1 session.go:577] Close Session 3a0bed1a-604a-491c-a8b3-b648c45e9986
I0731 07:35:30.804766       1 cache.go:1581] "SnapShot for scheduling" jobNum=0 QueueNum=5 NodeNum=1
I0731 07:35:30.804814       1 session.go:1036] Start adjusting jobs' network topology spec according to hyperNodeTierNameMap map[]
I0731 07:35:30.804838       1 session.go:1079] Finish adjusting jobs' network topology spec according to hyperNodeTierNameMap map[]
I0731 07:35:30.804861       1 session.go:279] Open Session a14772ba-8153-42e8-897b-8ba358f69d84 with <0> Job and <5> Queues. HyperNodesReadyToSchedule: true
I0731 07:35:30.805382       1 enqueue.go:79] Try to enqueue PodGroup to 0 Queues
I0731 07:35:30.805405       1 allocate.go:138] Try to allocate resource to 0 Queues
I0731 07:35:30.805530       1 session.go:577] Close Session a14772ba-8153-42e8-897b-8ba358f69d84
I0731 07:35:31.806166       1 cache.go:1581] "SnapShot for scheduling" jobNum=0 QueueNum=5 NodeNum=1
I0731 07:35:31.806212       1 session.go:1036] Start adjusting jobs' network topology spec according to hyperNodeTierNameMap map[]
I0731 07:35:31.806236       1 session.go:1079] Finish adjusting jobs' network topology spec according to hyperNodeTierNameMap map[]
I0731 07:35:31.806259       1 session.go:279] Open Session 02564984-da27-406c-a110-8d9660328a91 with <0> Job and <5> Queues. HyperNodesReadyToSchedule: true
I0731 07:35:31.806768       1 enqueue.go:79] Try to enqueue PodGroup to 0 Queues
I0731 07:35:31.806791       1 allocate.go:138] Try to allocate resource to 0 Queues
I0731 07:35:31.806887       1 session.go:577] Close Session 02564984-da27-406c-a110-8d9660328a91
I0731 07:35:32.807567       1 cache.go:1581] "SnapShot for scheduling" jobNum=0 QueueNum=5 NodeNum=1
I0731 07:35:32.807609       1 session.go:1036] Start adjusting jobs' network topology spec according to hyperNodeTierNameMap map[]
I0731 07:35:32.807632       1 session.go:1079] Finish adjusting jobs' network topology spec according to hyperNodeTierNameMap map[]
I0731 07:35:32.807656       1 session.go:279] Open Session a73fb662-4858-4112-ae74-387ee1f5e8fb with <0> Job and <5> Queues. HyperNodesReadyToSchedule: true
I0731 07:35:32.808091       1 enqueue.go:79] Try to enqueue PodGroup to 0 Queues
I0731 07:35:32.808113       1 allocate.go:138] Try to allocate resource to 0 Queues
I0731 07:35:32.808210       1 session.go:577] Close Session a73fb662-4858-4112-ae74-387ee1f5e8fb
I0731 07:35:33.808887       1 cache.go:1581] "SnapShot for scheduling" jobNum=0 QueueNum=5 NodeNum=1
I0731 07:35:33.808933       1 session.go:1036] Start adjusting jobs' network topology spec according to hyperNodeTierNameMap map[]
I0731 07:35:33.808959       1 session.go:1079] Finish adjusting jobs' network topology spec according to hyperNodeTierNameMap map[]
I0731 07:35:33.808985       1 session.go:279] Open Session 50e52bae-b6a2-4169-86f0-2d1a4931a371 with <0> Job and <5> Queues. HyperNodesReadyToSchedule: true
I0731 07:35:33.809470       1 enqueue.go:79] Try to enqueue PodGroup to 0 Queues
I0731 07:35:33.809493       1 allocate.go:138] Try to allocate resource to 0 Queues
I0731 07:35:33.809592       1 session.go:577] Close Session 50e52bae-b6a2-4169-86f0-2d1a4931a371
I0731 07:35:34.810798       1 cache.go:1581] "SnapShot for scheduling" jobNum=0 QueueNum=5 NodeNum=1
I0731 07:35:34.810846       1 session.go:1036] Start adjusting jobs' network topology spec according to hyperNodeTierNameMap map[]
I0731 07:35:34.810871       1 session.go:1079] Finish adjusting jobs' network topology spec according to hyperNodeTierNameMap map[]
I0731 07:35:34.810894       1 session.go:279] Open Session a7af9f8f-dbf2-4712-9817-8192f79dba8f with <0> Job and <5> Queues. HyperNodesReadyToSchedule: true
I0731 07:35:34.811343       1 enqueue.go:79] Try to enqueue PodGroup to 0 Queues
I0731 07:35:34.811364       1 allocate.go:138] Try to allocate resource to 0 Queues
I0731 07:35:34.811463       1 session.go:577] Close Session a7af9f8f-dbf2-4712-9817-8192f79dba8f
I0731 07:35:35.812747       1 cache.go:1581] "SnapShot for scheduling" jobNum=0 QueueNum=5 NodeNum=1
I0731 07:35:35.812791       1 session.go:1036] Start adjusting jobs' network topology spec according to hyperNodeTierNameMap map[]
I0731 07:35:35.812814       1 session.go:1079] Finish adjusting jobs' network topology spec according to hyperNodeTierNameMap map[]
I0731 07:35:35.812839       1 session.go:279] Open Session 270b7716-c699-4b12-a22b-be86f507768a with <0> Job and <5> Queues. HyperNodesReadyToSchedule: true
I0731 07:35:35.813280       1 enqueue.go:79] Try to enqueue PodGroup to 0 Queues
I0731 07:35:35.813305       1 allocate.go:138] Try to allocate resource to 0 Queues
I0731 07:35:35.813411       1 session.go:577] Close Session 270b7716-c699-4b12-a22b-be86f507768a
I0731 07:35:36.814412       1 cache.go:1581] "SnapShot for scheduling" jobNum=0 QueueNum=5 NodeNum=1
I0731 07:35:36.814458       1 session.go:1036] Start adjusting jobs' network topology spec according to hyperNodeTierNameMap map[]
I0731 07:35:36.814481       1 session.go:1079] Finish adjusting jobs' network topology spec according to hyperNodeTierNameMap map[]
I0731 07:35:36.814503       1 session.go:279] Open Session b645006d-a7b7-4f18-8859-4e790440589f with <0> Job and <5> Queues. HyperNodesReadyToSchedule: true
I0731 07:35:36.815064       1 enqueue.go:79] Try to enqueue PodGroup to 0 Queues
I0731 07:35:36.815086       1 allocate.go:138] Try to allocate resource to 0 Queues
I0731 07:35:36.815183       1 session.go:577] Close Session b645006d-a7b7-4f18-8859-4e790440589f
I0731 07:35:37.816433       1 cache.go:1581] "SnapShot for scheduling" jobNum=0 QueueNum=5 NodeNum=1
I0731 07:35:37.816474       1 session.go:1036] Start adjusting jobs' network topology spec according to hyperNodeTierNameMap map[]
I0731 07:35:37.816496       1 session.go:1079] Finish adjusting jobs' network topology spec according to hyperNodeTierNameMap map[]
I0731 07:35:37.816518       1 session.go:279] Open Session 41139d47-0bd5-419a-96a9-2648f9a02270 with <0> Job and <5> Queues. HyperNodesReadyToSchedule: true
I0731 07:35:37.818971       1 enqueue.go:79] Try to enqueue PodGroup to 0 Queues
I0731 07:35:37.819065       1 allocate.go:138] Try to allocate resource to 0 Queues
I0731 07:35:37.819236       1 session.go:577] Close Session 41139d47-0bd5-419a-96a9-2648f9a02270
I0731 07:35:38.820806       1 cache.go:1581] "SnapShot for scheduling" jobNum=0 QueueNum=5 NodeNum=1
I0731 07:35:38.820867       1 session.go:1036] Start adjusting jobs' network topology spec according to hyperNodeTierNameMap map[]
I0731 07:35:38.820892       1 session.go:1079] Finish adjusting jobs' network topology spec according to hyperNodeTierNameMap map[]
I0731 07:35:38.820918       1 session.go:279] Open Session 749d02bb-5499-4b7e-8455-12d7600028b8 with <0> Job and <5> Queues. HyperNodesReadyToSchedule: true
I0731 07:35:38.821381       1 enqueue.go:79] Try to enqueue PodGroup to 0 Queues
I0731 07:35:38.821405       1 allocate.go:138] Try to allocate resource to 0 Queues
I0731 07:35:38.821507       1 session.go:577] Close Session 749d02bb-5499-4b7e-8455-12d7600028b8
I0731 07:35:39.822308       1 cache.go:1581] "SnapShot for scheduling" jobNum=0 QueueNum=5 NodeNum=1
I0731 07:35:39.822377       1 session.go:1036] Start adjusting jobs' network topology spec according to hyperNodeTierNameMap map[]
I0731 07:35:39.822406       1 session.go:1079] Finish adjusting jobs' network topology spec according to hyperNodeTierNameMap map[]
I0731 07:35:39.822432       1 session.go:279] Open Session 514f09e6-aafc-4363-8964-efc18a4f11db with <0> Job and <5> Queues. HyperNodesReadyToSchedule: true
I0731 07:35:39.822993       1 enqueue.go:79] Try to enqueue PodGroup to 0 Queues
I0731 07:35:39.823020       1 allocate.go:138] Try to allocate resource to 0 Queues
I0731 07:35:39.823137       1 session.go:577] Close Session 514f09e6-aafc-4363-8964-efc18a4f11db
I0731 07:35:40.824074       1 cache.go:1581] "SnapShot for scheduling" jobNum=0 QueueNum=5 NodeNum=1
I0731 07:35:40.824105       1 session.go:1036] Start adjusting jobs' network topology spec according to hyperNodeTierNameMap map[]
I0731 07:35:40.824122       1 session.go:1079] Finish adjusting jobs' network topology spec according to hyperNodeTierNameMap map[]
I0731 07:35:40.824144       1 session.go:279] Open Session 779ccf01-71d7-43da-84c7-dbdd310103a8 with <0> Job and <5> Queues. HyperNodesReadyToSchedule: true
I0731 07:35:40.824521       1 enqueue.go:79] Try to enqueue PodGroup to 0 Queues
I0731 07:35:40.824540       1 allocate.go:138] Try to allocate resource to 0 Queues
I0731 07:35:40.824621       1 session.go:577] Close Session 779ccf01-71d7-43da-84c7-dbdd310103a8
I0731 07:35:41.825276       1 cache.go:1581] "SnapShot for scheduling" jobNum=0 QueueNum=5 NodeNum=1
I0731 07:35:41.825322       1 session.go:1036] Start adjusting jobs' network topology spec according to hyperNodeTierNameMap map[]
I0731 07:35:41.825346       1 session.go:1079] Finish adjusting jobs' network topology spec according to hyperNodeTierNameMap map[]
I0731 07:35:41.825370       1 session.go:279] Open Session bb6e7cc7-a75f-480c-99ba-3d3fb222f83b with <0> Job and <5> Queues. HyperNodesReadyToSchedule: true
I0731 07:35:41.825842       1 enqueue.go:79] Try to enqueue PodGroup to 0 Queues
I0731 07:35:41.825865       1 allocate.go:138] Try to allocate resource to 0 Queues
I0731 07:35:41.825967       1 session.go:577] Close Session bb6e7cc7-a75f-480c-99ba-3d3fb222f83b
I0731 07:35:42.826679       1 cache.go:1581] "SnapShot for scheduling" jobNum=0 QueueNum=5 NodeNum=1
I0731 07:35:42.826751       1 session.go:1036] Start adjusting jobs' network topology spec according to hyperNodeTierNameMap map[]
I0731 07:35:42.826776       1 session.go:1079] Finish adjusting jobs' network topology spec according to hyperNodeTierNameMap map[]
I0731 07:35:42.826800       1 session.go:279] Open Session 8ed49550-dd6d-4712-8039-76edc2405c04 with <0> Job and <5> Queues. HyperNodesReadyToSchedule: true
I0731 07:35:42.827312       1 enqueue.go:79] Try to enqueue PodGroup to 0 Queues
I0731 07:35:42.827335       1 allocate.go:138] Try to allocate resource to 0 Queues
I0731 07:35:42.827433       1 session.go:577] Close Session 8ed49550-dd6d-4712-8039-76edc2405c04
I0731 07:35:43.828578       1 cache.go:1581] "SnapShot for scheduling" jobNum=0 QueueNum=5 NodeNum=1
I0731 07:35:43.828623       1 session.go:1036] Start adjusting jobs' network topology spec according to hyperNodeTierNameMap map[]
I0731 07:35:43.828646       1 session.go:1079] Finish adjusting jobs' network topology spec according to hyperNodeTierNameMap map[]
I0731 07:35:43.828667       1 session.go:279] Open Session e06496eb-1d33-4276-b552-5aef0425fa50 with <0> Job and <5> Queues. HyperNodesReadyToSchedule: true
I0731 07:35:43.829126       1 enqueue.go:79] Try to enqueue PodGroup to 0 Queues
I0731 07:35:43.829148       1 allocate.go:138] Try to allocate resource to 0 Queues
I0731 07:35:43.829244       1 session.go:577] Close Session e06496eb-1d33-4276-b552-5aef0425fa50
I0731 07:35:44.830254       1 cache.go:1581] "SnapShot for scheduling" jobNum=0 QueueNum=5 NodeNum=1
I0731 07:35:44.830296       1 session.go:1036] Start adjusting jobs' network topology spec according to hyperNodeTierNameMap map[]
I0731 07:35:44.830316       1 session.go:1079] Finish adjusting jobs' network topology spec according to hyperNodeTierNameMap map[]
I0731 07:35:44.830338       1 session.go:279] Open Session 3fa3d76d-b298-43a1-9e38-54385a3af507 with <0> Job and <5> Queues. HyperNodesReadyToSchedule: true
I0731 07:35:44.830770       1 enqueue.go:79] Try to enqueue PodGroup to 0 Queues
I0731 07:35:44.830793       1 allocate.go:138] Try to allocate resource to 0 Queues
I0731 07:35:44.830894       1 session.go:577] Close Session 3fa3d76d-b298-43a1-9e38-54385a3af507
I0731 07:35:45.832284       1 cache.go:1581] "SnapShot for scheduling" jobNum=0 QueueNum=5 NodeNum=1
I0731 07:35:45.832326       1 session.go:1036] Start adjusting jobs' network topology spec according to hyperNodeTierNameMap map[]
I0731 07:35:45.832349       1 session.go:1079] Finish adjusting jobs' network topology spec according to hyperNodeTierNameMap map[]
I0731 07:35:45.832373       1 session.go:279] Open Session 12379e90-f902-47fe-913d-9af75e0b4e8d with <0> Job and <5> Queues. HyperNodesReadyToSchedule: true
I0731 07:35:45.832836       1 enqueue.go:79] Try to enqueue PodGroup to 0 Queues
I0731 07:35:45.832859       1 allocate.go:138] Try to allocate resource to 0 Queues
I0731 07:35:45.832957       1 session.go:577] Close Session 12379e90-f902-47fe-913d-9af75e0b4e8d
I0731 07:35:46.486753       1 cache.go:1771] The metrics type is not set in the volcano scheduler configmap file. As a result, the CPU and memory load information of the node is not collected.
I0731 07:35:46.833400       1 cache.go:1581] "SnapShot for scheduling" jobNum=0 QueueNum=5 NodeNum=1
I0731 07:35:46.833424       1 session.go:1036] Start adjusting jobs' network topology spec according to hyperNodeTierNameMap map[]
I0731 07:35:46.833440       1 session.go:1079] Finish adjusting jobs' network topology spec according to hyperNodeTierNameMap map[]
I0731 07:35:46.833465       1 session.go:279] Open Session 073284c2-8da2-4e24-862d-5a8eb99ca6c3 with <0> Job and <5> Queues. HyperNodesReadyToSchedule: true
I0731 07:35:46.833820       1 enqueue.go:79] Try to enqueue PodGroup to 0 Queues
I0731 07:35:46.833841       1 allocate.go:138] Try to allocate resource to 0 Queues
I0731 07:35:46.833919       1 session.go:577] Close Session 073284c2-8da2-4e24-862d-5a8eb99ca6c3
I0731 07:35:47.835066       1 cache.go:1581] "SnapShot for scheduling" jobNum=0 QueueNum=5 NodeNum=1
I0731 07:35:47.835112       1 session.go:1036] Start adjusting jobs' network topology spec according to hyperNodeTierNameMap map[]
I0731 07:35:47.835135       1 session.go:1079] Finish adjusting jobs' network topology spec according to hyperNodeTierNameMap map[]
I0731 07:35:47.835158       1 session.go:279] Open Session 6789ab36-b34c-410c-88c2-1657453a02a3 with <0> Job and <5> Queues. HyperNodesReadyToSchedule: true
I0731 07:35:47.835601       1 enqueue.go:79] Try to enqueue PodGroup to 0 Queues
I0731 07:35:47.835628       1 allocate.go:138] Try to allocate resource to 0 Queues
I0731 07:35:47.835723       1 session.go:577] Close Session 6789ab36-b34c-410c-88c2-1657453a02a3
I0731 07:35:48.837048       1 cache.go:1581] "SnapShot for scheduling" jobNum=0 QueueNum=5 NodeNum=1
I0731 07:35:48.837094       1 session.go:1036] Start adjusting jobs' network topology spec according to hyperNodeTierNameMap map[]
I0731 07:35:48.837118       1 session.go:1079] Finish adjusting jobs' network topology spec according to hyperNodeTierNameMap map[]
I0731 07:35:48.837140       1 session.go:279] Open Session 79a67acb-d17f-41ca-a369-84d5aae21b00 with <0> Job and <5> Queues. HyperNodesReadyToSchedule: true
I0731 07:35:48.837617       1 enqueue.go:79] Try to enqueue PodGroup to 0 Queues
I0731 07:35:48.837638       1 allocate.go:138] Try to allocate resource to 0 Queues
I0731 07:35:48.837736       1 session.go:577] Close Session 79a67acb-d17f-41ca-a369-84d5aae21b00
I0731 07:35:49.838990       1 cache.go:1581] "SnapShot for scheduling" jobNum=0 QueueNum=5 NodeNum=1
I0731 07:35:49.839036       1 session.go:1036] Start adjusting jobs' network topology spec according to hyperNodeTierNameMap map[]
I0731 07:35:49.839065       1 session.go:1079] Finish adjusting jobs' network topology spec according to hyperNodeTierNameMap map[]
I0731 07:35:49.839089       1 session.go:279] Open Session 6687cb69-3573-4881-907f-01d48d352a6b with <0> Job and <5> Queues. HyperNodesReadyToSchedule: true
I0731 07:35:49.839531       1 enqueue.go:79] Try to enqueue PodGroup to 0 Queues
I0731 07:35:49.839554       1 allocate.go:138] Try to allocate resource to 0 Queues
I0731 07:35:49.839650       1 session.go:577] Close Session 6687cb69-3573-4881-907f-01d48d352a6b
I0731 07:35:50.840864       1 cache.go:1581] "SnapShot for scheduling" jobNum=0 QueueNum=5 NodeNum=1
I0731 07:35:50.840910       1 session.go:1036] Start adjusting jobs' network topology spec according to hyperNodeTierNameMap map[]
I0731 07:35:50.840932       1 session.go:1079] Finish adjusting jobs' network topology spec according to hyperNodeTierNameMap map[]
I0731 07:35:50.840955       1 session.go:279] Open Session f926f9ad-5e44-4d69-9da2-74bc8a587737 with <0> Job and <5> Queues. HyperNodesReadyToSchedule: true
I0731 07:35:50.841388       1 enqueue.go:79] Try to enqueue PodGroup to 0 Queues
I0731 07:35:50.841409       1 allocate.go:138] Try to allocate resource to 0 Queues
I0731 07:35:50.841505       1 session.go:577] Close Session f926f9ad-5e44-4d69-9da2-74bc8a587737
I0731 07:35:51.842247       1 cache.go:1581] "SnapShot for scheduling" jobNum=0 QueueNum=2 NodeNum=1
I0731 07:35:51.842296       1 session.go:1036] Start adjusting jobs' network topology spec according to hyperNodeTierNameMap map[]
I0731 07:35:51.842319       1 session.go:1079] Finish adjusting jobs' network topology spec according to hyperNodeTierNameMap map[]
I0731 07:35:51.842342       1 session.go:279] Open Session 1eedc868-9228-45eb-a02b-295938bc1f7f with <0> Job and <2> Queues. HyperNodesReadyToSchedule: true
I0731 07:35:51.842823       1 enqueue.go:79] Try to enqueue PodGroup to 0 Queues
I0731 07:35:51.842850       1 allocate.go:138] Try to allocate resource to 0 Queues
I0731 07:35:51.842926       1 session.go:577] Close Session 1eedc868-9228-45eb-a02b-295938bc1f7f
I0731 07:35:52.844254       1 cache.go:1581] "SnapShot for scheduling" jobNum=0 QueueNum=2 NodeNum=1
I0731 07:35:52.844298       1 session.go:1036] Start adjusting jobs' network topology spec according to hyperNodeTierNameMap map[]
I0731 07:35:52.844321       1 session.go:1079] Finish adjusting jobs' network topology spec according to hyperNodeTierNameMap map[]
I0731 07:35:52.844344       1 session.go:279] Open Session 065a8fcd-00b4-484d-aa3f-09c7dedbf5b2 with <0> Job and <2> Queues. HyperNodesReadyToSchedule: true
I0731 07:35:52.844784       1 enqueue.go:79] Try to enqueue PodGroup to 0 Queues
I0731 07:35:52.844807       1 allocate.go:138] Try to allocate resource to 0 Queues
I0731 07:35:52.844881       1 session.go:577] Close Session 065a8fcd-00b4-484d-aa3f-09c7dedbf5b2
I0731 07:35:53.846330       1 cache.go:1581] "SnapShot for scheduling" jobNum=0 QueueNum=2 NodeNum=1
I0731 07:35:53.846389       1 session.go:1036] Start adjusting jobs' network topology spec according to hyperNodeTierNameMap map[]
I0731 07:35:53.846416       1 session.go:1079] Finish adjusting jobs' network topology spec according to hyperNodeTierNameMap map[]
I0731 07:35:53.846443       1 session.go:279] Open Session 03d937be-2253-4d4d-8c1c-5f55b1ab601f with <0> Job and <2> Queues. HyperNodesReadyToSchedule: true
I0731 07:35:53.847033       1 enqueue.go:79] Try to enqueue PodGroup to 0 Queues
I0731 07:35:53.847059       1 allocate.go:138] Try to allocate resource to 0 Queues
I0731 07:35:53.847146       1 session.go:577] Close Session 03d937be-2253-4d4d-8c1c-5f55b1ab601f
I0731 07:35:54.847638       1 cache.go:1581] "SnapShot for scheduling" jobNum=0 QueueNum=2 NodeNum=1
I0731 07:35:54.847676       1 session.go:1036] Start adjusting jobs' network topology spec according to hyperNodeTierNameMap map[]
I0731 07:35:54.847699       1 session.go:1079] Finish adjusting jobs' network topology spec according to hyperNodeTierNameMap map[]
I0731 07:35:54.847722       1 session.go:279] Open Session 5c4cde48-6788-40d5-bf5a-93f7a63c95fb with <0> Job and <2> Queues. HyperNodesReadyToSchedule: true
I0731 07:35:54.848125       1 enqueue.go:79] Try to enqueue PodGroup to 0 Queues
I0731 07:35:54.848147       1 allocate.go:138] Try to allocate resource to 0 Queues
I0731 07:35:54.848214       1 session.go:577] Close Session 5c4cde48-6788-40d5-bf5a-93f7a63c95fb
I0731 07:35:55.848967       1 cache.go:1581] "SnapShot for scheduling" jobNum=0 QueueNum=2 NodeNum=1
I0731 07:35:55.849016       1 session.go:1036] Start adjusting jobs' network topology spec according to hyperNodeTierNameMap map[]
I0731 07:35:55.849042       1 session.go:1079] Finish adjusting jobs' network topology spec according to hyperNodeTierNameMap map[]
I0731 07:35:55.849065       1 session.go:279] Open Session a7f4dd15-c5bf-40d3-a87d-88fcdb951032 with <0> Job and <2> Queues. HyperNodesReadyToSchedule: true
I0731 07:35:55.849584       1 enqueue.go:79] Try to enqueue PodGroup to 0 Queues
I0731 07:35:55.849606       1 allocate.go:138] Try to allocate resource to 0 Queues
I0731 07:35:55.849684       1 session.go:577] Close Session a7f4dd15-c5bf-40d3-a87d-88fcdb951032
I0731 07:35:56.850329       1 cache.go:1581] "SnapShot for scheduling" jobNum=0 QueueNum=2 NodeNum=1
I0731 07:35:56.850377       1 session.go:1036] Start adjusting jobs' network topology spec according to hyperNodeTierNameMap map[]
I0731 07:35:56.850400       1 session.go:1079] Finish adjusting jobs' network topology spec according to hyperNodeTierNameMap map[]
I0731 07:35:56.850424       1 session.go:279] Open Session f8182263-8101-41fc-ba98-459fe4ad24f4 with <0> Job and <2> Queues. HyperNodesReadyToSchedule: true
I0731 07:35:56.850861       1 enqueue.go:79] Try to enqueue PodGroup to 0 Queues
I0731 07:35:56.850884       1 allocate.go:138] Try to allocate resource to 0 Queues
I0731 07:35:56.850958       1 session.go:577] Close Session f8182263-8101-41fc-ba98-459fe4ad24f4
I0731 07:35:57.851607       1 cache.go:1581] "SnapShot for scheduling" jobNum=0 QueueNum=2 NodeNum=1
I0731 07:35:57.851651       1 session.go:1036] Start adjusting jobs' network topology spec according to hyperNodeTierNameMap map[]
I0731 07:35:57.851673       1 session.go:1079] Finish adjusting jobs' network topology spec according to hyperNodeTierNameMap map[]
I0731 07:35:57.851698       1 session.go:279] Open Session 7afaed29-2fc5-41ba-af53-3cb665ac1ee9 with <0> Job and <2> Queues. HyperNodesReadyToSchedule: true
I0731 07:35:57.852230       1 enqueue.go:79] Try to enqueue PodGroup to 0 Queues
I0731 07:35:57.852253       1 allocate.go:138] Try to allocate resource to 0 Queues
I0731 07:35:57.852330       1 session.go:577] Close Session 7afaed29-2fc5-41ba-af53-3cb665ac1ee9
I0731 07:35:58.852639       1 cache.go:1581] "SnapShot for scheduling" jobNum=0 QueueNum=2 NodeNum=1
I0731 07:35:58.852679       1 session.go:1036] Start adjusting jobs' network topology spec according to hyperNodeTierNameMap map[]
I0731 07:35:58.852700       1 session.go:1079] Finish adjusting jobs' network topology spec according to hyperNodeTierNameMap map[]
I0731 07:35:58.852724       1 session.go:279] Open Session a733e040-b079-483f-8a66-8b6379f3dac1 with <0> Job and <2> Queues. HyperNodesReadyToSchedule: true
I0731 07:35:58.853120       1 enqueue.go:79] Try to enqueue PodGroup to 0 Queues
I0731 07:35:58.853141       1 allocate.go:138] Try to allocate resource to 0 Queues
I0731 07:35:58.853212       1 session.go:577] Close Session a733e040-b079-483f-8a66-8b6379f3dac1
I0731 07:35:59.853780       1 cache.go:1581] "SnapShot for scheduling" jobNum=0 QueueNum=2 NodeNum=1
I0731 07:35:59.853829       1 session.go:1036] Start adjusting jobs' network topology spec according to hyperNodeTierNameMap map[]
I0731 07:35:59.853852       1 session.go:1079] Finish adjusting jobs' network topology spec according to hyperNodeTierNameMap map[]
I0731 07:35:59.853877       1 session.go:279] Open Session 296dc753-07ca-4d22-a42e-037fdd09c2c7 with <0> Job and <2> Queues. HyperNodesReadyToSchedule: true
I0731 07:35:59.854360       1 enqueue.go:79] Try to enqueue PodGroup to 0 Queues
I0731 07:35:59.854384       1 allocate.go:138] Try to allocate resource to 0 Queues
I0731 07:35:59.854458       1 session.go:577] Close Session 296dc753-07ca-4d22-a42e-037fdd09c2c7
I0731 07:36:00.854961       1 cache.go:1581] "SnapShot for scheduling" jobNum=0 QueueNum=2 NodeNum=1
I0731 07:36:00.855007       1 session.go:1036] Start adjusting jobs' network topology spec according to hyperNodeTierNameMap map[]
I0731 07:36:00.855030       1 session.go:1079] Finish adjusting jobs' network topology spec according to hyperNodeTierNameMap map[]
I0731 07:36:00.855054       1 session.go:279] Open Session d0af0484-3b53-4a6f-8bfe-2158d86c0710 with <0> Job and <2> Queues. HyperNodesReadyToSchedule: true
I0731 07:36:00.855495       1 enqueue.go:79] Try to enqueue PodGroup to 0 Queues
I0731 07:36:00.855516       1 allocate.go:138] Try to allocate resource to 0 Queues
I0731 07:36:00.855593       1 session.go:577] Close Session d0af0484-3b53-4a6f-8bfe-2158d86c0710
I0731 07:36:01.856418       1 cache.go:1581] "SnapShot for scheduling" jobNum=0 QueueNum=2 NodeNum=1
I0731 07:36:01.856467       1 session.go:1036] Start adjusting jobs' network topology spec according to hyperNodeTierNameMap map[]
I0731 07:36:01.856490       1 session.go:1079] Finish adjusting jobs' network topology spec according to hyperNodeTierNameMap map[]
I0731 07:36:01.856515       1 session.go:279] Open Session 245f6f55-ba59-4ed2-9dc5-ad86fddff791 with <0> Job and <2> Queues. HyperNodesReadyToSchedule: true
I0731 07:36:01.856993       1 enqueue.go:79] Try to enqueue PodGroup to 0 Queues
I0731 07:36:01.857019       1 allocate.go:138] Try to allocate resource to 0 Queues
I0731 07:36:01.857101       1 session.go:577] Close Session 245f6f55-ba59-4ed2-9dc5-ad86fddff791
I0731 07:36:02.857890       1 cache.go:1581] "SnapShot for scheduling" jobNum=0 QueueNum=2 NodeNum=1
I0731 07:36:02.857943       1 session.go:1036] Start adjusting jobs' network topology spec according to hyperNodeTierNameMap map[]
I0731 07:36:02.857966       1 session.go:1079] Finish adjusting jobs' network topology spec according to hyperNodeTierNameMap map[]
I0731 07:36:02.857990       1 session.go:279] Open Session 44f96fc9-ad9c-47bb-953f-28336cb877ca with <0> Job and <2> Queues. HyperNodesReadyToSchedule: true
I0731 07:36:02.858429       1 enqueue.go:79] Try to enqueue PodGroup to 0 Queues
I0731 07:36:02.858453       1 allocate.go:138] Try to allocate resource to 0 Queues
I0731 07:36:02.858530       1 session.go:577] Close Session 44f96fc9-ad9c-47bb-953f-28336cb877ca
I0731 07:36:03.859559       1 cache.go:1581] "SnapShot for scheduling" jobNum=0 QueueNum=2 NodeNum=1
I0731 07:36:03.859607       1 session.go:1036] Start adjusting jobs' network topology spec according to hyperNodeTierNameMap map[]
I0731 07:36:03.859630       1 session.go:1079] Finish adjusting jobs' network topology spec according to hyperNodeTierNameMap map[]
I0731 07:36:03.859655       1 session.go:279] Open Session 502c4c95-550d-4370-b72e-0840c523f2fa with <0> Job and <2> Queues. HyperNodesReadyToSchedule: true
I0731 07:36:03.860094       1 enqueue.go:79] Try to enqueue PodGroup to 0 Queues
I0731 07:36:03.860118       1 allocate.go:138] Try to allocate resource to 0 Queues
I0731 07:36:03.860188       1 session.go:577] Close Session 502c4c95-550d-4370-b72e-0840c523f2fa
I0731 07:36:04.860575       1 cache.go:1581] "SnapShot for scheduling" jobNum=0 QueueNum=2 NodeNum=1
I0731 07:36:04.860627       1 session.go:1036] Start adjusting jobs' network topology spec according to hyperNodeTierNameMap map[]
I0731 07:36:04.860650       1 session.go:1079] Finish adjusting jobs' network topology spec according to hyperNodeTierNameMap map[]
I0731 07:36:04.860676       1 session.go:279] Open Session b24e201f-dde7-407d-9b07-a0b2cc5bfa75 with <0> Job and <2> Queues. HyperNodesReadyToSchedule: true
I0731 07:36:04.861118       1 enqueue.go:79] Try to enqueue PodGroup to 0 Queues
I0731 07:36:04.861141       1 allocate.go:138] Try to allocate resource to 0 Queues
I0731 07:36:04.861220       1 session.go:577] Close Session b24e201f-dde7-407d-9b07-a0b2cc5bfa75
I0731 07:36:05.862280       1 cache.go:1581] "SnapShot for scheduling" jobNum=0 QueueNum=2 NodeNum=1
I0731 07:36:05.862313       1 session.go:1036] Start adjusting jobs' network topology spec according to hyperNodeTierNameMap map[]
I0731 07:36:05.862332       1 session.go:1079] Finish adjusting jobs' network topology spec according to hyperNodeTierNameMap map[]
I0731 07:36:05.862356       1 session.go:279] Open Session 671d8d2d-42d3-4595-abb2-cd6684a11005 with <0> Job and <2> Queues. HyperNodesReadyToSchedule: true
I0731 07:36:05.862804       1 enqueue.go:79] Try to enqueue PodGroup to 0 Queues
I0731 07:36:05.862825       1 allocate.go:138] Try to allocate resource to 0 Queues
I0731 07:36:05.862895       1 session.go:577] Close Session 671d8d2d-42d3-4595-abb2-cd6684a11005
I0731 07:36:06.864092       1 cache.go:1581] "SnapShot for scheduling" jobNum=0 QueueNum=2 NodeNum=1
I0731 07:36:06.864131       1 session.go:1036] Start adjusting jobs' network topology spec according to hyperNodeTierNameMap map[]
I0731 07:36:06.864153       1 session.go:1079] Finish adjusting jobs' network topology spec according to hyperNodeTierNameMap map[]
I0731 07:36:06.864175       1 session.go:279] Open Session c2427ed5-3ccb-4449-b44c-354155918dca with <0> Job and <2> Queues. HyperNodesReadyToSchedule: true
I0731 07:36:06.864679       1 enqueue.go:79] Try to enqueue PodGroup to 0 Queues
I0731 07:36:06.864700       1 allocate.go:138] Try to allocate resource to 0 Queues
I0731 07:36:06.864770       1 session.go:577] Close Session c2427ed5-3ccb-4449-b44c-354155918dca
I0731 07:36:07.866085       1 cache.go:1581] "SnapShot for scheduling" jobNum=0 QueueNum=2 NodeNum=1
I0731 07:36:07.866130       1 session.go:1036] Start adjusting jobs' network topology spec according to hyperNodeTierNameMap map[]
I0731 07:36:07.866152       1 session.go:1079] Finish adjusting jobs' network topology spec according to hyperNodeTierNameMap map[]
I0731 07:36:07.866175       1 session.go:279] Open Session 3acb6693-8263-4418-81eb-f20ccb8e08c5 with <0> Job and <2> Queues. HyperNodesReadyToSchedule: true
I0731 07:36:07.866618       1 enqueue.go:79] Try to enqueue PodGroup to 0 Queues
I0731 07:36:07.866639       1 allocate.go:138] Try to allocate resource to 0 Queues
I0731 07:36:07.866715       1 session.go:577] Close Session 3acb6693-8263-4418-81eb-f20ccb8e08c5
I0731 07:36:08.867955       1 cache.go:1581] "SnapShot for scheduling" jobNum=0 QueueNum=2 NodeNum=1
I0731 07:36:08.868006       1 session.go:1036] Start adjusting jobs' network topology spec according to hyperNodeTierNameMap map[]
I0731 07:36:08.868029       1 session.go:1079] Finish adjusting jobs' network topology spec according to hyperNodeTierNameMap map[]
I0731 07:36:08.868053       1 session.go:279] Open Session 8065f29b-93fc-42da-a84f-f1932f77c42a with <0> Job and <2> Queues. HyperNodesReadyToSchedule: true
I0731 07:36:08.868527       1 enqueue.go:79] Try to enqueue PodGroup to 0 Queues
I0731 07:36:08.868549       1 allocate.go:138] Try to allocate resource to 0 Queues
I0731 07:36:08.868625       1 session.go:577] Close Session 8065f29b-93fc-42da-a84f-f1932f77c42a
I0731 07:36:09.869619       1 cache.go:1581] "SnapShot for scheduling" jobNum=0 QueueNum=2 NodeNum=1
I0731 07:36:09.869660       1 session.go:1036] Start adjusting jobs' network topology spec according to hyperNodeTierNameMap map[]
I0731 07:36:09.869683       1 session.go:1079] Finish adjusting jobs' network topology spec according to hyperNodeTierNameMap map[]
I0731 07:36:09.869706       1 session.go:279] Open Session 1bd3e238-99aa-4b92-8308-008612d9910a with <0> Job and <2> Queues. HyperNodesReadyToSchedule: true
I0731 07:36:09.871624       1 enqueue.go:79] Try to enqueue PodGroup to 0 Queues
I0731 07:36:09.871783       1 allocate.go:138] Try to allocate resource to 0 Queues
I0731 07:36:09.871972       1 session.go:577] Close Session 1bd3e238-99aa-4b92-8308-008612d9910a
I0731 07:36:10.872720       1 cache.go:1581] "SnapShot for scheduling" jobNum=0 QueueNum=2 NodeNum=1
I0731 07:36:10.872776       1 session.go:1036] Start adjusting jobs' network topology spec according to hyperNodeTierNameMap map[]
I0731 07:36:10.872801       1 session.go:1079] Finish adjusting jobs' network topology spec according to hyperNodeTierNameMap map[]
I0731 07:36:10.872825       1 session.go:279] Open Session 41e19c36-b3e7-40e7-bba2-49d7b5af6f8a with <0> Job and <2> Queues. HyperNodesReadyToSchedule: true
I0731 07:36:10.873257       1 enqueue.go:79] Try to enqueue PodGroup to 0 Queues
I0731 07:36:10.873279       1 allocate.go:138] Try to allocate resource to 0 Queues
I0731 07:36:10.873358       1 session.go:577] Close Session 41e19c36-b3e7-40e7-bba2-49d7b5af6f8a
I0731 07:36:11.873960       1 cache.go:1581] "SnapShot for scheduling" jobNum=0 QueueNum=2 NodeNum=1
I0731 07:36:11.874011       1 session.go:1036] Start adjusting jobs' network topology spec according to hyperNodeTierNameMap map[]
I0731 07:36:11.874037       1 session.go:1079] Finish adjusting jobs' network topology spec according to hyperNodeTierNameMap map[]
I0731 07:36:11.874063       1 session.go:279] Open Session 505527e0-efcb-4efd-b103-f28a3b9a7558 with <0> Job and <2> Queues. HyperNodesReadyToSchedule: true
I0731 07:36:11.874496       1 enqueue.go:79] Try to enqueue PodGroup to 0 Queues
I0731 07:36:11.874518       1 allocate.go:138] Try to allocate resource to 0 Queues
I0731 07:36:11.874589       1 session.go:577] Close Session 505527e0-efcb-4efd-b103-f28a3b9a7558
I0731 07:36:12.875266       1 cache.go:1581] "SnapShot for scheduling" jobNum=0 QueueNum=2 NodeNum=1
I0731 07:36:12.875301       1 session.go:1036] Start adjusting jobs' network topology spec according to hyperNodeTierNameMap map[]
I0731 07:36:12.875320       1 session.go:1079] Finish adjusting jobs' network topology spec according to hyperNodeTierNameMap map[]
I0731 07:36:12.875343       1 session.go:279] Open Session 4dac64d9-5a5a-4879-800b-d6d3251e4a9b with <0> Job and <2> Queues. HyperNodesReadyToSchedule: true
I0731 07:36:12.875802       1 enqueue.go:79] Try to enqueue PodGroup to 0 Queues
I0731 07:36:12.875824       1 allocate.go:138] Try to allocate resource to 0 Queues
I0731 07:36:12.875884       1 session.go:577] Close Session 4dac64d9-5a5a-4879-800b-d6d3251e4a9b
I0731 07:36:13.876421       1 cache.go:1581] "SnapShot for scheduling" jobNum=0 QueueNum=2 NodeNum=1
I0731 07:36:13.876469       1 session.go:1036] Start adjusting jobs' network topology spec according to hyperNodeTierNameMap map[]
I0731 07:36:13.876493       1 session.go:1079] Finish adjusting jobs' network topology spec according to hyperNodeTierNameMap map[]
I0731 07:36:13.876518       1 session.go:279] Open Session af97fb79-175b-47ae-889f-94cdce9eaed7 with <0> Job and <2> Queues. HyperNodesReadyToSchedule: true
I0731 07:36:13.877049       1 enqueue.go:79] Try to enqueue PodGroup to 0 Queues
I0731 07:36:13.877073       1 allocate.go:138] Try to allocate resource to 0 Queues
I0731 07:36:13.877156       1 session.go:577] Close Session af97fb79-175b-47ae-889f-94cdce9eaed7
I0731 07:36:14.878129       1 cache.go:1581] "SnapShot for scheduling" jobNum=0 QueueNum=2 NodeNum=1
I0731 07:36:14.878163       1 session.go:1036] Start adjusting jobs' network topology spec according to hyperNodeTierNameMap map[]
I0731 07:36:14.878179       1 session.go:1079] Finish adjusting jobs' network topology spec according to hyperNodeTierNameMap map[]
I0731 07:36:14.878201       1 session.go:279] Open Session 3752ad41-3dd9-465d-a02a-1af866a1654a with <0> Job and <2> Queues. HyperNodesReadyToSchedule: true
I0731 07:36:14.878533       1 enqueue.go:79] Try to enqueue PodGroup to 0 Queues
I0731 07:36:14.878552       1 allocate.go:138] Try to allocate resource to 0 Queues
I0731 07:36:14.878611       1 session.go:577] Close Session 3752ad41-3dd9-465d-a02a-1af866a1654a
I0731 07:36:15.879526       1 cache.go:1581] "SnapShot for scheduling" jobNum=0 QueueNum=2 NodeNum=1
I0731 07:36:15.879572       1 session.go:1036] Start adjusting jobs' network topology spec according to hyperNodeTierNameMap map[]
I0731 07:36:15.879595       1 session.go:1079] Finish adjusting jobs' network topology spec according to hyperNodeTierNameMap map[]
I0731 07:36:15.879619       1 session.go:279] Open Session 20af7186-7772-49a1-a59f-baff181f145b with <0> Job and <2> Queues. HyperNodesReadyToSchedule: true
I0731 07:36:15.880123       1 enqueue.go:79] Try to enqueue PodGroup to 0 Queues
I0731 07:36:15.880148       1 allocate.go:138] Try to allocate resource to 0 Queues
I0731 07:36:15.880225       1 session.go:577] Close Session 20af7186-7772-49a1-a59f-baff181f145b
I0731 07:36:16.487514       1 cache.go:1771] The metrics type is not set in the volcano scheduler configmap file. As a result, the CPU and memory load information of the node is not collected.
I0731 07:36:16.881436       1 cache.go:1581] "SnapShot for scheduling" jobNum=0 QueueNum=2 NodeNum=1
I0731 07:36:16.881493       1 session.go:1036] Start adjusting jobs' network topology spec according to hyperNodeTierNameMap map[]
I0731 07:36:16.881518       1 session.go:1079] Finish adjusting jobs' network topology spec according to hyperNodeTierNameMap map[]
I0731 07:36:16.881543       1 session.go:279] Open Session ff6e1f59-6d39-4307-91e2-7c04ca6cc22b with <0> Job and <2> Queues. HyperNodesReadyToSchedule: true
I0731 07:36:16.882042       1 enqueue.go:79] Try to enqueue PodGroup to 0 Queues
I0731 07:36:16.882065       1 allocate.go:138] Try to allocate resource to 0 Queues
I0731 07:36:16.882141       1 session.go:577] Close Session ff6e1f59-6d39-4307-91e2-7c04ca6cc22b
I0731 07:36:17.882716       1 cache.go:1581] "SnapShot for scheduling" jobNum=0 QueueNum=2 NodeNum=1
I0731 07:36:17.882766       1 session.go:1036] Start adjusting jobs' network topology spec according to hyperNodeTierNameMap map[]
I0731 07:36:17.882789       1 session.go:1079] Finish adjusting jobs' network topology spec according to hyperNodeTierNameMap map[]
I0731 07:36:17.882813       1 session.go:279] Open Session 1240a1b5-ef59-4946-99a8-538ee7efd723 with <0> Job and <2> Queues. HyperNodesReadyToSchedule: true
I0731 07:36:17.883299       1 enqueue.go:79] Try to enqueue PodGroup to 0 Queues
I0731 07:36:17.883322       1 allocate.go:138] Try to allocate resource to 0 Queues
I0731 07:36:17.883397       1 session.go:577] Close Session 1240a1b5-ef59-4946-99a8-538ee7efd723
I0731 07:36:18.884697       1 cache.go:1581] "SnapShot for scheduling" jobNum=0 QueueNum=2 NodeNum=1
I0731 07:36:18.884753       1 session.go:1036] Start adjusting jobs' network topology spec according to hyperNodeTierNameMap map[]
I0731 07:36:18.884777       1 session.go:1079] Finish adjusting jobs' network topology spec according to hyperNodeTierNameMap map[]
I0731 07:36:18.884802       1 session.go:279] Open Session 0bbee8cc-d914-456f-95b9-b92c2860df7c with <0> Job and <2> Queues. HyperNodesReadyToSchedule: true
I0731 07:36:18.885339       1 enqueue.go:79] Try to enqueue PodGroup to 0 Queues
I0731 07:36:18.885366       1 allocate.go:138] Try to allocate resource to 0 Queues
I0731 07:36:18.885447       1 session.go:577] Close Session 0bbee8cc-d914-456f-95b9-b92c2860df7c
I0731 07:36:19.886817       1 cache.go:1581] "SnapShot for scheduling" jobNum=0 QueueNum=2 NodeNum=1
I0731 07:36:19.886860       1 session.go:1036] Start adjusting jobs' network topology spec according to hyperNodeTierNameMap map[]
I0731 07:36:19.886883       1 session.go:1079] Finish adjusting jobs' network topology spec according to hyperNodeTierNameMap map[]
I0731 07:36:19.886907       1 session.go:279] Open Session e479fbfb-d22c-491a-97ce-72c4a352aeb3 with <0> Job and <2> Queues. HyperNodesReadyToSchedule: true
I0731 07:36:19.887354       1 enqueue.go:79] Try to enqueue PodGroup to 0 Queues
I0731 07:36:19.887376       1 allocate.go:138] Try to allocate resource to 0 Queues
I0731 07:36:19.887450       1 session.go:577] Close Session e479fbfb-d22c-491a-97ce-72c4a352aeb3
I0731 07:36:20.887776       1 cache.go:1581] "SnapShot for scheduling" jobNum=0 QueueNum=2 NodeNum=1
I0731 07:36:20.887821       1 session.go:1036] Start adjusting jobs' network topology spec according to hyperNodeTierNameMap map[]
I0731 07:36:20.887847       1 session.go:1079] Finish adjusting jobs' network topology spec according to hyperNodeTierNameMap map[]
I0731 07:36:20.887871       1 session.go:279] Open Session 65f8f668-688a-41dd-bb04-e9f5c6db4761 with <0> Job and <2> Queues. HyperNodesReadyToSchedule: true
I0731 07:36:20.888325       1 enqueue.go:79] Try to enqueue PodGroup to 0 Queues
I0731 07:36:20.888345       1 allocate.go:138] Try to allocate resource to 0 Queues
I0731 07:36:20.888422       1 session.go:577] Close Session 65f8f668-688a-41dd-bb04-e9f5c6db4761
I0731 07:36:21.888956       1 cache.go:1581] "SnapShot for scheduling" jobNum=0 QueueNum=2 NodeNum=1
I0731 07:36:21.889000       1 session.go:1036] Start adjusting jobs' network topology spec according to hyperNodeTierNameMap map[]
I0731 07:36:21.889023       1 session.go:1079] Finish adjusting jobs' network topology spec according to hyperNodeTierNameMap map[]
I0731 07:36:21.889046       1 session.go:279] Open Session 17097b4f-2e74-4de8-80db-a678e03963ef with <0> Job and <2> Queues. HyperNodesReadyToSchedule: true
I0731 07:36:21.889475       1 enqueue.go:79] Try to enqueue PodGroup to 0 Queues
I0731 07:36:21.889498       1 allocate.go:138] Try to allocate resource to 0 Queues
I0731 07:36:21.889571       1 session.go:577] Close Session 17097b4f-2e74-4de8-80db-a678e03963ef
I0731 07:36:22.890944       1 cache.go:1581] "SnapShot for scheduling" jobNum=0 QueueNum=2 NodeNum=1
I0731 07:36:22.890987       1 session.go:1036] Start adjusting jobs' network topology spec according to hyperNodeTierNameMap map[]
I0731 07:36:22.891009       1 session.go:1079] Finish adjusting jobs' network topology spec according to hyperNodeTierNameMap map[]
I0731 07:36:22.891032       1 session.go:279] Open Session d4ee6311-79d0-4fcb-896e-857761c4d0c0 with <0> Job and <2> Queues. HyperNodesReadyToSchedule: true
I0731 07:36:22.891483       1 enqueue.go:79] Try to enqueue PodGroup to 0 Queues
I0731 07:36:22.891504       1 allocate.go:138] Try to allocate resource to 0 Queues
I0731 07:36:22.891575       1 session.go:577] Close Session d4ee6311-79d0-4fcb-896e-857761c4d0c0
I0731 07:36:23.892838       1 cache.go:1581] "SnapShot for scheduling" jobNum=0 QueueNum=2 NodeNum=1
I0731 07:36:23.892882       1 session.go:1036] Start adjusting jobs' network topology spec according to hyperNodeTierNameMap map[]
I0731 07:36:23.892904       1 session.go:1079] Finish adjusting jobs' network topology spec according to hyperNodeTierNameMap map[]
I0731 07:36:23.892929       1 session.go:279] Open Session b4cc4e17-7bf8-4025-84ce-90812213b0c3 with <0> Job and <2> Queues. HyperNodesReadyToSchedule: true
I0731 07:36:23.893402       1 enqueue.go:79] Try to enqueue PodGroup to 0 Queues
I0731 07:36:23.893423       1 allocate.go:138] Try to allocate resource to 0 Queues
I0731 07:36:23.893496       1 session.go:577] Close Session b4cc4e17-7bf8-4025-84ce-90812213b0c3
I0731 07:36:24.894409       1 cache.go:1581] "SnapShot for scheduling" jobNum=0 QueueNum=2 NodeNum=1
I0731 07:36:24.894466       1 session.go:1036] Start adjusting jobs' network topology spec according to hyperNodeTierNameMap map[]
I0731 07:36:24.894490       1 session.go:1079] Finish adjusting jobs' network topology spec according to hyperNodeTierNameMap map[]
I0731 07:36:24.894517       1 session.go:279] Open Session 4311485b-e258-4bf0-8c47-c802e1407d96 with <0> Job and <2> Queues. HyperNodesReadyToSchedule: true
I0731 07:36:24.895055       1 enqueue.go:79] Try to enqueue PodGroup to 0 Queues
I0731 07:36:24.895083       1 allocate.go:138] Try to allocate resource to 0 Queues
I0731 07:36:24.895164       1 session.go:577] Close Session 4311485b-e258-4bf0-8c47-c802e1407d96
I0731 07:36:25.895964       1 cache.go:1581] "SnapShot for scheduling" jobNum=0 QueueNum=2 NodeNum=1
I0731 07:36:25.896018       1 session.go:1036] Start adjusting jobs' network topology spec according to hyperNodeTierNameMap map[]
I0731 07:36:25.896054       1 session.go:1079] Finish adjusting jobs' network topology spec according to hyperNodeTierNameMap map[]
I0731 07:36:25.896078       1 session.go:279] Open Session a3df9bf8-2fba-4432-8312-a6744a2ef509 with <0> Job and <2> Queues. HyperNodesReadyToSchedule: true
I0731 07:36:25.896514       1 enqueue.go:79] Try to enqueue PodGroup to 0 Queues
I0731 07:36:25.896536       1 allocate.go:138] Try to allocate resource to 0 Queues
I0731 07:36:25.896614       1 session.go:577] Close Session a3df9bf8-2fba-4432-8312-a6744a2ef509
I0731 07:36:26.897176       1 cache.go:1581] "SnapShot for scheduling" jobNum=0 QueueNum=2 NodeNum=1
I0731 07:36:26.897225       1 session.go:1036] Start adjusting jobs' network topology spec according to hyperNodeTierNameMap map[]
I0731 07:36:26.897249       1 session.go:1079] Finish adjusting jobs' network topology spec according to hyperNodeTierNameMap map[]
I0731 07:36:26.897273       1 session.go:279] Open Session 854c3005-7469-46bc-86c7-f0fb9f418e09 with <0> Job and <2> Queues. HyperNodesReadyToSchedule: true
I0731 07:36:26.897864       1 enqueue.go:79] Try to enqueue PodGroup to 0 Queues
I0731 07:36:26.897888       1 allocate.go:138] Try to allocate resource to 0 Queues
I0731 07:36:26.897976       1 session.go:577] Close Session 854c3005-7469-46bc-86c7-f0fb9f418e09
I0731 07:36:27.898599       1 cache.go:1581] "SnapShot for scheduling" jobNum=0 QueueNum=2 NodeNum=1
I0731 07:36:27.898648       1 session.go:1036] Start adjusting jobs' network topology spec according to hyperNodeTierNameMap map[]
I0731 07:36:27.898674       1 session.go:1079] Finish adjusting jobs' network topology spec according to hyperNodeTierNameMap map[]
I0731 07:36:27.898699       1 session.go:279] Open Session b1cc6553-ade6-49e2-93d0-1fb235257a96 with <0> Job and <2> Queues. HyperNodesReadyToSchedule: true
I0731 07:36:27.899246       1 enqueue.go:79] Try to enqueue PodGroup to 0 Queues
I0731 07:36:27.899271       1 allocate.go:138] Try to allocate resource to 0 Queues
I0731 07:36:27.899355       1 session.go:577] Close Session b1cc6553-ade6-49e2-93d0-1fb235257a96
I0731 07:36:28.900662       1 cache.go:1581] "SnapShot for scheduling" jobNum=0 QueueNum=2 NodeNum=1
I0731 07:36:28.900708       1 session.go:1036] Start adjusting jobs' network topology spec according to hyperNodeTierNameMap map[]
I0731 07:36:28.900732       1 session.go:1079] Finish adjusting jobs' network topology spec according to hyperNodeTierNameMap map[]
I0731 07:36:28.900755       1 session.go:279] Open Session 0d210676-dcd4-45a3-a008-eacde1f7d07f with <0> Job and <2> Queues. HyperNodesReadyToSchedule: true
I0731 07:36:28.901206       1 enqueue.go:79] Try to enqueue PodGroup to 0 Queues
I0731 07:36:28.901229       1 allocate.go:138] Try to allocate resource to 0 Queues
I0731 07:36:28.901305       1 session.go:577] Close Session 0d210676-dcd4-45a3-a008-eacde1f7d07f
I0731 07:36:29.902208       1 cache.go:1581] "SnapShot for scheduling" jobNum=0 QueueNum=2 NodeNum=1
I0731 07:36:29.902257       1 session.go:1036] Start adjusting jobs' network topology spec according to hyperNodeTierNameMap map[]
I0731 07:36:29.902280       1 session.go:1079] Finish adjusting jobs' network topology spec according to hyperNodeTierNameMap map[]
I0731 07:36:29.902304       1 session.go:279] Open Session bc8fc226-022f-48ab-857c-40bf7bfe7e8e with <0> Job and <2> Queues. HyperNodesReadyToSchedule: true
I0731 07:36:29.902796       1 enqueue.go:79] Try to enqueue PodGroup to 0 Queues
I0731 07:36:29.902818       1 allocate.go:138] Try to allocate resource to 0 Queues
I0731 07:36:29.902894       1 session.go:577] Close Session bc8fc226-022f-48ab-857c-40bf7bfe7e8e
I0731 07:36:30.903603       1 cache.go:1581] "SnapShot for scheduling" jobNum=0 QueueNum=2 NodeNum=1
I0731 07:36:30.903645       1 session.go:1036] Start adjusting jobs' network topology spec according to hyperNodeTierNameMap map[]
I0731 07:36:30.903667       1 session.go:1079] Finish adjusting jobs' network topology spec according to hyperNodeTierNameMap map[]
I0731 07:36:30.903692       1 session.go:279] Open Session cfc7b928-5a5c-4830-88c0-e2bf341a5ca7 with <0> Job and <2> Queues. HyperNodesReadyToSchedule: true
I0731 07:36:30.904134       1 enqueue.go:79] Try to enqueue PodGroup to 0 Queues
I0731 07:36:30.904155       1 allocate.go:138] Try to allocate resource to 0 Queues
I0731 07:36:30.904229       1 session.go:577] Close Session cfc7b928-5a5c-4830-88c0-e2bf341a5ca7
I0731 07:36:31.904812       1 cache.go:1581] "SnapShot for scheduling" jobNum=0 QueueNum=2 NodeNum=1
I0731 07:36:31.904861       1 session.go:1036] Start adjusting jobs' network topology spec according to hyperNodeTierNameMap map[]
I0731 07:36:31.904884       1 session.go:1079] Finish adjusting jobs' network topology spec according to hyperNodeTierNameMap map[]
I0731 07:36:31.904909       1 session.go:279] Open Session 2c861011-9fd6-49ab-bda4-307f7ca1ad04 with <0> Job and <2> Queues. HyperNodesReadyToSchedule: true
I0731 07:36:31.905339       1 enqueue.go:79] Try to enqueue PodGroup to 0 Queues
I0731 07:36:31.905362       1 allocate.go:138] Try to allocate resource to 0 Queues
I0731 07:36:31.905433       1 session.go:577] Close Session 2c861011-9fd6-49ab-bda4-307f7ca1ad04
I0731 07:36:32.905779       1 cache.go:1581] "SnapShot for scheduling" jobNum=0 QueueNum=2 NodeNum=1
I0731 07:36:32.905817       1 session.go:1036] Start adjusting jobs' network topology spec according to hyperNodeTierNameMap map[]
I0731 07:36:32.905839       1 session.go:1079] Finish adjusting jobs' network topology spec according to hyperNodeTierNameMap map[]
I0731 07:36:32.905862       1 session.go:279] Open Session dc79e920-01db-469e-821e-e45913721f4e with <0> Job and <2> Queues. HyperNodesReadyToSchedule: true
I0731 07:36:32.906278       1 enqueue.go:79] Try to enqueue PodGroup to 0 Queues
I0731 07:36:32.906299       1 allocate.go:138] Try to allocate resource to 0 Queues
I0731 07:36:32.906365       1 session.go:577] Close Session dc79e920-01db-469e-821e-e45913721f4e
I0731 07:36:33.906874       1 cache.go:1581] "SnapShot for scheduling" jobNum=0 QueueNum=2 NodeNum=1
I0731 07:36:33.906921       1 session.go:1036] Start adjusting jobs' network topology spec according to hyperNodeTierNameMap map[]
I0731 07:36:33.906943       1 session.go:1079] Finish adjusting jobs' network topology spec according to hyperNodeTierNameMap map[]
I0731 07:36:33.906967       1 session.go:279] Open Session dcece3fe-e507-45b5-b213-47ad0b0a2786 with <0> Job and <2> Queues. HyperNodesReadyToSchedule: true
I0731 07:36:33.907397       1 enqueue.go:79] Try to enqueue PodGroup to 0 Queues
I0731 07:36:33.907419       1 allocate.go:138] Try to allocate resource to 0 Queues
I0731 07:36:33.907493       1 session.go:577] Close Session dcece3fe-e507-45b5-b213-47ad0b0a2786
I0731 07:36:34.908837       1 cache.go:1581] "SnapShot for scheduling" jobNum=0 QueueNum=2 NodeNum=1
I0731 07:36:34.908880       1 session.go:1036] Start adjusting jobs' network topology spec according to hyperNodeTierNameMap map[]
I0731 07:36:34.908904       1 session.go:1079] Finish adjusting jobs' network topology spec according to hyperNodeTierNameMap map[]
I0731 07:36:34.908929       1 session.go:279] Open Session fe999147-dc1c-4153-8034-6ae7d0fd5020 with <0> Job and <2> Queues. HyperNodesReadyToSchedule: true
I0731 07:36:34.909399       1 enqueue.go:79] Try to enqueue PodGroup to 0 Queues
I0731 07:36:34.909424       1 allocate.go:138] Try to allocate resource to 0 Queues
I0731 07:36:34.909498       1 session.go:577] Close Session fe999147-dc1c-4153-8034-6ae7d0fd5020
I0731 07:36:35.910308       1 cache.go:1581] "SnapShot for scheduling" jobNum=0 QueueNum=2 NodeNum=1
I0731 07:36:35.910355       1 session.go:1036] Start adjusting jobs' network topology spec according to hyperNodeTierNameMap map[]
I0731 07:36:35.910380       1 session.go:1079] Finish adjusting jobs' network topology spec according to hyperNodeTierNameMap map[]
I0731 07:36:35.910404       1 session.go:279] Open Session eee94fd5-d26b-44e0-a4d6-98b2cfe5976a with <0> Job and <2> Queues. HyperNodesReadyToSchedule: true
I0731 07:36:35.910847       1 enqueue.go:79] Try to enqueue PodGroup to 0 Queues
I0731 07:36:35.910871       1 allocate.go:138] Try to allocate resource to 0 Queues
I0731 07:36:35.910938       1 session.go:577] Close Session eee94fd5-d26b-44e0-a4d6-98b2cfe5976a
I0731 07:36:36.911749       1 cache.go:1581] "SnapShot for scheduling" jobNum=0 QueueNum=2 NodeNum=1
I0731 07:36:36.911798       1 session.go:1036] Start adjusting jobs' network topology spec according to hyperNodeTierNameMap map[]
I0731 07:36:36.911821       1 session.go:1079] Finish adjusting jobs' network topology spec according to hyperNodeTierNameMap map[]
I0731 07:36:36.911846       1 session.go:279] Open Session 6a2054c2-b893-48e8-8809-ba0635e481dd with <0> Job and <2> Queues. HyperNodesReadyToSchedule: true
I0731 07:36:36.912391       1 enqueue.go:79] Try to enqueue PodGroup to 0 Queues
I0731 07:36:36.912414       1 allocate.go:138] Try to allocate resource to 0 Queues
I0731 07:36:36.912495       1 session.go:577] Close Session 6a2054c2-b893-48e8-8809-ba0635e481dd
I0731 07:36:37.913461       1 cache.go:1581] "SnapShot for scheduling" jobNum=0 QueueNum=2 NodeNum=1
I0731 07:36:37.913507       1 session.go:1036] Start adjusting jobs' network topology spec according to hyperNodeTierNameMap map[]
I0731 07:36:37.913531       1 session.go:1079] Finish adjusting jobs' network topology spec according to hyperNodeTierNameMap map[]
I0731 07:36:37.913560       1 session.go:279] Open Session 8993db2d-d167-4df0-97ac-2de6264e7b85 with <0> Job and <2> Queues. HyperNodesReadyToSchedule: true
I0731 07:36:37.913998       1 enqueue.go:79] Try to enqueue PodGroup to 0 Queues
I0731 07:36:37.914019       1 allocate.go:138] Try to allocate resource to 0 Queues
I0731 07:36:37.914091       1 session.go:577] Close Session 8993db2d-d167-4df0-97ac-2de6264e7b85
I0731 07:36:38.915457       1 cache.go:1581] "SnapShot for scheduling" jobNum=0 QueueNum=2 NodeNum=1
I0731 07:36:38.915506       1 session.go:1036] Start adjusting jobs' network topology spec according to hyperNodeTierNameMap map[]
I0731 07:36:38.915530       1 session.go:1079] Finish adjusting jobs' network topology spec according to hyperNodeTierNameMap map[]
I0731 07:36:38.915554       1 session.go:279] Open Session 9fdd6bf2-88fd-4fd8-b857-9d2a9f090734 with <0> Job and <2> Queues. HyperNodesReadyToSchedule: true
I0731 07:36:38.916066       1 enqueue.go:79] Try to enqueue PodGroup to 0 Queues
I0731 07:36:38.916088       1 allocate.go:138] Try to allocate resource to 0 Queues
I0731 07:36:38.916167       1 session.go:577] Close Session 9fdd6bf2-88fd-4fd8-b857-9d2a9f090734
I0731 07:36:39.917470       1 cache.go:1581] "SnapShot for scheduling" jobNum=0 QueueNum=2 NodeNum=1
I0731 07:36:39.917522       1 session.go:1036] Start adjusting jobs' network topology spec according to hyperNodeTierNameMap map[]
I0731 07:36:39.917548       1 session.go:1079] Finish adjusting jobs' network topology spec according to hyperNodeTierNameMap map[]
I0731 07:36:39.917573       1 session.go:279] Open Session 83acfe26-ceb0-4385-a0f5-4b2d643887d0 with <0> Job and <2> Queues. HyperNodesReadyToSchedule: true
I0731 07:36:39.918026       1 enqueue.go:79] Try to enqueue PodGroup to 0 Queues
I0731 07:36:39.918049       1 allocate.go:138] Try to allocate resource to 0 Queues
I0731 07:36:39.918130       1 session.go:577] Close Session 83acfe26-ceb0-4385-a0f5-4b2d643887d0
I0731 07:36:40.919018       1 cache.go:1581] "SnapShot for scheduling" jobNum=0 QueueNum=2 NodeNum=1
I0731 07:36:40.919070       1 session.go:1036] Start adjusting jobs' network topology spec according to hyperNodeTierNameMap map[]
I0731 07:36:40.919093       1 session.go:1079] Finish adjusting jobs' network topology spec according to hyperNodeTierNameMap map[]
I0731 07:36:40.919116       1 session.go:279] Open Session 46d5ea59-84a1-46a5-bf1f-4f73be08acdf with <0> Job and <2> Queues. HyperNodesReadyToSchedule: true
I0731 07:36:40.919575       1 enqueue.go:79] Try to enqueue PodGroup to 0 Queues
I0731 07:36:40.919598       1 allocate.go:138] Try to allocate resource to 0 Queues
I0731 07:36:40.919675       1 session.go:577] Close Session 46d5ea59-84a1-46a5-bf1f-4f73be08acdf
I0731 07:36:41.920213       1 cache.go:1581] "SnapShot for scheduling" jobNum=0 QueueNum=2 NodeNum=1
I0731 07:36:41.920265       1 session.go:1036] Start adjusting jobs' network topology spec according to hyperNodeTierNameMap map[]
I0731 07:36:41.920287       1 session.go:1079] Finish adjusting jobs' network topology spec according to hyperNodeTierNameMap map[]
I0731 07:36:41.920312       1 session.go:279] Open Session 1f85604c-20ff-4ff2-8ad2-ba3738b63d12 with <0> Job and <2> Queues. HyperNodesReadyToSchedule: true
I0731 07:36:41.920772       1 enqueue.go:79] Try to enqueue PodGroup to 0 Queues
I0731 07:36:41.920795       1 allocate.go:138] Try to allocate resource to 0 Queues
I0731 07:36:41.920873       1 session.go:577] Close Session 1f85604c-20ff-4ff2-8ad2-ba3738b63d12
I0731 07:36:42.922126       1 cache.go:1581] "SnapShot for scheduling" jobNum=0 QueueNum=2 NodeNum=1
I0731 07:36:42.922167       1 session.go:1036] Start adjusting jobs' network topology spec according to hyperNodeTierNameMap map[]
I0731 07:36:42.922187       1 session.go:1079] Finish adjusting jobs' network topology spec according to hyperNodeTierNameMap map[]
I0731 07:36:42.922211       1 session.go:279] Open Session 3bac49f1-34de-480d-b115-a590250dc602 with <0> Job and <2> Queues. HyperNodesReadyToSchedule: true
I0731 07:36:42.922621       1 enqueue.go:79] Try to enqueue PodGroup to 0 Queues
I0731 07:36:42.922642       1 allocate.go:138] Try to allocate resource to 0 Queues
I0731 07:36:42.922715       1 session.go:577] Close Session 3bac49f1-34de-480d-b115-a590250dc602
I0731 07:36:43.924105       1 cache.go:1581] "SnapShot for scheduling" jobNum=0 QueueNum=2 NodeNum=1
I0731 07:36:43.924149       1 session.go:1036] Start adjusting jobs' network topology spec according to hyperNodeTierNameMap map[]
I0731 07:36:43.924173       1 session.go:1079] Finish adjusting jobs' network topology spec according to hyperNodeTierNameMap map[]
I0731 07:36:43.924196       1 session.go:279] Open Session 81eff204-11b7-41d3-b9dc-c1badcd3b36d with <0> Job and <2> Queues. HyperNodesReadyToSchedule: true
I0731 07:36:43.924640       1 enqueue.go:79] Try to enqueue PodGroup to 0 Queues
I0731 07:36:43.924662       1 allocate.go:138] Try to allocate resource to 0 Queues
I0731 07:36:43.924733       1 session.go:577] Close Session 81eff204-11b7-41d3-b9dc-c1badcd3b36d
I0731 07:36:44.925668       1 cache.go:1581] "SnapShot for scheduling" jobNum=0 QueueNum=2 NodeNum=1
I0731 07:36:44.925707       1 session.go:1036] Start adjusting jobs' network topology spec according to hyperNodeTierNameMap map[]
I0731 07:36:44.925728       1 session.go:1079] Finish adjusting jobs' network topology spec according to hyperNodeTierNameMap map[]
I0731 07:36:44.925753       1 session.go:279] Open Session 098b8c70-18d8-4a12-bc3e-02b7cefd7025 with <0> Job and <2> Queues. HyperNodesReadyToSchedule: true
I0731 07:36:44.926150       1 enqueue.go:79] Try to enqueue PodGroup to 0 Queues
I0731 07:36:44.926171       1 allocate.go:138] Try to allocate resource to 0 Queues
I0731 07:36:44.926241       1 session.go:577] Close Session 098b8c70-18d8-4a12-bc3e-02b7cefd7025
I0731 07:36:45.927021       1 cache.go:1581] "SnapShot for scheduling" jobNum=0 QueueNum=2 NodeNum=1
I0731 07:36:45.927065       1 session.go:1036] Start adjusting jobs' network topology spec according to hyperNodeTierNameMap map[]
I0731 07:36:45.927088       1 session.go:1079] Finish adjusting jobs' network topology spec according to hyperNodeTierNameMap map[]
I0731 07:36:45.927111       1 session.go:279] Open Session b0ae6c00-fa5c-491d-8fcd-5e6e33564e86 with <0> Job and <2> Queues. HyperNodesReadyToSchedule: true
I0731 07:36:45.928278       1 enqueue.go:79] Try to enqueue PodGroup to 0 Queues
I0731 07:36:45.928308       1 allocate.go:138] Try to allocate resource to 0 Queues
I0731 07:36:45.928411       1 session.go:577] Close Session b0ae6c00-fa5c-491d-8fcd-5e6e33564e86
I0731 07:36:46.487746       1 cache.go:1771] The metrics type is not set in the volcano scheduler configmap file. As a result, the CPU and memory load information of the node is not collected.
I0731 07:36:46.930041       1 cache.go:1581] "SnapShot for scheduling" jobNum=0 QueueNum=2 NodeNum=1
I0731 07:36:46.930101       1 session.go:1036] Start adjusting jobs' network topology spec according to hyperNodeTierNameMap map[]
I0731 07:36:46.930130       1 session.go:1079] Finish adjusting jobs' network topology spec according to hyperNodeTierNameMap map[]
I0731 07:36:46.930153       1 session.go:279] Open Session bd50cb42-3594-4d86-bc15-51ca256c29a7 with <0> Job and <2> Queues. HyperNodesReadyToSchedule: true
I0731 07:36:46.930692       1 enqueue.go:79] Try to enqueue PodGroup to 0 Queues
I0731 07:36:46.930731       1 allocate.go:138] Try to allocate resource to 0 Queues
I0731 07:36:46.930822       1 session.go:577] Close Session bd50cb42-3594-4d86-bc15-51ca256c29a7
I0731 07:36:47.931691       1 cache.go:1581] "SnapShot for scheduling" jobNum=0 QueueNum=2 NodeNum=1
I0731 07:36:47.931739       1 session.go:1036] Start adjusting jobs' network topology spec according to hyperNodeTierNameMap map[]
I0731 07:36:47.931761       1 session.go:1079] Finish adjusting jobs' network topology spec according to hyperNodeTierNameMap map[]
I0731 07:36:47.931784       1 session.go:279] Open Session 39924c86-641e-4742-856c-402724ad6e00 with <0> Job and <2> Queues. HyperNodesReadyToSchedule: true
I0731 07:36:47.932219       1 enqueue.go:79] Try to enqueue PodGroup to 0 Queues
I0731 07:36:47.932242       1 allocate.go:138] Try to allocate resource to 0 Queues
I0731 07:36:47.932316       1 session.go:577] Close Session 39924c86-641e-4742-856c-402724ad6e00
I0731 07:36:48.932826       1 cache.go:1581] "SnapShot for scheduling" jobNum=0 QueueNum=2 NodeNum=1
I0731 07:36:48.932868       1 session.go:1036] Start adjusting jobs' network topology spec according to hyperNodeTierNameMap map[]
I0731 07:36:48.932890       1 session.go:1079] Finish adjusting jobs' network topology spec according to hyperNodeTierNameMap map[]
I0731 07:36:48.932917       1 session.go:279] Open Session c38af748-7da1-4c2f-8fbd-e87214171566 with <0> Job and <2> Queues. HyperNodesReadyToSchedule: true
I0731 07:36:48.933349       1 enqueue.go:79] Try to enqueue PodGroup to 0 Queues
I0731 07:36:48.933372       1 allocate.go:138] Try to allocate resource to 0 Queues
I0731 07:36:48.933444       1 session.go:577] Close Session c38af748-7da1-4c2f-8fbd-e87214171566
I0731 07:36:49.933786       1 cache.go:1581] "SnapShot for scheduling" jobNum=0 QueueNum=2 NodeNum=1
I0731 07:36:49.933817       1 session.go:1036] Start adjusting jobs' network topology spec according to hyperNodeTierNameMap map[]
I0731 07:36:49.933832       1 session.go:1079] Finish adjusting jobs' network topology spec according to hyperNodeTierNameMap map[]
I0731 07:36:49.933846       1 session.go:279] Open Session aaa6c2f9-f901-4a9a-b79e-ac08a459f439 with <0> Job and <2> Queues. HyperNodesReadyToSchedule: true
I0731 07:36:49.934152       1 enqueue.go:79] Try to enqueue PodGroup to 0 Queues
I0731 07:36:49.934169       1 allocate.go:138] Try to allocate resource to 0 Queues
I0731 07:36:49.934224       1 session.go:577] Close Session aaa6c2f9-f901-4a9a-b79e-ac08a459f439
I0731 07:36:50.934862       1 cache.go:1581] "SnapShot for scheduling" jobNum=0 QueueNum=2 NodeNum=1
I0731 07:36:50.934895       1 session.go:1036] Start adjusting jobs' network topology spec according to hyperNodeTierNameMap map[]
I0731 07:36:50.934914       1 session.go:1079] Finish adjusting jobs' network topology spec according to hyperNodeTierNameMap map[]
I0731 07:36:50.934935       1 session.go:279] Open Session 3e1a82d8-7b35-4341-9138-046566ec92ef with <0> Job and <2> Queues. HyperNodesReadyToSchedule: true
I0731 07:36:50.935346       1 enqueue.go:79] Try to enqueue PodGroup to 0 Queues
I0731 07:36:50.935366       1 allocate.go:138] Try to allocate resource to 0 Queues
I0731 07:36:50.935436       1 session.go:577] Close Session 3e1a82d8-7b35-4341-9138-046566ec92ef
I0731 07:36:51.936773       1 cache.go:1581] "SnapShot for scheduling" jobNum=0 QueueNum=2 NodeNum=1
I0731 07:36:51.936816       1 session.go:1036] Start adjusting jobs' network topology spec according to hyperNodeTierNameMap map[]
I0731 07:36:51.936838       1 session.go:1079] Finish adjusting jobs' network topology spec according to hyperNodeTierNameMap map[]
I0731 07:36:51.936866       1 session.go:279] Open Session 1c05b759-a746-43b6-ab5b-f359d1c8a93e with <0> Job and <2> Queues. HyperNodesReadyToSchedule: true
I0731 07:36:51.937316       1 enqueue.go:79] Try to enqueue PodGroup to 0 Queues
I0731 07:36:51.937338       1 allocate.go:138] Try to allocate resource to 0 Queues
I0731 07:36:51.937409       1 session.go:577] Close Session 1c05b759-a746-43b6-ab5b-f359d1c8a93e
I0731 07:36:52.938691       1 cache.go:1581] "SnapShot for scheduling" jobNum=0 QueueNum=2 NodeNum=1
I0731 07:36:52.938746       1 session.go:1036] Start adjusting jobs' network topology spec according to hyperNodeTierNameMap map[]
I0731 07:36:52.938775       1 session.go:1079] Finish adjusting jobs' network topology spec according to hyperNodeTierNameMap map[]
I0731 07:36:52.938800       1 session.go:279] Open Session a6823d8e-8b64-4d4d-87c8-a2018cfd506d with <0> Job and <2> Queues. HyperNodesReadyToSchedule: true
I0731 07:36:52.939246       1 enqueue.go:79] Try to enqueue PodGroup to 0 Queues
I0731 07:36:52.939269       1 allocate.go:138] Try to allocate resource to 0 Queues
I0731 07:36:52.939342       1 session.go:577] Close Session a6823d8e-8b64-4d4d-87c8-a2018cfd506d
I0731 07:36:53.940303       1 cache.go:1581] "SnapShot for scheduling" jobNum=0 QueueNum=2 NodeNum=1
I0731 07:36:53.940343       1 session.go:1036] Start adjusting jobs' network topology spec according to hyperNodeTierNameMap map[]
I0731 07:36:53.940362       1 session.go:1079] Finish adjusting jobs' network topology spec according to hyperNodeTierNameMap map[]
I0731 07:36:53.940388       1 session.go:279] Open Session 3c1f8103-14d6-464a-af87-7f08cd0b4581 with <0> Job and <2> Queues. HyperNodesReadyToSchedule: true
I0731 07:36:53.940925       1 enqueue.go:79] Try to enqueue PodGroup to 0 Queues
I0731 07:36:53.940947       1 allocate.go:138] Try to allocate resource to 0 Queues
I0731 07:36:53.941012       1 session.go:577] Close Session 3c1f8103-14d6-464a-af87-7f08cd0b4581
I0731 07:36:54.941800       1 cache.go:1581] "SnapShot for scheduling" jobNum=0 QueueNum=2 NodeNum=1
I0731 07:36:54.941832       1 session.go:1036] Start adjusting jobs' network topology spec according to hyperNodeTierNameMap map[]
I0731 07:36:54.941853       1 session.go:1079] Finish adjusting jobs' network topology spec according to hyperNodeTierNameMap map[]
I0731 07:36:54.941875       1 session.go:279] Open Session c9ff04a2-7f72-4265-9910-f07b9d0b6911 with <0> Job and <2> Queues. HyperNodesReadyToSchedule: true
I0731 07:36:54.942257       1 enqueue.go:79] Try to enqueue PodGroup to 0 Queues
I0731 07:36:54.942278       1 allocate.go:138] Try to allocate resource to 0 Queues
I0731 07:36:54.942344       1 session.go:577] Close Session c9ff04a2-7f72-4265-9910-f07b9d0b6911
I0731 07:36:55.943003       1 cache.go:1581] "SnapShot for scheduling" jobNum=0 QueueNum=2 NodeNum=1
I0731 07:36:55.943031       1 session.go:1036] Start adjusting jobs' network topology spec according to hyperNodeTierNameMap map[]
I0731 07:36:55.943050       1 session.go:1079] Finish adjusting jobs' network topology spec according to hyperNodeTierNameMap map[]
I0731 07:36:55.943072       1 session.go:279] Open Session 1c36f2e6-27b4-48b8-8552-5bdc285e8221 with <0> Job and <2> Queues. HyperNodesReadyToSchedule: true
I0731 07:36:55.943460       1 enqueue.go:79] Try to enqueue PodGroup to 0 Queues
I0731 07:36:55.943480       1 allocate.go:138] Try to allocate resource to 0 Queues
I0731 07:36:55.943537       1 session.go:577] Close Session 1c36f2e6-27b4-48b8-8552-5bdc285e8221
I0731 07:36:56.944974       1 cache.go:1581] "SnapShot for scheduling" jobNum=0 QueueNum=2 NodeNum=1
I0731 07:36:56.945025       1 session.go:1036] Start adjusting jobs' network topology spec according to hyperNodeTierNameMap map[]
I0731 07:36:56.945050       1 session.go:1079] Finish adjusting jobs' network topology spec according to hyperNodeTierNameMap map[]
I0731 07:36:56.945073       1 session.go:279] Open Session 5f2131d3-25fb-4f15-93c6-439e68716de8 with <0> Job and <2> Queues. HyperNodesReadyToSchedule: true
I0731 07:36:56.945520       1 enqueue.go:79] Try to enqueue PodGroup to 0 Queues
I0731 07:36:56.945541       1 allocate.go:138] Try to allocate resource to 0 Queues
I0731 07:36:56.945612       1 session.go:577] Close Session 5f2131d3-25fb-4f15-93c6-439e68716de8
I0731 07:36:57.947075       1 cache.go:1581] "SnapShot for scheduling" jobNum=0 QueueNum=2 NodeNum=1
I0731 07:36:57.947125       1 session.go:1036] Start adjusting jobs' network topology spec according to hyperNodeTierNameMap map[]
I0731 07:36:57.947150       1 session.go:1079] Finish adjusting jobs' network topology spec according to hyperNodeTierNameMap map[]
I0731 07:36:57.947183       1 session.go:279] Open Session 836a4823-6e97-4891-8c46-6f242d33fe95 with <0> Job and <2> Queues. HyperNodesReadyToSchedule: true
I0731 07:36:57.947724       1 enqueue.go:79] Try to enqueue PodGroup to 0 Queues
I0731 07:36:57.947748       1 allocate.go:138] Try to allocate resource to 0 Queues
I0731 07:36:57.947833       1 session.go:577] Close Session 836a4823-6e97-4891-8c46-6f242d33fe95
I0731 07:36:58.948774       1 cache.go:1581] "SnapShot for scheduling" jobNum=0 QueueNum=2 NodeNum=1
I0731 07:36:58.948817       1 session.go:1036] Start adjusting jobs' network topology spec according to hyperNodeTierNameMap map[]
I0731 07:36:58.948839       1 session.go:1079] Finish adjusting jobs' network topology spec according to hyperNodeTierNameMap map[]
I0731 07:36:58.948862       1 session.go:279] Open Session 505b3601-8c71-4f49-a04f-2deb7bf777eb with <0> Job and <2> Queues. HyperNodesReadyToSchedule: true
I0731 07:36:58.949381       1 enqueue.go:79] Try to enqueue PodGroup to 0 Queues
I0731 07:36:58.949403       1 allocate.go:138] Try to allocate resource to 0 Queues
I0731 07:36:58.949483       1 session.go:577] Close Session 505b3601-8c71-4f49-a04f-2deb7bf777eb
I0731 07:36:59.949977       1 cache.go:1581] "SnapShot for scheduling" jobNum=0 QueueNum=2 NodeNum=1
I0731 07:36:59.950004       1 session.go:1036] Start adjusting jobs' network topology spec according to hyperNodeTierNameMap map[]
I0731 07:36:59.950022       1 session.go:1079] Finish adjusting jobs' network topology spec according to hyperNodeTierNameMap map[]
I0731 07:36:59.950044       1 session.go:279] Open Session bda170e1-1465-4c63-8404-d8718d4f7a06 with <0> Job and <2> Queues. HyperNodesReadyToSchedule: true
I0731 07:36:59.950381       1 enqueue.go:79] Try to enqueue PodGroup to 0 Queues
I0731 07:36:59.950401       1 allocate.go:138] Try to allocate resource to 0 Queues
I0731 07:36:59.950452       1 session.go:577] Close Session bda170e1-1465-4c63-8404-d8718d4f7a06
I0731 07:37:00.951170       1 cache.go:1581] "SnapShot for scheduling" jobNum=0 QueueNum=2 NodeNum=1
I0731 07:37:00.951214       1 session.go:1036] Start adjusting jobs' network topology spec according to hyperNodeTierNameMap map[]
I0731 07:37:00.951239       1 session.go:1079] Finish adjusting jobs' network topology spec according to hyperNodeTierNameMap map[]
I0731 07:37:00.951268       1 session.go:279] Open Session a69c25ca-2926-4065-8c44-1affc0c06865 with <0> Job and <2> Queues. HyperNodesReadyToSchedule: true
I0731 07:37:00.951717       1 enqueue.go:79] Try to enqueue PodGroup to 0 Queues
I0731 07:37:00.951738       1 allocate.go:138] Try to allocate resource to 0 Queues
I0731 07:37:00.951815       1 session.go:577] Close Session a69c25ca-2926-4065-8c44-1affc0c06865
I0731 07:37:01.953214       1 cache.go:1581] "SnapShot for scheduling" jobNum=0 QueueNum=2 NodeNum=1
I0731 07:37:01.953274       1 session.go:1036] Start adjusting jobs' network topology spec according to hyperNodeTierNameMap map[]
I0731 07:37:01.953300       1 session.go:1079] Finish adjusting jobs' network topology spec according to hyperNodeTierNameMap map[]
I0731 07:37:01.953326       1 session.go:279] Open Session a082febc-8e19-4a22-a0a0-860bd2f586ed with <0> Job and <2> Queues. HyperNodesReadyToSchedule: true
I0731 07:37:01.953879       1 enqueue.go:79] Try to enqueue PodGroup to 0 Queues
I0731 07:37:01.953906       1 allocate.go:138] Try to allocate resource to 0 Queues
I0731 07:37:01.953996       1 session.go:577] Close Session a082febc-8e19-4a22-a0a0-860bd2f586ed
I0731 07:37:02.955058       1 cache.go:1581] "SnapShot for scheduling" jobNum=0 QueueNum=2 NodeNum=1
I0731 07:37:02.955107       1 session.go:1036] Start adjusting jobs' network topology spec according to hyperNodeTierNameMap map[]
I0731 07:37:02.955130       1 session.go:1079] Finish adjusting jobs' network topology spec according to hyperNodeTierNameMap map[]
I0731 07:37:02.955153       1 session.go:279] Open Session c31e9604-b487-4d44-a3ae-e9b715621c99 with <0> Job and <2> Queues. HyperNodesReadyToSchedule: true
I0731 07:37:02.955600       1 enqueue.go:79] Try to enqueue PodGroup to 0 Queues
I0731 07:37:02.955623       1 allocate.go:138] Try to allocate resource to 0 Queues
I0731 07:37:02.955701       1 session.go:577] Close Session c31e9604-b487-4d44-a3ae-e9b715621c99
I0731 07:37:03.956229       1 cache.go:1581] "SnapShot for scheduling" jobNum=0 QueueNum=2 NodeNum=1
I0731 07:37:03.956283       1 session.go:1036] Start adjusting jobs' network topology spec according to hyperNodeTierNameMap map[]
I0731 07:37:03.956308       1 session.go:1079] Finish adjusting jobs' network topology spec according to hyperNodeTierNameMap map[]
I0731 07:37:03.956334       1 session.go:279] Open Session f495ffe9-71c3-4241-810e-2a72f8651c19 with <0> Job and <2> Queues. HyperNodesReadyToSchedule: true
I0731 07:37:03.956846       1 enqueue.go:79] Try to enqueue PodGroup to 0 Queues
I0731 07:37:03.956869       1 allocate.go:138] Try to allocate resource to 0 Queues
I0731 07:37:03.956953       1 session.go:577] Close Session f495ffe9-71c3-4241-810e-2a72f8651c19
I0731 07:37:04.957664       1 cache.go:1581] "SnapShot for scheduling" jobNum=0 QueueNum=2 NodeNum=1
I0731 07:37:04.957718       1 session.go:1036] Start adjusting jobs' network topology spec according to hyperNodeTierNameMap map[]
I0731 07:37:04.957744       1 session.go:1079] Finish adjusting jobs' network topology spec according to hyperNodeTierNameMap map[]
I0731 07:37:04.957768       1 session.go:279] Open Session 0cb53e33-6fc4-4e07-b6a3-202c33dbde82 with <0> Job and <2> Queues. HyperNodesReadyToSchedule: true
I0731 07:37:04.958270       1 enqueue.go:79] Try to enqueue PodGroup to 0 Queues
I0731 07:37:04.958295       1 allocate.go:138] Try to allocate resource to 0 Queues
I0731 07:37:04.958377       1 session.go:577] Close Session 0cb53e33-6fc4-4e07-b6a3-202c33dbde82
I0731 07:37:05.958965       1 cache.go:1581] "SnapShot for scheduling" jobNum=0 QueueNum=2 NodeNum=1
I0731 07:37:05.959021       1 session.go:1036] Start adjusting jobs' network topology spec according to hyperNodeTierNameMap map[]
I0731 07:37:05.959048       1 session.go:1079] Finish adjusting jobs' network topology spec according to hyperNodeTierNameMap map[]
I0731 07:37:05.959074       1 session.go:279] Open Session 46aeda62-5543-4a3b-b3c9-1c808bf1002c with <0> Job and <2> Queues. HyperNodesReadyToSchedule: true
I0731 07:37:05.959664       1 enqueue.go:79] Try to enqueue PodGroup to 0 Queues
I0731 07:37:05.959692       1 allocate.go:138] Try to allocate resource to 0 Queues
I0731 07:37:05.959773       1 session.go:577] Close Session 46aeda62-5543-4a3b-b3c9-1c808bf1002c
I0731 07:37:06.960477       1 cache.go:1581] "SnapShot for scheduling" jobNum=0 QueueNum=2 NodeNum=1
I0731 07:37:06.960542       1 session.go:1036] Start adjusting jobs' network topology spec according to hyperNodeTierNameMap map[]
I0731 07:37:06.960571       1 session.go:1079] Finish adjusting jobs' network topology spec according to hyperNodeTierNameMap map[]
I0731 07:37:06.960595       1 session.go:279] Open Session 995229b1-a735-4a4e-a7c6-4a5423bf6176 with <0> Job and <2> Queues. HyperNodesReadyToSchedule: true
I0731 07:37:06.961214       1 enqueue.go:79] Try to enqueue PodGroup to 0 Queues
I0731 07:37:06.961238       1 allocate.go:138] Try to allocate resource to 0 Queues
I0731 07:37:06.961327       1 session.go:577] Close Session 995229b1-a735-4a4e-a7c6-4a5423bf6176
I0731 07:37:07.962329       1 cache.go:1581] "SnapShot for scheduling" jobNum=0 QueueNum=2 NodeNum=1
I0731 07:37:07.962384       1 session.go:1036] Start adjusting jobs' network topology spec according to hyperNodeTierNameMap map[]
I0731 07:37:07.962409       1 session.go:1079] Finish adjusting jobs' network topology spec according to hyperNodeTierNameMap map[]
I0731 07:37:07.962434       1 session.go:279] Open Session 8c702d14-7fa4-488d-adaf-e9657f34aba0 with <0> Job and <2> Queues. HyperNodesReadyToSchedule: true
I0731 07:37:07.962967       1 enqueue.go:79] Try to enqueue PodGroup to 0 Queues
I0731 07:37:07.962993       1 allocate.go:138] Try to allocate resource to 0 Queues
I0731 07:37:07.963077       1 session.go:577] Close Session 8c702d14-7fa4-488d-adaf-e9657f34aba0
I0731 07:37:08.964050       1 cache.go:1581] "SnapShot for scheduling" jobNum=0 QueueNum=2 NodeNum=1
I0731 07:37:08.964109       1 session.go:1036] Start adjusting jobs' network topology spec according to hyperNodeTierNameMap map[]
I0731 07:37:08.964135       1 session.go:1079] Finish adjusting jobs' network topology spec according to hyperNodeTierNameMap map[]
I0731 07:37:08.964160       1 session.go:279] Open Session a6112804-57e4-4c74-9e74-937d37e5f23e with <0> Job and <2> Queues. HyperNodesReadyToSchedule: true
I0731 07:37:08.964684       1 enqueue.go:79] Try to enqueue PodGroup to 0 Queues
I0731 07:37:08.964710       1 allocate.go:138] Try to allocate resource to 0 Queues
I0731 07:37:08.964794       1 session.go:577] Close Session a6112804-57e4-4c74-9e74-937d37e5f23e
I0731 07:37:09.965445       1 cache.go:1581] "SnapShot for scheduling" jobNum=0 QueueNum=2 NodeNum=1
I0731 07:37:09.965491       1 session.go:1036] Start adjusting jobs' network topology spec according to hyperNodeTierNameMap map[]
I0731 07:37:09.965518       1 session.go:1079] Finish adjusting jobs' network topology spec according to hyperNodeTierNameMap map[]
I0731 07:37:09.965543       1 session.go:279] Open Session 2109d2d7-6234-4a4b-9f99-f357931d3751 with <0> Job and <2> Queues. HyperNodesReadyToSchedule: true
I0731 07:37:09.966015       1 enqueue.go:79] Try to enqueue PodGroup to 0 Queues
I0731 07:37:09.966038       1 allocate.go:138] Try to allocate resource to 0 Queues
I0731 07:37:09.966120       1 session.go:577] Close Session 2109d2d7-6234-4a4b-9f99-f357931d3751
I0731 07:37:10.966582       1 cache.go:1581] "SnapShot for scheduling" jobNum=0 QueueNum=2 NodeNum=1
I0731 07:37:10.966623       1 session.go:1036] Start adjusting jobs' network topology spec according to hyperNodeTierNameMap map[]
I0731 07:37:10.966645       1 session.go:1079] Finish adjusting jobs' network topology spec according to hyperNodeTierNameMap map[]
I0731 07:37:10.966671       1 session.go:279] Open Session 27d3b431-d782-4781-8cc9-ef398c84b818 with <0> Job and <2> Queues. HyperNodesReadyToSchedule: true
I0731 07:37:10.967094       1 enqueue.go:79] Try to enqueue PodGroup to 0 Queues
I0731 07:37:10.967116       1 allocate.go:138] Try to allocate resource to 0 Queues
I0731 07:37:10.967189       1 session.go:577] Close Session 27d3b431-d782-4781-8cc9-ef398c84b818
I0731 07:37:11.968619       1 cache.go:1581] "SnapShot for scheduling" jobNum=0 QueueNum=2 NodeNum=1
I0731 07:37:11.968679       1 session.go:1036] Start adjusting jobs' network topology spec according to hyperNodeTierNameMap map[]
I0731 07:37:11.968706       1 session.go:1079] Finish adjusting jobs' network topology spec according to hyperNodeTierNameMap map[]
I0731 07:37:11.968738       1 session.go:279] Open Session 20182692-d731-48bc-8103-a309e8c869a3 with <0> Job and <2> Queues. HyperNodesReadyToSchedule: true
I0731 07:37:11.969239       1 enqueue.go:79] Try to enqueue PodGroup to 0 Queues
I0731 07:37:11.969264       1 allocate.go:138] Try to allocate resource to 0 Queues
I0731 07:37:11.969349       1 session.go:577] Close Session 20182692-d731-48bc-8103-a309e8c869a3
I0731 07:37:12.969755       1 cache.go:1581] "SnapShot for scheduling" jobNum=0 QueueNum=2 NodeNum=1
I0731 07:37:12.969785       1 session.go:1036] Start adjusting jobs' network topology spec according to hyperNodeTierNameMap map[]
I0731 07:37:12.969801       1 session.go:1079] Finish adjusting jobs' network topology spec according to hyperNodeTierNameMap map[]
I0731 07:37:12.969825       1 session.go:279] Open Session 4be071f6-d237-4663-b6a1-d4eb6ffa3c65 with <0> Job and <2> Queues. HyperNodesReadyToSchedule: true
I0731 07:37:12.970142       1 enqueue.go:79] Try to enqueue PodGroup to 0 Queues
I0731 07:37:12.970161       1 allocate.go:138] Try to allocate resource to 0 Queues
I0731 07:37:12.970207       1 session.go:577] Close Session 4be071f6-d237-4663-b6a1-d4eb6ffa3c65
I0731 07:37:13.970890       1 cache.go:1581] "SnapShot for scheduling" jobNum=0 QueueNum=2 NodeNum=1
I0731 07:37:13.970917       1 session.go:1036] Start adjusting jobs' network topology spec according to hyperNodeTierNameMap map[]
I0731 07:37:13.970932       1 session.go:1079] Finish adjusting jobs' network topology spec according to hyperNodeTierNameMap map[]
I0731 07:37:13.970952       1 session.go:279] Open Session 174da131-1724-4257-92e4-e2223a564e9d with <0> Job and <2> Queues. HyperNodesReadyToSchedule: true
I0731 07:37:13.971262       1 enqueue.go:79] Try to enqueue PodGroup to 0 Queues
I0731 07:37:13.971280       1 allocate.go:138] Try to allocate resource to 0 Queues
I0731 07:37:13.971331       1 session.go:577] Close Session 174da131-1724-4257-92e4-e2223a564e9d
I0731 07:37:14.971886       1 cache.go:1581] "SnapShot for scheduling" jobNum=0 QueueNum=2 NodeNum=1
I0731 07:37:14.971944       1 session.go:1036] Start adjusting jobs' network topology spec according to hyperNodeTierNameMap map[]
I0731 07:37:14.971969       1 session.go:1079] Finish adjusting jobs' network topology spec according to hyperNodeTierNameMap map[]
I0731 07:37:14.971994       1 session.go:279] Open Session d861f966-abe9-46ae-aefa-6d41694f9124 with <0> Job and <2> Queues. HyperNodesReadyToSchedule: true
I0731 07:37:14.972540       1 enqueue.go:79] Try to enqueue PodGroup to 0 Queues
I0731 07:37:14.972563       1 allocate.go:138] Try to allocate resource to 0 Queues
I0731 07:37:14.972653       1 session.go:577] Close Session d861f966-abe9-46ae-aefa-6d41694f9124
I0731 07:37:15.974015       1 cache.go:1581] "SnapShot for scheduling" jobNum=0 QueueNum=2 NodeNum=1
I0731 07:37:15.974082       1 session.go:1036] Start adjusting jobs' network topology spec according to hyperNodeTierNameMap map[]
I0731 07:37:15.974109       1 session.go:1079] Finish adjusting jobs' network topology spec according to hyperNodeTierNameMap map[]
I0731 07:37:15.974134       1 session.go:279] Open Session 1b3d7209-8364-4646-a420-f298f095c1f5 with <0> Job and <2> Queues. HyperNodesReadyToSchedule: true
I0731 07:37:15.974761       1 enqueue.go:79] Try to enqueue PodGroup to 0 Queues
I0731 07:37:15.974789       1 allocate.go:138] Try to allocate resource to 0 Queues
I0731 07:37:15.974879       1 session.go:577] Close Session 1b3d7209-8364-4646-a420-f298f095c1f5
I0731 07:37:16.488217       1 cache.go:1771] The metrics type is not set in the volcano scheduler configmap file. As a result, the CPU and memory load information of the node is not collected.
I0731 07:37:16.975424       1 cache.go:1581] "SnapShot for scheduling" jobNum=0 QueueNum=2 NodeNum=1
I0731 07:37:16.975473       1 session.go:1036] Start adjusting jobs' network topology spec according to hyperNodeTierNameMap map[]
I0731 07:37:16.975496       1 session.go:1079] Finish adjusting jobs' network topology spec according to hyperNodeTierNameMap map[]
I0731 07:37:16.975520       1 session.go:279] Open Session 351711b9-c20d-4e51-98f2-713c08d3a7ab with <0> Job and <2> Queues. HyperNodesReadyToSchedule: true
I0731 07:37:16.975966       1 enqueue.go:79] Try to enqueue PodGroup to 0 Queues
I0731 07:37:16.975989       1 allocate.go:138] Try to allocate resource to 0 Queues
I0731 07:37:16.976065       1 session.go:577] Close Session 351711b9-c20d-4e51-98f2-713c08d3a7ab
I0731 07:37:17.976570       1 cache.go:1581] "SnapShot for scheduling" jobNum=0 QueueNum=2 NodeNum=1
I0731 07:37:17.976615       1 session.go:1036] Start adjusting jobs' network topology spec according to hyperNodeTierNameMap map[]
I0731 07:37:17.976638       1 session.go:1079] Finish adjusting jobs' network topology spec according to hyperNodeTierNameMap map[]
I0731 07:37:17.976663       1 session.go:279] Open Session 9e98b8b7-62bd-47e7-936e-066eaed9997f with <0> Job and <2> Queues. HyperNodesReadyToSchedule: true
I0731 07:37:17.977112       1 enqueue.go:79] Try to enqueue PodGroup to 0 Queues
I0731 07:37:17.977683       1 allocate.go:138] Try to allocate resource to 0 Queues
I0731 07:37:17.977811       1 session.go:577] Close Session 9e98b8b7-62bd-47e7-936e-066eaed9997f
I0731 07:37:18.978768       1 cache.go:1581] "SnapShot for scheduling" jobNum=0 QueueNum=2 NodeNum=1
I0731 07:37:18.978822       1 session.go:1036] Start adjusting jobs' network topology spec according to hyperNodeTierNameMap map[]
I0731 07:37:18.978845       1 session.go:1079] Finish adjusting jobs' network topology spec according to hyperNodeTierNameMap map[]
I0731 07:37:18.978870       1 session.go:279] Open Session 9bac0a1f-14af-4c16-941a-6daacdedf980 with <0> Job and <2> Queues. HyperNodesReadyToSchedule: true
I0731 07:37:18.979398       1 enqueue.go:79] Try to enqueue PodGroup to 0 Queues
I0731 07:37:18.979424       1 allocate.go:138] Try to allocate resource to 0 Queues
I0731 07:37:18.979505       1 session.go:577] Close Session 9bac0a1f-14af-4c16-941a-6daacdedf980
I0731 07:37:19.980327       1 cache.go:1581] "SnapShot for scheduling" jobNum=0 QueueNum=2 NodeNum=1
I0731 07:37:19.980382       1 session.go:1036] Start adjusting jobs' network topology spec according to hyperNodeTierNameMap map[]
I0731 07:37:19.980406       1 session.go:1079] Finish adjusting jobs' network topology spec according to hyperNodeTierNameMap map[]
I0731 07:37:19.980434       1 session.go:279] Open Session b1436758-5e5c-46f0-88b3-5d547d3ef64a with <0> Job and <2> Queues. HyperNodesReadyToSchedule: true
I0731 07:37:19.980931       1 enqueue.go:79] Try to enqueue PodGroup to 0 Queues
I0731 07:37:19.980954       1 allocate.go:138] Try to allocate resource to 0 Queues
I0731 07:37:19.981031       1 session.go:577] Close Session b1436758-5e5c-46f0-88b3-5d547d3ef64a
I0731 07:37:20.982094       1 cache.go:1581] "SnapShot for scheduling" jobNum=0 QueueNum=2 NodeNum=1
I0731 07:37:20.982127       1 session.go:1036] Start adjusting jobs' network topology spec according to hyperNodeTierNameMap map[]
I0731 07:37:20.982147       1 session.go:1079] Finish adjusting jobs' network topology spec according to hyperNodeTierNameMap map[]
I0731 07:37:20.982172       1 session.go:279] Open Session 85d79ff0-4b2f-4b3e-9e43-53918b4744bb with <0> Job and <2> Queues. HyperNodesReadyToSchedule: true
I0731 07:37:20.982579       1 enqueue.go:79] Try to enqueue PodGroup to 0 Queues
I0731 07:37:20.982598       1 allocate.go:138] Try to allocate resource to 0 Queues
I0731 07:37:20.982663       1 session.go:577] Close Session 85d79ff0-4b2f-4b3e-9e43-53918b4744bb
I0731 07:37:21.983139       1 cache.go:1581] "SnapShot for scheduling" jobNum=0 QueueNum=2 NodeNum=1
I0731 07:37:21.983182       1 session.go:1036] Start adjusting jobs' network topology spec according to hyperNodeTierNameMap map[]
I0731 07:37:21.983204       1 session.go:1079] Finish adjusting jobs' network topology spec according to hyperNodeTierNameMap map[]
I0731 07:37:21.983227       1 session.go:279] Open Session f52953a6-b79f-4dde-8fa0-77903b39e64f with <0> Job and <2> Queues. HyperNodesReadyToSchedule: true
I0731 07:37:21.983678       1 enqueue.go:79] Try to enqueue PodGroup to 0 Queues
I0731 07:37:21.983700       1 allocate.go:138] Try to allocate resource to 0 Queues
I0731 07:37:21.983776       1 session.go:577] Close Session f52953a6-b79f-4dde-8fa0-77903b39e64f
I0731 07:37:22.984882       1 cache.go:1581] "SnapShot for scheduling" jobNum=0 QueueNum=2 NodeNum=1
I0731 07:37:22.984922       1 session.go:1036] Start adjusting jobs' network topology spec according to hyperNodeTierNameMap map[]
I0731 07:37:22.984944       1 session.go:1079] Finish adjusting jobs' network topology spec according to hyperNodeTierNameMap map[]
I0731 07:37:22.984969       1 session.go:279] Open Session af2fa790-7e8a-4868-82e3-8b4ffb634b1c with <0> Job and <2> Queues. HyperNodesReadyToSchedule: true
I0731 07:37:22.985432       1 enqueue.go:79] Try to enqueue PodGroup to 0 Queues
I0731 07:37:22.985453       1 allocate.go:138] Try to allocate resource to 0 Queues
I0731 07:37:22.985523       1 session.go:577] Close Session af2fa790-7e8a-4868-82e3-8b4ffb634b1c
I0731 07:37:23.986548       1 cache.go:1581] "SnapShot for scheduling" jobNum=0 QueueNum=2 NodeNum=1
I0731 07:37:23.986591       1 session.go:1036] Start adjusting jobs' network topology spec according to hyperNodeTierNameMap map[]
I0731 07:37:23.986615       1 session.go:1079] Finish adjusting jobs' network topology spec according to hyperNodeTierNameMap map[]
I0731 07:37:23.986638       1 session.go:279] Open Session 7b56b474-6a88-4258-ae23-fb851854ada7 with <0> Job and <2> Queues. HyperNodesReadyToSchedule: true
I0731 07:37:23.987116       1 enqueue.go:79] Try to enqueue PodGroup to 0 Queues
I0731 07:37:23.987138       1 allocate.go:138] Try to allocate resource to 0 Queues
I0731 07:37:23.987207       1 session.go:577] Close Session 7b56b474-6a88-4258-ae23-fb851854ada7
I0731 07:37:24.987895       1 cache.go:1581] "SnapShot for scheduling" jobNum=0 QueueNum=2 NodeNum=1
I0731 07:37:24.987946       1 session.go:1036] Start adjusting jobs' network topology spec according to hyperNodeTierNameMap map[]
I0731 07:37:24.987970       1 session.go:1079] Finish adjusting jobs' network topology spec according to hyperNodeTierNameMap map[]
I0731 07:37:24.987994       1 session.go:279] Open Session 94ca951a-41ac-4828-b479-8ac2c35eaabe with <0> Job and <2> Queues. HyperNodesReadyToSchedule: true
I0731 07:37:24.988511       1 enqueue.go:79] Try to enqueue PodGroup to 0 Queues
I0731 07:37:24.988533       1 allocate.go:138] Try to allocate resource to 0 Queues
I0731 07:37:24.988616       1 session.go:577] Close Session 94ca951a-41ac-4828-b479-8ac2c35eaabe
I0731 07:37:25.989266       1 cache.go:1581] "SnapShot for scheduling" jobNum=0 QueueNum=2 NodeNum=1
I0731 07:37:25.989311       1 session.go:1036] Start adjusting jobs' network topology spec according to hyperNodeTierNameMap map[]
I0731 07:37:25.989335       1 session.go:1079] Finish adjusting jobs' network topology spec according to hyperNodeTierNameMap map[]
I0731 07:37:25.989359       1 session.go:279] Open Session 798c9b11-116c-4db4-b669-949a818485ae with <0> Job and <2> Queues. HyperNodesReadyToSchedule: true
I0731 07:37:25.989838       1 enqueue.go:79] Try to enqueue PodGroup to 0 Queues
I0731 07:37:25.989863       1 allocate.go:138] Try to allocate resource to 0 Queues
I0731 07:37:25.989940       1 session.go:577] Close Session 798c9b11-116c-4db4-b669-949a818485ae
I0731 07:37:26.990501       1 cache.go:1581] "SnapShot for scheduling" jobNum=0 QueueNum=2 NodeNum=1
I0731 07:37:26.990535       1 session.go:1036] Start adjusting jobs' network topology spec according to hyperNodeTierNameMap map[]
I0731 07:37:26.990552       1 session.go:1079] Finish adjusting jobs' network topology spec according to hyperNodeTierNameMap map[]
I0731 07:37:26.990578       1 session.go:279] Open Session b22d4718-1b4d-415b-98a6-6e0df8848163 with <0> Job and <2> Queues. HyperNodesReadyToSchedule: true
I0731 07:37:26.990961       1 enqueue.go:79] Try to enqueue PodGroup to 0 Queues
I0731 07:37:26.990980       1 allocate.go:138] Try to allocate resource to 0 Queues
I0731 07:37:26.991042       1 session.go:577] Close Session b22d4718-1b4d-415b-98a6-6e0df8848163
I0731 07:37:27.991700       1 cache.go:1581] "SnapShot for scheduling" jobNum=0 QueueNum=2 NodeNum=1
I0731 07:37:27.991731       1 session.go:1036] Start adjusting jobs' network topology spec according to hyperNodeTierNameMap map[]
I0731 07:37:27.991749       1 session.go:1079] Finish adjusting jobs' network topology spec according to hyperNodeTierNameMap map[]
I0731 07:37:27.991771       1 session.go:279] Open Session afa963ca-a76c-4af9-9e88-da8adc3766ce with <0> Job and <2> Queues. HyperNodesReadyToSchedule: true
I0731 07:37:27.992139       1 enqueue.go:79] Try to enqueue PodGroup to 0 Queues
I0731 07:37:27.992158       1 allocate.go:138] Try to allocate resource to 0 Queues
I0731 07:37:27.992221       1 session.go:577] Close Session afa963ca-a76c-4af9-9e88-da8adc3766ce
I0731 07:37:28.992556       1 cache.go:1581] "SnapShot for scheduling" jobNum=0 QueueNum=2 NodeNum=1
I0731 07:37:28.992604       1 session.go:1036] Start adjusting jobs' network topology spec according to hyperNodeTierNameMap map[]
I0731 07:37:28.992626       1 session.go:1079] Finish adjusting jobs' network topology spec according to hyperNodeTierNameMap map[]
I0731 07:37:28.992650       1 session.go:279] Open Session 48c78367-442f-41a8-b14c-7cbfc2a416c8 with <0> Job and <2> Queues. HyperNodesReadyToSchedule: true
I0731 07:37:28.993167       1 enqueue.go:79] Try to enqueue PodGroup to 0 Queues
I0731 07:37:28.993190       1 allocate.go:138] Try to allocate resource to 0 Queues
I0731 07:37:28.993267       1 session.go:577] Close Session 48c78367-442f-41a8-b14c-7cbfc2a416c8
I0731 07:37:29.994360       1 cache.go:1581] "SnapShot for scheduling" jobNum=0 QueueNum=2 NodeNum=1
I0731 07:37:29.994404       1 session.go:1036] Start adjusting jobs' network topology spec according to hyperNodeTierNameMap map[]
I0731 07:37:29.994427       1 session.go:1079] Finish adjusting jobs' network topology spec according to hyperNodeTierNameMap map[]
I0731 07:37:29.994451       1 session.go:279] Open Session d9848ad9-5f6a-41a8-a1f1-9f05b57555d5 with <0> Job and <2> Queues. HyperNodesReadyToSchedule: true
I0731 07:37:29.994918       1 enqueue.go:79] Try to enqueue PodGroup to 0 Queues
I0731 07:37:29.994941       1 allocate.go:138] Try to allocate resource to 0 Queues
I0731 07:37:29.995015       1 session.go:577] Close Session d9848ad9-5f6a-41a8-a1f1-9f05b57555d5
I0731 07:37:30.995663       1 cache.go:1581] "SnapShot for scheduling" jobNum=0 QueueNum=2 NodeNum=1
I0731 07:37:30.995720       1 session.go:1036] Start adjusting jobs' network topology spec according to hyperNodeTierNameMap map[]
I0731 07:37:30.995748       1 session.go:1079] Finish adjusting jobs' network topology spec according to hyperNodeTierNameMap map[]
I0731 07:37:30.995774       1 session.go:279] Open Session 71da6db0-9496-4cfc-a69f-048a5e4bce1b with <0> Job and <2> Queues. HyperNodesReadyToSchedule: true
I0731 07:37:30.996302       1 enqueue.go:79] Try to enqueue PodGroup to 0 Queues
I0731 07:37:30.996327       1 allocate.go:138] Try to allocate resource to 0 Queues
I0731 07:37:30.996414       1 session.go:577] Close Session 71da6db0-9496-4cfc-a69f-048a5e4bce1b
I0731 07:37:31.996852       1 cache.go:1581] "SnapShot for scheduling" jobNum=0 QueueNum=2 NodeNum=1
I0731 07:37:31.996900       1 session.go:1036] Start adjusting jobs' network topology spec according to hyperNodeTierNameMap map[]
I0731 07:37:31.996923       1 session.go:1079] Finish adjusting jobs' network topology spec according to hyperNodeTierNameMap map[]
I0731 07:37:31.996949       1 session.go:279] Open Session 1cf4c566-f49b-46b8-83fb-f3da0a1cfb8b with <0> Job and <2> Queues. HyperNodesReadyToSchedule: true
I0731 07:37:31.997402       1 enqueue.go:79] Try to enqueue PodGroup to 0 Queues
I0731 07:37:31.997425       1 allocate.go:138] Try to allocate resource to 0 Queues
I0731 07:37:31.997506       1 session.go:577] Close Session 1cf4c566-f49b-46b8-83fb-f3da0a1cfb8b
I0731 07:37:32.998139       1 cache.go:1581] "SnapShot for scheduling" jobNum=0 QueueNum=2 NodeNum=1
I0731 07:37:32.998175       1 session.go:1036] Start adjusting jobs' network topology spec according to hyperNodeTierNameMap map[]
I0731 07:37:32.998196       1 session.go:1079] Finish adjusting jobs' network topology spec according to hyperNodeTierNameMap map[]
I0731 07:37:32.998219       1 session.go:279] Open Session 132e69ac-293f-4d69-9dd3-3eda8c8b83c7 with <0> Job and <2> Queues. HyperNodesReadyToSchedule: true
I0731 07:37:32.998645       1 enqueue.go:79] Try to enqueue PodGroup to 0 Queues
I0731 07:37:32.998666       1 allocate.go:138] Try to allocate resource to 0 Queues
I0731 07:37:32.998749       1 session.go:577] Close Session 132e69ac-293f-4d69-9dd3-3eda8c8b83c7
I0731 07:37:33.999461       1 cache.go:1581] "SnapShot for scheduling" jobNum=0 QueueNum=2 NodeNum=1
I0731 07:37:33.999512       1 session.go:1036] Start adjusting jobs' network topology spec according to hyperNodeTierNameMap map[]
I0731 07:37:33.999539       1 session.go:1079] Finish adjusting jobs' network topology spec according to hyperNodeTierNameMap map[]
I0731 07:37:33.999563       1 session.go:279] Open Session 5004708e-6f26-4941-8d44-db5582bdc0ed with <0> Job and <2> Queues. HyperNodesReadyToSchedule: true
I0731 07:37:34.000140       1 enqueue.go:79] Try to enqueue PodGroup to 0 Queues
I0731 07:37:34.000166       1 allocate.go:138] Try to allocate resource to 0 Queues
I0731 07:37:34.000253       1 session.go:577] Close Session 5004708e-6f26-4941-8d44-db5582bdc0ed
I0731 07:37:35.001380       1 cache.go:1581] "SnapShot for scheduling" jobNum=0 QueueNum=2 NodeNum=1
I0731 07:37:35.001427       1 session.go:1036] Start adjusting jobs' network topology spec according to hyperNodeTierNameMap map[]
I0731 07:37:35.001453       1 session.go:1079] Finish adjusting jobs' network topology spec according to hyperNodeTierNameMap map[]
I0731 07:37:35.001477       1 session.go:279] Open Session ff0766fb-3534-4234-b939-aae314f64b09 with <0> Job and <2> Queues. HyperNodesReadyToSchedule: true
I0731 07:37:35.001988       1 enqueue.go:79] Try to enqueue PodGroup to 0 Queues
I0731 07:37:35.002012       1 allocate.go:138] Try to allocate resource to 0 Queues
I0731 07:37:35.002090       1 session.go:577] Close Session ff0766fb-3534-4234-b939-aae314f64b09
I0731 07:37:36.002436       1 cache.go:1581] "SnapShot for scheduling" jobNum=0 QueueNum=2 NodeNum=1
I0731 07:37:36.002481       1 session.go:1036] Start adjusting jobs' network topology spec according to hyperNodeTierNameMap map[]
I0731 07:37:36.002507       1 session.go:1079] Finish adjusting jobs' network topology spec according to hyperNodeTierNameMap map[]
I0731 07:37:36.002536       1 session.go:279] Open Session 01a79a7e-ca4a-4346-ad4d-be4d8174b4b3 with <0> Job and <2> Queues. HyperNodesReadyToSchedule: true
I0731 07:37:36.003037       1 enqueue.go:79] Try to enqueue PodGroup to 0 Queues
I0731 07:37:36.003061       1 allocate.go:138] Try to allocate resource to 0 Queues
I0731 07:37:36.003136       1 session.go:577] Close Session 01a79a7e-ca4a-4346-ad4d-be4d8174b4b3
I0731 07:37:37.003834       1 cache.go:1581] "SnapShot for scheduling" jobNum=0 QueueNum=2 NodeNum=1
I0731 07:37:37.003875       1 session.go:1036] Start adjusting jobs' network topology spec according to hyperNodeTierNameMap map[]
I0731 07:37:37.003900       1 session.go:1079] Finish adjusting jobs' network topology spec according to hyperNodeTierNameMap map[]
I0731 07:37:37.003925       1 session.go:279] Open Session f8946e91-8400-47d6-8b61-a0c1edcfdf90 with <0> Job and <2> Queues. HyperNodesReadyToSchedule: true
I0731 07:37:37.004358       1 enqueue.go:79] Try to enqueue PodGroup to 0 Queues
I0731 07:37:37.004380       1 allocate.go:138] Try to allocate resource to 0 Queues
I0731 07:37:37.004455       1 session.go:577] Close Session f8946e91-8400-47d6-8b61-a0c1edcfdf90
I0731 07:37:38.005810       1 cache.go:1581] "SnapShot for scheduling" jobNum=0 QueueNum=2 NodeNum=1
I0731 07:37:38.005855       1 session.go:1036] Start adjusting jobs' network topology spec according to hyperNodeTierNameMap map[]
I0731 07:37:38.005877       1 session.go:1079] Finish adjusting jobs' network topology spec according to hyperNodeTierNameMap map[]
I0731 07:37:38.005901       1 session.go:279] Open Session 6e8461b5-7b44-433c-8779-96ab131af10d with <0> Job and <2> Queues. HyperNodesReadyToSchedule: true
I0731 07:37:38.006356       1 enqueue.go:79] Try to enqueue PodGroup to 0 Queues
I0731 07:37:38.006378       1 allocate.go:138] Try to allocate resource to 0 Queues
I0731 07:37:38.006451       1 session.go:577] Close Session 6e8461b5-7b44-433c-8779-96ab131af10d
I0731 07:37:39.007805       1 cache.go:1581] "SnapShot for scheduling" jobNum=0 QueueNum=2 NodeNum=1
I0731 07:37:39.007852       1 session.go:1036] Start adjusting jobs' network topology spec according to hyperNodeTierNameMap map[]
I0731 07:37:39.007875       1 session.go:1079] Finish adjusting jobs' network topology spec according to hyperNodeTierNameMap map[]
I0731 07:37:39.007899       1 session.go:279] Open Session b00ccdda-d68f-4fe7-bb9a-166dd00071f4 with <0> Job and <2> Queues. HyperNodesReadyToSchedule: true
I0731 07:37:39.008300       1 enqueue.go:79] Try to enqueue PodGroup to 0 Queues
I0731 07:37:39.008321       1 allocate.go:138] Try to allocate resource to 0 Queues
I0731 07:37:39.008388       1 session.go:577] Close Session b00ccdda-d68f-4fe7-bb9a-166dd00071f4
I0731 07:37:40.009675       1 cache.go:1581] "SnapShot for scheduling" jobNum=0 QueueNum=2 NodeNum=1
I0731 07:37:40.009718       1 session.go:1036] Start adjusting jobs' network topology spec according to hyperNodeTierNameMap map[]
I0731 07:37:40.009740       1 session.go:1079] Finish adjusting jobs' network topology spec according to hyperNodeTierNameMap map[]
I0731 07:37:40.009764       1 session.go:279] Open Session 8946aca5-2977-4606-8598-ff2434061e15 with <0> Job and <2> Queues. HyperNodesReadyToSchedule: true
I0731 07:37:40.010184       1 enqueue.go:79] Try to enqueue PodGroup to 0 Queues
I0731 07:37:40.010206       1 allocate.go:138] Try to allocate resource to 0 Queues
I0731 07:37:40.010278       1 session.go:577] Close Session 8946aca5-2977-4606-8598-ff2434061e15
I0731 07:37:41.010872       1 cache.go:1581] "SnapShot for scheduling" jobNum=0 QueueNum=2 NodeNum=1
I0731 07:37:41.010913       1 session.go:1036] Start adjusting jobs' network topology spec according to hyperNodeTierNameMap map[]
I0731 07:37:41.010936       1 session.go:1079] Finish adjusting jobs' network topology spec according to hyperNodeTierNameMap map[]
I0731 07:37:41.010959       1 session.go:279] Open Session 838216ec-56c7-4e14-b4ad-211513d305f5 with <0> Job and <2> Queues. HyperNodesReadyToSchedule: true
I0731 07:37:41.011442       1 enqueue.go:79] Try to enqueue PodGroup to 0 Queues
I0731 07:37:41.011465       1 allocate.go:138] Try to allocate resource to 0 Queues
I0731 07:37:41.011538       1 session.go:577] Close Session 838216ec-56c7-4e14-b4ad-211513d305f5
I0731 07:37:42.012761       1 cache.go:1581] "SnapShot for scheduling" jobNum=0 QueueNum=2 NodeNum=1
I0731 07:37:42.012805       1 session.go:1036] Start adjusting jobs' network topology spec according to hyperNodeTierNameMap map[]
I0731 07:37:42.012828       1 session.go:1079] Finish adjusting jobs' network topology spec according to hyperNodeTierNameMap map[]
I0731 07:37:42.012851       1 session.go:279] Open Session e17cf99a-2b10-407a-a87e-4e6f1277efc4 with <0> Job and <2> Queues. HyperNodesReadyToSchedule: true
I0731 07:37:42.013289       1 enqueue.go:79] Try to enqueue PodGroup to 0 Queues
I0731 07:37:42.013314       1 allocate.go:138] Try to allocate resource to 0 Queues
I0731 07:37:42.013388       1 session.go:577] Close Session e17cf99a-2b10-407a-a87e-4e6f1277efc4
I0731 07:37:43.013724       1 cache.go:1581] "SnapShot for scheduling" jobNum=0 QueueNum=2 NodeNum=1
I0731 07:37:43.013767       1 session.go:1036] Start adjusting jobs' network topology spec according to hyperNodeTierNameMap map[]
I0731 07:37:43.013790       1 session.go:1079] Finish adjusting jobs' network topology spec according to hyperNodeTierNameMap map[]
I0731 07:37:43.013814       1 session.go:279] Open Session 3c5ec11f-5efb-4f74-8bab-00536e306f31 with <0> Job and <2> Queues. HyperNodesReadyToSchedule: true
I0731 07:37:43.014284       1 enqueue.go:79] Try to enqueue PodGroup to 0 Queues
I0731 07:37:43.014307       1 allocate.go:138] Try to allocate resource to 0 Queues
I0731 07:37:43.014382       1 session.go:577] Close Session 3c5ec11f-5efb-4f74-8bab-00536e306f31
I0731 07:37:44.015645       1 cache.go:1581] "SnapShot for scheduling" jobNum=0 QueueNum=2 NodeNum=1
I0731 07:37:44.015686       1 session.go:1036] Start adjusting jobs' network topology spec according to hyperNodeTierNameMap map[]
I0731 07:37:44.015709       1 session.go:1079] Finish adjusting jobs' network topology spec according to hyperNodeTierNameMap map[]
I0731 07:37:44.015733       1 session.go:279] Open Session 0c002f4d-5540-4a64-bb25-f2da39d46e4d with <0> Job and <2> Queues. HyperNodesReadyToSchedule: true
I0731 07:37:44.016176       1 enqueue.go:79] Try to enqueue PodGroup to 0 Queues
I0731 07:37:44.016199       1 allocate.go:138] Try to allocate resource to 0 Queues
I0731 07:37:44.016276       1 session.go:577] Close Session 0c002f4d-5540-4a64-bb25-f2da39d46e4d
I0731 07:37:45.017568       1 cache.go:1581] "SnapShot for scheduling" jobNum=0 QueueNum=2 NodeNum=1
I0731 07:37:45.017612       1 session.go:1036] Start adjusting jobs' network topology spec according to hyperNodeTierNameMap map[]
I0731 07:37:45.017635       1 session.go:1079] Finish adjusting jobs' network topology spec according to hyperNodeTierNameMap map[]
I0731 07:37:45.017660       1 session.go:279] Open Session fc8a07d5-2ab0-4297-a995-1d8042bf46e8 with <0> Job and <2> Queues. HyperNodesReadyToSchedule: true
I0731 07:37:45.018120       1 enqueue.go:79] Try to enqueue PodGroup to 0 Queues
I0731 07:37:45.018142       1 allocate.go:138] Try to allocate resource to 0 Queues
I0731 07:37:45.018211       1 session.go:577] Close Session fc8a07d5-2ab0-4297-a995-1d8042bf46e8
I0731 07:37:46.019342       1 cache.go:1581] "SnapShot for scheduling" jobNum=0 QueueNum=2 NodeNum=1
I0731 07:37:46.019385       1 session.go:1036] Start adjusting jobs' network topology spec according to hyperNodeTierNameMap map[]
I0731 07:37:46.019409       1 session.go:1079] Finish adjusting jobs' network topology spec according to hyperNodeTierNameMap map[]
I0731 07:37:46.019432       1 session.go:279] Open Session 687aa7cc-94fd-481a-b44b-59829d24dafd with <0> Job and <2> Queues. HyperNodesReadyToSchedule: true
I0731 07:37:46.019899       1 enqueue.go:79] Try to enqueue PodGroup to 0 Queues
I0731 07:37:46.019922       1 allocate.go:138] Try to allocate resource to 0 Queues
I0731 07:37:46.019991       1 session.go:577] Close Session 687aa7cc-94fd-481a-b44b-59829d24dafd
I0731 07:37:46.489077       1 cache.go:1771] The metrics type is not set in the volcano scheduler configmap file. As a result, the CPU and memory load information of the node is not collected.
I0731 07:37:47.020654       1 cache.go:1581] "SnapShot for scheduling" jobNum=0 QueueNum=2 NodeNum=1
I0731 07:37:47.020698       1 session.go:1036] Start adjusting jobs' network topology spec according to hyperNodeTierNameMap map[]
I0731 07:37:47.020721       1 session.go:1079] Finish adjusting jobs' network topology spec according to hyperNodeTierNameMap map[]
I0731 07:37:47.020745       1 session.go:279] Open Session 7e3de8cf-3a56-4f0b-9404-6db3748fa7ce with <0> Job and <2> Queues. HyperNodesReadyToSchedule: true
I0731 07:37:47.021189       1 enqueue.go:79] Try to enqueue PodGroup to 0 Queues
I0731 07:37:47.021211       1 allocate.go:138] Try to allocate resource to 0 Queues
I0731 07:37:47.021282       1 session.go:577] Close Session 7e3de8cf-3a56-4f0b-9404-6db3748fa7ce
I0731 07:37:48.022499       1 cache.go:1581] "SnapShot for scheduling" jobNum=0 QueueNum=2 NodeNum=1
I0731 07:37:48.022534       1 session.go:1036] Start adjusting jobs' network topology spec according to hyperNodeTierNameMap map[]
I0731 07:37:48.022558       1 session.go:1079] Finish adjusting jobs' network topology spec according to hyperNodeTierNameMap map[]
I0731 07:37:48.022581       1 session.go:279] Open Session 2d27170a-2547-44bd-9985-49fc03031ba8 with <0> Job and <2> Queues. HyperNodesReadyToSchedule: true
I0731 07:37:48.023061       1 enqueue.go:79] Try to enqueue PodGroup to 0 Queues
I0731 07:37:48.023085       1 allocate.go:138] Try to allocate resource to 0 Queues
I0731 07:37:48.023153       1 session.go:577] Close Session 2d27170a-2547-44bd-9985-49fc03031ba8
I0731 07:37:49.024269       1 cache.go:1581] "SnapShot for scheduling" jobNum=0 QueueNum=2 NodeNum=1
I0731 07:37:49.024312       1 session.go:1036] Start adjusting jobs' network topology spec according to hyperNodeTierNameMap map[]
I0731 07:37:49.024336       1 session.go:1079] Finish adjusting jobs' network topology spec according to hyperNodeTierNameMap map[]
I0731 07:37:49.024360       1 session.go:279] Open Session aabe496a-9872-483a-899a-17758a2e9a5b with <0> Job and <2> Queues. HyperNodesReadyToSchedule: true
I0731 07:37:49.024798       1 enqueue.go:79] Try to enqueue PodGroup to 0 Queues
I0731 07:37:49.024820       1 allocate.go:138] Try to allocate resource to 0 Queues
I0731 07:37:49.024890       1 session.go:577] Close Session aabe496a-9872-483a-899a-17758a2e9a5b
I0731 07:37:50.025952       1 cache.go:1581] "SnapShot for scheduling" jobNum=0 QueueNum=2 NodeNum=1
I0731 07:37:50.025994       1 session.go:1036] Start adjusting jobs' network topology spec according to hyperNodeTierNameMap map[]
I0731 07:37:50.026016       1 session.go:1079] Finish adjusting jobs' network topology spec according to hyperNodeTierNameMap map[]
I0731 07:37:50.026040       1 session.go:279] Open Session d722b97d-dafd-401e-a9b2-5d446ad95a52 with <0> Job and <2> Queues. HyperNodesReadyToSchedule: true
I0731 07:37:50.026487       1 enqueue.go:79] Try to enqueue PodGroup to 0 Queues
I0731 07:37:50.026512       1 allocate.go:138] Try to allocate resource to 0 Queues
I0731 07:37:50.026586       1 session.go:577] Close Session d722b97d-dafd-401e-a9b2-5d446ad95a52
I0731 07:37:51.027762       1 cache.go:1581] "SnapShot for scheduling" jobNum=0 QueueNum=2 NodeNum=1
I0731 07:37:51.027802       1 session.go:1036] Start adjusting jobs' network topology spec according to hyperNodeTierNameMap map[]
I0731 07:37:51.027824       1 session.go:1079] Finish adjusting jobs' network topology spec according to hyperNodeTierNameMap map[]
I0731 07:37:51.027850       1 session.go:279] Open Session 2a83766a-9688-4fc0-9a5b-f7a6034c4677 with <0> Job and <2> Queues. HyperNodesReadyToSchedule: true
I0731 07:37:51.028280       1 enqueue.go:79] Try to enqueue PodGroup to 0 Queues
I0731 07:37:51.028305       1 allocate.go:138] Try to allocate resource to 0 Queues
I0731 07:37:51.028378       1 session.go:577] Close Session 2a83766a-9688-4fc0-9a5b-f7a6034c4677
I0731 07:37:52.029470       1 cache.go:1581] "SnapShot for scheduling" jobNum=0 QueueNum=2 NodeNum=1
I0731 07:37:52.029508       1 session.go:1036] Start adjusting jobs' network topology spec according to hyperNodeTierNameMap map[]
I0731 07:37:52.029529       1 session.go:1079] Finish adjusting jobs' network topology spec according to hyperNodeTierNameMap map[]
I0731 07:37:52.029554       1 session.go:279] Open Session 4f84f3a9-c691-4374-b26b-9183b0442c6b with <0> Job and <2> Queues. HyperNodesReadyToSchedule: true
I0731 07:37:52.029990       1 enqueue.go:79] Try to enqueue PodGroup to 0 Queues
I0731 07:37:52.030040       1 allocate.go:138] Try to allocate resource to 0 Queues
I0731 07:37:52.030113       1 session.go:577] Close Session 4f84f3a9-c691-4374-b26b-9183b0442c6b
I0731 07:37:53.031372       1 cache.go:1581] "SnapShot for scheduling" jobNum=0 QueueNum=2 NodeNum=1
I0731 07:37:53.031408       1 session.go:1036] Start adjusting jobs' network topology spec according to hyperNodeTierNameMap map[]
I0731 07:37:53.031429       1 session.go:1079] Finish adjusting jobs' network topology spec according to hyperNodeTierNameMap map[]
I0731 07:37:53.031452       1 session.go:279] Open Session e7d43fd3-22b7-44cf-8b7f-fec21dbb7411 with <0> Job and <2> Queues. HyperNodesReadyToSchedule: true
I0731 07:37:53.031871       1 enqueue.go:79] Try to enqueue PodGroup to 0 Queues
I0731 07:37:53.031893       1 allocate.go:138] Try to allocate resource to 0 Queues
I0731 07:37:53.031961       1 session.go:577] Close Session e7d43fd3-22b7-44cf-8b7f-fec21dbb7411
I0731 07:37:54.032916       1 cache.go:1581] "SnapShot for scheduling" jobNum=0 QueueNum=2 NodeNum=1
I0731 07:37:54.032954       1 session.go:1036] Start adjusting jobs' network topology spec according to hyperNodeTierNameMap map[]
I0731 07:37:54.032975       1 session.go:1079] Finish adjusting jobs' network topology spec according to hyperNodeTierNameMap map[]
I0731 07:37:54.032999       1 session.go:279] Open Session 525e99aa-9f3e-4503-86e9-de30785b4848 with <0> Job and <2> Queues. HyperNodesReadyToSchedule: true
I0731 07:37:54.033411       1 enqueue.go:79] Try to enqueue PodGroup to 0 Queues
I0731 07:37:54.033430       1 allocate.go:138] Try to allocate resource to 0 Queues
I0731 07:37:54.033497       1 session.go:577] Close Session 525e99aa-9f3e-4503-86e9-de30785b4848
I0731 07:37:55.034592       1 cache.go:1581] "SnapShot for scheduling" jobNum=0 QueueNum=2 NodeNum=1
I0731 07:37:55.034640       1 session.go:1036] Start adjusting jobs' network topology spec according to hyperNodeTierNameMap map[]
I0731 07:37:55.034664       1 session.go:1079] Finish adjusting jobs' network topology spec according to hyperNodeTierNameMap map[]
I0731 07:37:55.034687       1 session.go:279] Open Session c076b7f7-eb26-4e62-918d-5616f393638d with <0> Job and <2> Queues. HyperNodesReadyToSchedule: true
I0731 07:37:55.035155       1 enqueue.go:79] Try to enqueue PodGroup to 0 Queues
I0731 07:37:55.035180       1 allocate.go:138] Try to allocate resource to 0 Queues
I0731 07:37:55.035258       1 session.go:577] Close Session c076b7f7-eb26-4e62-918d-5616f393638d
I0731 07:37:56.036074       1 cache.go:1581] "SnapShot for scheduling" jobNum=0 QueueNum=2 NodeNum=1
I0731 07:37:56.036123       1 session.go:1036] Start adjusting jobs' network topology spec according to hyperNodeTierNameMap map[]
I0731 07:37:56.036146       1 session.go:1079] Finish adjusting jobs' network topology spec according to hyperNodeTierNameMap map[]
I0731 07:37:56.036169       1 session.go:279] Open Session 7f95612f-66b4-4a27-892b-c6ad02c6e8b6 with <0> Job and <2> Queues. HyperNodesReadyToSchedule: true
I0731 07:37:56.036712       1 enqueue.go:79] Try to enqueue PodGroup to 0 Queues
I0731 07:37:56.036736       1 allocate.go:138] Try to allocate resource to 0 Queues
I0731 07:37:56.036815       1 session.go:577] Close Session 7f95612f-66b4-4a27-892b-c6ad02c6e8b6
I0731 07:37:57.037838       1 cache.go:1581] "SnapShot for scheduling" jobNum=0 QueueNum=2 NodeNum=1
I0731 07:37:57.037881       1 session.go:1036] Start adjusting jobs' network topology spec according to hyperNodeTierNameMap map[]
I0731 07:37:57.037904       1 session.go:1079] Finish adjusting jobs' network topology spec according to hyperNodeTierNameMap map[]
I0731 07:37:57.037929       1 session.go:279] Open Session b209b711-e6da-4a58-afe4-c18bae19e505 with <0> Job and <2> Queues. HyperNodesReadyToSchedule: true
I0731 07:37:57.038378       1 enqueue.go:79] Try to enqueue PodGroup to 0 Queues
I0731 07:37:57.038402       1 allocate.go:138] Try to allocate resource to 0 Queues
I0731 07:37:57.038484       1 session.go:577] Close Session b209b711-e6da-4a58-afe4-c18bae19e505
I0731 07:37:58.038858       1 cache.go:1581] "SnapShot for scheduling" jobNum=0 QueueNum=2 NodeNum=1
I0731 07:37:58.038902       1 session.go:1036] Start adjusting jobs' network topology spec according to hyperNodeTierNameMap map[]
I0731 07:37:58.038926       1 session.go:1079] Finish adjusting jobs' network topology spec according to hyperNodeTierNameMap map[]
I0731 07:37:58.038949       1 session.go:279] Open Session 7498ffef-4b87-43e3-b2b8-2f649a3fb985 with <0> Job and <2> Queues. HyperNodesReadyToSchedule: true
I0731 07:37:58.039449       1 enqueue.go:79] Try to enqueue PodGroup to 0 Queues
I0731 07:37:58.039472       1 allocate.go:138] Try to allocate resource to 0 Queues
I0731 07:37:58.039549       1 session.go:577] Close Session 7498ffef-4b87-43e3-b2b8-2f649a3fb985
I0731 07:37:59.040906       1 cache.go:1581] "SnapShot for scheduling" jobNum=0 QueueNum=2 NodeNum=1
I0731 07:37:59.040952       1 session.go:1036] Start adjusting jobs' network topology spec according to hyperNodeTierNameMap map[]
I0731 07:37:59.040976       1 session.go:1079] Finish adjusting jobs' network topology spec according to hyperNodeTierNameMap map[]
I0731 07:37:59.041003       1 session.go:279] Open Session 2cb861d0-3434-46ba-a456-eb582a2f5c7e with <0> Job and <2> Queues. HyperNodesReadyToSchedule: true
I0731 07:37:59.042428       1 enqueue.go:79] Try to enqueue PodGroup to 0 Queues
I0731 07:37:59.042467       1 allocate.go:138] Try to allocate resource to 0 Queues
I0731 07:37:59.042918       1 session.go:577] Close Session 2cb861d0-3434-46ba-a456-eb582a2f5c7e
I0731 07:38:00.044233       1 cache.go:1581] "SnapShot for scheduling" jobNum=0 QueueNum=2 NodeNum=1
I0731 07:38:00.044289       1 session.go:1036] Start adjusting jobs' network topology spec according to hyperNodeTierNameMap map[]
I0731 07:38:00.044315       1 session.go:1079] Finish adjusting jobs' network topology spec according to hyperNodeTierNameMap map[]
I0731 07:38:00.044337       1 session.go:279] Open Session 28d14414-f49c-4ddc-8167-e9d9f42a822b with <0> Job and <2> Queues. HyperNodesReadyToSchedule: true
I0731 07:38:00.044829       1 enqueue.go:79] Try to enqueue PodGroup to 0 Queues
I0731 07:38:00.044854       1 allocate.go:138] Try to allocate resource to 0 Queues
I0731 07:38:00.044933       1 session.go:577] Close Session 28d14414-f49c-4ddc-8167-e9d9f42a822b
I0731 07:38:01.045546       1 cache.go:1581] "SnapShot for scheduling" jobNum=0 QueueNum=2 NodeNum=1
I0731 07:38:01.045582       1 session.go:1036] Start adjusting jobs' network topology spec according to hyperNodeTierNameMap map[]
I0731 07:38:01.045601       1 session.go:1079] Finish adjusting jobs' network topology spec according to hyperNodeTierNameMap map[]
I0731 07:38:01.045624       1 session.go:279] Open Session ea47278a-49f7-49aa-8dfe-86a7b2eaf132 with <0> Job and <2> Queues. HyperNodesReadyToSchedule: true
I0731 07:38:01.046046       1 enqueue.go:79] Try to enqueue PodGroup to 0 Queues
I0731 07:38:01.046067       1 allocate.go:138] Try to allocate resource to 0 Queues
I0731 07:38:01.046129       1 session.go:577] Close Session ea47278a-49f7-49aa-8dfe-86a7b2eaf132
I0731 07:38:02.047502       1 cache.go:1581] "SnapShot for scheduling" jobNum=0 QueueNum=2 NodeNum=1
I0731 07:38:02.047547       1 session.go:1036] Start adjusting jobs' network topology spec according to hyperNodeTierNameMap map[]
I0731 07:38:02.047571       1 session.go:1079] Finish adjusting jobs' network topology spec according to hyperNodeTierNameMap map[]
I0731 07:38:02.047595       1 session.go:279] Open Session 6372a430-e097-4539-b62a-7f1394a62bf9 with <0> Job and <2> Queues. HyperNodesReadyToSchedule: true
I0731 07:38:02.048069       1 enqueue.go:79] Try to enqueue PodGroup to 0 Queues
I0731 07:38:02.048092       1 allocate.go:138] Try to allocate resource to 0 Queues
I0731 07:38:02.048173       1 session.go:577] Close Session 6372a430-e097-4539-b62a-7f1394a62bf9
I0731 07:38:03.048993       1 cache.go:1581] "SnapShot for scheduling" jobNum=0 QueueNum=2 NodeNum=1
I0731 07:38:03.049021       1 session.go:1036] Start adjusting jobs' network topology spec according to hyperNodeTierNameMap map[]
I0731 07:38:03.049031       1 session.go:1079] Finish adjusting jobs' network topology spec according to hyperNodeTierNameMap map[]
I0731 07:38:03.049040       1 session.go:279] Open Session c7217e3e-c973-40cf-a8ca-e272883ca817 with <0> Job and <2> Queues. HyperNodesReadyToSchedule: true
I0731 07:38:03.049352       1 enqueue.go:79] Try to enqueue PodGroup to 0 Queues
I0731 07:38:03.049363       1 allocate.go:138] Try to allocate resource to 0 Queues
I0731 07:38:03.049403       1 session.go:577] Close Session c7217e3e-c973-40cf-a8ca-e272883ca817
I0731 07:38:04.050465       1 cache.go:1581] "SnapShot for scheduling" jobNum=0 QueueNum=2 NodeNum=1
I0731 07:38:04.050505       1 session.go:1036] Start adjusting jobs' network topology spec according to hyperNodeTierNameMap map[]
I0731 07:38:04.050529       1 session.go:1079] Finish adjusting jobs' network topology spec according to hyperNodeTierNameMap map[]
I0731 07:38:04.050552       1 session.go:279] Open Session 2745cd92-84de-46b1-9bc3-b92a18f33f44 with <0> Job and <2> Queues. HyperNodesReadyToSchedule: true
I0731 07:38:04.051096       1 enqueue.go:79] Try to enqueue PodGroup to 0 Queues
I0731 07:38:04.051118       1 allocate.go:138] Try to allocate resource to 0 Queues
I0731 07:38:04.051189       1 session.go:577] Close Session 2745cd92-84de-46b1-9bc3-b92a18f33f44
I0731 07:38:05.052580       1 cache.go:1581] "SnapShot for scheduling" jobNum=0 QueueNum=2 NodeNum=1
I0731 07:38:05.052621       1 session.go:1036] Start adjusting jobs' network topology spec according to hyperNodeTierNameMap map[]
I0731 07:38:05.052647       1 session.go:1079] Finish adjusting jobs' network topology spec according to hyperNodeTierNameMap map[]
I0731 07:38:05.052670       1 session.go:279] Open Session a970babc-81de-4c26-a054-9471a76bf1ef with <0> Job and <2> Queues. HyperNodesReadyToSchedule: true
I0731 07:38:05.053243       1 enqueue.go:79] Try to enqueue PodGroup to 0 Queues
I0731 07:38:05.053265       1 allocate.go:138] Try to allocate resource to 0 Queues
I0731 07:38:05.053356       1 session.go:577] Close Session a970babc-81de-4c26-a054-9471a76bf1ef
I0731 07:38:06.054099       1 cache.go:1581] "SnapShot for scheduling" jobNum=0 QueueNum=2 NodeNum=1
I0731 07:38:06.054143       1 session.go:1036] Start adjusting jobs' network topology spec according to hyperNodeTierNameMap map[]
I0731 07:38:06.054166       1 session.go:1079] Finish adjusting jobs' network topology spec according to hyperNodeTierNameMap map[]
I0731 07:38:06.054191       1 session.go:279] Open Session af95ef81-0da4-448f-8186-7412b216e71c with <0> Job and <2> Queues. HyperNodesReadyToSchedule: true
I0731 07:38:06.054829       1 enqueue.go:79] Try to enqueue PodGroup to 0 Queues
I0731 07:38:06.054853       1 allocate.go:138] Try to allocate resource to 0 Queues
I0731 07:38:06.054930       1 session.go:577] Close Session af95ef81-0da4-448f-8186-7412b216e71c
I0731 07:38:07.055480       1 cache.go:1581] "SnapShot for scheduling" jobNum=0 QueueNum=2 NodeNum=1
I0731 07:38:07.055530       1 session.go:1036] Start adjusting jobs' network topology spec according to hyperNodeTierNameMap map[]
I0731 07:38:07.055557       1 session.go:1079] Finish adjusting jobs' network topology spec according to hyperNodeTierNameMap map[]
I0731 07:38:07.055581       1 session.go:279] Open Session bf499678-314c-463d-aaec-2968f571abd1 with <0> Job and <2> Queues. HyperNodesReadyToSchedule: true
I0731 07:38:07.056070       1 enqueue.go:79] Try to enqueue PodGroup to 0 Queues
I0731 07:38:07.056091       1 allocate.go:138] Try to allocate resource to 0 Queues
I0731 07:38:07.056161       1 session.go:577] Close Session bf499678-314c-463d-aaec-2968f571abd1
I0731 07:38:08.057528       1 cache.go:1581] "SnapShot for scheduling" jobNum=0 QueueNum=2 NodeNum=1
I0731 07:38:08.057571       1 session.go:1036] Start adjusting jobs' network topology spec according to hyperNodeTierNameMap map[]
I0731 07:38:08.057595       1 session.go:1079] Finish adjusting jobs' network topology spec according to hyperNodeTierNameMap map[]
I0731 07:38:08.057620       1 session.go:279] Open Session 5112e53b-1909-4fe0-9c49-77ef3537a19d with <0> Job and <2> Queues. HyperNodesReadyToSchedule: true
I0731 07:38:08.058101       1 enqueue.go:79] Try to enqueue PodGroup to 0 Queues
I0731 07:38:08.058124       1 allocate.go:138] Try to allocate resource to 0 Queues
I0731 07:38:08.058198       1 session.go:577] Close Session 5112e53b-1909-4fe0-9c49-77ef3537a19d
I0731 07:38:09.059255       1 cache.go:1581] "SnapShot for scheduling" jobNum=0 QueueNum=2 NodeNum=1
I0731 07:38:09.059303       1 session.go:1036] Start adjusting jobs' network topology spec according to hyperNodeTierNameMap map[]
I0731 07:38:09.059326       1 session.go:1079] Finish adjusting jobs' network topology spec according to hyperNodeTierNameMap map[]
I0731 07:38:09.059349       1 session.go:279] Open Session ad8d371e-0858-42c7-ae0e-4798bf4df186 with <0> Job and <2> Queues. HyperNodesReadyToSchedule: true
I0731 07:38:09.059809       1 enqueue.go:79] Try to enqueue PodGroup to 0 Queues
I0731 07:38:09.059834       1 allocate.go:138] Try to allocate resource to 0 Queues
I0731 07:38:09.059904       1 session.go:577] Close Session ad8d371e-0858-42c7-ae0e-4798bf4df186
I0731 07:38:10.061170       1 cache.go:1581] "SnapShot for scheduling" jobNum=0 QueueNum=2 NodeNum=1
I0731 07:38:10.061213       1 session.go:1036] Start adjusting jobs' network topology spec according to hyperNodeTierNameMap map[]
I0731 07:38:10.061236       1 session.go:1079] Finish adjusting jobs' network topology spec according to hyperNodeTierNameMap map[]
I0731 07:38:10.061259       1 session.go:279] Open Session fe012b26-de6b-457a-a3c0-5bd3a7c5dafe with <0> Job and <2> Queues. HyperNodesReadyToSchedule: true
I0731 07:38:10.061691       1 enqueue.go:79] Try to enqueue PodGroup to 0 Queues
I0731 07:38:10.061712       1 allocate.go:138] Try to allocate resource to 0 Queues
I0731 07:38:10.061784       1 session.go:577] Close Session fe012b26-de6b-457a-a3c0-5bd3a7c5dafe
I0731 07:38:11.063081       1 cache.go:1581] "SnapShot for scheduling" jobNum=0 QueueNum=2 NodeNum=1
I0731 07:38:11.063131       1 session.go:1036] Start adjusting jobs' network topology spec according to hyperNodeTierNameMap map[]
I0731 07:38:11.063155       1 session.go:1079] Finish adjusting jobs' network topology spec according to hyperNodeTierNameMap map[]
I0731 07:38:11.063179       1 session.go:279] Open Session 9fe095f9-395a-47f6-aec5-e267bcd653a9 with <0> Job and <2> Queues. HyperNodesReadyToSchedule: true
I0731 07:38:11.063737       1 enqueue.go:79] Try to enqueue PodGroup to 0 Queues
I0731 07:38:11.063759       1 allocate.go:138] Try to allocate resource to 0 Queues
I0731 07:38:11.063838       1 session.go:577] Close Session 9fe095f9-395a-47f6-aec5-e267bcd653a9
I0731 07:38:12.065087       1 cache.go:1581] "SnapShot for scheduling" jobNum=0 QueueNum=2 NodeNum=1
I0731 07:38:12.065128       1 session.go:1036] Start adjusting jobs' network topology spec according to hyperNodeTierNameMap map[]
I0731 07:38:12.065150       1 session.go:1079] Finish adjusting jobs' network topology spec according to hyperNodeTierNameMap map[]
I0731 07:38:12.065174       1 session.go:279] Open Session 290f0a49-a9e4-4a70-9641-d10744503e12 with <0> Job and <2> Queues. HyperNodesReadyToSchedule: true
I0731 07:38:12.065709       1 enqueue.go:79] Try to enqueue PodGroup to 0 Queues
I0731 07:38:12.065731       1 allocate.go:138] Try to allocate resource to 0 Queues
I0731 07:38:12.065802       1 session.go:577] Close Session 290f0a49-a9e4-4a70-9641-d10744503e12
I0731 07:38:13.067083       1 cache.go:1581] "SnapShot for scheduling" jobNum=0 QueueNum=2 NodeNum=1
I0731 07:38:13.067123       1 session.go:1036] Start adjusting jobs' network topology spec according to hyperNodeTierNameMap map[]
I0731 07:38:13.067146       1 session.go:1079] Finish adjusting jobs' network topology spec according to hyperNodeTierNameMap map[]
I0731 07:38:13.067169       1 session.go:279] Open Session b3580fb8-d360-4c0e-a967-e2b2cdc9c611 with <0> Job and <2> Queues. HyperNodesReadyToSchedule: true
I0731 07:38:13.067580       1 enqueue.go:79] Try to enqueue PodGroup to 0 Queues
I0731 07:38:13.067601       1 allocate.go:138] Try to allocate resource to 0 Queues
I0731 07:38:13.067687       1 session.go:577] Close Session b3580fb8-d360-4c0e-a967-e2b2cdc9c611
I0731 07:38:14.068922       1 cache.go:1581] "SnapShot for scheduling" jobNum=0 QueueNum=2 NodeNum=1
I0731 07:38:14.068964       1 session.go:1036] Start adjusting jobs' network topology spec according to hyperNodeTierNameMap map[]
I0731 07:38:14.068986       1 session.go:1079] Finish adjusting jobs' network topology spec according to hyperNodeTierNameMap map[]
I0731 07:38:14.069014       1 session.go:279] Open Session a5817065-12cf-47d6-9ea5-08baae43fcbf with <0> Job and <2> Queues. HyperNodesReadyToSchedule: true
I0731 07:38:14.069472       1 enqueue.go:79] Try to enqueue PodGroup to 0 Queues
I0731 07:38:14.069513       1 allocate.go:138] Try to allocate resource to 0 Queues
I0731 07:38:14.069595       1 session.go:577] Close Session a5817065-12cf-47d6-9ea5-08baae43fcbf
I0731 07:38:15.069917       1 cache.go:1581] "SnapShot for scheduling" jobNum=0 QueueNum=2 NodeNum=1
I0731 07:38:15.069962       1 session.go:1036] Start adjusting jobs' network topology spec according to hyperNodeTierNameMap map[]
I0731 07:38:15.069986       1 session.go:1079] Finish adjusting jobs' network topology spec according to hyperNodeTierNameMap map[]
I0731 07:38:15.070011       1 session.go:279] Open Session 775596e1-49e9-4a87-a115-7dbd9b365c7f with <0> Job and <2> Queues. HyperNodesReadyToSchedule: true
I0731 07:38:15.070453       1 enqueue.go:79] Try to enqueue PodGroup to 0 Queues
I0731 07:38:15.070475       1 allocate.go:138] Try to allocate resource to 0 Queues
I0731 07:38:15.070545       1 session.go:577] Close Session 775596e1-49e9-4a87-a115-7dbd9b365c7f
I0731 07:38:16.071353       1 cache.go:1581] "SnapShot for scheduling" jobNum=0 QueueNum=2 NodeNum=1
I0731 07:38:16.071397       1 session.go:1036] Start adjusting jobs' network topology spec according to hyperNodeTierNameMap map[]
I0731 07:38:16.071423       1 session.go:1079] Finish adjusting jobs' network topology spec according to hyperNodeTierNameMap map[]
I0731 07:38:16.071448       1 session.go:279] Open Session e38a877a-7400-42d4-a697-4941ce339e9f with <0> Job and <2> Queues. HyperNodesReadyToSchedule: true
I0731 07:38:16.071941       1 enqueue.go:79] Try to enqueue PodGroup to 0 Queues
I0731 07:38:16.071963       1 allocate.go:138] Try to allocate resource to 0 Queues
I0731 07:38:16.072040       1 session.go:577] Close Session e38a877a-7400-42d4-a697-4941ce339e9f
I0731 07:38:16.489918       1 cache.go:1771] The metrics type is not set in the volcano scheduler configmap file. As a result, the CPU and memory load information of the node is not collected.
I0731 07:38:17.072663       1 cache.go:1581] "SnapShot for scheduling" jobNum=0 QueueNum=2 NodeNum=1
I0731 07:38:17.072701       1 session.go:1036] Start adjusting jobs' network topology spec according to hyperNodeTierNameMap map[]
I0731 07:38:17.072724       1 session.go:1079] Finish adjusting jobs' network topology spec according to hyperNodeTierNameMap map[]
I0731 07:38:17.072748       1 session.go:279] Open Session 1dd2bdcb-2b17-41f3-bc10-57033800b4ae with <0> Job and <2> Queues. HyperNodesReadyToSchedule: true
I0731 07:38:17.073190       1 enqueue.go:79] Try to enqueue PodGroup to 0 Queues
I0731 07:38:17.073212       1 allocate.go:138] Try to allocate resource to 0 Queues
I0731 07:38:17.073286       1 session.go:577] Close Session 1dd2bdcb-2b17-41f3-bc10-57033800b4ae
I0731 07:38:18.074599       1 cache.go:1581] "SnapShot for scheduling" jobNum=0 QueueNum=2 NodeNum=1
I0731 07:38:18.074641       1 session.go:1036] Start adjusting jobs' network topology spec according to hyperNodeTierNameMap map[]
I0731 07:38:18.074664       1 session.go:1079] Finish adjusting jobs' network topology spec according to hyperNodeTierNameMap map[]
I0731 07:38:18.074689       1 session.go:279] Open Session 791373af-9b7b-470b-b895-f0c4cb0659ed with <0> Job and <2> Queues. HyperNodesReadyToSchedule: true
I0731 07:38:18.075155       1 enqueue.go:79] Try to enqueue PodGroup to 0 Queues
I0731 07:38:18.075177       1 allocate.go:138] Try to allocate resource to 0 Queues
I0731 07:38:18.075251       1 session.go:577] Close Session 791373af-9b7b-470b-b895-f0c4cb0659ed
I0731 07:38:19.076285       1 cache.go:1581] "SnapShot for scheduling" jobNum=0 QueueNum=2 NodeNum=1
I0731 07:38:19.076314       1 session.go:1036] Start adjusting jobs' network topology spec according to hyperNodeTierNameMap map[]
I0731 07:38:19.076331       1 session.go:1079] Finish adjusting jobs' network topology spec according to hyperNodeTierNameMap map[]
I0731 07:38:19.076353       1 session.go:279] Open Session 3de3ca64-f5c6-4509-92f2-67dc7d34f2cd with <0> Job and <2> Queues. HyperNodesReadyToSchedule: true
I0731 07:38:19.076698       1 enqueue.go:79] Try to enqueue PodGroup to 0 Queues
I0731 07:38:19.076718       1 allocate.go:138] Try to allocate resource to 0 Queues
I0731 07:38:19.076771       1 session.go:577] Close Session 3de3ca64-f5c6-4509-92f2-67dc7d34f2cd
I0731 07:38:20.077304       1 cache.go:1581] "SnapShot for scheduling" jobNum=0 QueueNum=2 NodeNum=1
I0731 07:38:20.077327       1 session.go:1036] Start adjusting jobs' network topology spec according to hyperNodeTierNameMap map[]
I0731 07:38:20.077343       1 session.go:1079] Finish adjusting jobs' network topology spec according to hyperNodeTierNameMap map[]
I0731 07:38:20.077364       1 session.go:279] Open Session 272c465e-3c25-436b-b4ba-e2b35bdfe47a with <0> Job and <2> Queues. HyperNodesReadyToSchedule: true
I0731 07:38:20.077675       1 enqueue.go:79] Try to enqueue PodGroup to 0 Queues
I0731 07:38:20.077696       1 allocate.go:138] Try to allocate resource to 0 Queues
I0731 07:38:20.077745       1 session.go:577] Close Session 272c465e-3c25-436b-b4ba-e2b35bdfe47a
I0731 07:38:21.078347       1 cache.go:1581] "SnapShot for scheduling" jobNum=0 QueueNum=2 NodeNum=1
I0731 07:38:21.078375       1 session.go:1036] Start adjusting jobs' network topology spec according to hyperNodeTierNameMap map[]
I0731 07:38:21.078392       1 session.go:1079] Finish adjusting jobs' network topology spec according to hyperNodeTierNameMap map[]
I0731 07:38:21.078414       1 session.go:279] Open Session fdbf65ae-a54e-4a8a-b5ed-ab38f3ec7fa6 with <0> Job and <2> Queues. HyperNodesReadyToSchedule: true
I0731 07:38:21.078746       1 enqueue.go:79] Try to enqueue PodGroup to 0 Queues
I0731 07:38:21.078764       1 allocate.go:138] Try to allocate resource to 0 Queues
I0731 07:38:21.078815       1 session.go:577] Close Session fdbf65ae-a54e-4a8a-b5ed-ab38f3ec7fa6
I0731 07:38:22.080205       1 cache.go:1581] "SnapShot for scheduling" jobNum=0 QueueNum=2 NodeNum=1
I0731 07:38:22.080252       1 session.go:1036] Start adjusting jobs' network topology spec according to hyperNodeTierNameMap map[]
I0731 07:38:22.080277       1 session.go:1079] Finish adjusting jobs' network topology spec according to hyperNodeTierNameMap map[]
I0731 07:38:22.080300       1 session.go:279] Open Session af09a511-6153-4d98-87f9-bfa44f5483d2 with <0> Job and <2> Queues. HyperNodesReadyToSchedule: true
I0731 07:38:22.080732       1 enqueue.go:79] Try to enqueue PodGroup to 0 Queues
I0731 07:38:22.080753       1 allocate.go:138] Try to allocate resource to 0 Queues
I0731 07:38:22.080826       1 session.go:577] Close Session af09a511-6153-4d98-87f9-bfa44f5483d2
I0731 07:38:23.082024       1 cache.go:1581] "SnapShot for scheduling" jobNum=0 QueueNum=2 NodeNum=1
I0731 07:38:23.082067       1 session.go:1036] Start adjusting jobs' network topology spec according to hyperNodeTierNameMap map[]
I0731 07:38:23.082092       1 session.go:1079] Finish adjusting jobs' network topology spec according to hyperNodeTierNameMap map[]
I0731 07:38:23.082116       1 session.go:279] Open Session c6a2132a-8990-43ba-873d-040e4ae4f04e with <0> Job and <2> Queues. HyperNodesReadyToSchedule: true
I0731 07:38:23.082541       1 enqueue.go:79] Try to enqueue PodGroup to 0 Queues
I0731 07:38:23.082598       1 allocate.go:138] Try to allocate resource to 0 Queues
I0731 07:38:23.082675       1 session.go:577] Close Session c6a2132a-8990-43ba-873d-040e4ae4f04e
I0731 07:38:24.083928       1 cache.go:1581] "SnapShot for scheduling" jobNum=0 QueueNum=2 NodeNum=1
I0731 07:38:24.083959       1 session.go:1036] Start adjusting jobs' network topology spec according to hyperNodeTierNameMap map[]
I0731 07:38:24.083973       1 session.go:1079] Finish adjusting jobs' network topology spec according to hyperNodeTierNameMap map[]
I0731 07:38:24.083990       1 session.go:279] Open Session 454651be-ed7a-4b67-a5d8-5b9119986f0d with <0> Job and <2> Queues. HyperNodesReadyToSchedule: true
I0731 07:38:24.084296       1 enqueue.go:79] Try to enqueue PodGroup to 0 Queues
I0731 07:38:24.084310       1 allocate.go:138] Try to allocate resource to 0 Queues
I0731 07:38:24.084358       1 session.go:577] Close Session 454651be-ed7a-4b67-a5d8-5b9119986f0d
I0731 07:38:25.085101       1 cache.go:1581] "SnapShot for scheduling" jobNum=0 QueueNum=2 NodeNum=1
I0731 07:38:25.085147       1 session.go:1036] Start adjusting jobs' network topology spec according to hyperNodeTierNameMap map[]
I0731 07:38:25.085170       1 session.go:1079] Finish adjusting jobs' network topology spec according to hyperNodeTierNameMap map[]
I0731 07:38:25.085194       1 session.go:279] Open Session 78624664-2874-4c3a-ac63-9d0e465ce4d0 with <0> Job and <2> Queues. HyperNodesReadyToSchedule: true
I0731 07:38:25.085631       1 enqueue.go:79] Try to enqueue PodGroup to 0 Queues
I0731 07:38:25.085653       1 allocate.go:138] Try to allocate resource to 0 Queues
I0731 07:38:25.085731       1 session.go:577] Close Session 78624664-2874-4c3a-ac63-9d0e465ce4d0
I0731 07:38:26.086375       1 cache.go:1581] "SnapShot for scheduling" jobNum=0 QueueNum=2 NodeNum=1
I0731 07:38:26.086415       1 session.go:1036] Start adjusting jobs' network topology spec according to hyperNodeTierNameMap map[]
I0731 07:38:26.086437       1 session.go:1079] Finish adjusting jobs' network topology spec according to hyperNodeTierNameMap map[]
I0731 07:38:26.086461       1 session.go:279] Open Session 4863325c-242f-4269-9ed7-4897d85a3c11 with <0> Job and <2> Queues. HyperNodesReadyToSchedule: true
I0731 07:38:26.086908       1 enqueue.go:79] Try to enqueue PodGroup to 0 Queues
I0731 07:38:26.086930       1 allocate.go:138] Try to allocate resource to 0 Queues
I0731 07:38:26.086999       1 session.go:577] Close Session 4863325c-242f-4269-9ed7-4897d85a3c11
I0731 07:38:27.087878       1 cache.go:1581] "SnapShot for scheduling" jobNum=0 QueueNum=2 NodeNum=1
I0731 07:38:27.087922       1 session.go:1036] Start adjusting jobs' network topology spec according to hyperNodeTierNameMap map[]
I0731 07:38:27.087944       1 session.go:1079] Finish adjusting jobs' network topology spec according to hyperNodeTierNameMap map[]
I0731 07:38:27.087967       1 session.go:279] Open Session d4a17885-2517-4f9c-b615-00fd5e216929 with <0> Job and <2> Queues. HyperNodesReadyToSchedule: true
I0731 07:38:27.088393       1 enqueue.go:79] Try to enqueue PodGroup to 0 Queues
I0731 07:38:27.088416       1 allocate.go:138] Try to allocate resource to 0 Queues
I0731 07:38:27.088491       1 session.go:577] Close Session d4a17885-2517-4f9c-b615-00fd5e216929
I0731 07:38:28.089172       1 cache.go:1581] "SnapShot for scheduling" jobNum=0 QueueNum=2 NodeNum=1
I0731 07:38:28.089235       1 session.go:1036] Start adjusting jobs' network topology spec according to hyperNodeTierNameMap map[]
I0731 07:38:28.089263       1 session.go:1079] Finish adjusting jobs' network topology spec according to hyperNodeTierNameMap map[]
I0731 07:38:28.089293       1 session.go:279] Open Session ff3a0ad1-6a84-472b-80ba-f47ecec101dc with <0> Job and <2> Queues. HyperNodesReadyToSchedule: true
I0731 07:38:28.089825       1 enqueue.go:79] Try to enqueue PodGroup to 0 Queues
I0731 07:38:28.089852       1 allocate.go:138] Try to allocate resource to 0 Queues
I0731 07:38:28.089944       1 session.go:577] Close Session ff3a0ad1-6a84-472b-80ba-f47ecec101dc
I0731 07:38:29.090473       1 cache.go:1581] "SnapShot for scheduling" jobNum=0 QueueNum=2 NodeNum=1
I0731 07:38:29.090506       1 session.go:1036] Start adjusting jobs' network topology spec according to hyperNodeTierNameMap map[]
I0731 07:38:29.090524       1 session.go:1079] Finish adjusting jobs' network topology spec according to hyperNodeTierNameMap map[]
I0731 07:38:29.090546       1 session.go:279] Open Session 7f6ecbc0-3ab7-43da-bb7c-746313d17f2e with <0> Job and <2> Queues. HyperNodesReadyToSchedule: true
I0731 07:38:29.090970       1 enqueue.go:79] Try to enqueue PodGroup to 0 Queues
I0731 07:38:29.090990       1 allocate.go:138] Try to allocate resource to 0 Queues
I0731 07:38:29.091043       1 session.go:577] Close Session 7f6ecbc0-3ab7-43da-bb7c-746313d17f2e
I0731 07:38:30.092176       1 cache.go:1581] "SnapShot for scheduling" jobNum=0 QueueNum=2 NodeNum=1
I0731 07:38:30.092201       1 session.go:1036] Start adjusting jobs' network topology spec according to hyperNodeTierNameMap map[]
I0731 07:38:30.092217       1 session.go:1079] Finish adjusting jobs' network topology spec according to hyperNodeTierNameMap map[]
I0731 07:38:30.092237       1 session.go:279] Open Session cf6a2d1b-b6e0-49c1-ab17-fb537742df4c with <0> Job and <2> Queues. HyperNodesReadyToSchedule: true
I0731 07:38:30.092562       1 enqueue.go:79] Try to enqueue PodGroup to 0 Queues
I0731 07:38:30.092579       1 allocate.go:138] Try to allocate resource to 0 Queues
I0731 07:38:30.092625       1 session.go:577] Close Session cf6a2d1b-b6e0-49c1-ab17-fb537742df4c
I0731 07:38:31.093133       1 cache.go:1581] "SnapShot for scheduling" jobNum=0 QueueNum=2 NodeNum=1
I0731 07:38:31.093156       1 session.go:1036] Start adjusting jobs' network topology spec according to hyperNodeTierNameMap map[]
I0731 07:38:31.093169       1 session.go:1079] Finish adjusting jobs' network topology spec according to hyperNodeTierNameMap map[]
I0731 07:38:31.093189       1 session.go:279] Open Session 44f4c27c-0c1e-45de-8201-9a8e3a21a9ae with <0> Job and <2> Queues. HyperNodesReadyToSchedule: true
I0731 07:38:31.093479       1 enqueue.go:79] Try to enqueue PodGroup to 0 Queues
I0731 07:38:31.093496       1 allocate.go:138] Try to allocate resource to 0 Queues
I0731 07:38:31.093540       1 session.go:577] Close Session 44f4c27c-0c1e-45de-8201-9a8e3a21a9ae
I0731 07:38:32.095063       1 cache.go:1581] "SnapShot for scheduling" jobNum=0 QueueNum=2 NodeNum=1
I0731 07:38:32.095124       1 session.go:1036] Start adjusting jobs' network topology spec according to hyperNodeTierNameMap map[]
I0731 07:38:32.095147       1 session.go:1079] Finish adjusting jobs' network topology spec according to hyperNodeTierNameMap map[]
I0731 07:38:32.095172       1 session.go:279] Open Session 7c4695a2-084d-46cd-8f63-55447c2e5bae with <0> Job and <2> Queues. HyperNodesReadyToSchedule: true
I0731 07:38:32.095670       1 enqueue.go:79] Try to enqueue PodGroup to 0 Queues
I0731 07:38:32.095695       1 allocate.go:138] Try to allocate resource to 0 Queues
I0731 07:38:32.095772       1 session.go:577] Close Session 7c4695a2-084d-46cd-8f63-55447c2e5bae
I0731 07:38:33.096283       1 cache.go:1581] "SnapShot for scheduling" jobNum=0 QueueNum=2 NodeNum=1
I0731 07:38:33.096319       1 session.go:1036] Start adjusting jobs' network topology spec according to hyperNodeTierNameMap map[]
I0731 07:38:33.096342       1 session.go:1079] Finish adjusting jobs' network topology spec according to hyperNodeTierNameMap map[]
I0731 07:38:33.096365       1 session.go:279] Open Session 225253f8-e49b-418a-8ae2-f50f3ade6d29 with <0> Job and <2> Queues. HyperNodesReadyToSchedule: true
I0731 07:38:33.096792       1 enqueue.go:79] Try to enqueue PodGroup to 0 Queues
I0731 07:38:33.096813       1 allocate.go:138] Try to allocate resource to 0 Queues
I0731 07:38:33.096886       1 session.go:577] Close Session 225253f8-e49b-418a-8ae2-f50f3ade6d29
I0731 07:38:34.097399       1 cache.go:1581] "SnapShot for scheduling" jobNum=0 QueueNum=2 NodeNum=1
I0731 07:38:34.097447       1 session.go:1036] Start adjusting jobs' network topology spec according to hyperNodeTierNameMap map[]
I0731 07:38:34.097474       1 session.go:1079] Finish adjusting jobs' network topology spec according to hyperNodeTierNameMap map[]
I0731 07:38:34.097498       1 session.go:279] Open Session 3ebe90f9-8e88-4772-8405-713f7034a57e with <0> Job and <2> Queues. HyperNodesReadyToSchedule: true
I0731 07:38:34.097968       1 enqueue.go:79] Try to enqueue PodGroup to 0 Queues
I0731 07:38:34.097992       1 allocate.go:138] Try to allocate resource to 0 Queues
I0731 07:38:34.098070       1 session.go:577] Close Session 3ebe90f9-8e88-4772-8405-713f7034a57e
I0731 07:38:35.098420       1 cache.go:1581] "SnapShot for scheduling" jobNum=0 QueueNum=2 NodeNum=1
I0731 07:38:35.098464       1 session.go:1036] Start adjusting jobs' network topology spec according to hyperNodeTierNameMap map[]
I0731 07:38:35.098487       1 session.go:1079] Finish adjusting jobs' network topology spec according to hyperNodeTierNameMap map[]
I0731 07:38:35.098512       1 session.go:279] Open Session 852dd83c-8a6c-462c-b460-d2e09bc23d0d with <0> Job and <2> Queues. HyperNodesReadyToSchedule: true
I0731 07:38:35.098952       1 enqueue.go:79] Try to enqueue PodGroup to 0 Queues
I0731 07:38:35.098975       1 allocate.go:138] Try to allocate resource to 0 Queues
I0731 07:38:35.099052       1 session.go:577] Close Session 852dd83c-8a6c-462c-b460-d2e09bc23d0d
I0731 07:38:36.099469       1 cache.go:1581] "SnapShot for scheduling" jobNum=0 QueueNum=2 NodeNum=1
I0731 07:38:36.099513       1 session.go:1036] Start adjusting jobs' network topology spec according to hyperNodeTierNameMap map[]
I0731 07:38:36.099536       1 session.go:1079] Finish adjusting jobs' network topology spec according to hyperNodeTierNameMap map[]
I0731 07:38:36.099561       1 session.go:279] Open Session 40d93f31-dc79-4c17-94bc-f9b6d3a64ba9 with <0> Job and <2> Queues. HyperNodesReadyToSchedule: true
I0731 07:38:36.100121       1 enqueue.go:79] Try to enqueue PodGroup to 0 Queues
I0731 07:38:36.100144       1 allocate.go:138] Try to allocate resource to 0 Queues
I0731 07:38:36.100223       1 session.go:577] Close Session 40d93f31-dc79-4c17-94bc-f9b6d3a64ba9
I0731 07:38:37.101180       1 cache.go:1581] "SnapShot for scheduling" jobNum=0 QueueNum=2 NodeNum=1
I0731 07:38:37.101222       1 session.go:1036] Start adjusting jobs' network topology spec according to hyperNodeTierNameMap map[]
I0731 07:38:37.101247       1 session.go:1079] Finish adjusting jobs' network topology spec according to hyperNodeTierNameMap map[]
I0731 07:38:37.101272       1 session.go:279] Open Session 069ab609-c050-4670-9c3e-2d44cee26b20 with <0> Job and <2> Queues. HyperNodesReadyToSchedule: true
I0731 07:38:37.101728       1 enqueue.go:79] Try to enqueue PodGroup to 0 Queues
I0731 07:38:37.101749       1 allocate.go:138] Try to allocate resource to 0 Queues
I0731 07:38:37.101822       1 session.go:577] Close Session 069ab609-c050-4670-9c3e-2d44cee26b20
I0731 07:38:38.102947       1 cache.go:1581] "SnapShot for scheduling" jobNum=0 QueueNum=2 NodeNum=1
I0731 07:38:38.102993       1 session.go:1036] Start adjusting jobs' network topology spec according to hyperNodeTierNameMap map[]
I0731 07:38:38.103015       1 session.go:1079] Finish adjusting jobs' network topology spec according to hyperNodeTierNameMap map[]
I0731 07:38:38.103040       1 session.go:279] Open Session 87d57899-926f-436a-8b13-b59d81660cda with <0> Job and <2> Queues. HyperNodesReadyToSchedule: true
I0731 07:38:38.103486       1 enqueue.go:79] Try to enqueue PodGroup to 0 Queues
I0731 07:38:38.103506       1 allocate.go:138] Try to allocate resource to 0 Queues
I0731 07:38:38.103573       1 session.go:577] Close Session 87d57899-926f-436a-8b13-b59d81660cda
